Workbook

Sheet Read me
G4: European Commission
G6: Directorate-General for Economic and Financial Affairs
G7: Unit C2 - Sustainability of public finances
G8: ECFIN-Secretariat-C2@ec.europa.eu
C16: FILE DESCRIPTION
C18: Data reported in this file are based on the European Commission (EC) 2026 spring forecast (SF 2026) and macroeconomic and budgetary projections from the joint EC-EPC Ageing Report 2024 (AR 2024) as well as from updated projections endorsed by the EPC in case of Czechia.
C22: This file contains a simplified version of the EC model used to calculate the general governement debt ratio dynamics for EU countries under different scenarios. A detailed description of the EC's general governement debt projections can be found in the "Debt Sustainability Monitor 2023" (DSM, March 2024).
C27: HOW TO USE THIS TOOL TO CALCULATE NEW DEBT PROJECTIONS
C29: This tool can be used to calculate debt projections under different macroeconomic and structural primary balance adjustment assumptions. Debt projections for each scenario will update automatically with changes in the macroeconomic assumptions or the adjustment parameters. The fulfilment of DSA-based criteria, the safeguards and the benchmark will be automatically calculated in the sheet "Criteria results". Formulas are fully visible. To assess the impact of alternative fiscal paths or to check the robustness of underlying macroeconomic assumptions, the user can modify the content of key cells in the sheets "Criteria results" and "Input data" (see below). Note that, for a proper functioning of the file, you should make sure that Excel is in "Automatic" computation mode, i.e. in the File menu, Option tab, click on "Formulas", "Calculation Options" and "Automatic".
C31: The spreadsheet is composed of the following elements:
D33: The grey sheet "Criteria results" contains three types of cells identified by different colours:
F34: Cells with a yellow background and a red frame can be modified to see the impact of a different duration or pace of adjustment.
F35: Cells with a white or pale red (in case the deficit resilience safeguard is binding) background provide results obtained with the adjustment chosen in the yellow cells. To replicate the Commission's calculations, the underlying formulas should not be modified.
F37: Cells with a pale blue background correspond to the Commission's prior guidance provided to the Member State. Those are hard numbers that do not depend on the adjustment chosen in the file.
D39: "Criteria results" contains five tables. Table 1 "Adjustment input data": the user can set the duration of the plan in cell F5 (4 years without extension or 7 years with extension), the yearly adjustment pace under the scenario that does not take into account the deficit resilience safeguard (F7) and for the scenario that automatically applies that safeguard (F6). Note that the country cell (F4) cannot be changed.
D40: The adjustement in F7 needs to be selected first so that the message on line 13 signals that the two DSA-based criteria are fulfilled. As a second step, the adjustment in F6 can be selected (and cannot be lower than in F7) so that line 12 reports compliance with the requirements.
D41: Table 2 "DSA-based criteria and deficit resilience safeguard" reports whether the chosen adjustment fulfils the DSA-based criteria (cells H12:I13) and whether the deficit resillience safeguard is binding.
D42: Table 3 "Main fiscal variables with automatic deficit resilience safeguard" reports the annual adjustment over the adjustment period, in terms of change in SPB (line 18), level of the structural balance (line 19) and SPB level at the end of the adjustment (line 20). This table reports the results for the scenario that automatically applies the deficit resillience safeguard. For this reason, the SB is highlighted in red if it is lower than -1.5% of GDP.
D43: Table 4 "Main fiscal variables without automatic deficit resilience safeguard" reports the annual adjustment over the adjustment period, in terms of change in SPB (line 25), level of the structural balance (line 26) and SPB level at the end of the adjustment (line 27). This table reports the results for the scenario without the deficit resillience safeguard.
D44: Table 5 "Technical information" reports the SPB level at the end of the adjustment period that fulfils the DSA-based criteria and takes into account the deficit resilience safeguard, both without and with extension.
D46: The sheet "Input data" in light blue presents the input data, including fiscal and GDP growth assumptions as well as additional fiscal parameters. Unless stated otherwise below, the user can change all values in this tab.
D47: Coloured cells indicate data sources as follows (this colour-coding holds in the other spreadsheets):
F48: Cells in light grey indicate Commission forecast (available in the AMECO database)
F49: Cells in light blue indicate values from the Ageing Report 2024
F50: Cells in light orange provide parameters needed to compute the decomposition of government debt according to its maturity structure (i.e. short-term and long-term debt, maturing, rolled-over and non-maturing debt). These are fixed shares which the user cannot change.
F51: Cells in dark orange indicate financial market prices.
D52: Non coloured parameters in cells C50:C70 were calibrated based on different data sources. Data sources are given in corresponding cells of column E.
C54: The next spreadsheets present the no-fiscal-policy-change baseline and the adjustment scenario, with and without the impact of the deficit resilience safeguard. Each deterministic projection provides a single path for debt until 10 years after the end of the adjustment period under certain assumptions for budgetary, macroeconomic and financial variables.
D56: The sheet in blue provides, as a reference, the baseline no-fiscal-policy-change scenario. The background colour coding is the same as in the sheet "Input data".
D58: The sheet in orange presents the scenario that automatically corrects the yearly adjustment path to account for the deficit resillience safeguard.
D60: The sheet in green presents the adjustment scenarios without the deficit resilience safeguard. This scenario is computed automatically based on the yearly adjustment path set in "Criteria results" (see above).
C62: Within the orange sheet and each green sheet, the background of the SPB line has three colours. Each colour corresponds to a specific period of the projections:
E63: Light grey indicates the pre-plan period, corresponding to the EC forecast
E64: Mild grey indicates the period during which the SPB adjusts according to the path set in sheet "Criteria results"
E65: Dark grey indicates the period in which the SPB, net of changes in cost of ageing, remains constant at its value of end of adjustment.
C68: WHERE ARE THE MAIN RESULTS LOCATED?
C69: The fullfilment of the criteria is checked in the sheet "Criteria results". Debt projections can be found in line 57 of each scenario.
D71: The 'FASTOP reporting' sheet in violet provides help for preparing reporting tables. It readily provides all the tables foreseen by the guidance notice on the "Information Requirements for the Medium-Term Fiscal-Structural Plans" once the parameters are set in the rest of this file. This sheet is meant to be an assistance. The need for a thorough scrutiny of the figures before submitting such tables remains.

Sheet Criteria results
U2: 4 | V2: -1.5
D3: Table 1 - Adjustment input data | U3: 7 | V3: -1.48
D4: Country | F4: CZ | V4: -1.46
D5: Number of years of adjustment | F5: 4 | V5: -1.44
C6: 2. | D6: Annual adjustment (with safeguard) | F6: 0.46 | V6: -1.42
C7: 1. | D7: Annual adjustment (without safeguard) | F7: 0.46 | V7: -1.4
V8: -1.38
H9: Table 2 - DSA-based criteria and deficit resilience safeguard | V9: -1.36
H10: DSA-based criteria | J10: Deficit resilience safeguard | V10: -1.34
H11: Deficit below 3% of GDP | I11: ="Debt below 60% of GDP in T+"&10+F5 -> Debt below 60% of GDP in T+14 | V11: -1.32
C12: 2. | D12: Adjustment scenario with automatic deficit resilience safeguard * (sheet "Adjustment scenario") | H12: =IF(MIN(OFFSET('Adjustment scenario'!$D$77,0,$F$5,1,11))>-3,"ok","Not met") -> ok | I12: =IF(OFFSET('Adjustment scenario'!$D$57,0,$F$5+10,1,1)<60,"ok","Not met") -> ok | J12: =IF(AND($F$5=4,COUNTIF(G18:J18,">" & F6)=0),"Not binding",IF(AND($F$5=7,COUNTIF(G18:M18,">" & F6)=0),"Not binding","Binding")) -> Not binding | K12: =IF(OR($H$13="Not met",$I$13="Not met"),"Please adjust cell F7 so that both DSA-based criteria are met", IF($F$6<$F$7,"The adjustment in F6 cannot be lower than in F7", IF(AND($H$12="ok",$I$12="ok",$H$13="ok",$I$13="ok",$F$6>=$F$7, OR(AND($F$5=4,$G$18>=$H$18,$H$18>=$I$18,$I$18>=$J$18,OR($J$18>=0.4,$J$19>-1.5)), AND($F$5=7,$G$18>=$H$18,$H$18>=$I$18,$I$18>=$J$18,$J$18>=$K$18,$K$18>=$L$18,$L$18>=$M$18,OR($M$18>=0.25,$M$19>-1.5)))), "OK"&CHAR(10)&"The adjustment in F6 fulfills all requirements including the deficit resilience safeguard", "NOT OK"&CHAR(10)&"The adjustment in F6 does not fulfill all requirements"))) -> OK The adjustment in F6 fulfills all requirements including the deficit resilience safeguard | V12: -1.3
C13: 1. | D13: Adjustment scenario without deficit resilience safeguard (sheet "Adjust. no safeguard") | H13: =IF(MIN(OFFSET('Adjust. no safeguard'!$D$77,0,$F$5,1,11))>-3,"ok","Not met") -> ok | I13: =IF(OFFSET('Adjust. no safeguard'!$D$57,0,$F$5+10,1,1)<60,"ok","Not met") -> ok | K13: =IF(AND($H$13="ok",$I$13="ok"), "OK"&CHAR(10)&"The adjustment in F7 ensures that the debt and deficit remain"&CHAR(10)&"below the Treaty reference values over the medium term", "NOT OK"&CHAR(10)&"The adjustment in F7 does not ensure that the debt and deficit remain"&CHAR(10)&"below the Treaty reference values over the medium term") -> OK The adjustment in F7 ensures that the debt and deficit remain below the Treaty reference values over the medium term | V13: -1.28
D14: * Under a plan without (with) extension, an adjustment of 0.40 pps (0.25 pps) of GDP in SPB terms is applied if the structural deficit in the previous year exceeds 1.5% of GDP. | V14: -1.26
V15: -1.24
G16: Table 3 - Main fiscal variables with automatic deficit resilience safeguard * | V16: -1.22
G17: ='Input data'!$C$5+1 -> 2027 | H17: =G17+1 -> 2028 | I17: =H17+1 -> 2029 | J17: =I17+1 -> 2030 | K17: =J17+1 -> 2031 | L17: =K17+1 -> 2032 | M17: =L17+1 -> 2033 | V17: -1.2
D18: Annual adjustment (change in SPB) | G18: ='Adjustment scenario'!E12-'Adjustment scenario'!D12 -> 0.46 | H18: ='Adjustment scenario'!F12-'Adjustment scenario'!E12 -> 0.46 | I18: ='Adjustment scenario'!G12-'Adjustment scenario'!F12 -> 0.46 | J18: ='Adjustment scenario'!H12-'Adjustment scenario'!G12 -> 0.46 | K18: ='Adjustment scenario'!I12-'Adjustment scenario'!H12 -> 0 | L18: ='Adjustment scenario'!J12-'Adjustment scenario'!I12 -> 0 | M18: ='Adjustment scenario'!K12-'Adjustment scenario'!J12 -> 0 | V18: -1.18
D19: Structural balance | G19: ='Adjustment scenario'!E78 -> -2.1823295 | H19: ='Adjustment scenario'!F78 -> -1.8742338 | I19: ='Adjustment scenario'!G78 -> -1.5129912 | J19: ='Adjustment scenario'!H78 -> -1.134607 | K19: ='Adjustment scenario'!I78 -> -1.3068405 | L19: ='Adjustment scenario'!J78 -> -1.3831522 | M19: ='Adjustment scenario'!K78 -> -1.4587376 | V19: -1.16
D20: SPB at the end of the adjustment | J20: =IF(F5=4,'Adjustment scenario'!H12,"") -> 0.507241 | M20: =IF(F5=7,'Adjustment scenario'!K12,"") | V20: -1.14
D21: * The structural balance is flagged in red if it is below -1.5% of GDP. | V21: -1.12
V22: -1.1
G23: Table 4 - Main fiscal variables without automatic deficit resilience safeguard | V23: -1.08
G24: ='Input data'!$C$5+1 -> 2027 | H24: =G24+1 -> 2028 | I24: =H24+1 -> 2029 | J24: =I24+1 -> 2030 | K24: =J24+1 -> 2031 | L24: =K24+1 -> 2032 | M24: =L24+1 -> 2033 | V24: -1.06
D25: Annual adjustment (change in SPB) | G25: ='Adjust. no safeguard'!E12-'Adjust. no safeguard'!D12 -> 0.46 | H25: ='Adjust. no safeguard'!F12-'Adjust. no safeguard'!E12 -> 0.46 | I25: ='Adjust. no safeguard'!G12-'Adjust. no safeguard'!F12 -> 0.46 | J25: ='Adjust. no safeguard'!H12-'Adjust. no safeguard'!G12 -> 0.46 | K25: ='Adjust. no safeguard'!I12-'Adjust. no safeguard'!H12 -> 0 | L25: ='Adjust. no safeguard'!J12-'Adjust. no safeguard'!I12 -> 0 | M25: ='Adjust. no safeguard'!K12-'Adjust. no safeguard'!J12 -> 0 | V25: -1.04
D26: Structural balance | G26: ='Adjust. no safeguard'!E78 -> -2.1823295 | H26: ='Adjust. no safeguard'!F78 -> -1.8742338 | I26: ='Adjust. no safeguard'!G78 -> -1.5129912 | J26: ='Adjust. no safeguard'!H78 -> -1.134607 | K26: ='Adjust. no safeguard'!I78 -> -1.3068405 | L26: ='Adjust. no safeguard'!J78 -> -1.3831522 | M26: ='Adjust. no safeguard'!K78 -> -1.4587376 | V26: -1.02
D27: SPB at the end of the adjustment | J27: =IF(F5=4,'Adjust. no safeguard'!H12,"") -> 0.507241 | M27: =IF(F5=7,'Adjust. no safeguard'!K12,"") | V27: -1
V28: -0.98
V29: -0.96
V30: -0.94
G31: Table 5 - Technical information* | V31: -0.92
G32: Without extension | H32: With extension | V32: -0.9
D33: Number of years of adjustment | G33: 4 | H33: 7 | V33: -0.88
D34: SPB at the end of the adjustment | G34: 0.507241 | H34: 0.907241 | V34: -0.86
D35: * The technical information provides the structural primary balance necessary to ensure that the deficit remains below 3% of GDP and debt remains below 60% of GDP over the medium term in the absence of additional fiscal measures beyond the adjustment period. In line with the deficit resilience safeguard, and when necessary, an adjustment of 0.4 pps (0.25 pps in case of extension) in structural primary terms is applied until the structural balance is at least equal to -1.5% of GDP. Note that the SPB at the end of the adjustment period may be lower than the SPB at the beginning of the plan, indicating that the Member State does not need to adjust. | V35: -0.84
V36: -0.82
V37: -0.8
V38: -0.78
V39: -0.76
V40: -0.74
V41: -0.72
...

Sheet Prior guidance
B3: Country | D3: CZ | F3: Czechia
B6: Main budgetary, macroeconomic and financial variables
B8: Budgetary variables: initial conditions | D8: 2025 | F8: 2026
B9: Government budget balance (% of GDP) | D9: -2.147432 | F9: -2.7944635
B10: Government debt (% of GDP) | D10: 44.25023 | F10: 45.838496
B11: Net expenditure growth (%) | D11: 4.9156095 | F11: 6.3502551
B12: Structural primary balance (% of GDP) | D12: -0.5110157 | F12: -1.332759
B14: Main assumptions for a plan without extension (4 years) | D14: Assumption | F14: Period
B15: Change in the cost of ageing (pps) | D15: 0.9 | F15: 2030-2040
B16: Stock-flow adjustment (% of GDP) | D16: 0.060711421 | F16: 2027-2040 average
B17: Real GDP growth (%) | D17: 1.364418 | F17: 2027-2040 average
B18: Inflation (change in the GDP deflator, %) | D18: 2.5559991 | F18: 2027-2040 average
B19: Nominal implicit interest rate (%) | D19: 2.5559991 | F19: 2027-2040 average
B21: Main assumptions for a plan with extension (7 years) | D21: Assumption | F21: Period
B22: Change in the cost of ageing (pps) | D22: 1.2 | F22: 2033-2043
B23: Stock-flow adjustment (% of GDP) | D23: 0.049997641 | F23: 2027-2043 average
B24: Real GDP growth (%) | D24: 1.4065908 | F24: 2027-2043 average
B25: Inflation (change in the GDP deflator, %) | D25: 2.4968816 | F25: 2027-2043 average
B26: Nominal implicit interest rate (%) | D26: 4.3128754 | F26: 2027-2043 average
B31: Technical information
B33: For a plan without extension (4 years) Czechia | D33: With the deficit resilience safeguard | F33: Without the deficit resilience safeguard
B34: Minimum level for the structural primary balance in 2030 (% of GDP) | D34: 0.507241 | F34: 0.507241
B35: Difference with 2026 structural primary balance (pps) | D35: 1.84 | F35: 1.84
B37: For a plan with extension (7 years) Czechia | D37: With the deficit resilience safeguard | F37: Without the deficit resilience safeguard
B38: Minimum level for the structural primary balance in 2033 (% of GDP) | D38: 0.907241 | F38: 0.907241
B39: Difference with 2026 structural primary balance (pps) | D39: 2.24 | F39: 2.24

Sheet Input data
B3: Country | C3: CZ
B4: Base for last forecast and T+10, T+30 years | C4: 2025
B5: Last year before the adjustment | C5: 2026
B6: Last year of adjustment | C6: =C5+'Criteria results'!$F$5 -> 2030
B8: Key assumptions
C9: 2025 | D9: 2026 | E9: 2027 | F9: 2028 | G9: 2029 | H9: 2030 | I9: 2031 | J9: 2032 | K9: 2033 | L9: 2034 | M9: 2035 | N9: 2036 | O9: 2037 | P9: 2038 | Q9: 2039 | R9: 2040 | S9: 2041 | T9: 2042 | U9: 2043
B10: Fiscal assumptions (% of GDP)
B11: Key fiscal variables (based on the Commission 2026 spring forecast ("SF 2026")
B12: Debt | C12: 44.25023 | D12: 45.8385
B13: Structural primary balance ('+' means 'surplus') | C13: -0.5110157 | D13: -1.332759
B14: One-off and other temporary measures | C14: -0.1168709 | D14: 0 | E14: 0 | F14: 0 | G14: 0 | H14: 0 | I14: 0 | J14: 0 | K14: 0 | L14: 0 | M14: 0 | N14: 0 | O14: 0 | P14: 0 | Q14: 0 | R14: 0 | S14: 0 | T14: 0 | U14: 0
B15: Stock-flow adjustments (without exchange rate effect) | C15: 1.388104 | D15: 0.7474777 | E15: 0.85 | F15: 0 | G15: 0 | H15: 0 | I15: 0 | J15: 0 | K15: 0 | L15: 0 | M15: 0 | N15: 0 | O15: 0 | P15: 0 | Q15: 0 | R15: 0 | S15: 0 | T15: 0 | U15: 0
B16: Stock-flow adjustment (total) | C16: 1.334119 | D16: 0.7014194 | E16: 0.8499599 | F16: 0 | G16: 0 | H16: 0 | I16: 0 | J16: 0 | K16: 0 | L16: 0 | M16: 0 | N16: 0 | O16: 0 | P16: 0 | Q16: 0 | R16: 0 | S16: 0 | T16: 0 | U16: 0
B17: Subject to an excessive deficit procedure (EDP) (0-no/1-yes) | C17: 0 | D17: 0
B19: Cost of ageing and selected public revenue (based on the Commission-Council 2024 Ageing Report ("AR 2024"))
B20: Total ageing cost (net of taxes on pensions) | C20: =(C21+C22+C23+C24-C25) -> 19.8 | D20: =(D21+D22+D23+D24-D25) -> 19.7 | E20: =(E21+E22+E23+E24-E25) -> 19.8 | F20: =(F21+F22+F23+F24-F25) -> 19.9 | G20: =(G21+G22+G23+G24-G25) -> 20 | H20: =(H21+H22+H23+H24-H25) -> 20 | I20: =(I21+I22+I23+I24-I25) -> 20.1 | J20: =(J21+J22+J23+J24-J25) -> 20.1 | ... U20: =(U21+U22+U23+U24-U25) -> 21.3
B21: of which: Public pensions expenditure | C21: 8.2 | D21: 8 | E21: 7.9 | F21: 8 | G21: 8 | H21: 8 | I21: 8 | J21: 8 | K21: 8 | L21: 8.1 | M21: 8.1 | N21: 8.2 | O21: 8.2 | P21: 8.3 | Q21: 8.3 | R21: 8.4 | S21: 8.5 | T21: 8.5 | U21: 8.6
B22: Health care expenditure | C22: 5.9 | D22: 5.9 | E22: 6 | F22: 6 | G22: 6 | H22: 6 | I22: 6.1 | J22: 6.1 | K22: 6.1 | L22: 6.2 | M22: 6.2 | N22: 6.2 | O22: 6.2 | P22: 6.3 | Q22: 6.3 | R22: 6.3 | S22: 6.3 | T22: 6.4 | U22: 6.4
B23: Long-term care expenditure | C23: 1.5 | D23: 1.5 | E23: 1.6 | F23: 1.6 | G23: 1.7 | H23: 1.7 | I23: 1.7 | J23: 1.8 | K23: 1.8 | L23: 1.9 | M23: 1.9 | N23: 1.9 | O23: 2 | P23: 2 | Q23: 2 | R23: 2 | S23: 2.1 | T23: 2.1 | U23: 2.1
B24: Education & unemployment benefits expenditure | C24: 4.2 | D24: 4.3 | E24: 4.3 | F24: 4.3 | G24: 4.3 | H24: 4.3 | I24: 4.3 | J24: 4.2 | K24: 4.2 | L24: 4.2 | M24: 4.2 | N24: 4.2 | O24: 4.2 | P24: 4.2 | Q24: 4.2 | R24: 4.2 | S24: 4.2 | T24: 4.2 | U24: 4.2
B25: Taxes on pensions | C25: 0 | D25: 0 | E25: 0 | F25: 0 | G25: 0 | H25: 0 | I25: 0 | J25: 0 | K25: 0 | L25: 0 | M25: 0 | N25: 0 | O25: 0 | P25: 0 | Q25: 0 | R25: 0 | S25: 0 | T25: 0 | U25: 0
B26: Property income | C26: 1.037865 | D26: 1.023357 | E26: 1.008848 | F26: 0.9943401 | G26: 0.9798318 | H26: 0.9653235 | I26: 0.9508152 | J26: 0.9363069 | K26: 0.9217986 | L26: 0.9072903 | M26: 0.892782 | N26: 0.8782737 | O26: 0.8637654 | P26: 0.8492571 | Q26: 0.8347487 | R26: 0.8202404 | S26: 0.8057321 | T26: 0.7912238 | U26: 0.7767155
B28: Real GDP growth assumptions (based on SF 2026 T+10 projections and AR 2024 projections)
B29: Actual GDP
B30: Growth rate | C30: 2.580467 | D30: 1.79727 | E30: 2.151977 | F30: 1.373251 | G30: 1.123538 | H30: 1.157076 | I30: 1.226085 | J30: 1.236268 | K30: 1.244196 | L30: 1.209247 | M30: 1.140828 | N30: 1.257218 | O30: 1.373611 | P30: 1.490002 | Q30: 1.519997 | R30: 1.600002 | S30: 1.600005 | T30: 1.6 | U30: 1.61
B31: Level (CZK bn) | C31: 6479.806
B32: Potential GDP
B33: Growth rate | C33: 1.560683 | D33: 1.64766 | E33: 1.492104 | F33: 1.456502 | G33: 1.234396 | H33: 1.212544 | I33: 1.226088 | J33: 1.236266 | K33: 1.2442 | L33: 1.209244 | M33: 1.140822 | N33: 1.257215 | O33: 1.373607 | P33: 1.49 | Q33: 1.52 | R33: 1.6 | S33: 1.6 | T33: 1.6 | U33: 1.61
B34: Level (CZK bn) | C34: 6515.4565
B36: Interest rates (SF 2026, %)
B37: Nominal implicit interest rate on debt | C37: 3.196961 | D37: 3.078103 | E37: 2.999835
B38: Short-term nominal interest rate | C38: 3.6 | D38: 3.649853 | E38: 4.267191
B39: Long-term nominal interest rate | C39: 4.29 | D39: 4.701964 | E39: 4.915649
D40: Bloomberg data, country-specific forward market rates.
B41: Inflation (SF 2026, %)
B42: GDP deflator (national currency) | C42: 3.512605 | D42: 2.656677 | E42: 3.068664
B44: Net primary expenditure growth (SF 2026, %)
B45: Net primary expenditure growth | C45: 4.9156095 | D45: 6.3502551
B47: Additional parameters
E48: Sources
...

Sheet Baseline NFPC
B3: Country | C3: ='Input data'!C3 -> CZ
B4: Key years
B5: ='Input data'!B5 -> Last year before the adjustment | C5: =+'Input data'!C5 -> 2026
B6: Last year of adjustment | C6: =+C5+'Criteria results'!$F$5 -> 2030
B9: Key assumptions
C10: ='Input data'!$C$5-1 -> 2025 | D10: =C10+1 -> 2026 | E10: =D10+1 -> 2027 | F10: =E10+1 -> 2028 | G10: =F10+1 -> 2029 | H10: =G10+1 -> 2030 | I10: =H10+1 -> 2031 | J10: =I10+1 -> 2032 | K10: =J10+1 -> 2033 | ... U10: =T10+1 -> 2043
B11: Fiscal assumptions (% of GDP)
B12: Structural primary balance ('+' means 'surplus') | C12: ='Input data'!C13 -> -0.5110157 | D12: ='Input data'!D13 -> -1.332759 | E12: =D12 -> -1.332759 | F12: =E12 -> -1.332759 | G12: =F12 -> -1.332759 | H12: =G12 -> -1.332759 | I12: =H12 -> -1.332759 | J12: =I12 -> -1.332759 | K12: =J12 -> -1.332759 | L12: =K12 -> -1.332759 | ... U12: =T12 -> -1.332759
B13: One-off and other temporary measures | C13: ='Input data'!C14 -> -0.1168709 | D13: ='Input data'!D14 -> 0 | E13: ='Input data'!E14 -> 0 | F13: ='Input data'!F14 -> 0 | G13: ='Input data'!G14 -> 0 | H13: ='Input data'!H14 -> 0 | I13: ='Input data'!I14 -> 0 | J13: ='Input data'!J14 -> 0 | ... U13: ='Input data'!U14 -> 0
B14: Stock flow adjustments (without exchange rate effect) | C14: ='Input data'!C15 -> 1.388104 | D14: ='Input data'!D15 -> 0.7474777 | E14: ='Input data'!E15 -> 0.85 | F14: ='Input data'!F15 -> 0 | G14: ='Input data'!G15 -> 0 | H14: ='Input data'!H15 -> 0 | I14: ='Input data'!I15 -> 0 | J14: ='Input data'!J15 -> 0 | ... U14: ='Input data'!U15 -> 0
B16: ='Input data'!B19 -> Cost of ageing and selected public revenue (based on the Commission-Council 2024 Ageing Report ("AR 2024"))
B17: Total ageing cost (net of taxes on pensions) | C17: ='Input data'!C20 -> 19.8 | D17: ='Input data'!D20 -> 19.7 | E17: ='Input data'!E20 -> 19.8 | F17: ='Input data'!F20 -> 19.9 | G17: ='Input data'!G20 -> 20 | H17: ='Input data'!H20 -> 20 | I17: ='Input data'!I20 -> 20.1 | J17: ='Input data'!J20 -> 20.1 | ... U17: ='Input data'!U20 -> 21.3
B18: ='Input data'!B26 -> Property income | C18: ='Input data'!C26 -> 1.037865 | D18: ='Input data'!D26 -> 1.023357 | E18: ='Input data'!E26 -> 1.008848 | F18: ='Input data'!F26 -> 0.9943401 | G18: ='Input data'!G26 -> 0.9798318 | H18: ='Input data'!H26 -> 0.9653235 | I18: ='Input data'!I26 -> 0.9508152 | ... U18: ='Input data'!U26 -> 0.7767155
B20: GDP growth assumptions
B21: Actual GDP (real)
B22: Level | C22: ='Input data'!C31 -> 6479.806 | D22: =C22*(D23/100+1) -> 6596.2656 | E22: =D22*(E23/100+1) -> 6738.2157 | F22: =E22*(F23/100+1) -> 6830.7484 | G22: =F22*(G23/100+1) -> 6907.4944 | H22: =G22*(H23/100+1) -> 6987.4194 | I22: =H22*(I23/100+1) -> 7073.0911 | J22: =I22*(J23/100+1) -> 7160.5334 | K22: =J22*(K23/100+1) -> 7249.6245 | ... U22: =T22*(U23/100+1) -> 8363.8374
B23: Growth rate | C23: =+'Input data'!C30 -> 2.580467 | D23: =+'Input data'!D30 -> 1.79727 | E23: =+'Input data'!E30 -> 2.151977 | F23: =+'Input data'!F30 -> 1.373251 | G23: =+'Input data'!G30 -> 1.123538 | H23: =+'Input data'!H30 -> 1.157076 | I23: =+'Input data'!I30 -> 1.226085 | J23: =+'Input data'!J30 -> 1.236268 | ... U23: =+'Input data'!U30 -> 1.61
B25: Potential GDP (real)
B26: Level | C26: ='Input data'!C34 -> 6515.4565 | D26: =+C26*(1+'Input data'!D33/100) -> 6622.8091 | E26: =+D26*(1+'Input data'!E33/100) -> 6721.6283 | F26: =+E26*(1+'Input data'!F33/100) -> 6819.529 | G26: =+F26*(1+'Input data'!G33/100) -> 6903.7089 | H26: =+G26*(1+'Input data'!H33/100) -> 6987.4195 | I26: =+H26*(1+'Input data'!I33/100) -> 7073.0914 | J26: =+I26*(1+'Input data'!J33/100) -> 7160.5336 | K26: =+J26*(1+'Input data'!K33/100) -> 7249.6249 | ... U26: =+T26*(1+'Input data'!U33/100) -> 8363.8361
B28: Output gap
B29: Output gap | C29: =100*(C22/C26-1) -> -0.54716846 | D29: =100*(D22/D26-1) -> -0.40078891 | E29: =100*(E22/E26-1) -> 0.24677703 | F29: =100*(F22/F26-1) -> 0.16451868 | G29: =100*(G22/G26-1) -> 0.054832264 | H29: =100*(H22/H26-1) -> -1.2698694e-06 | I29: =100*(I22/I26-1) -> -4.2335323e-06 | J29: =100*(J22/J26-1) -> -2.2579557e-06 | ... U29: =100*(U22/U26-1) -> 1.5501551e-05
B31: Actual GDP (nominal, national currency)
B32: Growth rate | C32: =100*((1+C23/100)*(1+C41/100)-1) -> 6.1837136 | D32: =100*((1+D23/100)*(1+D41/100)-1) -> 4.5016947 | E32: =100*((1+E23/100)*(1+E41/100)-1) -> 5.2866779 | F32: =100*((1+F23/100)*(1+F41/100)-1) -> 4.3917217 | G32: =100*((1+G23/100)*(1+G41/100)-1) -> 4.0424669 | H32: =100*((1+H23/100)*(1+H41/100)-1) -> 3.9848361 | I32: =100*((1+I23/100)*(1+I41/100)-1) -> 3.9635744 | J32: =100*((1+J23/100)*(1+J41/100)-1) -> 3.8818238 | ... U32: =100*((1+U23/100)*(1+U41/100)-1) -> 3.8494844
B34: Interest rate
B35: Nominal implicit interest rate on debt | C35: ='Input data'!C37 -> 3.196961 | D35: ='Input data'!D37 -> 3.078103 | E35: =IF(E$10<='Input data'!$C$4+2,'Input data'!E37,E96) -> 2.999835 | F35: =IF(F$10<='Input data'!$C$4+2,'Input data'!F37,F96) -> 3.2787529 | G35: =IF(G$10<='Input data'!$C$4+2,'Input data'!G37,G96) -> 3.515114 | H35: =IF(H$10<='Input data'!$C$4+2,'Input data'!H37,H96) -> 3.7446797 | I35: =IF(I$10<='Input data'!$C$4+2,'Input data'!I37,I96) -> 3.9632939 | J35: =IF(J$10<='Input data'!$C$4+2,'Input data'!J37,J96) -> 4.173594 | K35: =IF(K$10<='Input data'!$C$4+2,'Input data'!K37,K96) -> 4.3733956 | L35: =IF(L$10<='Input data'!$C$4+2,'Input data'!L37,L96) -> 4.5637138 | ... U35: =IF(U$10<='Input data'!$C$4+2,'Input data'!U37,U96) -> 5.1509376
B36: Long-term interest rate | C36: ='Input data'!C39 -> 4.29 | D36: ='Input data'!D39 -> 4.701964 | E36: =_xlfn.LET(_xlpm.lastForecast,INDEX('Input data'!$E$39:$G$39,MATCH('Input data'!$C$4+2,'Input data'!$E$9:$G$9)), _xlpm.Tplus10,'Input data'!$C$52, _xlpm.Tplus30,'Input data'!$C$54, IF(E$10<='Input data'!$C$4+2,'Input data'!E$39, IF(E$10<'Input data'!$C$4+10,_xlpm.lastForecast+(_xlpm.Tplus10-_xlpm.lastForecast)/8*(E$10-('Input data'!$C$4+2)), IF(E$10='Input data'!$C$4+10,_xlpm.Tplus10, _xlpm.Tplus10+(_xlpm.Tplus30-_xlpm.Tplus10)/20*(E$10-('Input data'!$C$4+10)))))) -> 4.915649 | F36: =_xlfn.LET(_xlpm.lastForecast,INDEX('Input data'!$E$39:$G$39,MATCH('Input data'!$C$4+2,'Input data'!$E$9:$G$9)), _xlpm.Tplus10,'Input data'!$C$52, _xlpm.Tplus30,'Input data'!$C$54, IF(F$10<='Input data'!$C$4+2,'Input data'!F$39, IF(F$10<'Input data'!$C$4+10,_xlpm.lastForecast+(_xlpm.Tplus10-_xlpm.lastForecast)/8*(F$10-('Input data'!$C$4+2)), IF(F$10='Input data'!$C$4+10,_xlpm.Tplus10, _xlpm.Tplus10+(_xlpm.Tplus30-_xlpm.Tplus10)/20*(F$10-('Input data'!$C$4+10)))))) -> 5.0370066 | G36: =_xlfn.LET(_xlpm.lastForecast,INDEX('Input data'!$E$39:$G$39,MATCH('Input data'!$C$4+2,'Input data'!$E$9:$G$9)), _xlpm.Tplus10,'Input data'!$C$52, _xlpm.Tplus30,'Input data'!$C$54, IF(G$10<='Input data'!$C$4+2,'Input data'!G$39, IF(G$10<'Input data'!$C$4+10,_xlpm.lastForecast+(_xlpm.Tplus10-_xlpm.lastForecast)/8*(G$10-('Input data'!$C$4+2)), IF(G$10='Input data'!$C$4+10,_xlpm.Tplus10, _xlpm.Tplus10+(_xlpm.Tplus30-_xlpm.Tplus10)/20*(G$10-('Input data'!$C$4+10)))))) -> 5.1583642 | H36: =_xlfn.LET(_xlpm.lastForecast,INDEX('Input data'!$E$39:$G$39,MATCH('Input data'!$C$4+2,'Input data'!$E$9:$G$9)), _xlpm.Tplus10,'Input data'!$C$52, _xlpm.Tplus30,'Input data'!$C$54, IF(H$10<='Input data'!$C$4+2,'Input data'!H$39, IF(H$10<'Input data'!$C$4+10,_xlpm.lastForecast+(_xlpm.Tplus10-_xlpm.lastForecast)/8*(H$10-('Input data'!$C$4+2)), IF(H$10='Input data'!$C$4+10,_xlpm.Tplus10, _xlpm.Tplus10+(_xlpm.Tplus30-_xlpm.Tplus10)/20*(H$10-('Input data'!$C$4+10)))))) -> 5.2797219 | I36: =_xlfn.LET(_xlpm.lastForecast,INDEX('Input data'!$E$39:$G$39,MATCH('Input data'!$C$4+2,'Input data'!$E$9:$G$9)), _xlpm.Tplus10,'Input data'!$C$52, _xlpm.Tplus30,'Input data'!$C$54, IF(I$10<='Input data'!$C$4+2,'Input data'!I$39, IF(I$10<'Input data'!$C$4+10,_xlpm.lastForecast+(_xlpm.Tplus10-_xlpm.lastForecast)/8*(I$10-('Input data'!$C$4+2)), IF(I$10='Input data'!$C$4+10,_xlpm.Tplus10, _xlpm.Tplus10+(_xlpm.Tplus30-_xlpm.Tplus10)/20*(I$10-('Input data'!$C$4+10)))))) -> 5.4010795 | J36: =_xlfn.LET(_xlpm.lastForecast,INDEX('Input data'!$E$39:$G$39,MATCH('Input data'!$C$4+2,'Input data'!$E$9:$G$9)), _xlpm.Tplus10,'Input data'!$C$52, _xlpm.Tplus30,'Input data'!$C$54, IF(J$10<='Input data'!$C$4+2,'Input data'!J$39, IF(J$10<'Input data'!$C$4+10,_xlpm.lastForecast+(_xlpm.Tplus10-_xlpm.lastForecast)/8*(J$10-('Input data'!$C$4+2)), IF(J$10='Input data'!$C$4+10,_xlpm.Tplus10, _xlpm.Tplus10+(_xlpm.Tplus30-_xlpm.Tplus10)/20*(J$10-('Input data'!$C$4+10)))))) -> 5.5224371 | K36: =_xlfn.LET(_xlpm.lastForecast,INDEX('Input data'!$E$39:$G$39,MATCH('Input data'!$C$4+2,'Input data'!$E$9:$G$9)), _xlpm.Tplus10,'Input data'!$C$52, _xlpm.Tplus30,'Input data'!$C$54, IF(K$10<='Input data'!$C$4+2,'Input data'!K$39, IF(K$10<'Input data'!$C$4+10,_xlpm.lastForecast+(_xlpm.Tplus10-_xlpm.lastForecast)/8*(K$10-('Input data'!$C$4+2)), IF(K$10='Input data'!$C$4+10,_xlpm.Tplus10, _xlpm.Tplus10+(_xlpm.Tplus30-_xlpm.Tplus10)/20*(K$10-('Input data'!$C$4+10)))))) -> 5.6437948 | L36: =_xlfn.LET(_xlpm.lastForecast,INDEX('Input data'!$E$39:$G$39,MATCH('Input data'!$C$4+2,'Input data'!$E$9:$G$9)), _xlpm.Tplus10,'Input data'!$C$52, _xlpm.Tplus30,'Input data'!$C$54, IF(L$10<='Input data'!$C$4+2,'Input data'!L$39, IF(L$10<'Input data'!$C$4+10,_xlpm.lastForecast+(_xlpm.Tplus10-_xlpm.lastForecast)/8*(L$10-('Input data'!$C$4+2)), IF(L$10='Input data'!$C$4+10,_xlpm.Tplus10, _xlpm.Tplus10+(_xlpm.Tplus30-_xlpm.Tplus10)/20*(L$10-('Input data'!$C$4+10)))))) -> 5.7651524 | ... U36: =_xlfn.LET(_xlpm.lastForecast,INDEX('Input data'!$E$39:$G$39,MATCH('Input data'!$C$4+2,'Input data'!$E$9:$G$9)), _xlpm.Tplus10,'Input data'!$C$52, _xlpm.Tplus30,'Input data'!$C$54, IF(U$10<='Input data'!$C$4+2,'Input data'!U$39, IF(U$10<'Input data'!$C$4+10,_xlpm.lastForecast+(_xlpm.Tplus10-_xlpm.lastForecast)/8*(U$10-('Input data'!$C$4+2)), IF(U$10='Input data'!$C$4+10,_xlpm.Tplus10, _xlpm.Tplus10+(_xlpm.Tplus30-_xlpm.Tplus10)/20*(U$10-('Input data'!$C$4+10)))))) -> 5.131906
B37: Short-term interest rate | C37: ='Input data'!C$38 -> 3.6 | D37: ='Input data'!D$38 -> 3.649853 | E37: =_xlfn.LET(_xlpm.lastForecast,INDEX('Input data'!$E$38:$G$38,MATCH('Input data'!$C$4+2,'Input data'!$E$9:$G$9)), _xlpm.Tplus10,'Input data'!$C$53, _xlpm.Tplus30,'Input data'!$C$55, IF(E$10<='Input data'!$C$4+2,'Input data'!E$38, IF(E$10<'Input data'!$C$4+10,_xlpm.lastForecast+(_xlpm.Tplus10-_xlpm.lastForecast)/8*(E$10-('Input data'!$C$4+2)), IF(E$10='Input data'!$C$4+10,_xlpm.Tplus10, _xlpm.Tplus10+(_xlpm.Tplus30-_xlpm.Tplus10)/20*(E$10-('Input data'!$C$4+10)))))) -> 4.267191 | F37: =_xlfn.LET(_xlpm.lastForecast,INDEX('Input data'!$E$38:$G$38,MATCH('Input data'!$C$4+2,'Input data'!$E$9:$G$9)), _xlpm.Tplus10,'Input data'!$C$53, _xlpm.Tplus30,'Input data'!$C$55, IF(F$10<='Input data'!$C$4+2,'Input data'!F$38, IF(F$10<'Input data'!$C$4+10,_xlpm.lastForecast+(_xlpm.Tplus10-_xlpm.lastForecast)/8*(F$10-('Input data'!$C$4+2)), IF(F$10='Input data'!$C$4+10,_xlpm.Tplus10, _xlpm.Tplus10+(_xlpm.Tplus30-_xlpm.Tplus10)/20*(F$10-('Input data'!$C$4+10)))))) -> 4.2826609 | G37: =_xlfn.LET(_xlpm.lastForecast,INDEX('Input data'!$E$38:$G$38,MATCH('Input data'!$C$4+2,'Input data'!$E$9:$G$9)), _xlpm.Tplus10,'Input data'!$C$53, _xlpm.Tplus30,'Input data'!$C$55, IF(G$10<='Input data'!$C$4+2,'Input data'!G$38, IF(G$10<'Input data'!$C$4+10,_xlpm.lastForecast+(_xlpm.Tplus10-_xlpm.lastForecast)/8*(G$10-('Input data'!$C$4+2)), IF(G$10='Input data'!$C$4+10,_xlpm.Tplus10, _xlpm.Tplus10+(_xlpm.Tplus30-_xlpm.Tplus10)/20*(G$10-('Input data'!$C$4+10)))))) -> 4.2981308 | H37: =_xlfn.LET(_xlpm.lastForecast,INDEX('Input data'!$E$38:$G$38,MATCH('Input data'!$C$4+2,'Input data'!$E$9:$G$9)), _xlpm.Tplus10,'Input data'!$C$53, _xlpm.Tplus30,'Input data'!$C$55, IF(H$10<='Input data'!$C$4+2,'Input data'!H$38, IF(H$10<'Input data'!$C$4+10,_xlpm.lastForecast+(_xlpm.Tplus10-_xlpm.lastForecast)/8*(H$10-('Input data'!$C$4+2)), IF(H$10='Input data'!$C$4+10,_xlpm.Tplus10, _xlpm.Tplus10+(_xlpm.Tplus30-_xlpm.Tplus10)/20*(H$10-('Input data'!$C$4+10)))))) -> 4.3136006 | I37: =_xlfn.LET(_xlpm.lastForecast,INDEX('Input data'!$E$38:$G$38,MATCH('Input data'!$C$4+2,'Input data'!$E$9:$G$9)), _xlpm.Tplus10,'Input data'!$C$53, _xlpm.Tplus30,'Input data'!$C$55, IF(I$10<='Input data'!$C$4+2,'Input data'!I$38, IF(I$10<'Input data'!$C$4+10,_xlpm.lastForecast+(_xlpm.Tplus10-_xlpm.lastForecast)/8*(I$10-('Input data'!$C$4+2)), IF(I$10='Input data'!$C$4+10,_xlpm.Tplus10, _xlpm.Tplus10+(_xlpm.Tplus30-_xlpm.Tplus10)/20*(I$10-('Input data'!$C$4+10)))))) -> 4.3290705 | J37: =_xlfn.LET(_xlpm.lastForecast,INDEX('Input data'!$E$38:$G$38,MATCH('Input data'!$C$4+2,'Input data'!$E$9:$G$9)), _xlpm.Tplus10,'Input data'!$C$53, _xlpm.Tplus30,'Input data'!$C$55, IF(J$10<='Input data'!$C$4+2,'Input data'!J$38, IF(J$10<'Input data'!$C$4+10,_xlpm.lastForecast+(_xlpm.Tplus10-_xlpm.lastForecast)/8*(J$10-('Input data'!$C$4+2)), IF(J$10='Input data'!$C$4+10,_xlpm.Tplus10, _xlpm.Tplus10+(_xlpm.Tplus30-_xlpm.Tplus10)/20*(J$10-('Input data'!$C$4+10)))))) -> 4.3445404 | K37: =_xlfn.LET(_xlpm.lastForecast,INDEX('Input data'!$E$38:$G$38,MATCH('Input data'!$C$4+2,'Input data'!$E$9:$G$9)), _xlpm.Tplus10,'Input data'!$C$53, _xlpm.Tplus30,'Input data'!$C$55, IF(K$10<='Input data'!$C$4+2,'Input data'!K$38, IF(K$10<'Input data'!$C$4+10,_xlpm.lastForecast+(_xlpm.Tplus10-_xlpm.lastForecast)/8*(K$10-('Input data'!$C$4+2)), IF(K$10='Input data'!$C$4+10,_xlpm.Tplus10, _xlpm.Tplus10+(_xlpm.Tplus30-_xlpm.Tplus10)/20*(K$10-('Input data'!$C$4+10)))))) -> 4.3600103 | L37: =_xlfn.LET(_xlpm.lastForecast,INDEX('Input data'!$E$38:$G$38,MATCH('Input data'!$C$4+2,'Input data'!$E$9:$G$9)), _xlpm.Tplus10,'Input data'!$C$53, _xlpm.Tplus30,'Input data'!$C$55, IF(L$10<='Input data'!$C$4+2,'Input data'!L$38, IF(L$10<'Input data'!$C$4+10,_xlpm.lastForecast+(_xlpm.Tplus10-_xlpm.lastForecast)/8*(L$10-('Input data'!$C$4+2)), IF(L$10='Input data'!$C$4+10,_xlpm.Tplus10, _xlpm.Tplus10+(_xlpm.Tplus30-_xlpm.Tplus10)/20*(L$10-('Input data'!$C$4+10)))))) -> 4.3754801 | ... U37: =_xlfn.LET(_xlpm.lastForecast,INDEX('Input data'!$E$38:$G$38,MATCH('Input data'!$C$4+2,'Input data'!$E$9:$G$9)), _xlpm.Tplus10,'Input data'!$C$53, _xlpm.Tplus30,'Input data'!$C$55, IF(U$10<='Input data'!$C$4+2,'Input data'!U$38, IF(U$10<'Input data'!$C$4+10,_xlpm.lastForecast+(_xlpm.Tplus10-_xlpm.lastForecast)/8*(U$10-('Input data'!$C$4+2)), IF(U$10='Input data'!$C$4+10,_xlpm.Tplus10, _xlpm.Tplus10+(_xlpm.Tplus30-_xlpm.Tplus10)/20*(U$10-('Input data'!$C$4+10)))))) -> 3.43457
B38: Share of long-term debt that matures every year | C38: 0.06796828 | D38: 0.06823518 | E38: 0.06905882 | F38: =IF(F$10>='Input data'!$C$4+10,'Input data'!$C$59, IF(OR($C$3="EL",$C$3="CY",$C$3="IE",$C$3="PT"),VLOOKUP($C$3,$B$110:$R$114,MATCH(F$10,$B$110:$R$110,0),0),$E$38+('Input data'!$C$59-$E$38)/('Input data'!$C$4+10-$E$10)*(F$10-$E$10))) -> 0.069882459 | G38: =IF(G$10>='Input data'!$C$4+10,'Input data'!$C$59, IF(OR($C$3="EL",$C$3="CY",$C$3="IE",$C$3="PT"),VLOOKUP($C$3,$B$110:$R$114,MATCH(G$10,$B$110:$R$110,0),0),$E$38+('Input data'!$C$59-$E$38)/('Input data'!$C$4+10-$E$10)*(G$10-$E$10))) -> 0.070706098 | H38: =IF(H$10>='Input data'!$C$4+10,'Input data'!$C$59, IF(OR($C$3="EL",$C$3="CY",$C$3="IE",$C$3="PT"),VLOOKUP($C$3,$B$110:$R$114,MATCH(H$10,$B$110:$R$110,0),0),$E$38+('Input data'!$C$59-$E$38)/('Input data'!$C$4+10-$E$10)*(H$10-$E$10))) -> 0.071529736 | I38: =IF(I$10>='Input data'!$C$4+10,'Input data'!$C$59, IF(OR($C$3="EL",$C$3="CY",$C$3="IE",$C$3="PT"),VLOOKUP($C$3,$B$110:$R$114,MATCH(I$10,$B$110:$R$110,0),0),$E$38+('Input data'!$C$59-$E$38)/('Input data'!$C$4+10-$E$10)*(I$10-$E$10))) -> 0.072353375 | J38: =IF(J$10>='Input data'!$C$4+10,'Input data'!$C$59, IF(OR($C$3="EL",$C$3="CY",$C$3="IE",$C$3="PT"),VLOOKUP($C$3,$B$110:$R$114,MATCH(J$10,$B$110:$R$110,0),0),$E$38+('Input data'!$C$59-$E$38)/('Input data'!$C$4+10-$E$10)*(J$10-$E$10))) -> 0.073177014 | K38: =IF(K$10>='Input data'!$C$4+10,'Input data'!$C$59, IF(OR($C$3="EL",$C$3="CY",$C$3="IE",$C$3="PT"),VLOOKUP($C$3,$B$110:$R$114,MATCH(K$10,$B$110:$R$110,0),0),$E$38+('Input data'!$C$59-$E$38)/('Input data'!$C$4+10-$E$10)*(K$10-$E$10))) -> 0.074000652 | L38: =IF(L$10>='Input data'!$C$4+10,'Input data'!$C$59, IF(OR($C$3="EL",$C$3="CY",$C$3="IE",$C$3="PT"),VLOOKUP($C$3,$B$110:$R$114,MATCH(L$10,$B$110:$R$110,0),0),$E$38+('Input data'!$C$59-$E$38)/('Input data'!$C$4+10-$E$10)*(L$10-$E$10))) -> 0.074824291 | M38: =IF(M$10>='Input data'!$C$4+10,'Input data'!$C$59, IF(OR($C$3="EL",$C$3="CY",$C$3="IE",$C$3="PT"),VLOOKUP($C$3,$B$110:$R$114,MATCH(M$10,$B$110:$R$110,0),0),$E$38+('Input data'!$C$59-$E$38)/('Input data'!$C$4+10-$E$10)*(M$10-$E$10))) -> 0.07564793 | ... U38: =IF(U$10>='Input data'!$C$4+10,'Input data'!$C$59, IF(OR($C$3="EL",$C$3="CY",$C$3="IE",$C$3="PT"),VLOOKUP($C$3,$B$110:$R$114,MATCH(U$10,$B$110:$R$110,0),0),$E$38+('Input data'!$C$59-$E$38)/('Input data'!$C$4+10-$E$10)*(U$10-$E$10))) -> 0.07564793
B40: Inflation and exchange rate
B41: GDP deflator (national currency) | C41: ='Input data'!C42 -> 3.512605 | D41: ='Input data'!D42 -> 2.656677 | E41: =_xlfn.LET(_xlpm.lastForecast,INDEX('Input data'!$E$42:$G$42,MATCH('Input data'!$C$4+2,'Input data'!$E$9:$G$9)), _xlpm.Tplus10,'Input data'!$C$61, _xlpm.Tplus30,'Input data'!$C$62, IF(E$10<='Input data'!$C$4+2,'Input data'!E$42, IF(E$10<'Input data'!$C$4+10,_xlpm.lastForecast+(_xlpm.Tplus10-_xlpm.lastForecast)/8*(E$10-('Input data'!$C$4+2)), IF(E$10='Input data'!$C$4+10,_xlpm.Tplus10, _xlpm.Tplus10+(_xlpm.Tplus30-_xlpm.Tplus10)/20*(E$10-('Input data'!$C$4+10)))))) -> 3.068664 | F41: =_xlfn.LET(_xlpm.lastForecast,INDEX('Input data'!$E$42:$G$42,MATCH('Input data'!$C$4+2,'Input data'!$E$9:$G$9)), _xlpm.Tplus10,'Input data'!$C$61, _xlpm.Tplus30,'Input data'!$C$62, IF(F$10<='Input data'!$C$4+2,'Input data'!F$42, IF(F$10<'Input data'!$C$4+10,_xlpm.lastForecast+(_xlpm.Tplus10-_xlpm.lastForecast)/8*(F$10-('Input data'!$C$4+2)), IF(F$10='Input data'!$C$4+10,_xlpm.Tplus10, _xlpm.Tplus10+(_xlpm.Tplus30-_xlpm.Tplus10)/20*(F$10-('Input data'!$C$4+10)))))) -> 2.977581 | G41: =_xlfn.LET(_xlpm.lastForecast,INDEX('Input data'!$E$42:$G$42,MATCH('Input data'!$C$4+2,'Input data'!$E$9:$G$9)), _xlpm.Tplus10,'Input data'!$C$61, _xlpm.Tplus30,'Input data'!$C$62, IF(G$10<='Input data'!$C$4+2,'Input data'!G$42, IF(G$10<'Input data'!$C$4+10,_xlpm.lastForecast+(_xlpm.Tplus10-_xlpm.lastForecast)/8*(G$10-('Input data'!$C$4+2)), IF(G$10='Input data'!$C$4+10,_xlpm.Tplus10, _xlpm.Tplus10+(_xlpm.Tplus30-_xlpm.Tplus10)/20*(G$10-('Input data'!$C$4+10)))))) -> 2.886498 | H41: =_xlfn.LET(_xlpm.lastForecast,INDEX('Input data'!$E$42:$G$42,MATCH('Input data'!$C$4+2,'Input data'!$E$9:$G$9)), _xlpm.Tplus10,'Input data'!$C$61, _xlpm.Tplus30,'Input data'!$C$62, IF(H$10<='Input data'!$C$4+2,'Input data'!H$42, IF(H$10<'Input data'!$C$4+10,_xlpm.lastForecast+(_xlpm.Tplus10-_xlpm.lastForecast)/8*(H$10-('Input data'!$C$4+2)), IF(H$10='Input data'!$C$4+10,_xlpm.Tplus10, _xlpm.Tplus10+(_xlpm.Tplus30-_xlpm.Tplus10)/20*(H$10-('Input data'!$C$4+10)))))) -> 2.795415 | I41: =_xlfn.LET(_xlpm.lastForecast,INDEX('Input data'!$E$42:$G$42,MATCH('Input data'!$C$4+2,'Input data'!$E$9:$G$9)), _xlpm.Tplus10,'Input data'!$C$61, _xlpm.Tplus30,'Input data'!$C$62, IF(I$10<='Input data'!$C$4+2,'Input data'!I$42, IF(I$10<'Input data'!$C$4+10,_xlpm.lastForecast+(_xlpm.Tplus10-_xlpm.lastForecast)/8*(I$10-('Input data'!$C$4+2)), IF(I$10='Input data'!$C$4+10,_xlpm.Tplus10, _xlpm.Tplus10+(_xlpm.Tplus30-_xlpm.Tplus10)/20*(I$10-('Input data'!$C$4+10)))))) -> 2.704332 | J41: =_xlfn.LET(_xlpm.lastForecast,INDEX('Input data'!$E$42:$G$42,MATCH('Input data'!$C$4+2,'Input data'!$E$9:$G$9)), _xlpm.Tplus10,'Input data'!$C$61, _xlpm.Tplus30,'Input data'!$C$62, IF(J$10<='Input data'!$C$4+2,'Input data'!J$42, IF(J$10<'Input data'!$C$4+10,_xlpm.lastForecast+(_xlpm.Tplus10-_xlpm.lastForecast)/8*(J$10-('Input data'!$C$4+2)), IF(J$10='Input data'!$C$4+10,_xlpm.Tplus10, _xlpm.Tplus10+(_xlpm.Tplus30-_xlpm.Tplus10)/20*(J$10-('Input data'!$C$4+10)))))) -> 2.613249 | K41: =_xlfn.LET(_xlpm.lastForecast,INDEX('Input data'!$E$42:$G$42,MATCH('Input data'!$C$4+2,'Input data'!$E$9:$G$9)), _xlpm.Tplus10,'Input data'!$C$61, _xlpm.Tplus30,'Input data'!$C$62, IF(K$10<='Input data'!$C$4+2,'Input data'!K$42, IF(K$10<'Input data'!$C$4+10,_xlpm.lastForecast+(_xlpm.Tplus10-_xlpm.lastForecast)/8*(K$10-('Input data'!$C$4+2)), IF(K$10='Input data'!$C$4+10,_xlpm.Tplus10, _xlpm.Tplus10+(_xlpm.Tplus30-_xlpm.Tplus10)/20*(K$10-('Input data'!$C$4+10)))))) -> 2.522166 | L41: =_xlfn.LET(_xlpm.lastForecast,INDEX('Input data'!$E$42:$G$42,MATCH('Input data'!$C$4+2,'Input data'!$E$9:$G$9)), _xlpm.Tplus10,'Input data'!$C$61, _xlpm.Tplus30,'Input data'!$C$62, IF(L$10<='Input data'!$C$4+2,'Input data'!L$42, IF(L$10<'Input data'!$C$4+10,_xlpm.lastForecast+(_xlpm.Tplus10-_xlpm.lastForecast)/8*(L$10-('Input data'!$C$4+2)), IF(L$10='Input data'!$C$4+10,_xlpm.Tplus10, _xlpm.Tplus10+(_xlpm.Tplus30-_xlpm.Tplus10)/20*(L$10-('Input data'!$C$4+10)))))) -> 2.431083 | ... U41: =_xlfn.LET(_xlpm.lastForecast,INDEX('Input data'!$E$42:$G$42,MATCH('Input data'!$C$4+2,'Input data'!$E$9:$G$9)), _xlpm.Tplus10,'Input data'!$C$61, _xlpm.Tplus30,'Input data'!$C$62, IF(U$10<='Input data'!$C$4+2,'Input data'!U$42, IF(U$10<'Input data'!$C$4+10,_xlpm.lastForecast+(_xlpm.Tplus10-_xlpm.lastForecast)/8*(U$10-('Input data'!$C$4+2)), IF(U$10='Input data'!$C$4+10,_xlpm.Tplus10, _xlpm.Tplus10+(_xlpm.Tplus30-_xlpm.Tplus10)/20*(U$10-('Input data'!$C$4+10)))))) -> 2.204
B42: Exchange rate composite change (weighted by share of debt in each currency) | C42: 0.9986759 | D42: 0.9989123 | E42: 0.9999991 | F42: 1 | G42: 1 | H42: 1 | I42: 1 | J42: 1 | K42: 1 | L42: 1 | M42: 1 | N42: 1 | O42: 1 | P42: 1 | Q42: 1 | R42: 1 | S42: 1 | T42: 1 | U42: 1
B44: Intermediate calculations (growth rate equation)
B46: Fiscal multiplier | C46: ='Input data'!C49 -> 0.6
B47: Budget balance semi-elasticity | C47: ='Input data'!C50 -> 0.395
B49: Auxiliary variable to control the closure of the output gap | C49: 0 | D49: =IF(AND(ABS((D12-C12)-('Input data'!D13-'Input data'!C13))>0.0001,ABS(D12-C12)>0.0001,D$10>$C$5),4,IF(C49=4,3,IF(C49=3,2,IF(C49=2,1,0)))) -> 0 | E49: =IF(AND(ABS(E12-D12)>0.0001,E$10>$C$5),4,IF(D49=4,3,IF(D49=3,2,IF(D49=2,1,0)))) -> 0 | F49: =IF(AND(ABS(F12-E12)>0.0001,F$10>$C$5),4,IF(E49=4,3,IF(E49=3,2,IF(E49=2,1,0)))) -> 0 | G49: =IF(AND(ABS(G12-F12)>0.0001,G$10>$C$5),4,IF(F49=4,3,IF(F49=3,2,IF(F49=2,1,0)))) -> 0 | H49: =IF(AND(ABS(H12-G12)>0.0001,H$10>$C$5),4,IF(G49=4,3,IF(G49=3,2,IF(G49=2,1,0)))) -> 0 | I49: =IF(AND(ABS(I12-H12)>0.0001,I$10>$C$5),4,IF(H49=4,3,IF(H49=3,2,IF(H49=2,1,0)))) -> 0 | J49: =IF(AND(ABS(J12-I12)>0.0001,J$10>$C$5),4,IF(I49=4,3,IF(I49=3,2,IF(I49=2,1,0)))) -> 0 | K49: =IF(AND(ABS(K12-J12)>0.0001,K$10>$C$5),4,IF(J49=4,3,IF(J49=3,2,IF(J49=2,1,0)))) -> 0 | L49: =IF(AND(ABS(L12-K12)>0.0001,L$10>$C$5),4,IF(K49=4,3,IF(K49=3,2,IF(K49=2,1,0)))) -> 0 | ... U49: =IF(AND(ABS(U12-T12)>0.0001,U$10>$C$5),4,IF(T49=4,3,IF(T49=3,2,IF(T49=2,1,0)))) -> 0
B50: OG intermediate auxiliary value | C50: 0 | D50: =IF(C49=4,2/3*C29,IF(C49=3,1/3*#REF!,0)) -> 0 | E50: =IF(D49=4,2/3*D29,IF(D49=3,1/3*C29,0)) -> 0 | F50: =IF(E49=4,2/3*E29,IF(E49=3,1/3*D29,0)) -> 0 | G50: =IF(F49=4,2/3*F29,IF(F49=3,1/3*E29,0)) -> 0 | H50: =IF(G49=4,2/3*G29,IF(G49=3,1/3*F29,0)) -> 0 | I50: =IF(H49=4,2/3*H29,IF(H49=3,1/3*G29,0)) -> 0 | J50: =IF(I49=4,2/3*I29,IF(I49=3,1/3*H29,0)) -> 0 | K50: =IF(J49=4,2/3*J29,IF(J49=3,1/3*I29,0)) -> 0 | L50: =IF(K49=4,2/3*K29,IF(K49=3,1/3*J29,0)) -> 0 | ... U50: =IF(T49=4,2/3*T29,IF(T49=3,1/3*S29,0)) -> 0
B51: GDP intermediate growth rate - only feedback effect and no closure of the OG | C51: 0 | D51: ='Input data'!D30-$C$46*((D12-C12)-('Input data'!D13-'Input data'!C13)) -> 1.79727 | E51: ='Input data'!E30-$C$46*((E12-D12)-('Input data'!E13-'Input data'!D13)) -> 2.9516324 | F51: ='Input data'!F30-$C$46*((F12-E12)) -> 1.373251 | G51: ='Input data'!G30-$C$46*((G12-F12)) -> 1.123538 | H51: ='Input data'!H30-$C$46*((H12-G12)) -> 1.157076 | I51: ='Input data'!I30-$C$46*((I12-H12)) -> 1.226085 | J51: ='Input data'!J30-$C$46*((J12-I12)) -> 1.236268 | K51: ='Input data'!K30-$C$46*((K12-J12)) -> 1.244196 | L51: ='Input data'!L30-$C$46*((L12-K12)) -> 1.209247 | M51: ='Input data'!M30-$C$46*((M12-L12)) -> 1.140828 | ... U51: ='Input data'!U30-$C$46*((U12-T12)) -> 1.61
B53: Debt projections
C55: ='Input data'!$C$5-1 -> 2025 | D55: =C55+1 -> 2026 | E55: =D55+1 -> 2027 | F55: =E55+1 -> 2028 | G55: =F55+1 -> 2029 | H55: =G55+1 -> 2030 | I55: =H55+1 -> 2031 | J55: =I55+1 -> 2032 | K55: =J55+1 -> 2033 | ... U55: =T55+1 -> 2043
B56: Gross debt | C56: =+'Input data'!C12 -> 44.25023 | D56: =+C56+D57 -> 45.838496 | E56: =+D56+E57 -> 47.042627 | F56: =+E56+F57 -> 48.037875 | G56: =+F56+G57 -> 49.449014 | H56: =+G56+H57 -> 51.025602 | I56: =+H56+I57 -> 52.830767 | J56: =+I56+J57 -> 54.798962 | K56: =+J56+K57 -> 56.937192 | ... U56: =+T56+U57 -> 91.692976
...

Sheet Adjustment scenario
B3: Country | C3: ='Input data'!C3 -> CZ
B4: Key years
B5: ='Input data'!B5 -> Last year before the adjustment | C5: =+'Input data'!C5 -> 2026
B6: Last year of adjustment | C6: =+C5+'Criteria results'!$F$5 -> 2030
B7: Last year of no-fiscal-policy-change projections | C7: =C5+'Criteria results'!$F$5+10 -> 2040
B9: Key assumptions
C10: ='Input data'!$C$5-1 -> 2025 | D10: =C10+1 -> 2026 | E10: =D10+1 -> 2027 | F10: =E10+1 -> 2028 | G10: =F10+1 -> 2029 | H10: =G10+1 -> 2030 | I10: =H10+1 -> 2031 | J10: =I10+1 -> 2032 | K10: =J10+1 -> 2033 | ... U10: =T10+1 -> 2043
B11: Fiscal assumptions (% of GDP)
B12: Structural primary balance ('+' means 'surplus') | C12: ='Input data'!C13 -> -0.5110157 | D12: ='Input data'!D13 -> -1.332759 | E12: =IF(E10<=$C$6, IF(AND(D78<=-1.5,'Criteria results'!$F$5=4,'Criteria results'!$F$6<0.4),D12+0.4, IF(AND(D78<=-1.5,'Criteria results'!$F$5=7,'Criteria results'!$F$6<0.25),D12+0.25, D12+'Criteria results'!$F$6)),D12) -> -0.872759 | F12: =IF(F10<=$C$6, IF(AND(E78<=-1.5,'Criteria results'!$F$5=4,'Criteria results'!$F$6<0.4),E12+0.4, IF(AND(E78<=-1.5,'Criteria results'!$F$5=7,'Criteria results'!$F$6<0.25),E12+0.25, E12+'Criteria results'!$F$6)),E12) -> -0.412759 | G12: =IF(G10<=$C$6, IF(AND(F78<=-1.5,'Criteria results'!$F$5=4,'Criteria results'!$F$6<0.4),F12+0.4, IF(AND(F78<=-1.5,'Criteria results'!$F$5=7,'Criteria results'!$F$6<0.25),F12+0.25, F12+'Criteria results'!$F$6)),F12) -> 0.047241 | H12: =IF(H10<=$C$6, IF(AND(G78<=-1.5,'Criteria results'!$F$5=4,'Criteria results'!$F$6<0.4),G12+0.4, IF(AND(G78<=-1.5,'Criteria results'!$F$5=7,'Criteria results'!$F$6<0.25),G12+0.25, G12+'Criteria results'!$F$6)),G12) -> 0.507241 | I12: =IF(I10<=$C$6, IF(AND(H78<=-1.5,'Criteria results'!$F$5=4,'Criteria results'!$F$6<0.4),H12+0.4, IF(AND(H78<=-1.5,'Criteria results'!$F$5=7,'Criteria results'!$F$6<0.25),H12+0.25, H12+'Criteria results'!$F$6)),H12) -> 0.507241 | J12: =IF(J10<=$C$6, IF(AND(I78<=-1.5,'Criteria results'!$F$5=4,'Criteria results'!$F$6<0.4),I12+0.4, IF(AND(I78<=-1.5,'Criteria results'!$F$5=7,'Criteria results'!$F$6<0.25),I12+0.25, I12+'Criteria results'!$F$6)),I12) -> 0.507241 | K12: =IF(K10<=$C$6, IF(AND(J78<=-1.5,'Criteria results'!$F$5=4,'Criteria results'!$F$6<0.4),J12+0.4, IF(AND(J78<=-1.5,'Criteria results'!$F$5=7,'Criteria results'!$F$6<0.25),J12+0.25, J12+'Criteria results'!$F$6)),J12) -> 0.507241 | L12: =K12 -> 0.507241 | M12: =L12 -> 0.507241 | N12: =M12 -> 0.507241 | O12: =N12 -> 0.507241 | P12: =O12 -> 0.507241 | Q12: =P12 -> 0.507241 | R12: =Q12 -> 0.507241 | S12: =R12 -> 0.507241 | ... U12: =T12 -> 0.507241
B13: Annual change in SPB | E13: =E12-D12 -> 0.46 | F13: =F12-E12 -> 0.46 | G13: =G12-F12 -> 0.46 | H13: =H12-G12 -> 0.46 | I13: =I12-H12 -> 0 | J13: =J12-I12 -> 0 | K13: =K12-J12 -> 0 | L13: =L12-K12 -> 0 | ... U13: =U12-T12 -> 0
B14: One-off and other temporary measures | C14: ='Input data'!C14 -> -0.1168709 | D14: ='Input data'!D14 -> 0 | E14: ='Input data'!E14 -> 0 | F14: ='Input data'!F14 -> 0 | G14: ='Input data'!G14 -> 0 | H14: ='Input data'!H14 -> 0 | I14: ='Input data'!I14 -> 0 | J14: ='Input data'!J14 -> 0 | ... U14: ='Input data'!U14 -> 0
B15: Stock flow adjustments (without exchange rate effect) | C15: ='Input data'!C15 -> 1.388104 | D15: ='Input data'!D15 -> 0.7474777 | E15: ='Input data'!E15 -> 0.85 | F15: ='Input data'!F15 -> 0 | G15: ='Input data'!G15 -> 0 | H15: ='Input data'!H15 -> 0 | I15: ='Input data'!I15 -> 0 | J15: ='Input data'!J15 -> 0 | ... U15: ='Input data'!U15 -> 0
B17: ='Input data'!B19 -> Cost of ageing and selected public revenue (based on the Commission-Council 2024 Ageing Report ("AR 2024"))
B18: Total ageing cost (net of taxes on pensions) | C18: ='Input data'!C20 -> 19.8 | D18: ='Input data'!D20 -> 19.7 | E18: ='Input data'!E20 -> 19.8 | F18: ='Input data'!F20 -> 19.9 | G18: ='Input data'!G20 -> 20 | H18: ='Input data'!H20 -> 20 | I18: ='Input data'!I20 -> 20.1 | J18: ='Input data'!J20 -> 20.1 | ... U18: ='Input data'!U20 -> 21.3
B19: Property income | C19: ='Input data'!C26 -> 1.037865 | D19: ='Input data'!D26 -> 1.023357 | E19: ='Input data'!E26 -> 1.008848 | F19: ='Input data'!F26 -> 0.9943401 | G19: ='Input data'!G26 -> 0.9798318 | H19: ='Input data'!H26 -> 0.9653235 | I19: ='Input data'!I26 -> 0.9508152 | J19: ='Input data'!J26 -> 0.9363069 | ... U19: ='Input data'!U26 -> 0.7767155
B21: GDP growth assumptions
B22: Actual GDP (real)
B23: Level | C23: ='Baseline NFPC'!C22 -> 6479.806 | D23: ='Baseline NFPC'!D22 -> 6596.2656 | E23: =IF(AND(E50>1,D50>1), IF(E$10<='Input data'!$C$4+2, E27*(1+('Baseline NFPC'!E$29+E51)/100)-D23*$C$47*(E12-D12)/100, E27*(1+E51/100)-D23*$C$47*(E12-D12)/100), IF(E50=1,E27,D23*(1+E52/100))) -> 6720.01 | F23: =IF(AND(F50>1,E50>1), IF(F$10<='Input data'!$C$4+2, F27*(1+('Baseline NFPC'!F$29+F51)/100)-E23*$C$47*(F12-E12)/100, F27*(1+F51/100)-E23*$C$47*(F12-E12)/100), IF(F50=1,F27,E23*(1+F52/100))) -> 6799.8872 | G23: =IF(AND(G50>1,F50>1), IF(G$10<='Input data'!$C$4+2, G27*(1+('Baseline NFPC'!G$29+G51)/100)-F23*$C$47*(G12-F12)/100, G27*(1+G51/100)-F23*$C$47*(G12-F12)/100), IF(G50=1,G27,F23*(1+G52/100))) -> 6871.6851 | H23: =IF(AND(H50>1,G50>1), H27*(1+H51/100)-G23*$C$47*(H12-G12)/100, IF(H50=1,H27,G23*(1+H52/100))) -> 6946.8455 | I23: =IF(AND(I50>1,H50>1), I27*(1+I51/100)-H23*$C$47*(I12-H12)/100, IF(I50=1,I27,H23*(1+I52/100))) -> 7045.7104 | J23: =IF(AND(J50>1,I50>1), J27*(1+J51/100)-I23*$C$47*(J12-I12)/100, IF(J50=1,J27,I23*(1+J52/100))) -> 7146.6739 | K23: =IF(AND(K50>1,J50>1), K27*(1+K51/100)-J23*$C$47*(K12-J12)/100, IF(K50=1,K27,J23*(1+K52/100))) -> 7249.6249 | L23: =IF(AND(L50>1,K50>1), L27*(1+L51/100)-K23*$C$47*(L12-K12)/100, IF(L50=1,L27,K23*(1+L52/100))) -> 7337.2908 | M23: =IF(AND(M50>1,L50>1), M27*(1+M51/100)-L23*$C$47*(M12-L12)/100, IF(M50=1,M27,L23*(1+M52/100))) -> 7420.9967 | N23: =IF(AND(N50>1,M50>1), N27*(1+N51/100)-M23*$C$47*(N12-M12)/100, IF(N50=1,N27,M23*(1+N52/100))) -> 7514.2948 | O23: =IF(AND(O50>1,N50>1), O27*(1+O51/100)-N23*$C$47*(O12-N12)/100, IF(O50=1,O27,N23*(1+O52/100))) -> 7617.512 | ... U23: =IF(AND(U50>1,T50>1), U27*(1+U51/100)-T23*$C$47*(U12-T12)/100, IF(U50=1,U27,T23*(1+U52/100))) -> 8363.8379
B24: Growth rate | C24: ='Baseline NFPC'!C23 -> 2.580467 | D24: ='Baseline NFPC'!D23 -> 1.79727 | E24: =100*(E23/D23-1) -> 1.875977 | F24: =100*(F23/E23-1) -> 1.188646 | G24: =100*(G23/F23-1) -> 1.0558694 | H24: =100*(H23/G23-1) -> 1.0937696 | I24: =100*(I23/H23-1) -> 1.4231627 | J24: =100*(J23/I23-1) -> 1.4329775 | K24: =100*(K23/J23-1) -> 1.4405454 | L24: =100*(L23/K23-1) -> 1.209247 | ... U24: =100*(U23/T23-1) -> 1.61
B26: Potential GDP (real)
B27: Level | C27: ='Input data'!C34 -> 6515.4565 | D27: =+C27*(1+'Input data'!D33/100) -> 6622.8091 | E27: =+D27*(1+'Input data'!E33/100) -> 6721.6283 | F27: =+E27*(1+'Input data'!F33/100) -> 6819.529 | G27: =+F27*(1+'Input data'!G33/100) -> 6903.7089 | H27: =+G27*(1+'Input data'!H33/100) -> 6987.4195 | I27: =+H27*(1+'Input data'!I33/100) -> 7073.0914 | J27: =+I27*(1+'Input data'!J33/100) -> 7160.5336 | K27: =+J27*(1+'Input data'!K33/100) -> 7249.6249 | ... U27: =+T27*(1+'Input data'!U33/100) -> 8363.8361
B29: Output gap
B30: Output gap | C30: =100*(C23/C27-1) -> -0.54716846 | D30: =100*(D23/D27-1) -> -0.40078891 | E30: =100*(E23/E27-1) -> -0.024075392 | F30: =100*(F23/F27-1) -> -0.28802253 | G30: =100*(G23/G27-1) -> -0.46386438 | H30: =100*(H23/H27-1) -> -0.58067146 | I30: =100*(I23/I27-1) -> -0.38711431 | J30: =100*(J23/J27-1) -> -0.19355715 | ... U30: =100*(U23/U27-1) -> 2.1710351e-05
B32: Actual GDP (nominal, national currency)
B33: Growth rate | C33: =100*((1+C24/100)*(1+C42/100)-1) -> 6.1837136 | D33: =100*((1+D24/100)*(1+D42/100)-1) -> 4.5016947 | E33: =100*((1+E24/100)*(1+E42/100)-1) -> 5.0022084 | F33: =100*((1+F24/100)*(1+F42/100)-1) -> 4.2016199 | G33: =100*((1+G24/100)*(1+G42/100)-1) -> 3.972845 | H33: =100*((1+H24/100)*(1+H42/100)-1) -> 3.91976 | I33: =100*((1+I24/100)*(1+I42/100)-1) -> 4.1659817 | J33: =100*((1+J24/100)*(1+J42/100)-1) -> 4.0836738 | ... U33: =100*((1+U24/100)*(1+U42/100)-1) -> 3.8494844
B35: Interest rates
B36: Nominal implicit interest rate on debt | C36: ='Input data'!C37 -> 3.196961 | D36: ='Input data'!D37 -> 3.078103 | E36: =IF(E$10<='Input data'!$C$4+2,'Input data'!E37,E99) -> 2.999835 | F36: =IF(F$10<='Input data'!$C$4+2,'Input data'!F37,F99) -> 3.2612235 | G36: =IF(G$10<='Input data'!$C$4+2,'Input data'!G37,G99) -> 3.466152 | H36: =H99 -> 3.6527919 | I36: =I99 -> 3.8227404 | J36: =J99 -> 3.9924506 | K36: =K99 -> 4.1585065 | L36: =L99 -> 4.3211098 | M36: =M99 -> 4.4916417 | N36: =N99 -> 4.6319413 | O36: =O99 -> 4.748543 | ... U36: =U99 -> 5.025283
B37: Long-term interest rate | C37: ='Input data'!C$39 -> 4.29 | D37: ='Input data'!D$39 -> 4.701964 | E37: ='Baseline NFPC'!E36 -> 4.915649 | F37: ='Baseline NFPC'!F36 -> 5.0370066 | G37: ='Baseline NFPC'!G36 -> 5.1583642 | H37: ='Baseline NFPC'!H36 -> 5.2797219 | I37: ='Baseline NFPC'!I36 -> 5.4010795 | J37: ='Baseline NFPC'!J36 -> 5.5224371 | K37: ='Baseline NFPC'!K36 -> 5.6437948 | L37: ='Baseline NFPC'!L36 -> 5.7651524 | ... U37: ='Baseline NFPC'!U36 -> 5.131906
B38: Short-term interest rate | C38: ='Input data'!C$38 -> 3.6 | D38: ='Input data'!D$38 -> 3.649853 | E38: ='Baseline NFPC'!E37 -> 4.267191 | F38: ='Baseline NFPC'!F37 -> 4.2826609 | G38: ='Baseline NFPC'!G37 -> 4.2981308 | H38: ='Baseline NFPC'!H37 -> 4.3136006 | I38: ='Baseline NFPC'!I37 -> 4.3290705 | J38: ='Baseline NFPC'!J37 -> 4.3445404 | K38: ='Baseline NFPC'!K37 -> 4.3600103 | L38: ='Baseline NFPC'!L37 -> 4.3754801 | ... U38: ='Baseline NFPC'!U37 -> 3.43457
B39: Share of long-term debt that matures every year | C39: ='Baseline NFPC'!C38 -> 0.06796828 | D39: ='Baseline NFPC'!D38 -> 0.06823518 | E39: ='Baseline NFPC'!E38 -> 0.06905882 | F39: ='Baseline NFPC'!F38 -> 0.069882459 | G39: ='Baseline NFPC'!G38 -> 0.070706098 | H39: ='Baseline NFPC'!H38 -> 0.071529736 | I39: ='Baseline NFPC'!I38 -> 0.072353375 | J39: ='Baseline NFPC'!J38 -> 0.073177014 | ... U39: ='Baseline NFPC'!U38 -> 0.07564793
B41: Inflation and exchange rate
B42: GDP deflator (National currency) | C42: ='Input data'!C42 -> 3.512605 | D42: ='Input data'!D42 -> 2.656677 | E42: ='Baseline NFPC'!E41 -> 3.068664 | F42: ='Baseline NFPC'!F41 -> 2.977581 | G42: ='Baseline NFPC'!G41 -> 2.886498 | H42: ='Baseline NFPC'!H41 -> 2.795415 | I42: ='Baseline NFPC'!I41 -> 2.704332 | J42: ='Baseline NFPC'!J41 -> 2.613249 | K42: ='Baseline NFPC'!K41 -> 2.522166 | L42: ='Baseline NFPC'!L41 -> 2.431083 | ... U42: ='Baseline NFPC'!U41 -> 2.204
B43: Exchange rate composite change (weighted by share of debt in each currency) | C43: ='Baseline NFPC'!C42 -> 0.9986759 | D43: ='Baseline NFPC'!D42 -> 0.9989123 | E43: ='Baseline NFPC'!E42 -> 0.9999991 | F43: ='Baseline NFPC'!F42 -> 1 | G43: ='Baseline NFPC'!G42 -> 1 | H43: ='Baseline NFPC'!H42 -> 1 | I43: ='Baseline NFPC'!I42 -> 1 | J43: ='Baseline NFPC'!J42 -> 1 | ... U43: ='Baseline NFPC'!U42 -> 1
B45: Intermediate calculations (growth rate equation)
B47: Fiscal multiplier | C47: ='Input data'!C49 -> 0.6
B48: Budget balance semi-elasticity | C48: ='Input data'!C50 -> 0.395
B50: Auxiliary variable to control the closure of the output gap | C50: 0 | D50: =IF(AND(ABS((D12-C12)-('Input data'!D13-'Input data'!C13))>0.0001,ABS(D12-C12)>0.0001,D$10>$C$5),4,IF(C50=4,3,IF(C50=3,2,IF(C50=2,1,0)))) -> 0 | E50: =IF(AND(ABS((E12-D12)-('Baseline NFPC'!E12-'Baseline NFPC'!D12))>0.0001,ABS(E12-D12)>0.0001,E$10>$C$5),4,IF(D50=4,3,IF(D50=3,2,IF(D50=2,1,0)))) -> 4 | F50: =IF(AND(ABS((F12-E12)-('Baseline NFPC'!F12-'Baseline NFPC'!E12))>0.0001,ABS(F12-E12)>0.0001,F$10>$C$5),4,IF(E50=4,3,IF(E50=3,2,IF(E50=2,1,0)))) -> 4 | G50: =IF(AND(ABS((G12-F12)-('Baseline NFPC'!G12-'Baseline NFPC'!F12))>0.0001,ABS(G12-F12)>0.0001,G$10>$C$5),4,IF(F50=4,3,IF(F50=3,2,IF(F50=2,1,0)))) -> 4 | H50: =IF(AND(ABS((H12-G12)-('Baseline NFPC'!H12-'Baseline NFPC'!G12))>0.0001,ABS(H12-G12)>0.0001,H$10>$C$5),4,IF(G50=4,3,IF(G50=3,2,IF(G50=2,1,0)))) -> 4 | I50: =IF(AND(ABS((I12-H12)-('Baseline NFPC'!I12-'Baseline NFPC'!H12))>0.0001,ABS(I12-H12)>0.0001,I$10>$C$5),4,IF(H50=4,3,IF(H50=3,2,IF(H50=2,1,0)))) -> 3 | J50: =IF(AND(ABS((J12-I12)-('Baseline NFPC'!J12-'Baseline NFPC'!I12))>0.0001,ABS(J12-I12)>0.0001,J$10>$C$5),4,IF(I50=4,3,IF(I50=3,2,IF(I50=2,1,0)))) -> 2 | K50: =IF(AND(ABS((K12-J12)-('Baseline NFPC'!K12-'Baseline NFPC'!J12))>0.0001,ABS(K12-J12)>0.0001,K$10>$C$5),4,IF(J50=4,3,IF(J50=3,2,IF(J50=2,1,0)))) -> 1 | L50: =IF(AND(ABS((L12-K12)-('Baseline NFPC'!L12-'Baseline NFPC'!K12))>0.0001,ABS(L12-K12)>0.0001,L$10>$C$5),4,IF(K50=4,3,IF(K50=3,2,IF(K50=2,1,0)))) -> 0 | ... U50: =IF(AND(ABS((U12-T12)-('Baseline NFPC'!U12-'Baseline NFPC'!T12))>0.0001,ABS(U12-T12)>0.0001,U$10>$C$5),4,IF(T50=4,3,IF(T50=3,2,IF(T50=2,1,0)))) -> 0
B51: OG intermediate auxiliary value | C51: 0 | D51: 0 | E51: =IF(D50=4, IF(E$10<='Input data'!$C$4+2,2/3*(D30-'Baseline NFPC'!D29),2/3*D30), IF(D50=3, IF(E$10<='Input data'!$C$4+2,1/3*(C30-'Baseline NFPC'!C29),1/3*C30), 0)) -> 0 | F51: =IF(E50=4, IF(F$10<='Input data'!$C$4+2,2/3*(E30-'Baseline NFPC'!E29),2/3*E30), IF(E50=3, IF(F$10<='Input data'!$C$4+2,1/3*(D30-'Baseline NFPC'!D29),1/3*D30), 0)) -> -0.016050261 | G51: =IF(F50=4, IF(G$10<='Input data'!$C$4+2,2/3*(F30-'Baseline NFPC'!F29),2/3*F30), IF(F50=3, IF(G$10<='Input data'!$C$4+2,1/3*(E30-'Baseline NFPC'!E29),1/3*E30), 0)) -> -0.19201502 | H51: =IF(G50=4,2/3*G30,IF(G50=3,1/3*F30,0)) -> -0.30924292 | I51: =IF(H50=4,2/3*H30,IF(H50=3,1/3*G30,0)) -> -0.38711431 | J51: =IF(I50=4,2/3*I30,IF(I50=3,1/3*H30,0)) -> -0.19355715 | K51: =IF(J50=4,2/3*J30,IF(J50=3,1/3*I30,0)) -> 0 | L51: =IF(K50=4,2/3*K30,IF(K50=3,1/3*J30,0)) -> 0 | M51: =IF(L50=4,2/3*L30,IF(L50=3,1/3*K30,0)) -> 0 | N51: =IF(M50=4,2/3*M30,IF(M50=3,1/3*L30,0)) -> 0 | O51: =IF(N50=4,2/3*N30,IF(N50=3,1/3*M30,0)) -> 0 | ... U51: =IF(T50=4,2/3*T30,IF(T50=3,1/3*S30,0)) -> 0
