Workbook

Sheet Read me
G4: European Commission
G6: Directorate-General for Economic and Financial Affairs
G7: Unit C2 - Sustainability of public finances
G8: ECFIN-Secretariat-C2@ec.europa.eu
C16: FILE DESCRIPTION
C18: Data reported in this file are based on the European Commission (EC) 2024 autumn forecast (AF 2024) and macroeconomic and budgetary projections from the joint EC-EPC Ageing Report 2024 (AR 2024).
C22: This file contains a simplified version of the EC model used to calculate the general governement debt ratio dynamics for EU countries under different scenarios. A detailed description of the EC's general governement debt projections can be found in the "Debt Sustainability Monitor 2023" (DSM, March 2024).
C27: HOW TO USE THIS TOOL TO CALCULATE NEW DEBT PROJECTIONS
C29: This tool can be used to calculate debt projections under different macroeconomic and structural primary balance adjustment assumptions. Debt projections for each scenario will update automatically with changes in the macroeconomic assumptions or the adjustment parameters. The fulfilment of DSA-based criteria, the safeguards and the benchmark will be automatically calculated in the sheet "Criteria results". Formulas are fully visible. To assess the impact of alternative adjustment paths compared with the reference trajectory calculated by the EC or to check its robustness to underlying macroeconomic assumptions, the user can modify the content of key cells in the sheets "Criteria results" and "Input data" (see below). Note that, for a proper functioning of the file, you should make sure that Excel is in "Automatic" computation mode, i.e. in the File menu, Option tab, click on "Formulas", "Calculation Options" and "Automatic".
C31: The spreadsheet is composed of the following elements:
D33: The grey sheet "Criteria results" contains three types of cells identified by different colours:
F34: Cells with a yellow background and a red frame can be modified to see the impact of a different duration or pace of adjustment.
F35: Cells with a white or grey background provide results obtained with the adjustment chosen in the yellow cells. To replicate the Commission's calculations, the underlying formulas should not be modified.
F37: Cells with a pale blue background correspond to the Commission's prior guidance provided to the Member State. Those are hard numbers that do not depend on the adjustment chosen in the file.
D39: The sheet "Criteria results" contains six tables: Table 1 "Adjustment input data": the user can set the duration of the plan (4 years under no extension or 7 years under extension) and the yearly adjustment pace in cells F5 and F6 in yellow. Note that the country cell (F4) cannot be changed.
D40: To the right of Table 1, a message automatically signals whether the chosen adjustment is sufficient to fulfill all the requirements, summarising the results from Tables 2 and 3.
D41: Table 2 "DSA-based criteria" reports whether the chosen adjustment fulfils each of the DSA-based criteria.
D42: Table 3 "Safeguards and benchmark" reports whether (i) the chosen adjustment ensures that the debt sustainability safeguard is met, (ii) the 'deficit benchmark', i.e. the minimum adjustment of 0.5 pp. of GDP as a benchmark when the country is in EDP and/or the deficit exceeds 3% of GDP, is binding, and (iii) the deficit resilience safeguard is binding.
D43: Table 4 "Main fiscal variables" reports the annual adjustment over the adjustment period, in terms of change in SPB (line 19) and net primary expenditure growth (line 20). The table also reports the headline balance, the structural balance and debt (lines 21 to 23). The average annual adjustment is reported in cells G24 (average change in SPB over the 4-year plan period), G25 (average change in SPB over the 4-year or 7-year adjustment period), G26 (average net primary expenditure growth over the plan period) and G27 (average net primary expenditure growth over the adjustment period).
D44: Table 5 "DSA-based adjustment" summarises the key characteristics of the adjustment path that complies with the DSA-based criteria before applying the safeguards and benchmark, for a plan both with and without extension.
D45: Table 6 "Reference trajectory" reports the net expenditure growth and the corresponding annual change in SPB that are consistent with all requirements including the safeguards and benchmark, both without and with extension.
D47: The sheet "Input data" in light blue presents the input data, including fiscal and GDP growth assumptions as well as additional fiscal parameters. Unless stated otherwise below, the user can change all values in this tab.
D48: Coloured cells indicate data sources as follows (this colour-coding holds in the other spreadsheets):
F49: Cells in light grey indicate a Commission forecast (available in the AMECO database)
F50: Cells in light red indicate whether the country is subject to an ongoing excessive deficit procedure (EDP) or whether the Commission's November 2024 report under Art. 126(3) of the Treaty recommends opening an EDP. If neither of these conditions are met, the deficit benchmark is not relevant and therefore not applied.
F51: Cells in light blue indicate values from the Ageing Report 2024
F52: Cells in light orange provide parameters needed to compute the decomposition of government debt according to its maturity structure (i.e. short-term and long-term debt, maturing, rolled-over and non-maturing debt). These are fixed shares which the user cannot change.
F53: Cells in dark orange indicate financial market prices.
D54: Non-coloured parameters in cells C49:C70 were calibrated based on different data sources. The data sources are indicated in the corresponding cells of column E. The last part of the sheet "Input data" (cells C73:G77) provides the parameters measuring the size of the cone of the fanchart that results from the stochastic analysis. For reproducibility reasons, these parameters are kept constant.
C56: The next spreadsheets present the deterministic and stochastic projections. Each deterministic projection provides a single path for debt until 2038 or 2041 under certain assumptions for budgetary, macroeconomic and financial variables, while the outcome of the stochastic projections is a distribution of debt paths resulting from a wide set of shocks. The sheets are grouped in four blocs, identified by their colour coding:
D58: The sheet in blue provides, as a reference, the baseline no-fiscal-policy-change scenario. The background colour coding is the same as in the sheet "Input data".
D60: The sheet in orange presents the scenario that automatically corrects the yearly adjustment path to account for the deficit benchmark and the deficit resillience safeguard. By contrast, the yearly adjustment profile is not automatically adjusted to ensure that the debt sustainability safeguard is met. However, the sheet "Criteria results" indicates whether that safeguard is met.
D62: The sheets in green present the deterministic projections that are used to compute the DSA-based requirements (in the sheet "Criteria results"). They include four scenarios:
D63: · Adjustment scenario without safeguard and benchmark
D64: · Financial stress scenario
D65: · Lower SPB scenario
D66: · Adverse 'r-g' scenario
D68: Each scenario is computed automatically based on the yearly adjustment path set in "Criteria results" (see above).
D70: The sheet in dark green presents the stochastic projections surrounding the adjustment scenario without safeguard and benchmark .
C72: Within the orange sheet and each green sheet, the background of the SPB line has three colours. Each colour corresponds to a specific period of the projections:
...

Sheet Criteria results
U2: 4 | V2: 0
D3: Table 1 - Adjustment input data | H3: =IF(OR(AND($G$12="ok",$G$13="ok",$G$14="ok",$G$15="ok",$H$12="ok",$I$12="ok",$L$12<>"Not met"), AND($I$12="ok",$J$12="ok",$J$13="ok",$J$14="ok",$J$15="ok",$L$12<>"Not met")), "OK"&CHAR(10)&"adjustment"&CHAR(10)&"complies with all requirements", "NOT OK"&CHAR(10)&"adjustment does not"&CHAR(10)&"comply with all requirements") -> #NAME? | U3: 7 | V3: 0.02
D4: Country | F4: HU | V4: 0.04
D5: Number of years of adjustment | F5: 4 | V5: 0.06
D6: Annual adjustment (when benchmark not binding) | F6: 0.54 | V6: 0.08
V7: 0.1
V8: 0.12
G9: Table 2 - DSA-based criteria | L9: Table 3 - Safeguards and benchmark | V9: 0.14
L10: Debt sustainability safeguard * | N10: Deficit benchmark ** | P10: Deficit resilience safeguard | V10: 0.16
G11: Criterion 1 (Debt decreasing under deterministic scenarios) | H11: Criterion 2 * (Debt declining with sufficient probability) | I11: Criterion 3 (Deficit below 3% of GDP) | J11: ="Debt below 60% of GDP in T+"&10+F5&" **" -> Debt below 60% of GDP in T+14 ** | L11: Debt declines by 1pp (0.5pp) of GDP on average as long as debt exceeds 90% (60%) of GDP | M11: Average change in debt | N11: 0.5 pp. of GDP adjustment if deficit in previous year > 3% of GDP | O11: Number of years the benchmark applies | P11: 0.40 pp. (0.25 pp.) of GDP adjustment under plan without (with) extension if structural deficit in previous year > 1.5% of GDP | Q11: Number of years the deficit resilience safeguard applies (over the adjustment horizon) | V11: 0.18
D12: Adjustment scenario | G12: =IF(OR('Adjust. no safeguard'!F57>60,'Adjust. no safeguard'!F77<-3),IF(SUM(OFFSET('Adjust. no safeguard'!$F$83,0,$F$5+1,1,10))=0,"ok","Not met"),"") -> ok | H12: =IF(OR('Adjust. no safeguard'!F57>60,'Adjust. no safeguard'!F77<-3),IF($F$5=4,IF(Stochastic!$O$17<Stochastic!$J$17,"ok","Not met"),IF(Stochastic!$R$17<Stochastic!$M$17,"ok","Not met")),"") -> ok | I12: =IF(MIN(OFFSET('Adjust. no safeguard'!$F$77,0,$F$5,1,11))>-3.05,"ok","Not met") -> ok | J12: =IF(OFFSET('Adjust. no safeguard'!$F$57,0,$F$5+10,1,1)<60,"ok","Not met") -> ok | L12: =_xlfn.LET(_xlpm.debtChange,OFFSET('Adjustment scenario'!F58,0,1,1,$F$5), _xlpm.debt6090,OFFSET('Adjustment scenario'!F85,0,1,1,$F$5), _xlpm.debt90,OFFSET('Adjustment scenario'!F84,0,1,1,$F$5), _xlpm.EDP,OFFSET('Adjustment scenario'!F87,0,1,1,$F$5), IF(AND(MAX(_xlpm.debt90)=0,MAX(_xlpm.debt6090)=0),"Debt below 60% of GDP over the adjustment period", IF(MIN(_xlpm.EDP)=1,"Not applicable, reference year is the last year of adjustment", IFERROR(IF(AND(MAX(_xlpm.debt90)=0,MAX(_xlpm.debt6090)=1),IF(AVERAGEIFS(_xlpm.debtChange,_xlpm.debt6090,1,_xlpm.EDP,0)<-0.5,"ok","Not met"), IF(AND(MAX(_xlpm.debt90)=1,MAX(_xlpm.debt6090)=0),IF(AVERAGEIFS(_xlpm.debtChange,_xlpm.EDP,0)<-1,"ok","Not met"), IF(AND(MAX(_xlpm.debt90)=1,MAX(_xlpm.debt6090)=1),IF(AND(AVERAGEIFS(_xlpm.debtChange,_xlpm.debt90,1,_xlpm.EDP,0)<-1,AVERAGEIFS(_xlpm.debtChange,_xlpm.debt6090,1,_xlpm.EDP,0)<-0.5),"ok","Not met")))), "Not applicable, debt below 60% of GDP by EDP correction")))) -> #NAME? | M12: =_xlfn.LET(_xlpm.debtChange,OFFSET('Adjustment scenario'!F58,0,1,1,$F$5), _xlpm.debt60,OFFSET('Adjustment scenario'!F86,0,1,1,$F$5), _xlpm.debt6090,OFFSET('Adjustment scenario'!F85,0,1,1,$F$5), _xlpm.debt90,OFFSET('Adjustment scenario'!F84,0,1,1,$F$5), _xlpm.EDP,OFFSET('Adjustment scenario'!F87,0,1,1,$F$5), IF(AND(MAX(_xlpm.debt90)=0,MAX(_xlpm.debt6090)=0),"Debt below 60% of GDP over the adjustment period", IF(MIN(_xlpm.EDP)=1,"Not applicable, reference year is the last year of adjustment", IFERROR(IF(AND(MAX(_xlpm.debt90)=0,MAX(_xlpm.debt6090)=1),AVERAGEIFS(_xlpm.debtChange,_xlpm.debt60,1,_xlpm.EDP,0), IF(AND(MAX(_xlpm.debt90)=1,MAX(_xlpm.debt6090)=0),AVERAGEIFS(_xlpm.debtChange,_xlpm.EDP,0), IF(AND(MAX(_xlpm.debt90)=1,MAX(_xlpm.debt6090)=1),AVERAGEIFS(_xlpm.debtChange,_xlpm.debt60,1,_xlpm.EDP,0)))), "Not applicable, debt below 60% of GDP by EDP correction")))) -> #NAME? | N12: =IF(AND(O12=0,F6<0.5),"not relevant","ok") -> ok | O12: =IF(AND('Input data'!$F$17=1,F6<0.5),COUNTIFS('Adjustment scenario'!F77:H77,"<="&-3.05),0)+IF(AND(F5=4,J19>0.4,J19>F6),1,COUNTIFS(J19:M19,">" & F6,J19:M19,">"&0.4)) -> 0 | P12: =IF(OR(AND(F5=4,Q12=0,F6<0.4),AND(F5=7,Q12=0,F6<0.25)),"not relevant, (over the adjustment horizon)","ok") -> ok | Q12: =IF(AND('Criteria results'!$F$5=4,'Criteria results'!$F$6<=0.4),COUNTIFS('Adjustment scenario'!G13:J13,0.4,'Adjustment scenario'!F88:I88,0),IF(AND('Criteria results'!$F$5=7,'Criteria results'!$F$6<=0.25),COUNTIFS('Adjustment scenario'!G13:M13,0.25,'Adjustment scenario'!F88:L88,0),0)) -> 0 | V12: 0.2
D13: Financial stress scenario | G13: =IF(OR('Adjustment scenario'!F57>60,'Adjustment scenario'!F77<-3),IF(SUM(OFFSET('Financial stress'!$F$75,0,$F$5+1,1,10))=0,"ok","Not met"),"") -> ok | J13: =IF(OR('Adjustment scenario'!F57>60,'Adjustment scenario'!F77<-3),IF(OFFSET('Financial stress'!$F$56,0,$F$5+10,1,1)<60,"ok","Not met"),"") -> ok | V13: 0.22
D14: Lower SPB scenario | G14: =IF(OR('Adjustment scenario'!F57>60,'Adjustment scenario'!F77<-3),IF(SUM(OFFSET('Lower SPB'!$F$75,0,$F$5+1,1,10))=0,"ok","Not met"),"") -> Not met | J14: =IF(OR('Adjustment scenario'!F57>60,'Adjustment scenario'!F77<-3),IF(OFFSET('Lower SPB'!$F$56,0,$F$5+10,1,1)<60,"ok","Not met"),"") -> ok | V14: 0.24
D15: Adverse r-g scenario | G15: =IF(OR('Adjustment scenario'!F57>60,'Adjustment scenario'!F77<-3),IF(SUM(OFFSET('Adverse (r-g)'!$F$76,0,$F$5+1,1,10))=0,"ok","Not met"),"") -> Not met | J15: =IF(OR('Adjustment scenario'!F57>60,'Adjustment scenario'!F77<-3),IF(OFFSET('Adverse (r-g)'!$F$57,0,$F$5+10,1,1)<60,"ok","Not met"),"") -> ok | V15: 0.26
D16: * The stochastic simulations are provided mainly for information, as the Excel worksheet only allows for an approximation of what is done in the Commission's Stata model. Indeed, in this Excel worksheet, the size of the cone of the fanchart is assumed to be constant over different adjustment paths. In ther Stata model, it is a non linear function of the level of debt, as shocks (in particular interest rate shocks) have different impacts according to the level of debt ratio. ** In case a smaller adjustment than the one implied by criterion 1 and criterion 2 is sufficient to ensure that debt is brought (and/or remains) below 60% of GDP under the adjustment scenario and all deterministic stress tests while ensuring that the criterion 3 is met, then that smaller, 'eased-up' adjustment is chosen. | L16: * The average change in debt is computed from the year before the start of the reference trajectory or the year in which the excessive deficit procedure is projected to be abrogated, whichever occurs last, until the end of the adjustment period. ** The deficit benchmark is applied in terms of change in SPB during the transitory period of 2025-2027 and in terms of change in SB thereafter. | V16: 0.28
G17: Table 4 - Main fiscal variables | V17: 0.3
G18: 2025 | H18: 2026 | I18: 2027 | J18: 2028 | K18: 2029 | L18: 2030 | M18: 2031 | V18: 0.32
D19: Annual adjustment (change in SPB) | G19: ='Adjustment scenario'!G12-'Adjustment scenario'!F12 -> 0.54 | H19: ='Adjustment scenario'!H12-'Adjustment scenario'!G12 -> 0.54 | I19: ='Adjustment scenario'!I12-'Adjustment scenario'!H12 -> 0.54 | J19: ='Adjustment scenario'!J12-'Adjustment scenario'!I12 -> 0.54 | K19: ='Adjustment scenario'!K12-'Adjustment scenario'!J12 -> 0 | L19: ='Adjustment scenario'!L12-'Adjustment scenario'!K12 -> 0 | M19: ='Adjustment scenario'!M12-'Adjustment scenario'!L12 -> 0 | V19: 0.34
D20: Net primary expenditure growth | G20: ='Adjustment scenario'!G79 -> 4.3473229 | H20: ='Adjustment scenario'!H79 -> 3.9515589 | I20: ='Adjustment scenario'!I79 -> 3.8782647 | J20: ='Adjustment scenario'!J79 -> 3.7186626 | K20: ='Adjustment scenario'!K79 -> 4.8725166 | L20: ='Adjustment scenario'!L79 -> 5.0202485 | M20: ='Adjustment scenario'!M79 -> 5.0859394 | V20: 0.36
D21: Headline balance | G21: ='Adjustment scenario'!G77 -> -3.5621614 | H21: ='Adjustment scenario'!H77 -> -2.4665795 | I21: ='Adjustment scenario'!I77 -> -2.0229571 | J21: ='Adjustment scenario'!J77 -> -1.5377055 | K21: ='Adjustment scenario'!K77 -> -1.3886474 | L21: ='Adjustment scenario'!L77 -> -1.2540637 | M21: ='Adjustment scenario'!M77 -> -1.1441947 | V21: 0.38
D22: Structural balance | G22: ='Adjustment scenario'!G78 -> -2.8066042 | H22: ='Adjustment scenario'!H78 -> -2.1796804 | I22: ='Adjustment scenario'!I78 -> -1.6524516 | J22: ='Adjustment scenario'!J78 -> -1.111623 | K22: ='Adjustment scenario'!K78 -> -1.1045924 | L22: ='Adjustment scenario'!L78 -> -1.1120362 | M22: ='Adjustment scenario'!M78 -> -1.1441947 | V22: 0.4
D23: Debt | G23: ='Adjustment scenario'!G57 -> 73.48544 | H23: ='Adjustment scenario'!H57 -> 71.299226 | I23: ='Adjustment scenario'!I57 -> 69.930407 | J23: ='Adjustment scenario'!J57 -> 68.203983 | K23: ='Adjustment scenario'!K57 -> 66.186518 | L23: ='Adjustment scenario'!L57 -> 64.043964 | M23: ='Adjustment scenario'!M57 -> 61.862434 | V23: 0.42
D24: Average annual adjustment over the plan period | G24: =AVERAGE(G19:J19) -> 0.54 | V24: 0.44
D25: Average annual adjustment over the adjustment period | G25: =IF(F5=4,AVERAGE(G19:J19),AVERAGE(G19:M19)) -> 0.54 | V25: 0.46
D26: Average net primary expenditure growth over the plan period | G26: =AVERAGE(G20:J20) -> 3.9739523 | V26: 0.48
D27: Average net primary expenditure growth over the adjustment period | G27: =IF(F5=4,AVERAGE(G20:J20),AVERAGE(G20:M20)) -> 3.9739523 | V27: 0.5
D28: In case of a plan with no extension, both the plan period and the adjustment period last 4 years. In case of a plan with extension, the plan period remains 4 years while the adjustment period lasts 7 years. Morever, in case of extension, if neither the deficit benchmark nor the deficit resilience safeguard are binding, the values in G24 and G25 (and G26 and G27) are the same. However, if the benchmark or the safeguard is binding, the values in those cells can be different. | V28: 0.52
V29: 0.54
G30: Table 5 - DSA-based adjustment * | V30: 0.56
G31: No extension | H31: Extension | V31: 0.58
D32: Number of years of adjustment | G32: 4 | H32: 7 | V32: 0.6
D33: Annual adjustment | G33: 0.7 | H33: 0.44 | V33: 0.62
D34: Probability that debt decreases | G34: 73.52 | H34: 72.809999 | V34: 0.64
D35: * The adjustment in this table does not account for the minimum adjustment of 0.5 pp. of GDP as a benchmark nor for the debt sustainability and deficit resillience safeguards. | V35: 0.66
V36: 0.68
H37: Table 6 - Reference trajectory | V37: 0.7
G38: Average (2025-28) | H38: 2025 | I38: 2026 | J38: 2027 | K38: 2028 | L38: 2029 | M38: 2030 | N38: 2031 | V38: 0.72
D39: Adjustment in a plan without extension | V39: 0.74
D40: Net primary expenditure growth | G40: 3.4713476 | H40: 3.9759682 | I40: 3.3802042 | J40: 3.33191 | K40: 3.1973079 | V40: 0.76
D41: Annual change in SPB | G41: 0.7 | H41: 0.7 | I41: 0.7 | J41: 0.7 | K41: 0.7 | V41: 0.78
...

Sheet Input data
B3: Country | C3: HU
B5: Last year before the adjustment | C5: 2024
B6: Last year of adjustment | C6: =C5+'Criteria results'!$F$5 -> 2028
B8: Key assumptions
C9: 2021 | D9: 2022 | E9: 2023 | F9: 2024 | G9: 2025 | H9: 2026 | I9: 2027 | J9: 2028 | K9: 2029 | L9: 2030 | M9: 2031 | N9: 2032 | O9: 2033 | P9: 2034 | Q9: 2035 | R9: 2036 | S9: 2037 | T9: 2038 | U9: 2039 | V9: 2040 | W9: 2041
B10: Fiscal assumptions (% of GDP)
B11: Key fiscal variables (based on the Commission 2024 autumn forecast ("AF 2024") T+2 forecast
B12: Debt | C12: 76.21938 | D12: 73.84293 | E12: 73.438 | F12: 74.041486
B13: Structural primary balance ('+' means 'surplus') | C13: -5.106841 | D13: -4.391969 | E13: -1.706974 | F13: 0.64244146
B14: One-off and other temporary measures | C14: -0.1079972 | D14: 0 | E14: 0 | F14: 0 | G14: 0 | H14: 0 | I14: 0 | J14: 0 | K14: 0 | L14: 0 | M14: 0 | N14: 0 | O14: 0 | P14: 0 | Q14: 0 | R14: 0 | S14: 0 | T14: 0 | U14: 0 | V14: 0 | W14: 0
B15: Stock-flow adjustments (without exchange rate effect) | C15: -0.1371056 | D15: 1.066777 | E15: 2.471388 | F15: 0.243711 | G15: -0.9088278 | H15: -0.250576 | I15: 0 | J15: 0 | K15: 0 | L15: 0 | M15: 0 | N15: 0 | O15: 0 | P15: 0 | Q15: 0 | R15: 0 | S15: 0 | T15: 0 | U15: 0 | V15: 0 | W15: 0
B16: Stock-flow adjustment (total) | C16: -0.0193077 | D16: 3.539191 | E16: 1.717452 | F16: 0.9714689 | G16: -0.3984276 | H16: -0.2505763 | I16: 0 | J16: 0 | K16: 0 | L16: 0 | M16: 0 | N16: 0 | O16: 0 | P16: 0 | Q16: 0 | R16: 0 | S16: 0 | T16: 0 | U16: 0 | V16: 0 | W16: 0
B17: Subject to an excessive deficit procedure (EDP) (0-no/1-yes) | D17: 0 | E17: 0 | F17: 1
B19: Cost of ageing and selected public revenue (based on the Commission-Council 2024 Ageing Report ("AR 2024"))
B20: Total ageing cost (net of taxes on pensions) | C20: =(C21+C22+C23+C24-C25) -> 0 | D20: =(D21+D22+D23+D24-D25) -> 16.0166 | E20: =(E21+E22+E23+E24-E25) -> 16.12175 | F20: =(F21+F22+F23+F24-F25) -> 16.12852 | G20: =(G21+G22+G23+G24-G25) -> 16.01381 | H20: =(H21+H22+H23+H24-H25) -> 15.92993 | I20: =(I21+I22+I23+I24-I25) -> 15.87402 | J20: =(J21+J22+J23+J24-J25) -> 15.87527 | ... W20: =(W21+W22+W23+W24-W25) -> 17.97964
B21: of which: Public pensions expenditure | C21: 0 | D21: 7.73961 | E21: 7.86712 | F21: 7.89282 | G21: 7.79042 | H21: 7.7091 | I21: 7.64957 | J21: 7.64073 | K21: 7.63699 | L21: 7.65466 | M21: 7.696 | N21: 7.75746 | O21: 7.84465 | P21: 7.95741 | Q21: 8.10221 | R21: 8.27487 | S21: 8.45598 | T21: 8.64171 | U21: 8.83856 | V21: 9.04742 | W21: 9.27667
B22: Health care expenditure | C22: 0 | D22: 4.25848 | E22: 4.26197 | F22: 4.27172 | G22: 4.29311 | H22: 4.31251 | I22: 4.33105 | J22: 4.34864 | K22: 4.36339 | L22: 4.3789 | M22: 4.39651 | N22: 4.4114 | O22: 4.42883 | P22: 4.44454 | Q22: 4.46141 | R22: 4.47899 | S22: 4.49627 | T22: 4.51363 | U22: 4.53049 | V22: 4.54811 | W22: 4.57039
B23: Long-term care expenditure | C23: 0 | D23: 0.54632 | E23: 0.55473 | F23: 0.55762 | G23: 0.55987 | H23: 0.56281 | I23: 0.57183 | J23: 0.57813 | K23: 0.58609 | L23: 0.59515 | M23: 0.6043 | N23: 0.61316 | O23: 0.62216 | P23: 0.63245 | Q23: 0.64295 | R23: 0.65212 | S23: 0.6596 | T23: 0.66717 | U23: 0.67515 | V23: 0.68309 | W23: 0.69041
B24: Education & unemployment benefits expenditure | C24: 0 | D24: 3.47219 | E24: 3.43793 | F24: 3.40636 | G24: 3.37041 | H24: 3.34551 | I24: 3.32157 | J24: 3.30777 | K24: 3.30112 | L24: 3.3021 | M24: 3.31313 | N24: 3.32796 | O24: 3.34261 | P24: 3.35719 | Q24: 3.37113 | R24: 3.38353 | S24: 3.39415 | T24: 3.40517 | U24: 3.41745 | V24: 3.43035 | W24: 3.44217
B25: Taxes on pensions | C25: 0 | D25: 0 | E25: 0 | F25: 0 | G25: 0 | H25: 0 | I25: 0 | J25: 0 | K25: 0 | L25: 0 | M25: 0 | N25: 0 | O25: 0 | P25: 0 | Q25: 0 | R25: 0 | S25: 0 | T25: 0 | U25: 0 | V25: 0 | W25: 0
B26: Property income | C26: 0.5353987 | D26: 1.178846 | E26: 2.102853 | F26: 2.07289 | G26: 2.042928 | H26: 2.012965 | I26: 1.983002 | J26: 1.953039 | K26: 1.923076 | L26: 1.893113 | M26: 1.86315 | N26: 1.833187 | O26: 1.803224 | P26: 1.773262 | Q26: 1.743299 | R26: 1.713336 | S26: 1.683373 | T26: 1.65341 | U26: 1.623447 | V26: 1.593484 | W26: 1.563521
B28: Real GDP growth assumptions (based on AF 2024 T+10 projections and AR 2024 projections)
B29: Actual GDP
B30: Growth rate | C30: 7.121139 | D30: 4.260908 | E30: -0.9462205 | F30: 0.584996 | G30: 1.621716 | H30: 3.054951 | I30: 1.70229 | J30: 1.604467 | K30: 1.566761 | L30: 1.78318 | M30: 1.910635 | N30: 1.917179 | O30: 1.834443 | P30: 1.853186 | Q30: 1.822487 | R30: 1.791788 | S30: 1.761082 | T30: 1.707647 | U30: 1.65297 | V30: 1.61876 | W30: 1.601132
B31: Level (billions, national currency) | C31: 133.9938
B32: Potential GDP
B33: Growth rate | C33: 3.162016 | D33: 2.736387 | E33: 1.87314 | F33: 1.38942 | G33: 1.533798 | H33: 1.720744 | I33: 1.709217 | J33: 1.611382 | K33: 1.573681 | L33: 1.78318 | M33: 1.910638 | N33: 1.917176 | O33: 1.834446 | P33: 1.853183 | Q33: 1.822484 | R33: 1.791785 | S33: 1.761086 | T33: 1.70765 | U33: 1.652967 | V33: 1.618756 | W33: 1.601132
B34: Level (billions, national currency) | C34: 132.9781
B36: Interest rates (AF 2024, %)
B37: Nominal implicit interest rate on debt | C37: 3.238231 | D37: 4.417456 | E37: 7.284665 | F37: 7.231643 | G37: 5.674904 | H37: 5.648431
B38: Short-term nominal interest rate | D38: 10.32 | E38: 15.97 | F38: 7.275548 | G38: 5.939488 | H38: 5.742086
B39: Long-term nominal interest rate | D39: 7.57 | E39: 7.51 | F39: 6.52395 | G39: 6.731379 | H39: 6.82931
F40: Bloomberg data, country-specific forward market rates.
B41: Inflation (AF 2024, %)
B42: GDP deflator (national currency) | C42: 6.261158 | D42: 14.22793 | E42: 14.56683 | F42: 7.183265 | G42: 4.066847 | H42: 3.484137
B44: Net primary expenditure growth (AF 2024, %)
B45: Net primary expenditure growth | C45: 0 | D45: 22.282169 | E45: 8.9931862 | F45: 4.6
B47: Additional parameters
E48: Sources
B49: Fiscal multiplier | C49: 0.75 | E49: Carnot, N. and de Castro, F. (2015), “The Discretionary Fiscal Effort: an Assessment of Fiscal Policy and its Output Effect”, European Economy, Economic Papers, No. 543.
...

Sheet Baseline NFPC
B3: Country | C3: ='Input data'!C3 -> HU
B4: Key years
B5: ='Input data'!B5 -> Last year before the adjustment | C5: =+'Input data'!C5 -> 2024
B6: Last year of adjustment | C6: =+C5+'Criteria results'!$F$5 -> 2028
B9: Key assumptions
C10: 2021 | D10: 2022 | E10: 2023 | F10: 2024 | G10: 2025 | H10: 2026 | I10: 2027 | J10: 2028 | K10: 2029 | L10: 2030 | M10: 2031 | N10: 2032 | O10: 2033 | P10: 2034 | Q10: 2035 | R10: 2036 | S10: 2037 | T10: 2038 | U10: 2039 | V10: 2040 | W10: 2041
B11: Fiscal assumptions (% of GDP)
B12: Structural primary balance ('+' means 'surplus') | C12: ='Input data'!C13 -> -5.106841 | D12: ='Input data'!D13 -> -4.391969 | E12: ='Input data'!E13 -> -1.706974 | F12: ='Input data'!F13 -> 0.64244146 | G12: =F12 -> 0.64244146 | H12: =G12 -> 0.64244146 | I12: =H12 -> 0.64244146 | J12: =I12 -> 0.64244146 | K12: =J12 -> 0.64244146 | L12: =K12 -> 0.64244146 | M12: =L12 -> 0.64244146 | N12: =M12 -> 0.64244146 | ... W12: =V12 -> 0.64244146
B13: One-off and other temporary measures | C13: ='Input data'!C14 -> -0.1079972 | D13: ='Input data'!D14 -> 0 | E13: ='Input data'!E14 -> 0 | F13: ='Input data'!F14 -> 0 | G13: ='Input data'!G14 -> 0 | H13: ='Input data'!H14 -> 0 | I13: ='Input data'!I14 -> 0 | J13: ='Input data'!J14 -> 0 | ... W13: ='Input data'!W14 -> 0
B14: Stock flow adjustments (without exchange rate effect) | C14: ='Input data'!C15 -> -0.1371056 | D14: ='Input data'!D15 -> 1.066777 | E14: ='Input data'!E15 -> 2.471388 | F14: ='Input data'!F15 -> 0.243711 | G14: ='Input data'!G15 -> -0.9088278 | H14: ='Input data'!H15 -> -0.250576 | I14: ='Input data'!I15 -> 0 | J14: ='Input data'!J15 -> 0 | ... W14: ='Input data'!W15 -> 0
B16: ='Input data'!B19 -> Cost of ageing and selected public revenue (based on the Commission-Council 2024 Ageing Report ("AR 2024"))
B17: Total ageing cost (net of taxes on pensions) | C17: ='Input data'!C20 -> 0 | D17: ='Input data'!D20 -> 16.0166 | E17: ='Input data'!E20 -> 16.12175 | F17: ='Input data'!F20 -> 16.12852 | G17: ='Input data'!G20 -> 16.01381 | H17: ='Input data'!H20 -> 15.92993 | I17: ='Input data'!I20 -> 15.87402 | J17: ='Input data'!J20 -> 15.87527 | ... W17: ='Input data'!W20 -> 17.97964
B18: ='Input data'!B26 -> Property income | C18: ='Input data'!C26 -> 0.5353987 | D18: ='Input data'!D26 -> 1.178846 | E18: ='Input data'!E26 -> 2.102853 | F18: ='Input data'!F26 -> 2.07289 | G18: ='Input data'!G26 -> 2.042928 | H18: ='Input data'!H26 -> 2.012965 | I18: ='Input data'!I26 -> 1.983002 | ... W18: ='Input data'!W26 -> 1.563521
B20: GDP growth assumptions
B21: Actual GDP (real)
B22: Level | C22: ='Input data'!C31 -> 133.9938 | D22: =C22*(D23/100+1) -> 139.70315 | E22: =D22*(E23/100+1) -> 138.38125 | F22: =E22*(F23/100+1) -> 139.19078 | G22: =F22*(G23/100+1) -> 141.44806 | H22: =G22*(H23/100+1) -> 145.76923 | I22: =H22*(I23/100+1) -> 148.25064 | J22: =I22*(J23/100+1) -> 150.62927 | K22: =J22*(K23/100+1) -> 152.98927 | ... W22: =V22*(W23/100+1) -> 188.86761
B23: Growth rate | C23: =+'Input data'!C30 -> 7.121139 | D23: =+'Input data'!D30 -> 4.260908 | E23: =+'Input data'!E30 -> -0.9462205 | F23: =+'Input data'!F30 -> 0.584996 | G23: =+'Input data'!G30 -> 1.621716 | H23: =+'Input data'!H30 -> 3.054951 | I23: =+'Input data'!I30 -> 1.70229 | J23: =+'Input data'!J30 -> 1.604467 | ... W23: =+'Input data'!W30 -> 1.601132
B25: Potential GDP (real)
B26: Level | C26: ='Input data'!C34 -> 132.9781 | D26: =+C26*(1+'Input data'!D33/100) -> 136.6169 | E26: =+D26*(1+'Input data'!E33/100) -> 139.17592 | F26: =+E26*(1+'Input data'!F33/100) -> 141.10966 | G26: =+F26*(1+'Input data'!G33/100) -> 143.274 | H26: =+G26*(1+'Input data'!H33/100) -> 145.73938 | I26: =+H26*(1+'Input data'!I33/100) -> 148.23038 | J26: =+I26*(1+'Input data'!J33/100) -> 150.61893 | K26: =+J26*(1+'Input data'!K33/100) -> 152.9892 | ... W26: =+V26*(1+'Input data'!W33/100) -> 188.8675
B28: Output gap
B29: Output gap | C29: =100*(C22/C26-1) -> 0.76380998 | D29: =100*(D22/D26-1) -> 2.2590596 | E29: =100*(E22/E26-1) -> -0.5709813 | F29: =100*(F22/F26-1) -> -1.3598515 | G29: =100*(G22/G26-1) -> -1.2744391 | H29: =100*(H22/H26-1) -> 0.020481993 | I29: =100*(I22/I26-1) -> 0.013670006 | J29: =100*(J22/J26-1) -> 0.0068637352 | ... W29: =100*(W22/W26-1) -> 5.637904e-05
B31: Actual GDP (nominal, national currency)
B32: Growth rate | C32: =100*((1+C23/100)*(1+C41/100)-1) -> 13.828163 | D32: =100*((1+D23/100)*(1+D41/100)-1) -> 19.095077 | E32: =100*((1+E23/100)*(1+E41/100)-1) -> 13.482775 | F32: =100*((1+F23/100)*(1+F41/100)-1) -> 7.8102828 | G32: =100*((1+G23/100)*(1+G41/100)-1) -> 5.7545157 | H32: =100*((1+H23/100)*(1+H41/100)-1) -> 6.6455267 | I32: =100*((1+I23/100)*(1+I41/100)-1) -> 5.1829185 | J32: =100*((1+J23/100)*(1+J41/100)-1) -> 5.0189895 | ... W32: =100*((1+W23/100)*(1+W41/100)-1) -> 4.6425619
B34: Interest rate
B35: Nominal implicit interest rate on debt | C35: ='Input data'!C37 -> 3.238231 | D35: ='Input data'!D37 -> 4.417456 | E35: ='Input data'!E37 -> 7.284665 | F35: ='Input data'!F37 -> 7.231643 | G35: ='Input data'!G37 -> 5.674904 | H35: ='Input data'!H37 -> 5.648431 | I35: =I96 -> 5.773885 | J35: =J96 -> 5.8928417 | K35: =K96 -> 6.002884 | L35: =L96 -> 6.1046284 | M35: =M96 -> 6.1987976 | N35: =N96 -> 6.2860989 | O35: =O96 -> 6.3670321 | P35: =P96 -> 6.4420993 | ... W35: =W96 -> 6.3394094
B36: Long-term interest rate | E36: ='Input data'!E39 -> 7.51 | F36: ='Input data'!F39 -> 6.52395 | G36: ='Input data'!G39 -> 6.731379 | H36: ='Input data'!H39 -> 6.82931 | I36: =H36+($P$36-$H$36)/($P$10-$H$10) -> 6.8414188 | J36: =I36+($P$36-$H$36)/($P$10-$H$10) -> 6.8535275 | K36: =J36+($P$36-$H$36)/($P$10-$H$10) -> 6.8656362 | L36: =K36+($P$36-$H$36)/($P$10-$H$10) -> 6.877745 | M36: =L36+($P$36-$H$36)/($P$10-$H$10) -> 6.8898537 | N36: =M36+($P$36-$H$36)/($P$10-$H$10) -> 6.9019625 | O36: =N36+($P$36-$H$36)/($P$10-$H$10) -> 6.9140712 | P36: ='Input data'!$C$52 -> 6.92618 | Q36: =$P$36+('Input data'!$C$54-'Input data'!$C$52)/20*(Q$10-$P$10) -> 6.829871 | R36: =$P$36+('Input data'!$C$54-'Input data'!$C$52)/20*(R$10-$P$10) -> 6.733562 | S36: =$P$36+('Input data'!$C$54-'Input data'!$C$52)/20*(S$10-$P$10) -> 6.637253 | T36: =$P$36+('Input data'!$C$54-'Input data'!$C$52)/20*(T$10-$P$10) -> 6.540944 | U36: =$P$36+('Input data'!$C$54-'Input data'!$C$52)/20*(U$10-$P$10) -> 6.444635 | V36: =$P$36+('Input data'!$C$54-'Input data'!$C$52)/20*(V$10-$P$10) -> 6.348326 | W36: =$P$36+('Input data'!$C$54-'Input data'!$C$52)/20*(W$10-$P$10) -> 6.252017
B37: Short-term interest rate | E37: ='Input data'!E$38 -> 15.97 | F37: ='Input data'!F$38 -> 7.275548 | G37: ='Input data'!G$38 -> 5.939488 | H37: ='Input data'!H$38 -> 5.742086 | I37: =H37+($P$37-$H$37)/($P$10-$H$10) -> 5.8370877 | J37: =I37+($P$37-$H$37)/($P$10-$H$10) -> 5.9320895 | K37: =J37+($P$37-$H$37)/($P$10-$H$10) -> 6.0270912 | L37: =K37+($P$37-$H$37)/($P$10-$H$10) -> 6.122093 | M37: =L37+($P$37-$H$37)/($P$10-$H$10) -> 6.2170947 | N37: =M37+($P$37-$H$37)/($P$10-$H$10) -> 6.3120965 | O37: =N37+($P$37-$H$37)/($P$10-$H$10) -> 6.4070982 | P37: ='Input data'!$C$53 -> 6.5021 | Q37: =$P$37+('Input data'!$C$55-'Input data'!$C$53)/20*(Q$10-$P$10) -> 6.301995 | R37: =$P$37+('Input data'!$C$55-'Input data'!$C$53)/20*(R$10-$P$10) -> 6.10189 | S37: =$P$37+('Input data'!$C$55-'Input data'!$C$53)/20*(S$10-$P$10) -> 5.901785 | T37: =$P$37+('Input data'!$C$55-'Input data'!$C$53)/20*(T$10-$P$10) -> 5.70168 | U37: =$P$37+('Input data'!$C$55-'Input data'!$C$53)/20*(U$10-$P$10) -> 5.501575 | V37: =$P$37+('Input data'!$C$55-'Input data'!$C$53)/20*(V$10-$P$10) -> 5.30147 | W37: =$P$37+('Input data'!$C$55-'Input data'!$C$53)/20*(W$10-$P$10) -> 5.101365
B38: Share of long-term debt that matures every year | C38: 0.07935879 | D38: 0.06020197 | E38: 0.05046041 | F38: 0.06743385 | G38: =IF(OR($C$3="EL",$C$3="CY",$C$3="IE",$C$3="PT"),VLOOKUP($C$3,$B$110:$T$114,MATCH(G$10,$B$110:$T$110,0),0),$F$38+('Input data'!$C$59-$F$38)/($P$10-$F$10)*(G10-$F$10)) -> 0.068498038 | H38: =IF(OR($C$3="EL",$C$3="CY",$C$3="IE",$C$3="PT"),VLOOKUP($C$3,$B$110:$T$114,MATCH(H$10,$B$110:$T$110,0),0),$F$38+('Input data'!$C$59-$F$38)/($P$10-$F$10)*(H10-$F$10)) -> 0.069562226 | I38: =IF(OR($C$3="EL",$C$3="CY",$C$3="IE",$C$3="PT"),VLOOKUP($C$3,$B$110:$T$114,MATCH(I$10,$B$110:$T$110,0),0),$F$38+('Input data'!$C$59-$F$38)/($P$10-$F$10)*(I10-$F$10)) -> 0.070626414 | J38: =IF(OR($C$3="EL",$C$3="CY",$C$3="IE",$C$3="PT"),VLOOKUP($C$3,$B$110:$T$114,MATCH(J$10,$B$110:$T$110,0),0),$F$38+('Input data'!$C$59-$F$38)/($P$10-$F$10)*(J10-$F$10)) -> 0.071690602 | K38: =IF(OR($C$3="EL",$C$3="CY",$C$3="IE",$C$3="PT"),VLOOKUP($C$3,$B$110:$T$114,MATCH(K$10,$B$110:$T$110,0),0),$F$38+('Input data'!$C$59-$F$38)/($P$10-$F$10)*(K10-$F$10)) -> 0.07275479 | L38: =IF(OR($C$3="EL",$C$3="CY",$C$3="IE",$C$3="PT"),VLOOKUP($C$3,$B$110:$T$114,MATCH(L$10,$B$110:$T$110,0),0),$F$38+('Input data'!$C$59-$F$38)/($P$10-$F$10)*(L10-$F$10)) -> 0.073818978 | M38: =IF(OR($C$3="EL",$C$3="CY",$C$3="IE",$C$3="PT"),VLOOKUP($C$3,$B$110:$T$114,MATCH(M$10,$B$110:$T$110,0),0),$F$38+('Input data'!$C$59-$F$38)/($P$10-$F$10)*(M10-$F$10)) -> 0.074883166 | N38: =IF(OR($C$3="EL",$C$3="CY",$C$3="IE",$C$3="PT"),VLOOKUP($C$3,$B$110:$T$114,MATCH(N$10,$B$110:$T$110,0),0),$F$38+('Input data'!$C$59-$F$38)/($P$10-$F$10)*(N10-$F$10)) -> 0.075947354 | O38: =IF(OR($C$3="EL",$C$3="CY",$C$3="IE",$C$3="PT"),VLOOKUP($C$3,$B$110:$T$114,MATCH(O$10,$B$110:$T$110,0),0),$F$38+('Input data'!$C$59-$F$38)/($P$10-$F$10)*(O10-$F$10)) -> 0.077011542 | P38: =IF(OR($C$3="EL",$C$3="CY",$C$3="IE",$C$3="PT"),VLOOKUP($C$3,$B$110:$T$114,MATCH(P$10,$B$110:$T$110,0),0),'Input data'!$C$59) -> 0.07807573 | Q38: =IF(OR($C$3="EL",$C$3="CY",$C$3="IE",$C$3="PT"),VLOOKUP($C$3,$B$110:$T$114,MATCH(Q$10,$B$110:$T$110,0),0),'Input data'!$C$59) -> 0.07807573 | R38: =IF(OR($C$3="EL",$C$3="CY",$C$3="IE",$C$3="PT"),VLOOKUP($C$3,$B$110:$T$114,MATCH(R$10,$B$110:$T$110,0),0),'Input data'!$C$59) -> 0.07807573 | S38: =IF(OR($C$3="EL",$C$3="CY",$C$3="IE",$C$3="PT"),VLOOKUP($C$3,$B$110:$T$114,MATCH(S$10,$B$110:$T$110,0),0),'Input data'!$C$59) -> 0.07807573 | T38: =IF(OR($C$3="EL",$C$3="CY",$C$3="IE",$C$3="PT"),VLOOKUP($C$3,$B$110:$T$114,MATCH(T$10,$B$110:$T$110,0),0),'Input data'!$C$59) -> 0.07807573 | U38: =IF(OR($C$3="EL",$C$3="CY",$C$3="IE",$C$3="PT"),VLOOKUP($C$3,$B$110:$W$114,MATCH(U$10,$B$110:$W$110,0),0),'Input data'!$C$59) -> 0.07807573 | V38: =IF(OR($C$3="EL",$C$3="CY",$C$3="IE",$C$3="PT"),VLOOKUP($C$3,$B$110:$W$114,MATCH(V$10,$B$110:$W$110,0),0),'Input data'!$C$59) -> 0.07807573 | W38: =IF(OR($C$3="EL",$C$3="CY",$C$3="IE",$C$3="PT"),VLOOKUP($C$3,$B$110:$W$114,MATCH(W$10,$B$110:$W$110,0),0),'Input data'!$C$59) -> 0.07807573
B40: Inflation and exchange rate
B41: GDP deflator (national currency) | C41: ='Input data'!C42 -> 6.261158 | D41: ='Input data'!D42 -> 14.22793 | E41: ='Input data'!E42 -> 14.56683 | F41: ='Input data'!F42 -> 7.183265 | G41: ='Input data'!G42 -> 4.066847 | H41: ='Input data'!H42 -> 3.484137 | I41: =$H$41+($P$41-$H$41)/($P$10-$H$10)*(I10-$H$10) -> 3.4223699 | J41: =$H$41+($P$41-$H$41)/($P$10-$H$10)*(J10-$H$10) -> 3.3606027 | K41: =$H$41+($P$41-$H$41)/($P$10-$H$10)*(K10-$H$10) -> 3.2988356 | L41: =$H$41+($P$41-$H$41)/($P$10-$H$10)*(L10-$H$10) -> 3.2370685 | M41: =$H$41+($P$41-$H$41)/($P$10-$H$10)*(M10-$H$10) -> 3.1753014 | N41: =$H$41+($P$41-$H$41)/($P$10-$H$10)*(N10-$H$10) -> 3.1135343 | O41: =$H$41+($P$41-$H$41)/($P$10-$H$10)*(O10-$H$10) -> 3.0517671 | P41: ='Input data'!$C$61 -> 2.99 | Q41: =$P$41+('Input data'!$C$62-'Input data'!$C$61)/20*(Q$10-$P$10) -> 2.9905 | R41: =$P$41+('Input data'!$C$62-'Input data'!$C$61)/20*(R$10-$P$10) -> 2.991 | S41: =$P$41+('Input data'!$C$62-'Input data'!$C$61)/20*(S$10-$P$10) -> 2.9915 | T41: =$P$41+('Input data'!$C$62-'Input data'!$C$61)/20*(T$10-$P$10) -> 2.992 | U41: =$P$41+('Input data'!$C$62-'Input data'!$C$61)/20*(U$10-$P$10) -> 2.9925 | V41: =$P$41+('Input data'!$C$62-'Input data'!$C$61)/20*(V$10-$P$10) -> 2.993 | W41: =$P$41+('Input data'!$C$62-'Input data'!$C$61)/20*(W$10-$P$10) -> 2.9935
B42: Exchange rate composite change (weighted by share of debt in each currency) | C42: 1.001704 | D42: 1.038632 | E42: 0.9884134 | F42: 1.010684 | G42: 1.007245 | H42: 1 | I42: 1 | J42: 1 | K42: 1 | L42: 1 | M42: 1 | N42: 1 | O42: 1 | P42: 1 | Q42: 1 | R42: 1 | S42: 1 | T42: 1 | U42: 1 | V42: 1 | W42: 1
B44: Intermediate calculations (growth rate equation)
B46: Fiscal multiplier | C46: ='Input data'!C49 -> 0.75
B47: Budget balance semi-elasticity | C47: ='Input data'!C50 -> 0.453
B49: Auxiliary variable to control the closure of the output gap | D49: =IF(AND(ABS((D12-C12)-('Input data'!D13-'Input data'!C13))>0.0001,ABS(D12-C12)>0.0001,D$10>$C$5),4,IF(C49=4,3,IF(C49=3,2,IF(C49=2,1,0)))) -> 0 | E49: =IF(AND(ABS((E12-D12)-('Input data'!E13-'Input data'!D13))>0.0001,ABS(E12-D12)>0.0001,E$10>$C$5),4,IF(D49=4,3,IF(D49=3,2,IF(D49=2,1,0)))) -> 0 | F49: =IF(AND(ABS((F12-E12)-('Input data'!F13-'Input data'!E13))>0.0001,ABS(F12-E12)>0.0001,F$10>$C$5),4,IF(E49=4,3,IF(E49=3,2,IF(E49=2,1,0)))) -> 0 | G49: =IF(AND(ABS(G12-F12)>0.0001,G$10>$C$5),4,IF(F49=4,3,IF(F49=3,2,IF(F49=2,1,0)))) -> 0 | H49: =IF(AND(ABS(H12-G12)>0.0001,H$10>$C$5),4,IF(G49=4,3,IF(G49=3,2,IF(G49=2,1,0)))) -> 0 | I49: =IF(AND(ABS(I12-H12)>0.0001,I$10>$C$5),4,IF(H49=4,3,IF(H49=3,2,IF(H49=2,1,0)))) -> 0 | J49: =IF(AND(ABS(J12-I12)>0.0001,J$10>$C$5),4,IF(I49=4,3,IF(I49=3,2,IF(I49=2,1,0)))) -> 0 | K49: =IF(AND(ABS(K12-J12)>0.0001,K$10>$C$5),4,IF(J49=4,3,IF(J49=3,2,IF(J49=2,1,0)))) -> 0 | L49: =IF(AND(ABS(L12-K12)>0.0001,L$10>$C$5),4,IF(K49=4,3,IF(K49=3,2,IF(K49=2,1,0)))) -> 0 | M49: =IF(AND(ABS(M12-L12)>0.0001,M$10>$C$5),4,IF(L49=4,3,IF(L49=3,2,IF(L49=2,1,0)))) -> 0 | N49: =IF(AND(ABS(N12-M12)>0.0001,N$10>$C$5),4,IF(M49=4,3,IF(M49=3,2,IF(M49=2,1,0)))) -> 0 | ... W49: =IF(AND(ABS(W12-V12)>0.0001,W$10>$C$5),4,IF(V49=4,3,IF(V49=3,2,IF(V49=2,1,0)))) -> 0
B50: OG intermediate auxiliary value | D50: =IF(C49=4,2/3*C29,IF(C49=3,1/3*B29,0)) -> 0 | E50: =IF(D49=4,2/3*D29,IF(D49=3,1/3*C29,0)) -> 0 | F50: =IF(E49=4,2/3*E29,IF(E49=3,1/3*D29,0)) -> 0 | G50: =IF(F49=4,2/3*F29,IF(F49=3,1/3*E29,0)) -> 0 | H50: =IF(G49=4,2/3*G29,IF(G49=3,1/3*F29,0)) -> 0 | I50: =IF(H49=4,2/3*H29,IF(H49=3,1/3*G29,0)) -> 0 | J50: =IF(I49=4,2/3*I29,IF(I49=3,1/3*H29,0)) -> 0 | K50: =IF(J49=4,2/3*J29,IF(J49=3,1/3*I29,0)) -> 0 | ... W50: =IF(V49=4,2/3*V29,IF(V49=3,1/3*U29,0)) -> 0
B51: GDP intermediate growth rate - only feedback effect and no closure of the OG | D51: ='Input data'!D30-$C$46*((D12-C12)-('Input data'!D13-'Input data'!C13)) -> 4.260908 | E51: ='Input data'!E30-$C$46*((E12-D12)-('Input data'!E13-'Input data'!D13)) -> -0.9462205 | F51: ='Input data'!F30-$C$46*((F12-E12)-('Input data'!F13-'Input data'!E13)) -> 0.584996 | G51: ='Input data'!G30-$C$46*((G12-F12)-('Input data'!G13-'Input data'!F13)) -> 1.1398849 | H51: ='Input data'!H30-$C$46*((H12-G12)) -> 3.054951 | I51: ='Input data'!I30-$C$46*((I12-H12)) -> 1.70229 | J51: ='Input data'!J30-$C$46*((J12-I12)) -> 1.604467 | K51: ='Input data'!K30-$C$46*((K12-J12)) -> 1.566761 | L51: ='Input data'!L30-$C$46*((L12-K12)) -> 1.78318 | M51: ='Input data'!M30-$C$46*((M12-L12)) -> 1.910635 | N51: ='Input data'!N30-$C$46*((N12-M12)) -> 1.917179 | O51: ='Input data'!O30-$C$46*((O12-N12)) -> 1.834443 | ... W51: ='Input data'!W30-$C$46*((W12-V12)) -> 1.601132
B53: Debt projections
C55: 2021 | D55: 2022 | E55: 2023 | F55: 2024 | G55: 2025 | H55: 2026 | I55: 2027 | J55: 2028 | K55: 2029 | L55: 2030 | M55: 2031 | N55: 2032 | O55: 2033 | P55: 2034 | Q55: 2035 | R55: 2036 | S55: 2037 | T55: 2038 | U55: 2039 | V55: 2040 | W55: 2041
B56: Gross debt | C56: =+'Input data'!C12 -> 76.21938 | D56: =+C56+D57 -> 73.842909 | E56: =+D56+E57 -> 73.437974 | F56: =+E56+F57 -> 74.041486 | G56: =+F56+G57 -> 73.466416 | H56: =+G56+H57 -> 71.738571 | I56: =+H56+I57 -> 71.328386 | J56: =+I56+J57 -> 71.142952 | K56: =+J56+K57 -> 71.145504 | ... W56: =+V56+W57 -> 88.591971
...

Sheet Adjustment scenario
B3: Country | C3: ='Input data'!C3 -> HU
B4: Key years
B5: ='Input data'!B5 -> Last year before the adjustment | C5: =+'Input data'!C5 -> 2024
B6: Last year of adjustment | C6: =+C5+'Criteria results'!$F$5 -> 2028
B7: Last year of no-fiscal-policy-change projections | C7: =C5+'Criteria results'!$F$5+10 -> 2038
B9: Key assumptions
C10: 2021 | D10: 2022 | E10: 2023 | F10: 2024 | G10: 2025 | H10: 2026 | I10: 2027 | J10: 2028 | K10: 2029 | L10: 2030 | M10: 2031 | N10: 2032 | O10: 2033 | P10: 2034 | Q10: 2035 | R10: 2036 | S10: 2037 | T10: 2038 | U10: 2039 | V10: 2040 | W10: 2041
B11: Fiscal assumptions (% of GDP)
B12: Structural primary balance ('+' means 'surplus') | C12: ='Input data'!C13 -> -5.106841 | D12: ='Input data'!D13 -> -4.391969 | E12: ='Input data'!E13 -> -1.706974 | F12: ='Input data'!F13 -> 0.64244146 | G12: =IF(G10<=$C$6, IF(AND(F87=1,F77<=-3.05,'Criteria results'!$F$6<0.5),F12+0.5, IF(AND(F78<=-1.55,'Criteria results'!$F$5=4,'Criteria results'!$F$6<0.4),F12+0.4, IF(AND(F78<=-1.55,'Criteria results'!$F$5=7,'Criteria results'!$F$6<0.25),F12+0.25, F12+'Criteria results'!$F$6))),F12) -> 1.1824415 | H12: =IF(H10<=$C$6, IF(AND(G87=1,G77<=-3.05,'Criteria results'!$F$6<0.5),G12+0.5, IF(AND(G78<=-1.55,'Criteria results'!$F$5=4,'Criteria results'!$F$6<0.4),G12+0.4, IF(AND(G78<=-1.55,'Criteria results'!$F$5=7,'Criteria results'!$F$6<0.25),G12+0.25, G12+'Criteria results'!$F$6))),G12) -> 1.7224415 | I12: =IF(I10<=$C$6, IF(AND(H87=1,H77<=-3.05,'Criteria results'!$F$6<0.5),H12+0.5, IF(AND(H78<=-1.55,'Criteria results'!$F$5=4,'Criteria results'!$F$6<0.4),H12+0.4, IF(AND(H78<=-1.55,'Criteria results'!$F$5=7,'Criteria results'!$F$6<0.25),H12+0.25, H12+'Criteria results'!$F$6))),H12) -> 2.2624415 | J12: =IF(J10<=$C$6, IF(AND(I87=1,I77<=-3.05,'Criteria results'!$F$6<0.5+J91),I12+0.5+J91, IF(AND(I78<=-1.55,'Criteria results'!$F$5=4,'Criteria results'!$F$6<0.4),I12+0.4, IF(AND(I78<=-1.55,'Criteria results'!$F$5=7,'Criteria results'!$F$6<0.25),I12+0.25, I12+'Criteria results'!$F$6))),I12) -> 2.8024415 | K12: =IF(K10<=$C$6, IF(AND(J87=1,J77<=-3.05,'Criteria results'!$F$6<0.5+K91),J12+0.5+K91, IF(AND(J78<=-1.55,'Criteria results'!$F$5=4,'Criteria results'!$F$6<0.4),J12+0.4, IF(AND(J78<=-1.55,'Criteria results'!$F$5=7,'Criteria results'!$F$6<0.25),J12+0.25, J12+'Criteria results'!$F$6))),J12) -> 2.8024415 | L12: =IF(L10<=$C$6, IF(AND(K87=1,K77<=-3.05,'Criteria results'!$F$6<0.5+L91),K12+0.5+L91, IF(AND(K78<=-1.55,'Criteria results'!$F$5=4,'Criteria results'!$F$6<0.4),K12+0.4, IF(AND(K78<=-1.55,'Criteria results'!$F$5=7,'Criteria results'!$F$6<0.25),K12+0.25, K12+'Criteria results'!$F$6))),K12) -> 2.8024415 | M12: =IF(M10<=$C$6, IF(AND(L87=1,L77<=-3.05,'Criteria results'!$F$6<0.5+M91),L12+0.5+M91, IF(AND(L78<=-1.55,'Criteria results'!$F$5=4,'Criteria results'!$F$6<0.4),L12+0.4, IF(AND(L78<=-1.55,'Criteria results'!$F$5=7,'Criteria results'!$F$6<0.25),L12+0.25, L12+'Criteria results'!$F$6))),L12) -> 2.8024415 | N12: =M12 -> 2.8024415 | O12: =N12 -> 2.8024415 | P12: =O12 -> 2.8024415 | Q12: =P12 -> 2.8024415 | R12: =Q12 -> 2.8024415 | S12: =R12 -> 2.8024415 | T12: =S12 -> 2.8024415 | U12: =T12 -> 2.8024415 | ... W12: =V12 -> 2.8024415
B13: Annual change in SPB | G13: =G12-F12 -> 0.54 | H13: =H12-G12 -> 0.54 | I13: =I12-H12 -> 0.54 | J13: =J12-I12 -> 0.54 | K13: =K12-J12 -> 0 | L13: =L12-K12 -> 0 | M13: =M12-L12 -> 0 | N13: =N12-M12 -> 0 | ... W13: =W12-V12 -> 0
B14: One-off and other temporary measures | C14: ='Input data'!C14 -> -0.1079972 | D14: ='Input data'!D14 -> 0 | E14: ='Input data'!E14 -> 0 | F14: ='Input data'!F14 -> 0 | G14: ='Input data'!G14 -> 0 | H14: ='Input data'!H14 -> 0 | I14: ='Input data'!I14 -> 0 | J14: ='Input data'!J14 -> 0 | ... W14: ='Input data'!W14 -> 0
B15: Stock flow adjustments (without exchange rate effect) | C15: ='Input data'!C15 -> -0.1371056 | D15: ='Input data'!D15 -> 1.066777 | E15: ='Input data'!E15 -> 2.471388 | F15: ='Input data'!F15 -> 0.243711 | G15: ='Input data'!G15 -> -0.9088278 | H15: ='Input data'!H15 -> -0.250576 | I15: ='Input data'!I15 -> 0 | J15: ='Input data'!J15 -> 0 | ... W15: ='Input data'!W15 -> 0
B17: ='Input data'!B19 -> Cost of ageing and selected public revenue (based on the Commission-Council 2024 Ageing Report ("AR 2024"))
B18: Total ageing cost (net of taxes on pensions) | C18: ='Input data'!C20 -> 0 | D18: ='Input data'!D20 -> 16.0166 | E18: ='Input data'!E20 -> 16.12175 | F18: ='Input data'!F20 -> 16.12852 | G18: ='Input data'!G20 -> 16.01381 | H18: ='Input data'!H20 -> 15.92993 | I18: ='Input data'!I20 -> 15.87402 | J18: ='Input data'!J20 -> 15.87527 | ... W18: ='Input data'!W20 -> 17.97964
B19: Property income | C19: ='Input data'!C26 -> 0.5353987 | D19: ='Input data'!D26 -> 1.178846 | E19: ='Input data'!E26 -> 2.102853 | F19: ='Input data'!F26 -> 2.07289 | G19: ='Input data'!G26 -> 2.042928 | H19: ='Input data'!H26 -> 2.012965 | I19: ='Input data'!I26 -> 1.983002 | J19: ='Input data'!J26 -> 1.953039 | ... W19: ='Input data'!W26 -> 1.563521
B21: GDP growth assumptions
B22: Actual GDP (real)
B23: Level | C23: ='Input data'!C31 -> 133.9938 | D23: ='Baseline NFPC'!D22 -> 139.70315 | E23: ='Baseline NFPC'!E22 -> 138.38125 | F23: ='Baseline NFPC'!F22 -> 139.19078 | G23: =IF(AND(G50>1,F50>1), G27*(1+('Baseline NFPC'!G$29+G51)/100)-F23*$C$47*(G12-F12)/100, IF(G50=1,G27,F23*(1+G52/100))) -> 140.88433 | H23: =IF(AND(H50>1,G50>1), H27*(1+('Baseline NFPC'!H$29+H51)/100)-G23*$C$47*(H12-G12)/100, IF(H50=1,H27,G23*(1+H52/100))) -> 144.81636 | I23: =IF(AND(I50>1,H50>1), I27*(1+I51/100)-H23*$C$47*(I12-H12)/100, IF(I50=1,I27,H23*(1+I52/100))) -> 147.01801 | J23: =IF(AND(J50>1,I50>1), J27*(1+J51/100)-I23*$C$47*(J12-I12)/100, IF(J50=1,J27,I23*(1+J52/100))) -> 149.20224 | K23: =IF(AND(K50>1,J50>1), K27*(1+K51/100)-J23*$C$47*(K12-J12)/100, IF(K50=1,K27,J23*(1+K52/100))) -> 152.02987 | L23: =IF(AND(L50>1,K50>1), L27*(1+L51/100)-K23*$C$47*(L12-K12)/100, IF(L50=1,L27,K23*(1+L52/100))) -> 155.22905 | M23: =IF(AND(M50>1,L50>1), M27*(1+M51/100)-L23*$C$47*(M12-L12)/100, IF(M50=1,M27,L23*(1+M52/100))) -> 158.69246 | N23: =IF(AND(N50>1,M50>1), N27*(1+N51/100)-M23*$C$47*(N12-M12)/100, IF(N50=1,N27,M23*(1+N52/100))) -> 161.73488 | O23: =IF(AND(O50>1,N50>1), O27*(1+O51/100)-N23*$C$47*(O12-N12)/100, IF(O50=1,O27,N23*(1+O52/100))) -> 164.70182 | P23: =IF(AND(P50>1,O50>1), P27*(1+P51/100)-O23*$C$47*(P12-O12)/100, IF(P50=1,P27,O23*(1+P52/100))) -> 167.75405 | ... W23: =IF(AND(W50>1,V50>1), W27*(1+W51/100)-V23*$C$47*(W12-V12)/100, IF(W50=1,W27,V23*(1+W52/100))) -> 188.86752
B24: Growth rate | C24: =+'Input data'!C30 -> 7.121139 | D24: ='Baseline NFPC'!D23 -> 4.260908 | E24: ='Baseline NFPC'!E23 -> -0.9462205 | F24: ='Baseline NFPC'!F23 -> 0.584996 | G24: =100*(G23/F23-1) -> 1.216716 | H24: =100*(H23/G23-1) -> 2.7909618 | I24: =100*(I23/H23-1) -> 1.5203043 | J24: =100*(J23/I23-1) -> 1.4856906 | K24: =100*(K23/J23-1) -> 1.8951652 | L24: =100*(L23/K23-1) -> 2.1043109 | M24: =100*(M23/L23-1) -> 2.2311598 | N24: =100*(N23/M23-1) -> 1.917179 | ... W24: =100*(W23/V23-1) -> 1.601132
B26: Potential GDP (real)
B27: Level | C27: ='Input data'!C34 -> 132.9781 | D27: =+C27*(1+'Input data'!D33/100) -> 136.6169 | E27: =+D27*(1+'Input data'!E33/100) -> 139.17592 | F27: =+E27*(1+'Input data'!F33/100) -> 141.10966 | G27: =+F27*(1+'Input data'!G33/100) -> 143.274 | H27: =+G27*(1+'Input data'!H33/100) -> 145.73938 | I27: =+H27*(1+'Input data'!I33/100) -> 148.23038 | J27: =+I27*(1+'Input data'!J33/100) -> 150.61893 | K27: =+J27*(1+'Input data'!K33/100) -> 152.9892 | ... W27: =+V27*(1+'Input data'!W33/100) -> 188.8675
B29: Output gap
B30: Output gap | C30: =100*(C23/C27-1) -> 0.76380998 | D30: =100*(D23/D27-1) -> 2.2590596 | E30: =100*(E23/E27-1) -> -0.5709813 | F30: =100*(F23/F27-1) -> -1.3598515 | G30: =100*(G23/G27-1) -> -1.6678968 | H30: =100*(H23/H27-1) -> -0.63333134 | I30: =100*(I23/I27-1) -> -0.81789301 | J30: =100*(J23/J27-1) -> -0.94057946 | ... W30: =100*(W23/W27-1) -> 8.8436136e-06
B32: Actual GDP (nominal, national currency)
B33: Growth rate | C33: =100*((1+C24/100)*(1+C42/100)-1) -> 13.828163 | D33: =100*((1+D24/100)*(1+D42/100)-1) -> 19.095077 | E33: =100*((1+E24/100)*(1+E42/100)-1) -> 13.482775 | F33: =100*((1+F24/100)*(1+F42/100)-1) -> 7.8102828 | G33: =100*((1+G24/100)*(1+G42/100)-1) -> 5.333045 | H33: =100*((1+H24/100)*(1+H42/100)-1) -> 6.3723398 | I33: =100*((1+I24/100)*(1+I42/100)-1) -> 4.9947046 | J33: =100*((1+J24/100)*(1+J42/100)-1) -> 4.8962215 | ... W33: =100*((1+W24/100)*(1+W42/100)-1) -> 4.6425619
B35: Interest rates
B36: Nominal implicit interest rate on debt | C36: ='Input data'!C37 -> 3.238231 | D36: ='Input data'!D37 -> 4.417456 | E36: ='Input data'!E37 -> 7.284665 | F36: ='Input data'!F37 -> 7.231643 | G36: ='Input data'!G37 -> 5.674904 | H36: =H109 -> 5.6484363 | I36: =I109 -> 5.7650421 | J36: =J109 -> 5.8711309 | K36: =K109 -> 5.9643176 | L36: =L109 -> 6.0503547 | M36: =M109 -> 6.1300808 | N36: =N109 -> 6.2043184 | O36: =O109 -> 6.2751747 | ... W36: =W109 -> 6.2915575
B37: Long-term interest rate | D37: ='Input data'!D$39 -> 7.57 | E37: ='Input data'!E$39 -> 7.51 | F37: ='Input data'!F$39 -> 6.52395 | G37: ='Input data'!G$39 -> 6.731379 | H37: ='Input data'!H$39 -> 6.82931 | I37: ='Baseline NFPC'!I36 -> 6.8414188 | J37: ='Baseline NFPC'!J36 -> 6.8535275 | K37: ='Baseline NFPC'!K36 -> 6.8656362 | L37: ='Baseline NFPC'!L36 -> 6.877745 | M37: ='Baseline NFPC'!M36 -> 6.8898537 | N37: ='Baseline NFPC'!N36 -> 6.9019625 | O37: ='Baseline NFPC'!O36 -> 6.9140712 | P37: ='Baseline NFPC'!P36 -> 6.92618 | ... W37: ='Baseline NFPC'!W36 -> 6.252017
B38: Short-term interest rate | D38: ='Input data'!D$38 -> 10.32 | E38: ='Input data'!E$38 -> 15.97 | F38: ='Input data'!F$38 -> 7.275548 | G38: ='Input data'!G$38 -> 5.939488 | H38: ='Input data'!H$38 -> 5.742086 | I38: ='Baseline NFPC'!I37 -> 5.8370877 | J38: ='Baseline NFPC'!J37 -> 5.9320895 | K38: ='Baseline NFPC'!K37 -> 6.0270912 | L38: ='Baseline NFPC'!L37 -> 6.122093 | M38: ='Baseline NFPC'!M37 -> 6.2170947 | N38: ='Baseline NFPC'!N37 -> 6.3120965 | O38: ='Baseline NFPC'!O37 -> 6.4070982 | P38: ='Baseline NFPC'!P37 -> 6.5021 | ... W38: ='Baseline NFPC'!W37 -> 5.101365
B39: Share of long-term debt that matures every year | C39: ='Baseline NFPC'!C38 -> 0.07935879 | D39: ='Baseline NFPC'!D38 -> 0.06020197 | E39: ='Baseline NFPC'!E38 -> 0.05046041 | F39: ='Baseline NFPC'!F38 -> 0.06743385 | G39: ='Baseline NFPC'!G38 -> 0.068498038 | H39: ='Baseline NFPC'!H38 -> 0.069562226 | I39: ='Baseline NFPC'!I38 -> 0.070626414 | J39: ='Baseline NFPC'!J38 -> 0.071690602 | ... W39: ='Baseline NFPC'!W38 -> 0.07807573
B41: Inflation and exchange rate
B42: GDP deflator (National currency) | C42: ='Input data'!C42 -> 6.261158 | D42: ='Input data'!D42 -> 14.22793 | E42: ='Input data'!E42 -> 14.56683 | F42: ='Input data'!F42 -> 7.183265 | G42: ='Input data'!G42 -> 4.066847 | H42: ='Input data'!H42 -> 3.484137 | I42: ='Baseline NFPC'!I41 -> 3.4223699 | J42: ='Baseline NFPC'!J41 -> 3.3606027 | K42: ='Baseline NFPC'!K41 -> 3.2988356 | L42: ='Baseline NFPC'!L41 -> 3.2370685 | M42: ='Baseline NFPC'!M41 -> 3.1753014 | N42: ='Baseline NFPC'!N41 -> 3.1135343 | O42: ='Baseline NFPC'!O41 -> 3.0517671 | P42: ='Baseline NFPC'!P41 -> 2.99 | ... W42: ='Baseline NFPC'!W41 -> 2.9935
B43: Exchange rate composite change (weighted by share of debt in each currency) | C43: ='Baseline NFPC'!C42 -> 1.001704 | D43: ='Baseline NFPC'!D42 -> 1.038632 | E43: ='Baseline NFPC'!E42 -> 0.9884134 | F43: ='Baseline NFPC'!F42 -> 1.010684 | G43: ='Baseline NFPC'!G42 -> 1.007245 | H43: ='Baseline NFPC'!H42 -> 1 | I43: ='Baseline NFPC'!I42 -> 1 | J43: ='Baseline NFPC'!J42 -> 1 | ... W43: ='Baseline NFPC'!W42 -> 1
B45: Intermediate calculations (growth rate equation)
B47: Fiscal multiplier | C47: ='Input data'!C49 -> 0.75
B48: Budget balance semi-elasticity | C48: ='Input data'!C50 -> 0.453
B50: Auxiliary variable to control the closure of the output gap | C50: 0 | D50: =IF(AND(ABS((D12-C12)-('Input data'!D13-'Input data'!C13))>0.0001,ABS(D12-C12)>0.0001,D$10>$C$5),4,IF(C50=4,3,IF(C50=3,2,IF(C50=2,1,0)))) -> 0 | E50: =IF(AND(ABS((E12-D12)-('Input data'!E13-'Input data'!D13))>0.0001,ABS(E12-D12)>0.0001,E$10>$C$5),4,IF(D50=4,3,IF(D50=3,2,IF(D50=2,1,0)))) -> 0 | F50: =IF(AND(ABS((F12-E12)-('Input data'!F13-'Input data'!E13))>0.0001,ABS(F12-E12)>0.0001,F$10>$C$5),4,IF(E50=4,3,IF(E50=3,2,IF(E50=2,1,0)))) -> 0 | G50: =IF(AND(ABS((G12-F12)-('Baseline NFPC'!G12-'Baseline NFPC'!F12))>0.0001,ABS(G12-F12)>0.0001,G$10>$C$5),4,IF(F50=4,3,IF(F50=3,2,IF(F50=2,1,0)))) -> 4 | H50: =IF(AND(ABS((H12-G12)-('Baseline NFPC'!H12-'Baseline NFPC'!G12))>0.0001,ABS(H12-G12)>0.0001,H$10>$C$5),4,IF(G50=4,3,IF(G50=3,2,IF(G50=2,1,0)))) -> 4 | I50: =IF(AND(ABS((I12-H12)-('Baseline NFPC'!I12-'Baseline NFPC'!H12))>0.0001,ABS(I12-H12)>0.0001,I$10>$C$5),4,IF(H50=4,3,IF(H50=3,2,IF(H50=2,1,0)))) -> 4 | J50: =IF(AND(ABS((J12-I12)-('Baseline NFPC'!J12-'Baseline NFPC'!I12))>0.0001,ABS(J12-I12)>0.0001,J$10>$C$5),4,IF(I50=4,3,IF(I50=3,2,IF(I50=2,1,0)))) -> 4 | K50: =IF(AND(ABS((K12-J12)-('Baseline NFPC'!K12-'Baseline NFPC'!J12))>0.0001,ABS(K12-J12)>0.0001,K$10>$C$5),4,IF(J50=4,3,IF(J50=3,2,IF(J50=2,1,0)))) -> 3 | L50: =IF(AND(ABS((L12-K12)-('Baseline NFPC'!L12-'Baseline NFPC'!K12))>0.0001,ABS(L12-K12)>0.0001,L$10>$C$5),4,IF(K50=4,3,IF(K50=3,2,IF(K50=2,1,0)))) -> 2 | M50: =IF(AND(ABS((M12-L12)-('Baseline NFPC'!M12-'Baseline NFPC'!L12))>0.0001,ABS(M12-L12)>0.0001,M$10>$C$5),4,IF(L50=4,3,IF(L50=3,2,IF(L50=2,1,0)))) -> 1 | N50: =IF(AND(ABS((N12-M12)-('Baseline NFPC'!N12-'Baseline NFPC'!M12))>0.0001,ABS(N12-M12)>0.0001,N$10>$C$5),4,IF(M50=4,3,IF(M50=3,2,IF(M50=2,1,0)))) -> 0 | ... W50: =IF(AND(ABS((W12-V12)-('Baseline NFPC'!W12-'Baseline NFPC'!V12))>0.0001,ABS(W12-V12)>0.0001,W$10>$C$5),4,IF(V50=4,3,IF(V50=3,2,IF(V50=2,1,0)))) -> 0
B51: OG intermediate auxiliary value | C51: 0 | D51: 0 | E51: =IF(D50=4,2/3*(D30-'Baseline NFPC'!D29),IF(D50=3,1/3*(C30-'Baseline NFPC'!C29),0)) -> 0 | F51: =IF(E50=4,2/3*(E30-'Baseline NFPC'!E29),IF(E50=3,1/3*(D30-'Baseline NFPC'!D29),0)) -> 0 | G51: =IF(F50=4,2/3*(F30-'Baseline NFPC'!F29),IF(F50=3,1/3*(E30-'Baseline NFPC'!E29),0)) -> 0 | H51: =IF(G50=4,2/3*(G30-'Baseline NFPC'!G29),IF(G50=3,1/3*(F30-'Baseline NFPC'!F29),0)) -> -0.26230517 | I51: =IF(H50=4,2/3*H30,IF(H50=3,1/3*G30,0)) -> -0.42222089 | J51: =IF(I50=4,2/3*I30,IF(I50=3,1/3*H30,0)) -> -0.545262 | K51: =IF(J50=4,2/3*J30,IF(J50=3,1/3*I30,0)) -> -0.62705298 | L51: =IF(K50=4,2/3*K30,IF(K50=3,1/3*J30,0)) -> -0.31352649 | M51: =IF(L50=4,2/3*L30,IF(L50=3,1/3*K30,0)) -> 0 | N51: =IF(M50=4,2/3*M30,IF(M50=3,1/3*L30,0)) -> 0 | O51: =IF(N50=4,2/3*N30,IF(N50=3,1/3*M30,0)) -> 0 | P51: =IF(O50=4,2/3*O30,IF(O50=3,1/3*N30,0)) -> 0 | ... W51: =IF(V50=4,2/3*V30,IF(V50=3,1/3*U30,0)) -> 0
B52: GDP intermediate growth rate - only feedback effect and no closure of the OG | D52: ='Input data'!D30-$C$47*((D12-C12)-('Input data'!D13-'Input data'!C13)) -> 4.260908 | E52: ='Input data'!E30-$C$47*((E12-D12)-('Input data'!E13-'Input data'!D13)) -> -0.9462205 | F52: ='Input data'!F30-$C$47*((F12-E12)-('Input data'!F13-'Input data'!E13)) -> 0.584996 | G52: ='Input data'!G30-$C$47*(G12-F12) -> 1.216716 | H52: ='Input data'!H30-$C$47*(H12-G12) -> 2.649951 | I52: ='Input data'!I30-$C$47*(I12-H12) -> 1.29729 | J52: ='Input data'!J30-$C$47*(J12-I12) -> 1.199467 | K52: ='Input data'!K30-$C$47*(K12-J12) -> 1.566761 | L52: ='Input data'!L30-$C$47*(L12-K12) -> 1.78318 | M52: ='Input data'!M30-$C$47*(M12-L12) -> 1.910635 | N52: ='Input data'!N30-$C$47*(N12-M12) -> 1.917179 | ... W52: ='Input data'!W30-$C$47*(W12-V12) -> 1.601132
B54: Debt projections
...

Sheet Adjust. no safeguard
B3: Country | C3: ='Input data'!C3 -> HU
B4: Key years
B5: ='Input data'!B5 -> Last year before the adjustment | C5: =+'Input data'!C5 -> 2024
B6: Last year of adjustment | C6: =+C5+'Criteria results'!$F$5 -> 2028
B7: Last year of no-fiscal-policy-change projections | C7: =C5+'Criteria results'!$F$5+10 -> 2038
B9: Key assumptions
C10: 2021 | D10: 2022 | E10: 2023 | F10: 2024 | G10: 2025 | H10: 2026 | I10: 2027 | J10: 2028 | K10: 2029 | L10: 2030 | M10: 2031 | N10: 2032 | O10: 2033 | P10: 2034 | Q10: 2035 | R10: 2036 | S10: 2037 | T10: 2038 | U10: 2039 | V10: 2040 | W10: 2041
B11: Fiscal assumptions (% of GDP)
B12: Structural primary balance ('+' means 'surplus') | C12: ='Input data'!C13 -> -5.106841 | D12: ='Input data'!D13 -> -4.391969 | E12: ='Input data'!E13 -> -1.706974 | F12: ='Input data'!F13 -> 0.64244146 | G12: =IF(G10<=$C$6,F12+'Criteria results'!$F$6,F12) -> 1.1824415 | H12: =IF(H10<=$C$6,G12+'Criteria results'!$F$6,G12) -> 1.7224415 | I12: =IF(I10<=$C$6,H12+'Criteria results'!$F$6,H12) -> 2.2624415 | J12: =IF(J10<=$C$6,I12+'Criteria results'!$F$6,I12) -> 2.8024415 | K12: =IF(K10<=$C$6,J12+'Criteria results'!$F$6,J12) -> 2.8024415 | L12: =IF(L10<=$C$6,K12+'Criteria results'!$F$6,K12) -> 2.8024415 | M12: =IF(M10<=$C$6,L12+'Criteria results'!$F$6,L12) -> 2.8024415 | N12: =M12 -> 2.8024415 | O12: =N12 -> 2.8024415 | P12: =O12 -> 2.8024415 | Q12: =P12 -> 2.8024415 | R12: =Q12 -> 2.8024415 | S12: =R12 -> 2.8024415 | T12: =S12 -> 2.8024415 | U12: =T12 -> 2.8024415 | ... W12: =V12 -> 2.8024415
B13: Annual change in SPB | G13: =G12-F12 -> 0.54 | H13: =H12-G12 -> 0.54 | I13: =I12-H12 -> 0.54 | J13: =J12-I12 -> 0.54 | K13: =K12-J12 -> 0 | L13: =L12-K12 -> 0 | M13: =M12-L12 -> 0 | N13: =N12-M12 -> 0 | ... W13: =W12-V12 -> 0
B14: One-off and other temporary measures | C14: ='Input data'!C14 -> -0.1079972 | D14: ='Input data'!D14 -> 0 | E14: ='Input data'!E14 -> 0 | F14: ='Input data'!F14 -> 0 | G14: ='Input data'!G14 -> 0 | H14: ='Input data'!H14 -> 0 | I14: ='Input data'!I14 -> 0 | J14: ='Input data'!J14 -> 0 | ... W14: ='Input data'!W14 -> 0
B15: Stock flow adjustments (without exchange rate effect) | C15: ='Input data'!C15 -> -0.1371056 | D15: ='Input data'!D15 -> 1.066777 | E15: ='Input data'!E15 -> 2.471388 | F15: ='Input data'!F15 -> 0.243711 | G15: ='Input data'!G15 -> -0.9088278 | H15: ='Input data'!H15 -> -0.250576 | I15: ='Input data'!I15 -> 0 | J15: ='Input data'!J15 -> 0 | ... W15: ='Input data'!W15 -> 0
B17: ='Input data'!B19 -> Cost of ageing and selected public revenue (based on the Commission-Council 2024 Ageing Report ("AR 2024"))
B18: Total ageing cost (net of taxes on pensions) | C18: ='Input data'!C20 -> 0 | D18: ='Input data'!D20 -> 16.0166 | E18: ='Input data'!E20 -> 16.12175 | F18: ='Input data'!F20 -> 16.12852 | G18: ='Input data'!G20 -> 16.01381 | H18: ='Input data'!H20 -> 15.92993 | I18: ='Input data'!I20 -> 15.87402 | J18: ='Input data'!J20 -> 15.87527 | ... W18: ='Input data'!W20 -> 17.97964
B19: Property income | C19: ='Input data'!C26 -> 0.5353987 | D19: ='Input data'!D26 -> 1.178846 | E19: ='Input data'!E26 -> 2.102853 | F19: ='Input data'!F26 -> 2.07289 | G19: ='Input data'!G26 -> 2.042928 | H19: ='Input data'!H26 -> 2.012965 | I19: ='Input data'!I26 -> 1.983002 | J19: ='Input data'!J26 -> 1.953039 | ... W19: ='Input data'!W26 -> 1.563521
B21: GDP growth assumptions
B22: Actual GDP (real)
