Workbook

Sheet Read me
G4: European Commission
G6: Directorate-General for Economic and Financial Affairs
G7: Unit C2 - Sustainability of public finances
G8: ECFIN-Secretariat-C2@ec.europa.eu
C16: FILE DESCRIPTION
C18: Data reported in this file are based on the European Commission (EC) 2024 spring forecast (SF 2024) and macroeconomic and budgetary projections from the joint EC-EPC Ageing Report 2024 (AR 2024).
C22: This file contains a simplified version of the EC model used to calculate the general governement debt ratio dynamics for EU countries under different scenarios. A detailed description of the EC's general governement debt projections can be found in the "Debt Sustainability Monitor 2023" (DSM, March 2024).
C27: HOW TO USE THIS TOOL TO CALCULATE NEW DEBT PROJECTIONS
C29: This tool can be used to calculate debt projections under different macroeconomic and structural primary balance adjustment assumptions. Debt projections for each scenario will update automatically with changes in the macroeconomic assumptions or the adjustment parameters. The fulfilment of DSA-based criteria, the safeguards and the benchmark will be automatically calculated in the sheet "Criteria results". Formulas are fully visible. To assess the impact of alternative fiscal paths or to check the robustness of underlying macroeconomic assumptions, the user can modify the content of key cells in the sheets "Criteria results" and "Input data" (see below). Note that, for a proper functioning of the file, you should make sure that Excel is in "Automatic" computation mode, i.e. in the File menu, Option tab, click on "Formulas", "Calculation Options" and "Automatic".
C31: The spreadsheet is composed of the following elements:
D33: The grey sheet "Criteria results" contains two main types of cells identified by different colours:
F34: Cells with a yellow background and a red frame can be modified to see the impact of a different duration or pace of adjustment.
F35: Cells with a white or pale red (in case the deficit resilience safeguard is binding) background provide results obtained with the adjustment chosen in the yellow cells. To replicate the Commission's calculations, the underlying formulas should not be modified.
D38: "Criteria results" contains five tables. Table 1 "Adjustment input data": the user can set the duration of the plan in cell F5 (4 years without extension or 7 years with extension), the yearly adjustment pace under the scenario that does not take into account the deficit resilience safeguard (F7) and for the scenario that automatically applies that safeguard (F6). Note that the country cell (F4) cannot be changed.
D39: The adjustement in F7 needs to be selected first so that the message on line 13 signals that the two DSA-based criteria are fulfilled. As a second step, the adjustment in F6 can be selected (and cannot be lower than in F7) so that line 12 reports compliance with the requirements.
D40: Table 2 "DSA-based criteria and deficit resilience safeguard" reports whether the chosen adjustment fulfils the DSA-based criteria (cells H12:I13) and whether the deficit resillience safeguard is binding.
D41: Table 3 "Main fiscal variables with automatic deficit resilience safeguard" reports the annual adjustment over the adjustment period, in terms of change in SPB (line 18), level of the structural balance (line 19) and SPB level at the end of the adjustment (line 20). This table reports the results for the scenario that automatically applies the deficit resillience safeguard. For this reason, the SB is highlighted in red if it is lower than -1.5% of GDP.
D42: Table 4 "Main fiscal variables without automatic deficit resilience safeguard" reports the annual adjustment over the adjustment period, in terms of change in SPB (line 25), level of the structural balance (line 26) and SPB level at the end of the adjustment (line 27). This table reports the results for the scenario without the deficit resillience safeguard.
D44: The sheet "Input data" in light blue presents the input data, including fiscal and GDP growth assumptions as well as additional fiscal parameters. Unless stated otherwise below, the user can change all values in this tab.
D45: Coloured cells indicate data sources as follows (this colour-coding holds in the other spreadsheets):
F46: Cells in light grey indicate Commission forecast (available in the AMECO database)
F47: Cells in light blue indicate values from the Ageing Report 2024
F48: Cells in light orange provide parameters needed to compute the decomposition of government debt according to its maturity structure (i.e. short-term and long-term debt, maturing, rolled-over and non-maturing debt). These are fixed shares which the user cannot change.
F49: Cells in dark orange indicate financial market prices.
D50: Non coloured parameters in cells C50:C70 were calibrated based on different data sources. Data sources are given in corresponding cells of column E.
C52: The next spreadsheets present the no-fiscal-policy-change baseline and the adjustment scenario, with and without the impact of the deficit resilience safeguard. Each deterministic projection provides a single path for debt until 2038 or 2041 under certain assumptions for budgetary, macroeconomic and financial variables.
D54: The sheet in blue provides, as a reference, the baseline no-fiscal-policy-change scenario. The background colour coding is the same as in the sheet "Input data".
D56: The sheet in orange presents the scenario that automatically corrects the yearly adjustment path to account for the deficit resillience safeguard.
D58: The sheet in green presents the adjustment scenarios without the deficit resilience safeguard. This scenario is computed automatically based on the yearly adjustment path set in "Criteria results" (see above).
C60: Within the orange sheet and each green sheet, the background of the SPB line has three colours. Each colour corresponds to a specific period of the projections:
E61: Light grey indicates the pre-plan period, corresponding to the EC forecast
E62: Mild grey indicates the period during which the SPB adjusts according to the path set in sheet "Criteria results"
E63: Dark grey indicates the period in which the SPB, net of changes in cost of ageing, remains constant at its value of end of adjustment.
C66: WHERE ARE THE MAIN RESULTS LOCATED?
C67: The fullfilment of the criteria is checked in the sheet "Criteria results". Debt projections can be found in line 57 of each scenario.
D69: The 'FASTOP reporting' sheet in violet provides help for preparing reporting tables. It readily provides all the tables foreseen by the guidance notice on the "Information Requirements for the Medium-Term Fiscal-Structural Plans" once the parameters are set in the rest of this file. This sheet is meant to be an assistance. The need for a thorough scrutiny of the figures before submitting such tables remains.

Sheet Criteria results
U2: 4 | V2: -1.5
D3: Table 1 - Adjustment input data | U3: 7 | V3: -1.48
D4: Country | F4: IE | V4: -1.46
D5: Number of years of adjustment | F5: 4 | V5: -1.44
C6: 2. | D6: Annual adjustment (with safeguard) | F6: 0 | V6: -1.42
C7: 1. | D7: Annual adjustment (without safeguard) | F7: 0 | V7: -1.4
V8: -1.38
H9: Table 2 - DSA-based criteria and deficit resilience safeguard | V9: -1.36
H10: DSA-based criteria | J10: Deficit resilience safeguard | V10: -1.34
H11: Deficit below 3% of GDP | I11: ="Debt below 60% of GDP in T+"&10+F5 -> Debt below 60% of GDP in T+14 | V11: -1.32
C12: 2. | D12: Adjustment scenario with automatic deficit resilience safeguard * (sheet "Adjustment scenario") | H12: =IF(MIN(OFFSET('Adjustment scenario'!$F$77,0,$F$5,1,11))>-3.05,"ok","Not met") -> ok | I12: =IF(OFFSET('Adjustment scenario'!$F$57,0,$F$5+10,1,1)<60,"ok","Not met") -> ok | J12: =IF(AND($F$5=4,COUNTIF(G18:J18,">" & F6)=0),"Not binding",IF(AND($F$5=7,COUNTIF(G18:M18,">" & F6)=0),"Not binding","Binding")) -> Not binding | K12: =IF(OR($H$13="Not met",$I$13="Not met"),"Please adjust cell F7 so that both DSA-based criteria are met", IF($F$6<$F$7,"The adjustment in F6 cannot be lower than in F7", IF(AND($H$12="ok",$I$12="ok",$H$13="ok",$I$13="ok",$F$6>=$F$7, OR(AND($F$5=4,$G$18>=$H$18,$H$18>=$I$18,$I$18>=$J$18,OR($J$18>=0.4,$J$19>-1.55)), AND($F$5=7,$G$18>=$H$18,$H$18>=$I$18,$I$18>=$J$18,$J$18>=$K$18,$K$18>=$L$18,$L$18>=$M$18,OR($M$18>=0.25,$M$19>-1.55)))), "OK"&CHAR(10)&"The adjustment in F6 fulfills all requirements including the deficit resilience safeguard", "NOT OK"&CHAR(10)&"The adjustment in F6 does not fulfill all requirements"))) -> OK The adjustment in F6 fulfills all requirements including the deficit resilience safeguard | V12: -1.3
C13: 1. | D13: Adjustment scenario without deficit resilience safeguard (sheet "Adjust. no safeguard") | H13: =IF(MIN(OFFSET('Adjust. no safeguard'!$F$77,0,$F$5,1,11))>-3.05,"ok","Not met") -> ok | I13: =IF(OFFSET('Adjust. no safeguard'!$F$57,0,$F$5+10,1,1)<60,"ok","Not met") -> ok | K13: =IF(AND($H$13="ok",$I$13="ok"), "OK"&CHAR(10)&"The adjustment in F7 ensures that the debt and deficit remain"&CHAR(10)&"below the Treaty reference values over the medium term", "NOT OK"&CHAR(10)&"The adjustment in F7 does not ensure that the debt and deficit remain"&CHAR(10)&"below the Treaty reference values over the medium term") -> OK The adjustment in F7 ensures that the debt and deficit remain below the Treaty reference values over the medium term | V13: -1.28
D14: * Under a plan without (with) extension, an adjustment of 0.40 pp. (0.25 pp.) of GDP in SPB terms is applied if the structural deficit in the previous year exceeds 1.5% of GDP. | V14: -1.26
V15: -1.24
G16: Table 3 - Main fiscal variables with automatic deficit resilience safeguard * | V16: -1.22
G17: 2025 | H17: 2026 | I17: 2027 | J17: 2028 | K17: 2029 | L17: 2030 | M17: 2031 | V17: -1.2
D18: Annual adjustment (change in SPB) | G18: ='Adjustment scenario'!G12-'Adjustment scenario'!F12 -> 0 | H18: ='Adjustment scenario'!H12-'Adjustment scenario'!G12 -> 0 | I18: ='Adjustment scenario'!I12-'Adjustment scenario'!H12 -> 0 | J18: ='Adjustment scenario'!J12-'Adjustment scenario'!I12 -> 0 | K18: ='Adjustment scenario'!K12-'Adjustment scenario'!J12 -> 0 | L18: ='Adjustment scenario'!L12-'Adjustment scenario'!K12 -> 0 | M18: ='Adjustment scenario'!M12-'Adjustment scenario'!L12 -> 0 | V18: -1.18
D19: Structural balance | G19: ='Adjustment scenario'!G78 -> 1.8496221 | H19: ='Adjustment scenario'!H78 -> 1.829394 | I19: ='Adjustment scenario'!I78 -> 1.8755965 | J19: ='Adjustment scenario'!J78 -> 1.9330204 | K19: ='Adjustment scenario'!K78 -> 1.9066295 | L19: ='Adjustment scenario'!L78 -> 1.8555801 | M19: ='Adjustment scenario'!M78 -> 1.7898307 | V19: -1.16
D20: SPB at the end of the adjustment | J20: =IF(F5=4,'Adjustment scenario'!J12,"") -> 2.528801 | M20: =IF(F5=7,'Adjustment scenario'!M12,"") | V20: -1.14
D21: * The structural balance is flagged in red if it is below -1.5% of GDP. | V21: -1.12
V22: -1.1
G23: Table 4 - Main fiscal variables without automatic deficit resilience safeguard | V23: -1.08
G24: 2025 | H24: 2026 | I24: 2027 | J24: 2028 | K24: 2029 | L24: 2030 | M24: 2031 | V24: -1.06
D25: Annual adjustment (change in SPB) | G25: ='Adjust. no safeguard'!G12-'Adjust. no safeguard'!F12 -> 0 | H25: ='Adjust. no safeguard'!H12-'Adjust. no safeguard'!G12 -> 0 | I25: ='Adjust. no safeguard'!I12-'Adjust. no safeguard'!H12 -> 0 | J25: ='Adjust. no safeguard'!J12-'Adjust. no safeguard'!I12 -> 0 | K25: ='Adjust. no safeguard'!K12-'Adjust. no safeguard'!J12 -> 0 | L25: ='Adjust. no safeguard'!L12-'Adjust. no safeguard'!K12 -> 0 | M25: ='Adjust. no safeguard'!M12-'Adjust. no safeguard'!L12 -> 0 | V25: -1.04
D26: Structural balance | G26: ='Adjust. no safeguard'!G78 -> 1.8496221 | H26: ='Adjust. no safeguard'!H78 -> 1.829394 | I26: ='Adjust. no safeguard'!I78 -> 1.8755965 | J26: ='Adjust. no safeguard'!J78 -> 1.9330204 | K26: ='Adjust. no safeguard'!K78 -> 1.9066295 | L26: ='Adjust. no safeguard'!L78 -> 1.8555801 | M26: ='Adjust. no safeguard'!M78 -> 1.7898307 | V26: -1.02
D27: SPB at the end of the adjustment | J27: =IF(F5=4,'Adjust. no safeguard'!J12,"") -> 2.528801 | M27: =IF(F5=7,'Adjust. no safeguard'!M12,"") | V27: -1
V28: -0.98
V29: -0.96
V30: -0.82
V31: -0.8
V32: -0.78
V33: -0.76
V34: -0.74
V35: -0.72
V36: -0.7
V37: -0.68
V38: -0.66
V39: -0.64
... V146: 1.5

Sheet Input data
B3: Country | C3: IE
B5: Last year before the adjustment | C5: 2024
B6: Last year of adjustment | C6: =C5+'Criteria results'!$F$5 -> 2028
B8: Key assumptions
C9: 2021 | D9: 2022 | E9: 2023 | F9: 2024 | G9: 2025 | H9: 2026 | I9: 2027 | J9: 2028 | K9: 2029 | L9: 2030 | M9: 2031 | N9: 2032 | O9: 2033 | P9: 2034 | Q9: 2035 | R9: 2036 | S9: 2037 | T9: 2038 | U9: 2039 | V9: 2040 | W9: 2041
B10: Fiscal assumptions (% of GDP)
B11: Key fiscal variables (based on the Commission 2024 spring forecast ("SF 2024") T+2 forecast and the June 2024 report prepared under Art. 126(3) of the Treaty)
B12: Debt | C12: 54.39847 | D12: 44.39178 | E12: 43.73044 | F12: 42.48884
B13: Structural primary balance ('+' means 'surplus') | C13: -3.165318 | D13: -2.376722 | E13: 1.712465 | F13: 2.528801
B14: One-off and other temporary measures | C14: 0 | D14: 0 | E14: 0 | F14: 0 | G14: 0 | H14: 0 | I14: 0 | J14: 0 | K14: 0 | L14: 0 | M14: 0 | N14: 0 | O14: 0 | P14: 0 | Q14: 0 | R14: 0 | S14: 0 | T14: 0 | U14: 0 | V14: 0 | W14: 0
B15: Stock-flow adjustments (without exchange rate effect) | C15: 2.690274 | D15: -0.5420614 | E15: 0.8428086 | F15: 1.636568 | G15: 2.20024 | H15: 0 | I15: 0 | J15: 0 | K15: 0 | L15: 0 | M15: 0 | N15: 0 | O15: 0 | P15: 0 | Q15: 0 | R15: 0 | S15: 0 | T15: 0 | U15: 0 | V15: 0 | W15: 0
B16: Stock-flow adjustment (total) | C16: 2.690275 | D16: -0.5420594 | E16: 0.8428066 | F16: 1.636567 | G16: 2.200242 | H16: 0 | I16: 0 | J16: 0 | K16: 0 | L16: 0 | M16: 0 | N16: 0 | O16: 0 | P16: 0 | Q16: 0 | R16: 0 | S16: 0 | T16: 0 | U16: 0 | V16: 0 | W16: 0
B17: Subject to an excessive deficit procedure (EDP) (0-no/1-yes) | D17: 0 | E17: 0 | F17: 0
B19: Cost of ageing and selected public revenue (based on the Commission-Council 2024 Ageing Report ("AR 2024"))
B20: Total ageing cost (net of taxes on pensions) | C20: =(C21+C22+C23+C24-C25) -> 0 | D20: =(D21+D22+D23+D24-D25) -> 11.98063 | E20: =(E21+E22+E23+E24-E25) -> 11.58823 | F20: =(F21+F22+F23+F24-F25) -> 11.59789 | G20: =(G21+G22+G23+G24-G25) -> 11.65158 | H20: =(H21+H22+H23+H24-H25) -> 11.82718 | I20: =(I21+I22+I23+I24-I25) -> 12.01015 | J20: =(J21+J22+J23+J24-J25) -> 12.14108 | ... W20: =(W21+W22+W23+W24-W25) -> 13.69105
B21: of which: Public pensions expenditure | C21: 0 | D21: 3.82109 | E21: 3.61005 | F21: 3.62188 | G21: 3.65895 | H21: 3.80091 | I21: 3.9251 | J21: 4.01587 | K21: 4.06986 | L21: 4.15079 | M21: 4.25426 | N21: 4.41679 | O21: 4.47248 | P21: 4.57121 | Q21: 4.65947 | R21: 4.75886 | S21: 4.87392 | T21: 4.8967 | U21: 4.96666 | V21: 5.04151 | W21: 5.12081
B22: Health care expenditure | C22: 0 | D22: 4.11039 | E22: 4.00607 | F22: 4.05388 | G22: 4.10122 | H22: 4.14568 | I22: 4.18979 | J22: 4.23735 | K22: 4.283 | L22: 4.32876 | M22: 4.37176 | N22: 4.41288 | O22: 4.45283 | P22: 4.49271 | Q22: 4.53085 | R22: 4.56982 | S22: 4.60593 | T22: 4.64352 | U22: 4.6797 | V22: 4.71437 | W22: 4.74969
B23: Long-term care expenditure | C23: 0 | D23: 1.22676 | E23: 1.22151 | F23: 1.23167 | G23: 1.24944 | H23: 1.2728 | I23: 1.31549 | J23: 1.33901 | K23: 1.36255 | L23: 1.38546 | M23: 1.40747 | N23: 1.42945 | O23: 1.4528 | P23: 1.47653 | Q23: 1.50085 | R23: 1.52518 | S23: 1.54983 | T23: 1.57526 | U23: 1.60292 | V23: 1.63104 | W23: 1.65937
B24: Education & unemployment benefits expenditure | C24: 0 | D24: 2.82239 | E24: 2.7506 | F24: 2.69046 | G24: 2.64197 | H24: 2.60779 | I24: 2.57977 | J24: 2.54885 | K24: 2.51158 | L24: 2.47032 | M24: 2.4263 | N24: 2.3837 | O24: 2.34295 | P24: 2.30581 | Q24: 2.27257 | R24: 2.24263 | S24: 2.21659 | T24: 2.19551 | U24: 2.17909 | V24: 2.16772 | W24: 2.16118
B25: Taxes on pensions | C25: 0 | D25: 0 | E25: 0 | F25: 0 | G25: 0 | H25: 0 | I25: 0 | J25: 0 | K25: 0 | L25: 0 | M25: 0 | N25: 0 | O25: 0 | P25: 0 | Q25: 0 | R25: 0 | S25: 0 | T25: 0 | U25: 0 | V25: 0 | W25: 0
B26: Property income | C26: 0.1107195 | D26: 0.132752 | E26: 0.1349502 | F26: 0.1371484 | G26: 0.1393466 | H26: 0.1415448 | I26: 0.143743 | J26: 0.1459412 | K26: 0.1481394 | L26: 0.1503376 | M26: 0.1525358 | N26: 0.154734 | O26: 0.1569322 | P26: 0.1591305 | Q26: 0.1613287 | R26: 0.1635269 | S26: 0.1657251 | T26: 0.1679233 | U26: 0.1701215 | V26: 0.1723197 | W26: 0.1745179
B28: Real GDP growth assumptions (based on SF 2024 T+10 projections and AR 2024 projections)
B29: Actual GDP
B30: Growth rate | C30: 15.12522 | D30: 9.433022 | E30: -3.198788 | F30: 1.243702 | G30: 3.393806 | H30: 3.746114 | I30: 3.802369 | J30: 3.577386 | K30: 3.164204 | L30: 2.938014 | M30: 2.669411 | N30: 2.359786 | O30: 2.013409 | P30: 1.950457 | Q30: 1.887507 | R30: 1.824547 | S30: 1.823224 | T30: 1.784506 | U30: 1.734372 | V30: 1.668214 | W30: 1.571112
B31: Level (billions, national currency) | C31: 410.9464
B32: Potential GDP
B33: Growth rate | C33: 4.349017 | D33: 4.958035 | E33: 4.333524 | F33: 3.615591 | G33: 3.285812 | H33: 3.394844 | I33: 3.335869 | J33: 3.345161 | K33: 3.164205 | L33: 2.938014 | M33: 2.669409 | N33: 2.359784 | O33: 2.01341 | P33: 1.950456 | Q33: 1.887503 | R33: 1.824549 | S33: 1.823226 | T33: 1.784504 | U33: 1.734368 | V33: 1.668211 | W33: 1.571108
B34: Level (billions, national currency) | C34: 392.8036
B36: Interest rates (SF 2024, %)
B37: Nominal implicit interest rate on debt | C37: 1.510173 | D37: 1.408838 | E37: 1.550894 | F37: 1.641526 | G37: 1.684386
B38: Short-term nominal interest rate | D38: 0.35 | E38: 3.43 | F38: 3.564208 | G38: 2.816375
B39: Long-term nominal interest rate | D39: 1.75 | E39: 2.87 | F39: 2.837221 | G39: 2.903685
F40: Bloomberg data, country-specific forward market rates.
B41: Inflation (SF 2024, %)
B42: GDP deflator (national currency) | C42: 0.4774826 | D42: 6.582269 | E42: 2.965217 | F42: 2.574346 | G42: 1.914897
B44: Net primary expenditure growth (SF 2024, %)
B45: Net primary expenditure growth | C45: 6.1387469 | D45: 14.052581 | E45: 13.567155 | F45: 7.3776443
B47: Additional parameters
E48: Sources
B49: Fiscal multiplier | C49: 0.75 | E49: Carnot, N. and de Castro, F. (2015), “The Discretionary Fiscal Effort: an Assessment of Fiscal Policy and its Output Effect”, European Economy, Economic Papers, No. 543.
...

Sheet Baseline NFPC
B3: Country | C3: ='Input data'!C3 -> IE
B4: Key years
B5: ='Input data'!B5 -> Last year before the adjustment | C5: =+'Input data'!C5 -> 2024
B6: Last year of adjustment | C6: =+C5+'Criteria results'!$F$5 -> 2028
B9: Key assumptions
C10: 2021 | D10: 2022 | E10: 2023 | F10: 2024 | G10: 2025 | H10: 2026 | I10: 2027 | J10: 2028 | K10: 2029 | L10: 2030 | M10: 2031 | N10: 2032 | O10: 2033 | P10: 2034 | Q10: 2035 | R10: 2036 | S10: 2037 | T10: 2038 | U10: 2039 | V10: 2040 | W10: 2041
B11: Fiscal assumptions (% of GDP)
B12: Structural primary balance ('+' means 'surplus') | C12: ='Input data'!C13 -> -3.165318 | D12: ='Input data'!D13 -> -2.376722 | E12: ='Input data'!E13 -> 1.712465 | F12: ='Input data'!F13 -> 2.528801 | G12: =F12 -> 2.528801 | H12: =G12 -> 2.528801 | I12: =H12 -> 2.528801 | J12: =I12 -> 2.528801 | K12: =J12 -> 2.528801 | L12: =K12 -> 2.528801 | M12: =L12 -> 2.528801 | N12: =M12 -> 2.528801 | ... W12: =V12 -> 2.528801
B13: One-off and other temporary measures | C13: ='Input data'!C14 -> 0 | D13: ='Input data'!D14 -> 0 | E13: ='Input data'!E14 -> 0 | F13: ='Input data'!F14 -> 0 | G13: ='Input data'!G14 -> 0 | H13: 0 | I13: 0 | J13: 0 | K13: 0 | L13: 0 | M13: 0 | N13: 0 | O13: 0 | P13: 0 | Q13: 0 | R13: 0 | S13: 0 | T13: 0 | U13: 0 | V13: 0 | W13: 0
B14: Stock flow adjustments (without exchange rate effect) | C14: ='Input data'!C15 -> 2.690274 | D14: ='Input data'!D15 -> -0.5420614 | E14: ='Input data'!E15 -> 0.8428086 | F14: ='Input data'!F15 -> 1.636568 | G14: ='Input data'!G15 -> 2.20024 | H14: ='Input data'!H15 -> 0 | I14: ='Input data'!I15 -> 0 | J14: ='Input data'!J15 -> 0 | ... W14: ='Input data'!W15 -> 0
B16: ='Input data'!B19 -> Cost of ageing and selected public revenue (based on the Commission-Council 2024 Ageing Report ("AR 2024"))
B17: Total ageing cost (net of taxes on pensions) | C17: ='Input data'!C20 -> 0 | D17: ='Input data'!D20 -> 11.98063 | E17: ='Input data'!E20 -> 11.58823 | F17: ='Input data'!F20 -> 11.59789 | G17: ='Input data'!G20 -> 11.65158 | H17: ='Input data'!H20 -> 11.82718 | I17: ='Input data'!I20 -> 12.01015 | J17: ='Input data'!J20 -> 12.14108 | ... W17: ='Input data'!W20 -> 13.69105
B18: ='Input data'!B26 -> Property income | C18: ='Input data'!C26 -> 0.1107195 | D18: ='Input data'!D26 -> 0.132752 | E18: ='Input data'!E26 -> 0.1349502 | F18: ='Input data'!F26 -> 0.1371484 | G18: ='Input data'!G26 -> 0.1393466 | H18: ='Input data'!H26 -> 0.1415448 | I18: ='Input data'!I26 -> 0.143743 | ... W18: ='Input data'!W26 -> 0.1745179
B20: GDP growth assumptions
B21: Actual GDP (real)
B22: Level | C22: ='Input data'!C31 -> 410.9464 | D22: =C22*(D23/100+1) -> 449.71106 | E22: =D22*(E23/100+1) -> 435.32576 | F22: =E22*(F23/100+1) -> 440.73992 | G22: =F22*(G23/100+1) -> 455.69777 | H22: =IF(AND(H49>1,G49>1),IF(AND(H49>0,G49>0),H26*(H50/100+1),0)+IF(H49>0,G22*(1+H51/100),0)-G22*(1+'Input data'!H30/100),IF(H49=1,H26,G22*(1+H51/100))) -> 472.76873 | I22: =IF(AND(I49>1,H49>1),IF(AND(I49>0,H49>0),I26*(I50/100+1),0)+IF(I49>0,H22*(1+I51/100),0)-H22*(1+'Input data'!I30/100),IF(I49=1,I26,H22*(1+I51/100))) -> 490.74514 | J22: =IF(AND(J49>1,I49>1),IF(AND(J49>0,I49>0),J26*(J50/100+1),0)+IF(J49>0,I22*(1+J51/100),0)-I22*(1+'Input data'!J30/100),IF(J49=1,J26,I22*(1+J51/100))) -> 508.30099 | K22: =IF(AND(K49>1,J49>1),IF(AND(K49>0,J49>0),K26*(K50/100+1),0)+IF(K49>0,J22*(1+K51/100),0)-J22*(1+'Input data'!K30/100),IF(K49=1,K26,J22*(1+K51/100))) -> 524.38467 | L22: =IF(AND(L49>1,K49>1),IF(AND(L49>0,K49>0),L26*(L50/100+1),0)+IF(L49>0,K22*(1+L51/100),0)-K22*(1+'Input data'!L30/100),IF(L49=1,L26,K22*(1+L51/100))) -> 539.79117 | M22: =IF(AND(M49>1,L49>1),IF(AND(M49>0,L49>0),M26*(M50/100+1),0)+IF(M49>0,L22*(1+M51/100),0)-L22*(1+'Input data'!M30/100),IF(M49=1,M26,L22*(1+M51/100))) -> 554.20041 | N22: =IF(AND(N49>1,M49>1),IF(AND(N49>0,M49>0),N26*(N50/100+1),0)+IF(N49>0,M22*(1+N51/100),0)-M22*(1+'Input data'!N30/100),IF(N49=1,N26,M22*(1+N51/100))) -> 567.27836 | O22: =IF(AND(O49>1,N49>1),IF(AND(O49>0,N49>0),O26*(O50/100+1),0)+IF(O49>0,N22*(1+O51/100),0)-N22*(1+'Input data'!O30/100),IF(O49=1,O26,N22*(1+O51/100))) -> 578.69999 | ... W22: =IF(AND(W49>1,V49>1),IF(AND(W49>0,V49>0),W26*(W50/100+1),0)+IF(W49>0,V22*(1+W51/100),0)-V22*(1+'Input data'!W30/100),IF(W49=1,W26,V22*(1+W51/100))) -> 666.4502
B23: Growth rate | C23: =+'Input data'!C30 -> 15.12522 | D23: =+'Input data'!D30 -> 9.433022 | E23: =+'Input data'!E30 -> -3.198788 | F23: =+'Input data'!F30 -> 1.243702 | G23: =+'Input data'!G30 -> 3.393806 | H23: =100*(H22/G22-1) -> 3.746114 | I23: =100*(I22/H22-1) -> 3.802369 | J23: =100*(J22/I22-1) -> 3.577386 | K23: =100*(K22/J22-1) -> 3.164204 | L23: =100*(L22/K22-1) -> 2.938014 | M23: =100*(M22/L22-1) -> 2.669411 | N23: =100*(N22/M22-1) -> 2.359786 | O23: =100*(O22/N22-1) -> 2.013409 | ... W23: =100*(W22/V22-1) -> 1.571112
B25: Potential GDP (real)
B26: Level | C26: ='Input data'!C34 -> 392.8036 | D26: =+C26*(1+'Input data'!D33/100) -> 412.27894 | E26: =+D26*(1+'Input data'!E33/100) -> 430.14515 | F26: =+E26*(1+'Input data'!F33/100) -> 445.69744 | G26: =+F26*(1+'Input data'!G33/100) -> 460.34222 | H26: =+G26*(1+'Input data'!H33/100) -> 475.97012 | I26: =+H26*(1+'Input data'!I33/100) -> 491.84786 | J26: =+I26*(1+'Input data'!J33/100) -> 508.30096 | K26: =+J26*(1+'Input data'!K33/100) -> 524.38464 | ... W26: =+V26*(1+'Input data'!W33/100) -> 666.45005
B28: Output gap
B29: Output gap | C29: =100*(C22/C26-1) -> 4.6187968 | D29: =100*(D22/D26-1) -> 9.07932 | E29: =100*(E22/E26-1) -> 1.2043874 | F29: =100*(F22/F26-1) -> -1.1123062 | G29: =100*(G22/G26-1) -> -1.0089108 | H29: =100*(H22/H26-1) -> -0.67260192 | I29: =100*(I22/I26-1) -> -0.22419779 | J29: =100*(J22/J26-1) -> 6.5725915e-06 | ... W29: =100*(W22/W26-1) -> 2.2288956e-05
B31: Actual GDP (nominal, national currency)
B32: Growth rate | C32: =100*((1+C23/100)*(1+C41/100)-1) -> 15.674923 | D32: =100*((1+D23/100)*(1+D41/100)-1) -> 16.636198 | E32: =100*((1+E23/100)*(1+E41/100)-1) -> -0.32842201 | F32: =100*((1+F23/100)*(1+F41/100)-1) -> 3.8500652 | G32: =100*((1+G23/100)*(1+G41/100)-1) -> 5.3736909 | H32: =100*((1+H23/100)*(1+H41/100)-1) -> 5.8151071 | I32: =100*((1+I23/100)*(1+I41/100)-1) -> 5.9548904 | J32: =100*((1+J23/100)*(1+J41/100)-1) -> 5.8074699 | ... W32: =100*((1+W23/100)*(1+W41/100)-1) -> 3.9377189
B34: Interest rate
B35: Nominal implicit interest rate on debt | C35: ='Input data'!C37 -> 1.510173 | D35: ='Input data'!D37 -> 1.408838 | E35: ='Input data'!E37 -> 1.550894 | F35: ='Input data'!F37 -> 1.641526 | G35: ='Input data'!G37 -> 1.684386 | H35: =H96 -> 1.7995764 | I35: =I96 -> 1.8573201 | J35: =J96 -> 1.8994082 | K35: =K96 -> 1.9496329 | L35: =L96 -> 2.0061124 | M35: =M96 -> 2.0541018 | N35: =N96 -> 2.1281077 | O35: =O96 -> 2.2116501 | ... W35: =W96 -> 2.6116148
B36: Long-term interest rate | E36: ='Input data'!E39 -> 2.87 | F36: ='Input data'!F39 -> 2.837221 | G36: ='Input data'!G39 -> 2.903685 | H36: =G36+($O$36-$G$36)/($O$10-$G$10) -> 2.9987319 | I36: =H36+($O$36-$G$36)/($O$10-$G$10) -> 3.0937787 | J36: =I36+($O$36-$G$36)/($O$10-$G$10) -> 3.1888256 | K36: =J36+($O$36-$G$36)/($O$10-$G$10) -> 3.2838725 | L36: =K36+($O$36-$G$36)/($O$10-$G$10) -> 3.3789194 | M36: =L36+($O$36-$G$36)/($O$10-$G$10) -> 3.4739662 | N36: =M36+($O$36-$G$36)/($O$10-$G$10) -> 3.5690131 | O36: ='Input data'!$C$52 -> 3.66406 | P36: =$O$36+('Input data'!$C$54-'Input data'!$C$52)/20*('Baseline NFPC'!P$10-2033) -> 3.680857 | Q36: =$O$36+('Input data'!$C$54-'Input data'!$C$52)/20*('Baseline NFPC'!Q$10-2033) -> 3.697654 | R36: =$O$36+('Input data'!$C$54-'Input data'!$C$52)/20*('Baseline NFPC'!R$10-2033) -> 3.714451 | S36: =$O$36+('Input data'!$C$54-'Input data'!$C$52)/20*('Baseline NFPC'!S$10-2033) -> 3.731248 | T36: =$O$36+('Input data'!$C$54-'Input data'!$C$52)/20*('Baseline NFPC'!T$10-2033) -> 3.748045 | U36: =$O$36+('Input data'!$C$54-'Input data'!$C$52)/20*('Baseline NFPC'!U$10-2033) -> 3.764842 | V36: =$O$36+('Input data'!$C$54-'Input data'!$C$52)/20*('Baseline NFPC'!V$10-2033) -> 3.781639 | W36: =$O$36+('Input data'!$C$54-'Input data'!$C$52)/20*('Baseline NFPC'!W$10-2033) -> 3.798436
B37: Short-term interest rate | E37: ='Input data'!E$38 -> 3.43 | F37: ='Input data'!F$38 -> 3.564208 | G37: ='Input data'!G$38 -> 2.816375 | H37: =G37+($O$37-$G$37)/($O$10-$G$10) -> 2.8050894 | I37: =H37+($O$37-$G$37)/($O$10-$G$10) -> 2.7938037 | J37: =I37+($O$37-$G$37)/($O$10-$G$10) -> 2.7825181 | K37: =J37+($O$37-$G$37)/($O$10-$G$10) -> 2.7712325 | L37: =K37+($O$37-$G$37)/($O$10-$G$10) -> 2.7599469 | M37: =L37+($O$37-$G$37)/($O$10-$G$10) -> 2.7486612 | N37: =M37+($O$37-$G$37)/($O$10-$G$10) -> 2.7373756 | O37: ='Input data'!$C$53 -> 2.72609 | P37: =$O$37+('Input data'!$C$55-'Input data'!$C$53)/20*('Baseline NFPC'!P$10-2033) -> 2.6897855 | Q37: =$O$37+('Input data'!$C$55-'Input data'!$C$53)/20*('Baseline NFPC'!Q$10-2033) -> 2.653481 | R37: =$O$37+('Input data'!$C$55-'Input data'!$C$53)/20*('Baseline NFPC'!R$10-2033) -> 2.6171765 | S37: =$O$37+('Input data'!$C$55-'Input data'!$C$53)/20*('Baseline NFPC'!S$10-2033) -> 2.580872 | T37: =$O$37+('Input data'!$C$55-'Input data'!$C$53)/20*('Baseline NFPC'!T$10-2033) -> 2.5445675 | U37: =$O$37+('Input data'!$C$55-'Input data'!$C$53)/20*('Baseline NFPC'!U$10-2033) -> 2.508263 | V37: =$O$37+('Input data'!$C$55-'Input data'!$C$53)/20*('Baseline NFPC'!V$10-2033) -> 2.4719585 | W37: =$O$37+('Input data'!$C$55-'Input data'!$C$53)/20*('Baseline NFPC'!W$10-2033) -> 2.435654
B38: Share of long-term debt that matures every year | C38: 0.001 | D38: 0.07537306 | E38: 0.04688205 | F38: 0.05421672 | G38: =IF(OR($C$3="EL",$C$3="CY",$C$3="IE",$C$3="PT"),VLOOKUP($C$3,$B$110:$T$114,MATCH(G$10,$B$110:$T$110,0),0),$F$38+('Input data'!$C$59-$F$38)/($O$10-$F$10)*(G10-$F$10)) -> 0.06734311 | H38: =IF(OR($C$3="EL",$C$3="CY",$C$3="IE",$C$3="PT"),VLOOKUP($C$3,$B$110:$T$114,MATCH(H$10,$B$110:$T$110,0),0),$F$38+('Input data'!$C$59-$F$38)/($O$10-$F$10)*(H10-$F$10)) -> 0.07328111 | I38: =IF(OR($C$3="EL",$C$3="CY",$C$3="IE",$C$3="PT"),VLOOKUP($C$3,$B$110:$T$114,MATCH(I$10,$B$110:$T$110,0),0),$F$38+('Input data'!$C$59-$F$38)/($O$10-$F$10)*(I10-$F$10)) -> 0.06373561 | J38: =IF(OR($C$3="EL",$C$3="CY",$C$3="IE",$C$3="PT"),VLOOKUP($C$3,$B$110:$T$114,MATCH(J$10,$B$110:$T$110,0),0),$F$38+('Input data'!$C$59-$F$38)/($O$10-$F$10)*(J10-$F$10)) -> 0.07199902 | K38: =IF(OR($C$3="EL",$C$3="CY",$C$3="IE",$C$3="PT"),VLOOKUP($C$3,$B$110:$T$114,MATCH(K$10,$B$110:$T$110,0),0),$F$38+('Input data'!$C$59-$F$38)/($O$10-$F$10)*(K10-$F$10)) -> 0.07792014 | L38: =IF(OR($C$3="EL",$C$3="CY",$C$3="IE",$C$3="PT"),VLOOKUP($C$3,$B$110:$T$114,MATCH(L$10,$B$110:$T$110,0),0),$F$38+('Input data'!$C$59-$F$38)/($O$10-$F$10)*(L10-$F$10)) -> 0.07366593 | M38: =IF(OR($C$3="EL",$C$3="CY",$C$3="IE",$C$3="PT"),VLOOKUP($C$3,$B$110:$T$114,MATCH(M$10,$B$110:$T$110,0),0),$F$38+('Input data'!$C$59-$F$38)/($O$10-$F$10)*(M10-$F$10)) -> 0.09283323 | N38: =IF(OR($C$3="EL",$C$3="CY",$C$3="IE",$C$3="PT"),VLOOKUP($C$3,$B$110:$T$114,MATCH(N$10,$B$110:$T$110,0),0),$F$38+('Input data'!$C$59-$F$38)/($O$10-$F$10)*(N10-$F$10)) -> 0.09749916 | O38: =IF(OR($C$3="EL",$C$3="CY",$C$3="IE",$C$3="PT"),VLOOKUP($C$3,$B$110:$T$114,MATCH(O$10,$B$110:$T$110,0),0),'Input data'!$C$59) -> 0.10431984 | P38: =IF(OR($C$3="EL",$C$3="CY",$C$3="IE",$C$3="PT"),VLOOKUP($C$3,$B$110:$T$114,MATCH(P$10,$B$110:$T$110,0),0),'Input data'!$C$59) -> 0.07769295 | Q38: =IF(OR($C$3="EL",$C$3="CY",$C$3="IE",$C$3="PT"),VLOOKUP($C$3,$B$110:$T$114,MATCH(Q$10,$B$110:$T$110,0),0),'Input data'!$C$59) -> 0.08189674 | R38: =IF(OR($C$3="EL",$C$3="CY",$C$3="IE",$C$3="PT"),VLOOKUP($C$3,$B$110:$T$114,MATCH(R$10,$B$110:$T$110,0),0),'Input data'!$C$59) -> 0.07226059 | S38: =IF(OR($C$3="EL",$C$3="CY",$C$3="IE",$C$3="PT"),VLOOKUP($C$3,$B$110:$T$114,MATCH(S$10,$B$110:$T$110,0),0),'Input data'!$C$59) -> 0.07247516 | T38: =IF(OR($C$3="EL",$C$3="CY",$C$3="IE",$C$3="PT"),VLOOKUP($C$3,$B$110:$T$114,MATCH(T$10,$B$110:$T$110,0),0),'Input data'!$C$59) -> 0.07270425 | U38: =IF(OR($C$3="EL",$C$3="CY",$C$3="IE",$C$3="PT"),VLOOKUP($C$3,$B$110:$W$114,MATCH(U$10,$B$110:$W$110,0),0),'Input data'!$C$59) -> 0.07292216 | V38: =IF(OR($C$3="EL",$C$3="CY",$C$3="IE",$C$3="PT"),VLOOKUP($C$3,$B$110:$W$114,MATCH(V$10,$B$110:$W$110,0),0),'Input data'!$C$59) -> 0.07311259 | W38: =IF(OR($C$3="EL",$C$3="CY",$C$3="IE",$C$3="PT"),VLOOKUP($C$3,$B$110:$W$114,MATCH(W$10,$B$110:$W$110,0),0),'Input data'!$C$59) -> 0.07343585
B40: Inflation and exchange rate
B41: GDP deflator (national currency) | C41: ='Input data'!C42 -> 0.4774826 | D41: ='Input data'!D42 -> 6.582269 | E41: ='Input data'!E42 -> 2.965217 | F41: ='Input data'!F42 -> 2.574346 | G41: ='Input data'!G42 -> 1.914897 | H41: =$G$41+($O$41-$G$41)/($O$10-$G$10)*(H10-$G$10) -> 1.9942849 | I41: =$G$41+($O$41-$G$41)/($O$10-$G$10)*(I10-$G$10) -> 2.0736728 | J41: =$G$41+($O$41-$G$41)/($O$10-$G$10)*(J10-$G$10) -> 2.1530606 | K41: =$G$41+($O$41-$G$41)/($O$10-$G$10)*(K10-$G$10) -> 2.2324485 | L41: =$G$41+($O$41-$G$41)/($O$10-$G$10)*(L10-$G$10) -> 2.3118364 | M41: =$G$41+($O$41-$G$41)/($O$10-$G$10)*(M10-$G$10) -> 2.3912243 | N41: =$G$41+($O$41-$G$41)/($O$10-$G$10)*(N10-$G$10) -> 2.4706121 | O41: ='Input data'!$C$61 -> 2.55 | P41: =$O$41+('Input data'!$C$62-'Input data'!$C$61)/20*(P$10-2033) -> 2.5225 | Q41: =$O$41+('Input data'!$C$62-'Input data'!$C$61)/20*(Q$10-2033) -> 2.495 | R41: =$O$41+('Input data'!$C$62-'Input data'!$C$61)/20*(R$10-2033) -> 2.4675 | S41: =$O$41+('Input data'!$C$62-'Input data'!$C$61)/20*(S$10-2033) -> 2.44 | T41: =$O$41+('Input data'!$C$62-'Input data'!$C$61)/20*(T$10-2033) -> 2.4125 | U41: =$O$41+('Input data'!$C$62-'Input data'!$C$61)/20*(U$10-2033) -> 2.385 | V41: =$O$41+('Input data'!$C$62-'Input data'!$C$61)/20*(V$10-2033) -> 2.3575 | W41: =$O$41+('Input data'!$C$62-'Input data'!$C$61)/20*(W$10-2033) -> 2.33
B42: Exchange rate composite change (weighted by share of debt in each currency) | C42: 1 | D42: 1 | E42: 0.9999999 | F42: 1 | G42: 1 | H42: 1 | I42: 1 | J42: 1 | K42: 1 | L42: 1 | M42: 1 | N42: 1 | O42: 1 | P42: 1 | Q42: 1 | R42: 1 | S42: 1 | T42: 1 | U42: 1 | V42: 1 | W42: 1
B44: Intermediate calculations (growth rate equation)
B46: Fiscal multiplier | C46: ='Input data'!C49 -> 0.75
B47: Budget balance semi-elasticity | C47: ='Input data'!C50 -> 0.522
B49: Auxiliary variable to control the closure of the output gap | D49: =IF(AND(ABS((D12-C12)-('Input data'!D13-'Input data'!C13))>0.0001,ABS(D12-C12)>0.0001,D$10>$C$5),4,IF(C49=4,3,IF(C49=3,2,IF(C49=2,1,0)))) -> 0 | E49: =IF(AND(ABS((E12-D12)-('Input data'!E13-'Input data'!D13))>0.0001,ABS(E12-D12)>0.0001,E$10>$C$5),4,IF(D49=4,3,IF(D49=3,2,IF(D49=2,1,0)))) -> 0 | F49: =IF(AND(ABS((F12-E12)-('Input data'!F13-'Input data'!E13))>0.0001,ABS(F12-E12)>0.0001,F$10>$C$5),4,IF(E49=4,3,IF(E49=3,2,IF(E49=2,1,0)))) -> 0 | G49: =IF(AND(ABS((G12-F12)-('Input data'!G13-'Input data'!F13))>0.0001,ABS(G12-F12)>0.0001,G$10>$C$5),4,IF(F49=4,3,IF(F49=3,2,IF(F49=2,1,0)))) -> 0 | H49: =IF(AND(ABS((H12-G12)-('Input data'!H13-'Input data'!G13))>0.0001,ABS(H12-G12)>0.0001,H$10>$C$5),4,IF(G49=4,3,IF(G49=3,2,IF(G49=2,1,0)))) -> 0 | I49: =IF(AND(ABS((I12-H12)-('Input data'!I13-'Input data'!H13))>0.0001,ABS(I12-H12)>0.0001,I$10>$C$5),4,IF(H49=4,3,IF(H49=3,2,IF(H49=2,1,0)))) -> 0 | J49: =IF(AND(ABS((J12-I12)-('Input data'!J13-'Input data'!I13))>0.0001,ABS(J12-I12)>0.0001,J$10>$C$5),4,IF(I49=4,3,IF(I49=3,2,IF(I49=2,1,0)))) -> 0 | K49: =IF(AND(ABS((K12-J12)-('Input data'!K13-'Input data'!J13))>0.0001,ABS(K12-J12)>0.0001,K$10>$C$5),4,IF(J49=4,3,IF(J49=3,2,IF(J49=2,1,0)))) -> 0 | ... W49: =IF(AND(ABS((W12-V12)-('Input data'!W13-'Input data'!V13))>0.0001,ABS(W12-V12)>0.0001,W$10>$C$5),4,IF(V49=4,3,IF(V49=3,2,IF(V49=2,1,0)))) -> 0
B50: OG intermediate auxiliary value | D50: =IF(C49=4,2/3*C29,IF(C49=3,1/3*B29,0)) -> 0 | E50: =IF(D49=4,2/3*D29,IF(D49=3,1/3*C29,0)) -> 0 | F50: =IF(E49=4,2/3*E29,IF(E49=3,1/3*D29,0)) -> 0 | G50: =IF(F49=4,2/3*F29,IF(F49=3,1/3*E29,0)) -> 0 | H50: =IF(G49=4,2/3*G29,IF(G49=3,1/3*F29,0)) -> 0 | I50: =IF(H49=4,2/3*H29,IF(H49=3,1/3*G29,0)) -> 0 | J50: =IF(I49=4,2/3*I29,IF(I49=3,1/3*H29,0)) -> 0 | K50: =IF(J49=4,2/3*J29,IF(J49=3,1/3*I29,0)) -> 0 | ... W50: =IF(V49=4,2/3*V29,IF(V49=3,1/3*U29,0)) -> 0
B51: GDP intermediate growth rate - only feedback effect and no closure of the OG | D51: ='Input data'!D30-$C$46*((D12-C12)-('Input data'!D13-'Input data'!C13)) -> 9.433022 | E51: ='Input data'!E30-$C$46*((E12-D12)-('Input data'!E13-'Input data'!D13)) -> -3.198788 | F51: ='Input data'!F30-$C$46*((F12-E12)-('Input data'!F13-'Input data'!E13)) -> 1.243702 | G51: ='Input data'!G30-$C$46*((G12-F12)-('Input data'!G13-'Input data'!F13)) -> 1.4972052 | H51: ='Input data'!H30-$C$46*((H12-G12)) -> 3.746114 | I51: ='Input data'!I30-$C$46*((I12-H12)) -> 3.802369 | J51: ='Input data'!J30-$C$46*((J12-I12)) -> 3.577386 | K51: ='Input data'!K30-$C$46*((K12-J12)) -> 3.164204 | L51: ='Input data'!L30-$C$46*((L12-K12)) -> 2.938014 | M51: ='Input data'!M30-$C$46*((M12-L12)) -> 2.669411 | N51: ='Input data'!N30-$C$46*((N12-M12)) -> 2.359786 | O51: ='Input data'!O30-$C$46*((O12-N12)) -> 2.013409 | ... W51: ='Input data'!W30-$C$46*((W12-V12)) -> 1.571112
B53: Debt projections
C55: 2021 | D55: 2022 | E55: 2023 | F55: 2024 | G55: 2025 | H55: 2026 | I55: 2027 | J55: 2028 | K55: 2029 | L55: 2030 | M55: 2031 | N55: 2032 | O55: 2033 | P55: 2034 | Q55: 2035 | R55: 2036 | S55: 2037 | T55: 2038 | U55: 2039 | V55: 2040 | W55: 2041
B56: Gross debt | C56: =+'Input data'!C12 -> 54.39847 | D56: =+C56+D57 -> 44.391772 | E56: =+D56+E57 -> 43.730434 | F56: =+E56+F57 -> 42.488825 | G56: =+F56+G57 -> 41.250806 | H56: =+G56+H57 -> 37.732588 | I56: =+H56+I57 -> 34.267259 | J56: =+I56+J57 -> 31.007171 | K56: =+J56+K57 -> 28.062291 | ... W56: =+V56+W57 -> 9.8184426
...

Sheet Adjustment scenario
B3: Country | C3: ='Input data'!C3 -> IE
B4: Key years
B5: ='Input data'!B5 -> Last year before the adjustment | C5: =+'Input data'!C5 -> 2024
B6: Last year of adjustment | C6: =+C5+'Criteria results'!$F$5 -> 2028
B7: Last year of no-fiscal-policy-change projections | C7: =C5+'Criteria results'!$F$5+10 -> 2038
B9: Key assumptions
C10: 2021 | D10: 2022 | E10: 2023 | F10: 2024 | G10: 2025 | H10: 2026 | I10: 2027 | J10: 2028 | K10: 2029 | L10: 2030 | M10: 2031 | N10: 2032 | O10: 2033 | P10: 2034 | Q10: 2035 | R10: 2036 | S10: 2037 | T10: 2038 | U10: 2039 | V10: 2040 | W10: 2041
B11: Fiscal assumptions (% of GDP)
B12: Structural primary balance ('+' means 'surplus') | C12: ='Input data'!C13 -> -3.165318 | D12: ='Input data'!D13 -> -2.376722 | E12: ='Input data'!E13 -> 1.712465 | F12: ='Input data'!F13 -> 2.528801 | G12: =IF(G10<=$C$6, IF(AND(F78<=-1.55,'Criteria results'!$F$5=4,'Criteria results'!$F$6<0.4),F12+0.4, IF(AND(F78<=-1.55,'Criteria results'!$F$5=7,'Criteria results'!$F$6<0.25),F12+0.25, F12+'Criteria results'!$F$6)),F12) -> 2.528801 | H12: =IF(H10<=$C$6, IF(AND(G78<=-1.55,'Criteria results'!$F$5=4,'Criteria results'!$F$6<0.4),G12+0.4, IF(AND(G78<=-1.55,'Criteria results'!$F$5=7,'Criteria results'!$F$6<0.25),G12+0.25, G12+'Criteria results'!$F$6)),G12) -> 2.528801 | I12: =IF(I10<=$C$6, IF(AND(H78<=-1.55,'Criteria results'!$F$5=4,'Criteria results'!$F$6<0.4),H12+0.4, IF(AND(H78<=-1.55,'Criteria results'!$F$5=7,'Criteria results'!$F$6<0.25),H12+0.25, H12+'Criteria results'!$F$6)),H12) -> 2.528801 | J12: =IF(J10<=$C$6, IF(AND(I78<=-1.55,'Criteria results'!$F$5=4,'Criteria results'!$F$6<0.4),I12+0.4, IF(AND(I78<=-1.55,'Criteria results'!$F$5=7,'Criteria results'!$F$6<0.25),I12+0.25, I12+'Criteria results'!$F$6)),I12) -> 2.528801 | K12: =IF(K10<=$C$6, IF(AND(J78<=-1.55,'Criteria results'!$F$5=4,'Criteria results'!$F$6<0.4),J12+0.4, IF(AND(J78<=-1.55,'Criteria results'!$F$5=7,'Criteria results'!$F$6<0.25),J12+0.25, J12+'Criteria results'!$F$6)),J12) -> 2.528801 | L12: =IF(L10<=$C$6, IF(AND(K78<=-1.55,'Criteria results'!$F$5=4,'Criteria results'!$F$6<0.4),K12+0.4, IF(AND(K78<=-1.55,'Criteria results'!$F$5=7,'Criteria results'!$F$6<0.25),K12+0.25, K12+'Criteria results'!$F$6)),K12) -> 2.528801 | M12: =IF(M10<=$C$6, IF(AND(L78<=-1.55,'Criteria results'!$F$5=4,'Criteria results'!$F$6<0.4),L12+0.4, IF(AND(L78<=-1.55,'Criteria results'!$F$5=7,'Criteria results'!$F$6<0.25),L12+0.25, L12+'Criteria results'!$F$6)),L12) -> 2.528801 | N12: =M12 -> 2.528801 | O12: =N12 -> 2.528801 | P12: =O12 -> 2.528801 | Q12: =P12 -> 2.528801 | R12: =Q12 -> 2.528801 | S12: =R12 -> 2.528801 | T12: =S12 -> 2.528801 | U12: =T12 -> 2.528801 | ... W12: =V12 -> 2.528801
B13: Annual change in SPB | G13: =G12-F12 -> 0 | H13: =H12-G12 -> 0 | I13: =I12-H12 -> 0 | J13: =J12-I12 -> 0 | K13: =K12-J12 -> 0 | L13: =L12-K12 -> 0 | M13: =M12-L12 -> 0 | N13: =N12-M12 -> 0 | ... W13: =W12-V12 -> 0
B14: One-off and other temporary measures | C14: ='Input data'!C14 -> 0 | D14: ='Input data'!D14 -> 0 | E14: ='Input data'!E14 -> 0 | F14: ='Input data'!F14 -> 0 | G14: ='Input data'!G14 -> 0 | H14: =0 -> 0 | I14: =0 -> 0 | J14: =0 -> 0 | K14: =0 -> 0 | L14: =0 -> 0 | M14: =0 -> 0 | N14: =0 -> 0 | O14: =0 -> 0 | ... W14: =0 -> 0
B15: Stock flow adjustments (without exchange rate effect) | C15: ='Input data'!C15 -> 2.690274 | D15: ='Input data'!D15 -> -0.5420614 | E15: ='Input data'!E15 -> 0.8428086 | F15: ='Input data'!F15 -> 1.636568 | G15: ='Input data'!G15 -> 2.20024 | H15: ='Input data'!H15 -> 0 | I15: ='Input data'!I15 -> 0 | J15: ='Input data'!J15 -> 0 | ... W15: ='Input data'!W15 -> 0
B17: ='Input data'!B19 -> Cost of ageing and selected public revenue (based on the Commission-Council 2024 Ageing Report ("AR 2024"))
B18: Total ageing cost (net of taxes on pensions) | C18: ='Input data'!C20 -> 0 | D18: ='Input data'!D20 -> 11.98063 | E18: ='Input data'!E20 -> 11.58823 | F18: ='Input data'!F20 -> 11.59789 | G18: ='Input data'!G20 -> 11.65158 | H18: ='Input data'!H20 -> 11.82718 | I18: ='Input data'!I20 -> 12.01015 | J18: ='Input data'!J20 -> 12.14108 | ... W18: ='Input data'!W20 -> 13.69105
B19: Property income | C19: ='Input data'!C26 -> 0.1107195 | D19: ='Input data'!D26 -> 0.132752 | E19: ='Input data'!E26 -> 0.1349502 | F19: ='Input data'!F26 -> 0.1371484 | G19: ='Input data'!G26 -> 0.1393466 | H19: ='Input data'!H26 -> 0.1415448 | I19: ='Input data'!I26 -> 0.143743 | J19: ='Input data'!J26 -> 0.1459412 | ... W19: ='Input data'!W26 -> 0.1745179
B21: GDP growth assumptions
B22: Actual GDP (real)
B23: Level | C23: ='Input data'!C31 -> 410.9464 | D23: ='Baseline NFPC'!D22 -> 449.71106 | E23: ='Baseline NFPC'!E22 -> 435.32576 | F23: ='Baseline NFPC'!F22 -> 440.73992 | G23: =IF(AND(G50>1,F50>1),IF(AND(G50>0,F50>0),G27*(G51/100+1),0)+IF(G50>0,F23*(1+G52/100),0)-F23*(1+'Input data'!G30/100),IF(G50=1,G27,F23*(1+G52/100))) -> 455.69777 | H23: =IF(AND(H50>1,G50>1),IF(AND(H50>0,G50>0),H27*(H51/100+1),0)+IF(H50>0,G23*(1+H52/100),0)-G23*(1+'Input data'!H30/100),IF(H50=1,H27,G23*(1+H52/100))) -> 472.76873 | I23: =IF(AND(I50>1,H50>1),IF(AND(I50>0,H50>0),I27*(I51/100+1),0)+IF(I50>0,H23*(1+I52/100),0)-H23*(1+'Input data'!I30/100),IF(I50=1,I27,H23*(1+I52/100))) -> 490.74514 | J23: =IF(AND(J50>1,I50>1),IF(AND(J50>0,I50>0),J27*(J51/100+1),0)+IF(J50>0,I23*(1+J52/100),0)-I23*(1+'Input data'!J30/100),IF(J50=1,J27,I23*(1+J52/100))) -> 508.30099 | K23: =IF(AND(K50>1,J50>1),IF(AND(K50>0,J50>0),K27*(K51/100+1),0)+IF(K50>0,J23*(1+K52/100),0)-J23*(1+'Input data'!K30/100),IF(K50=1,K27,J23*(1+K52/100))) -> 524.38467 | L23: =IF(AND(L50>1,K50>1),IF(AND(L50>0,K50>0),L27*(L51/100+1),0)+IF(L50>0,K23*(1+L52/100),0)-K23*(1+'Input data'!L30/100),IF(L50=1,L27,K23*(1+L52/100))) -> 539.79117 | M23: =IF(AND(M50>1,L50>1),IF(AND(M50>0,L50>0),M27*(M51/100+1),0)+IF(M50>0,L23*(1+M52/100),0)-L23*(1+'Input data'!M30/100),IF(M50=1,M27,L23*(1+M52/100))) -> 554.20041 | N23: =IF(AND(N50>1,M50>1),IF(AND(N50>0,M50>0),N27*(N51/100+1),0)+IF(N50>0,M23*(1+N52/100),0)-M23*(1+'Input data'!N30/100),IF(N50=1,N27,M23*(1+N52/100))) -> 567.27836 | ... W23: =IF(AND(W50>1,V50>1),IF(AND(W50>0,V50>0),W27*(W51/100+1),0)+IF(W50>0,V23*(1+W52/100),0)-V23*(1+'Input data'!W30/100),IF(W50=1,W27,V23*(1+W52/100))) -> 666.4502
B24: Growth rate | C24: =+'Input data'!C30 -> 15.12522 | D24: ='Baseline NFPC'!D23 -> 9.433022 | E24: ='Baseline NFPC'!E23 -> -3.198788 | F24: ='Baseline NFPC'!F23 -> 1.243702 | G24: =100*(G23/F23-1) -> 3.393806 | H24: =100*(H23/G23-1) -> 3.746114 | I24: =100*(I23/H23-1) -> 3.802369 | J24: =100*(J23/I23-1) -> 3.577386 | K24: =100*(K23/J23-1) -> 3.164204 | L24: =100*(L23/K23-1) -> 2.938014 | M24: =100*(M23/L23-1) -> 2.669411 | N24: =100*(N23/M23-1) -> 2.359786 | ... W24: =100*(W23/V23-1) -> 1.571112
B26: Potential GDP (real)
B27: Level | C27: ='Input data'!C34 -> 392.8036 | D27: =+C27*(1+'Input data'!D33/100) -> 412.27894 | E27: =+D27*(1+'Input data'!E33/100) -> 430.14515 | F27: =+E27*(1+'Input data'!F33/100) -> 445.69744 | G27: =+F27*(1+'Input data'!G33/100) -> 460.34222 | H27: =+G27*(1+'Input data'!H33/100) -> 475.97012 | I27: =+H27*(1+'Input data'!I33/100) -> 491.84786 | J27: =+I27*(1+'Input data'!J33/100) -> 508.30096 | K27: =+J27*(1+'Input data'!K33/100) -> 524.38464 | ... W27: =+V27*(1+'Input data'!W33/100) -> 666.45005
B29: Output gap
B30: Output gap | C30: =100*(C23/C27-1) -> 4.6187968 | D30: =100*(D23/D27-1) -> 9.07932 | E30: =100*(E23/E27-1) -> 1.2043874 | F30: =100*(F23/F27-1) -> -1.1123062 | G30: =100*(G23/G27-1) -> -1.0089108 | H30: =100*(H23/H27-1) -> -0.67260192 | I30: =100*(I23/I27-1) -> -0.22419779 | J30: =100*(J23/J27-1) -> 6.5725915e-06 | ... W30: =100*(W23/W27-1) -> 2.2288956e-05
B32: Actual GDP (nominal, national currency)
B33: Growth rate | C33: =100*((1+C24/100)*(1+C42/100)-1) -> 15.674923 | D33: =100*((1+D24/100)*(1+D42/100)-1) -> 16.636198 | E33: =100*((1+E24/100)*(1+E42/100)-1) -> -0.32842201 | F33: =100*((1+F24/100)*(1+F42/100)-1) -> 3.8500652 | G33: =100*((1+G24/100)*(1+G42/100)-1) -> 5.3736909 | H33: =100*((1+H24/100)*(1+H42/100)-1) -> 5.8151071 | I33: =100*((1+I24/100)*(1+I42/100)-1) -> 5.9548904 | J33: =100*((1+J24/100)*(1+J42/100)-1) -> 5.8074699 | ... W33: =100*((1+W24/100)*(1+W42/100)-1) -> 3.9377189
B35: Interest rates
B36: Nominal implicit interest rate on debt | C36: ='Input data'!C37 -> 1.510173 | D36: ='Input data'!D37 -> 1.408838 | E36: ='Input data'!E37 -> 1.550894 | F36: ='Input data'!F37 -> 1.641526 | G36: ='Input data'!G37 -> 1.684386 | H36: =H99 -> 1.7963363 | I36: =I99 -> 1.8477296 | J36: =J99 -> 1.8765133 | K36: =K99 -> 1.9046582 | L36: =L99 -> 1.9309319 | M36: =M99 -> 1.9360734 | N36: =N99 -> 1.9574641 | O36: =O99 -> 1.9793499 | ... W36: =W99 -> 1.9944068
B37: Long-term interest rate | D37: ='Input data'!D$39 -> 1.75 | E37: ='Input data'!E$39 -> 2.87 | F37: ='Input data'!F$39 -> 2.837221 | G37: ='Input data'!G$39 -> 2.903685 | H37: =G37+($O$37-$G$37)/($O$10-$G$10) -> 2.9987319 | I37: =H37+($O$37-$G$37)/($O$10-$G$10) -> 3.0937787 | J37: =I37+($O$37-$G$37)/($O$10-$G$10) -> 3.1888256 | K37: =J37+($O$37-$G$37)/($O$10-$G$10) -> 3.2838725 | L37: =K37+($O$37-$G$37)/($O$10-$G$10) -> 3.3789194 | M37: =L37+($O$37-$G$37)/($O$10-$G$10) -> 3.4739662 | N37: =M37+($O$37-$G$37)/($O$10-$G$10) -> 3.5690131 | O37: ='Input data'!$C$52 -> 3.66406 | P37: ='Baseline NFPC'!P36 -> 3.680857 | Q37: ='Baseline NFPC'!Q36 -> 3.697654 | R37: ='Baseline NFPC'!R36 -> 3.714451 | S37: ='Baseline NFPC'!S36 -> 3.731248 | T37: ='Baseline NFPC'!T36 -> 3.748045 | U37: ='Baseline NFPC'!U36 -> 3.764842 | V37: ='Baseline NFPC'!V36 -> 3.781639 | W37: ='Baseline NFPC'!W36 -> 3.798436
B38: Short-term interest rate | D38: ='Input data'!D$38 -> 0.35 | E38: ='Input data'!E$38 -> 3.43 | F38: ='Input data'!F$38 -> 3.564208 | G38: ='Input data'!G$38 -> 2.816375 | H38: =G38+($O$38-$G$38)/($O$10-$G$10) -> 2.8050894 | I38: =H38+($O$38-$G$38)/($O$10-$G$10) -> 2.7938037 | J38: =I38+($O$38-$G$38)/($O$10-$G$10) -> 2.7825181 | K38: =J38+($O$38-$G$38)/($O$10-$G$10) -> 2.7712325 | L38: =K38+($O$38-$G$38)/($O$10-$G$10) -> 2.7599469 | M38: =L38+($O$38-$G$38)/($O$10-$G$10) -> 2.7486612 | N38: =M38+($O$38-$G$38)/($O$10-$G$10) -> 2.7373756 | O38: ='Input data'!$C$53 -> 2.72609 | P38: ='Baseline NFPC'!P37 -> 2.6897855 | Q38: ='Baseline NFPC'!Q37 -> 2.653481 | R38: ='Baseline NFPC'!R37 -> 2.6171765 | S38: ='Baseline NFPC'!S37 -> 2.580872 | T38: ='Baseline NFPC'!T37 -> 2.5445675 | U38: ='Baseline NFPC'!U37 -> 2.508263 | V38: ='Baseline NFPC'!V37 -> 2.4719585 | W38: ='Baseline NFPC'!W37 -> 2.435654
B39: Share of long-term debt that matures every year | C39: ='Baseline NFPC'!C38 -> 0.001 | D39: ='Baseline NFPC'!D38 -> 0.07537306 | E39: ='Baseline NFPC'!E38 -> 0.04688205 | F39: ='Baseline NFPC'!F38 -> 0.05421672 | G39: ='Baseline NFPC'!G38 -> 0.06734311 | H39: ='Baseline NFPC'!H38 -> 0.07328111 | I39: ='Baseline NFPC'!I38 -> 0.06373561 | J39: ='Baseline NFPC'!J38 -> 0.07199902 | ... W39: ='Baseline NFPC'!W38 -> 0.07343585
B41: Inflation and exchange rate
B42: GDP deflator (National currency) | C42: ='Input data'!C42 -> 0.4774826 | D42: ='Input data'!D42 -> 6.582269 | E42: ='Input data'!E42 -> 2.965217 | F42: ='Input data'!F42 -> 2.574346 | G42: ='Input data'!G42 -> 1.914897 | H42: ='Baseline NFPC'!H41 -> 1.9942849 | I42: ='Baseline NFPC'!I41 -> 2.0736728 | J42: ='Baseline NFPC'!J41 -> 2.1530606 | K42: ='Baseline NFPC'!K41 -> 2.2324485 | L42: ='Baseline NFPC'!L41 -> 2.3118364 | M42: ='Baseline NFPC'!M41 -> 2.3912243 | N42: ='Baseline NFPC'!N41 -> 2.4706121 | O42: ='Baseline NFPC'!O41 -> 2.55 | ... W42: ='Baseline NFPC'!W41 -> 2.33
B43: Exchange rate composite change (weighted by share of debt in each currency) | C43: ='Baseline NFPC'!C42 -> 1 | D43: ='Baseline NFPC'!D42 -> 1 | E43: ='Baseline NFPC'!E42 -> 0.9999999 | F43: ='Baseline NFPC'!F42 -> 1 | G43: ='Baseline NFPC'!G42 -> 1 | H43: ='Baseline NFPC'!H42 -> 1 | I43: ='Baseline NFPC'!I42 -> 1 | J43: ='Baseline NFPC'!J42 -> 1 | ... W43: ='Baseline NFPC'!W42 -> 1
B45: Intermediate calculations (growth rate equation)
B47: Fiscal multiplier | C47: ='Input data'!C49 -> 0.75
B48: Budget balance semi-elasticity | C48: ='Input data'!C50 -> 0.522
B50: Auxiliary variable to control the closure of the output gap | C50: 0 | D50: =IF(AND(ABS((D12-C12)-('Input data'!D13-'Input data'!C13))>0.0001,ABS(D12-C12)>0.0001,D$10>$C$5),4,IF(C50=4,3,IF(C50=3,2,IF(C50=2,1,0)))) -> 0 | E50: =IF(AND(ABS((E12-D12)-('Input data'!E13-'Input data'!D13))>0.0001,ABS(E12-D12)>0.0001,E$10>$C$5),4,IF(D50=4,3,IF(D50=3,2,IF(D50=2,1,0)))) -> 0 | F50: =IF(AND(ABS((F12-E12)-('Input data'!F13-'Input data'!E13))>0.0001,ABS(F12-E12)>0.0001,F$10>$C$5),4,IF(E50=4,3,IF(E50=3,2,IF(E50=2,1,0)))) -> 0 | G50: =IF(AND(ABS((G12-F12)-('Input data'!G13-'Input data'!F13))>0.0001,ABS(G12-F12)>0.0001,G$10>$C$5),4,IF(F50=4,3,IF(F50=3,2,IF(F50=2,1,0)))) -> 0 | H50: =IF(AND(ABS((H12-G12)-('Input data'!H13-'Input data'!G13))>0.0001,ABS(H12-G12)>0.0001,H$10>$C$5),4,IF(G50=4,3,IF(G50=3,2,IF(G50=2,1,0)))) -> 0 | I50: =IF(AND(ABS((I12-H12)-('Input data'!I13-'Input data'!H13))>0.0001,ABS(I12-H12)>0.0001,I$10>$C$5),4,IF(H50=4,3,IF(H50=3,2,IF(H50=2,1,0)))) -> 0 | J50: =IF(AND(ABS((J12-I12)-('Input data'!J13-'Input data'!I13))>0.0001,ABS(J12-I12)>0.0001,J$10>$C$5),4,IF(I50=4,3,IF(I50=3,2,IF(I50=2,1,0)))) -> 0 | K50: =IF(AND(ABS((K12-J12)-('Input data'!K13-'Input data'!J13))>0.0001,ABS(K12-J12)>0.0001,K$10>$C$5),4,IF(J50=4,3,IF(J50=3,2,IF(J50=2,1,0)))) -> 0 | ... W50: =IF(AND(ABS((W12-V12)-('Input data'!W13-'Input data'!V13))>0.0001,ABS(W12-V12)>0.0001,W$10>$C$5),4,IF(V50=4,3,IF(V50=3,2,IF(V50=2,1,0)))) -> 0
B51: OG intermediate auxiliary value | C51: 0 | D51: =IF(C50=4,2/3*C30,IF(C50=3,1/3*B30,0)) -> 0 | E51: =IF(D50=4,2/3*D30,IF(D50=3,1/3*C30,0)) -> 0 | F51: =IF(E50=4,2/3*E30,IF(E50=3,1/3*D30,0)) -> 0 | G51: =IF(F50=4,2/3*F30,IF(F50=3,1/3*E30,0)) -> 0 | H51: =IF(G50=4,2/3*G30,IF(G50=3,1/3*F30,0)) -> 0 | I51: =IF(H50=4,2/3*H30,IF(H50=3,1/3*G30,0)) -> 0 | J51: =IF(I50=4,2/3*I30,IF(I50=3,1/3*H30,0)) -> 0 | K51: =IF(J50=4,2/3*J30,IF(J50=3,1/3*I30,0)) -> 0 | ... W51: =IF(V50=4,2/3*V30,IF(V50=3,1/3*U30,0)) -> 0
B52: GDP intermediate growth rate - only feedback effect and no closure of the OG | D52: ='Input data'!D30-$C$47*((D12-C12)-('Input data'!D13-'Input data'!C13)) -> 9.433022 | E52: ='Input data'!E30-$C$47*((E12-D12)-('Input data'!E13-'Input data'!D13)) -> -3.198788 | F52: ='Input data'!F30-$C$47*((F12-E12)-('Input data'!F13-'Input data'!E13)) -> 1.243702 | G52: ='Input data'!G30-$C$47*((G12-F12)) -> 3.393806 | H52: ='Input data'!H30-$C$47*((H12-G12)) -> 3.746114 | I52: ='Input data'!I30-$C$47*((I12-H12)) -> 3.802369 | J52: ='Input data'!J30-$C$47*((J12-I12)) -> 3.577386 | K52: ='Input data'!K30-$C$47*((K12-J12)) -> 3.164204 | L52: ='Input data'!L30-$C$47*((L12-K12)) -> 2.938014 | M52: ='Input data'!M30-$C$47*((M12-L12)) -> 2.669411 | N52: ='Input data'!N30-$C$47*((N12-M12)) -> 2.359786 | ... W52: ='Input data'!W30-$C$47*((W12-V12)) -> 1.571112
B54: Debt projections
...

Sheet Adjust. no safeguard
B3: Country | C3: ='Input data'!C3 -> IE
B4: Key years
B5: ='Input data'!B5 -> Last year before the adjustment | C5: =+'Input data'!C5 -> 2024
B6: Last year of adjustment | C6: =+C5+'Criteria results'!$F$5 -> 2028
B7: Last year of no-fiscal-policy-change projections | C7: =C5+'Criteria results'!$F$5+10 -> 2038
B9: Key assumptions
C10: 2021 | D10: 2022 | E10: 2023 | F10: 2024 | G10: 2025 | H10: 2026 | I10: 2027 | J10: 2028 | K10: 2029 | L10: 2030 | M10: 2031 | N10: 2032 | O10: 2033 | P10: 2034 | Q10: 2035 | R10: 2036 | S10: 2037 | T10: 2038 | U10: 2039 | V10: 2040 | W10: 2041
B11: Fiscal assumptions (% of GDP)
B12: Structural primary balance ('+' means 'surplus') | C12: ='Input data'!C13 -> -3.165318 | D12: ='Input data'!D13 -> -2.376722 | E12: ='Input data'!E13 -> 1.712465 | F12: ='Input data'!F13 -> 2.528801 | G12: =IF(G10<=$C$6,F12+'Criteria results'!$F$7,F12) -> 2.528801 | H12: =IF(H10<=$C$6,G12+'Criteria results'!$F$7,G12) -> 2.528801 | I12: =IF(I10<=$C$6,H12+'Criteria results'!$F$7,H12) -> 2.528801 | J12: =IF(J10<=$C$6,I12+'Criteria results'!$F$7,I12) -> 2.528801 | K12: =IF(K10<=$C$6,J12+'Criteria results'!$F$7,J12) -> 2.528801 | L12: =IF(L10<=$C$6,K12+'Criteria results'!$F$7,K12) -> 2.528801 | M12: =IF(M10<=$C$6,L12+'Criteria results'!$F$7,L12) -> 2.528801 | N12: =M12 -> 2.528801 | O12: =N12 -> 2.528801 | P12: =O12 -> 2.528801 | Q12: =P12 -> 2.528801 | R12: =Q12 -> 2.528801 | S12: =R12 -> 2.528801 | T12: =S12 -> 2.528801 | U12: =T12 -> 2.528801 | ... W12: =V12 -> 2.528801
B13: Annual change in SPB | G13: =G12-F12 -> 0 | H13: =H12-G12 -> 0 | I13: =I12-H12 -> 0 | J13: =J12-I12 -> 0 | K13: =K12-J12 -> 0 | L13: =L12-K12 -> 0 | M13: =M12-L12 -> 0 | N13: =N12-M12 -> 0 | ... W13: =W12-V12 -> 0
B14: One-off and other temporary measures | C14: ='Input data'!C14 -> 0 | D14: ='Input data'!D14 -> 0 | E14: ='Input data'!E14 -> 0 | F14: ='Input data'!F14 -> 0 | G14: ='Input data'!G14 -> 0 | H14: =0 -> 0 | I14: =0 -> 0 | J14: =0 -> 0 | K14: =0 -> 0 | L14: =0 -> 0 | M14: =0 -> 0 | N14: =0 -> 0 | O14: =0 -> 0 | ... W14: =0 -> 0
B15: Stock flow adjustments (without exchange rate effect) | C15: ='Input data'!C15 -> 2.690274 | D15: ='Input data'!D15 -> -0.5420614 | E15: ='Input data'!E15 -> 0.8428086 | F15: ='Input data'!F15 -> 1.636568 | G15: ='Input data'!G15 -> 2.20024 | H15: ='Input data'!H15 -> 0 | I15: ='Input data'!I15 -> 0 | J15: ='Input data'!J15 -> 0 | ... W15: ='Input data'!W15 -> 0
B17: ='Input data'!B19 -> Cost of ageing and selected public revenue (based on the Commission-Council 2024 Ageing Report ("AR 2024"))
B18: Total ageing cost (net of taxes on pensions) | C18: ='Input data'!C20 -> 0 | D18: ='Input data'!D20 -> 11.98063 | E18: ='Input data'!E20 -> 11.58823 | F18: ='Input data'!F20 -> 11.59789 | G18: ='Input data'!G20 -> 11.65158 | H18: ='Input data'!H20 -> 11.82718 | I18: ='Input data'!I20 -> 12.01015 | J18: ='Input data'!J20 -> 12.14108 | ... W18: ='Input data'!W20 -> 13.69105
B19: Property income | C19: ='Input data'!C26 -> 0.1107195 | D19: ='Input data'!D26 -> 0.132752 | E19: ='Input data'!E26 -> 0.1349502 | F19: ='Input data'!F26 -> 0.1371484 | G19: ='Input data'!G26 -> 0.1393466 | H19: ='Input data'!H26 -> 0.1415448 | I19: ='Input data'!I26 -> 0.143743 | J19: ='Input data'!J26 -> 0.1459412 | ... W19: ='Input data'!W26 -> 0.1745179
B21: GDP growth assumptions
B22: Actual GDP (real)
B23: Level | C23: ='Input data'!C31 -> 410.9464 | D23: ='Baseline NFPC'!D22 -> 449.71106 | E23: ='Baseline NFPC'!E22 -> 435.32576 | F23: ='Baseline NFPC'!F22 -> 440.73992 | G23: =IF(AND(G50>1,F50>1),IF(AND(G50>0,F50>0),G27*(G51/100+1),0)+IF(G50>0,F23*(1+G52/100),0)-F23*(1+'Input data'!G30/100),IF(G50=1,G27,F23*(1+G52/100))) -> 455.69777 | H23: =IF(AND(H50>1,G50>1),IF(AND(H50>0,G50>0),H27*(H51/100+1),0)+IF(H50>0,G23*(1+H52/100),0)-G23*(1+'Input data'!H30/100),IF(H50=1,H27,G23*(1+H52/100))) -> 472.76873 | I23: =IF(AND(I50>1,H50>1),IF(AND(I50>0,H50>0),I27*(I51/100+1),0)+IF(I50>0,H23*(1+I52/100),0)-H23*(1+'Input data'!I30/100),IF(I50=1,I27,H23*(1+I52/100))) -> 490.74514 | J23: =IF(AND(J50>1,I50>1),IF(AND(J50>0,I50>0),J27*(J51/100+1),0)+IF(J50>0,I23*(1+J52/100),0)-I23*(1+'Input data'!J30/100),IF(J50=1,J27,I23*(1+J52/100))) -> 508.30099 | K23: =IF(AND(K50>1,J50>1),IF(AND(K50>0,J50>0),K27*(K51/100+1),0)+IF(K50>0,J23*(1+K52/100),0)-J23*(1+'Input data'!K30/100),IF(K50=1,K27,J23*(1+K52/100))) -> 524.38467 | L23: =IF(AND(L50>1,K50>1),IF(AND(L50>0,K50>0),L27*(L51/100+1),0)+IF(L50>0,K23*(1+L52/100),0)-K23*(1+'Input data'!L30/100),IF(L50=1,L27,K23*(1+L52/100))) -> 539.79117 | M23: =IF(AND(M50>1,L50>1),IF(AND(M50>0,L50>0),M27*(M51/100+1),0)+IF(M50>0,L23*(1+M52/100),0)-L23*(1+'Input data'!M30/100),IF(M50=1,M27,L23*(1+M52/100))) -> 554.20041 | N23: =IF(AND(N50>1,M50>1),IF(AND(N50>0,M50>0),N27*(N51/100+1),0)+IF(N50>0,M23*(1+N52/100),0)-M23*(1+'Input data'!N30/100),IF(N50=1,N27,M23*(1+N52/100))) -> 567.27836 | ... W23: =IF(AND(W50>1,V50>1),IF(AND(W50>0,V50>0),W27*(W51/100+1),0)+IF(W50>0,V23*(1+W52/100),0)-V23*(1+'Input data'!W30/100),IF(W50=1,W27,V23*(1+W52/100))) -> 666.4502
B24: Growth rate | C24: =+'Input data'!C30 -> 15.12522 | D24: ='Baseline NFPC'!D23 -> 9.433022 | E24: ='Baseline NFPC'!E23 -> -3.198788 | F24: ='Baseline NFPC'!F23 -> 1.243702 | G24: =100*(G23/F23-1) -> 3.393806 | H24: =100*(H23/G23-1) -> 3.746114 | I24: =100*(I23/H23-1) -> 3.802369 | J24: =100*(J23/I23-1) -> 3.577386 | K24: =100*(K23/J23-1) -> 3.164204 | L24: =100*(L23/K23-1) -> 2.938014 | M24: =100*(M23/L23-1) -> 2.669411 | N24: =100*(N23/M23-1) -> 2.359786 | ... W24: =100*(W23/V23-1) -> 1.571112
B26: Potential GDP (real)
B27: Level | C27: ='Input data'!C34 -> 392.8036 | D27: =+C27*(1+'Input data'!D33/100) -> 412.27894 | E27: =+D27*(1+'Input data'!E33/100) -> 430.14515 | F27: =+E27*(1+'Input data'!F33/100) -> 445.69744 | G27: =+F27*(1+'Input data'!G33/100) -> 460.34222 | H27: =+G27*(1+'Input data'!H33/100) -> 475.97012 | I27: =+H27*(1+'Input data'!I33/100) -> 491.84786 | J27: =+I27*(1+'Input data'!J33/100) -> 508.30096 | K27: =+J27*(1+'Input data'!K33/100) -> 524.38464 | ... W27: =+V27*(1+'Input data'!W33/100) -> 666.45005
B29: Output gap
B30: Output gap | C30: =100*(C23/C27-1) -> 4.6187968 | D30: =100*(D23/D27-1) -> 9.07932 | E30: =100*(E23/E27-1) -> 1.2043874 | F30: =100*(F23/F27-1) -> -1.1123062 | G30: =100*(G23/G27-1) -> -1.0089108 | H30: =100*(H23/H27-1) -> -0.67260192 | I30: =100*(I23/I27-1) -> -0.22419779 | J30: =100*(J23/J27-1) -> 6.5725915e-06 | ... W30: =100*(W23/W27-1) -> 2.2288956e-05
B32: Actual GDP (nominal, national currency)
B33: Growth rate | C33: =100*((1+C24/100)*(1+C42/100)-1) -> 15.674923 | D33: =100*((1+D24/100)*(1+D42/100)-1) -> 16.636198 | E33: =100*((1+E24/100)*(1+E42/100)-1) -> -0.32842201 | F33: =100*((1+F24/100)*(1+F42/100)-1) -> 3.8500652 | G33: =100*((1+G24/100)*(1+G42/100)-1) -> 5.3736909 | H33: =100*((1+H24/100)*(1+H42/100)-1) -> 5.8151071 | I33: =100*((1+I24/100)*(1+I42/100)-1) -> 5.9548904 | J33: =100*((1+J24/100)*(1+J42/100)-1) -> 5.8074699 | ... W33: =100*((1+W24/100)*(1+W42/100)-1) -> 3.9377189
B35: Interest rates
B36: Nominal implicit interest rate on debt | C36: ='Input data'!C37 -> 1.510173 | D36: ='Input data'!D37 -> 1.408838 | E36: ='Input data'!E37 -> 1.550894 | F36: ='Input data'!F37 -> 1.641526 | G36: ='Input data'!G37 -> 1.684386 | H36: =H101 -> 1.7963363 | I36: =I101 -> 1.8477296 | J36: =J101 -> 1.8765133 | K36: =K101 -> 1.9046582 | L36: =L101 -> 1.9309319 | M36: =M101 -> 1.9360734 | N36: =N101 -> 1.9574641 | O36: =O101 -> 1.9793499 | ... W36: =W101 -> 1.9944068
B37: Long-term interest rate | D37: ='Input data'!D$39 -> 1.75 | E37: ='Input data'!E$39 -> 2.87 | F37: ='Input data'!F$39 -> 2.837221 | G37: ='Input data'!G$39 -> 2.903685 | H37: =G37+($O$37-$G$37)/($O$10-$G$10) -> 2.9987319 | I37: =H37+($O$37-$G$37)/($O$10-$G$10) -> 3.0937787 | J37: =I37+($O$37-$G$37)/($O$10-$G$10) -> 3.1888256 | K37: =J37+($O$37-$G$37)/($O$10-$G$10) -> 3.2838725 | L37: =K37+($O$37-$G$37)/($O$10-$G$10) -> 3.3789194 | M37: =L37+($O$37-$G$37)/($O$10-$G$10) -> 3.4739662 | N37: =M37+($O$37-$G$37)/($O$10-$G$10) -> 3.5690131 | O37: ='Input data'!$C$52 -> 3.66406 | P37: ='Baseline NFPC'!P36 -> 3.680857 | Q37: ='Baseline NFPC'!Q36 -> 3.697654 | R37: ='Baseline NFPC'!R36 -> 3.714451 | S37: ='Baseline NFPC'!S36 -> 3.731248 | T37: ='Baseline NFPC'!T36 -> 3.748045 | U37: ='Baseline NFPC'!U36 -> 3.764842 | V37: ='Baseline NFPC'!V36 -> 3.781639 | W37: ='Baseline NFPC'!W36 -> 3.798436
