Workbook

Sheet Read me
G4: European Commission
G6: Directorate-General for Economic and Financial Affairs
G7: Unit C2 - Sustainability of public finances
G8: ECFIN-Secretariat-C2@ec.europa.eu
C16: FILE DESCRIPTION
C18: Data reported in this file are based on the European Commission (EC) 2024 spring forecast (SF 2024) and macroeconomic and budgetary projections from the joint EC-EPC Ageing Report 2024 (AR 2024).
C22: This file contains a simplified version of the EC model used to calculate the general governement debt ratio dynamics for EU countries under different scenarios. A detailed description of the EC's general governement debt projections can be found in the "Debt Sustainability Monitor 2023" (DSM, March 2024).
C27: HOW TO USE THIS TOOL TO CALCULATE NEW DEBT PROJECTIONS
C29: This tool can be used to calculate debt projections under different macroeconomic and structural primary balance adjustment assumptions. Debt projections for each scenario will update automatically with changes in the macroeconomic assumptions or the adjustment parameters. The fulfilment of DSA-based criteria, the safeguards and the benchmark will be automatically calculated in the sheet "Criteria results". Formulas are fully visible. To assess the impact of alternative adjustment paths compared with the reference trajectory calculated by the EC or to check its robustness to underlying macroeconomic assumptions, the user can modify the content of key cells in the sheets "Criteria results" and "Input data" (see below). Note that, for a proper functioning of the file, you should make sure that Excel is in "Automatic" computation mode, i.e. in the File menu, Option tab, click on "Formulas", "Calculation Options" and "Automatic".
C31: The spreadsheet is composed of the following elements:
D33: The grey sheet "Criteria results" contains three types of cells identified by different colours:
F34: Cells with a yellow background and a red frame can be modified to see the impact of a different duration or pace of adjustment.
F35: Cells with a white or grey background provide results obtained with the adjustment chosen in the yellow cells. To replicate the Commission's calculations, the underlying formulas should not be modified.
F37: Cells with a pale blue background correspond to the Commission's prior guidance provided to the Member State. Those are hard numbers that do not depend on the adjustment chosen in the file.
D39: The sheet "Criteria results" contains six tables: Table 1 "Adjustment input data": the user can set the duration of the plan (4 years under no extension or 7 years under extension) and the yearly adjustment pace in cells F5 and F6 in yellow. Note that the country cell (F4) cannot be changed.
D40: To the right of Table 1, a message automatically signals whether the chosen adjustment is sufficient to fulfill all the requirements, summarising the results from Tables 2 and 3.
D41: Table 2 "DSA-based criteria" reports whether the chosen adjustment fulfils each of the DSA-based criteria.
D42: Table 3 "Safeguards and benchmark" reports whether (i) the chosen adjustment ensures that the debt sustainability safeguard is met, (ii) the 'deficit benchmark', i.e. the minimum adjustment of 0.5 pp. of GDP as a benchmark when the country is in EDP and/or the deficit exceeds 3% of GDP, is binding, and (iii) the deficit resilience safeguard is binding.
D43: Table 4 "Main fiscal variables" reports the annual adjustment over the adjustment period, in terms of change in SPB (line 19) and net primary expenditure growth (line 20). The table also reports the headline balance, the structural balance and debt (lines 21 to 23). The average annual adjustment is reported in cells G24 (average change in SPB over the 4-year plan period), G25 (average change in SPB over the 4-year or 7-year adjustment period), G26 (average net primary expenditure growth over the plan period) and G27 (average net primary expenditure growth over the adjustment period).
D44: Table 5 "DSA-based adjustment" summarises the key characteristics of the adjustment path that complies with the DSA-based criteria before applying the safeguards and benchmark, for a plan both with and without extension.
D45: Table 6 "Reference trajectory" reports the net expenditure growth and the corresponding annual change in SPB that are consistent with all requirements including the safeguards and benchmark, both without and with extension.
D47: The sheet "Input data" in light blue presents the input data, including fiscal and GDP growth assumptions as well as additional fiscal parameters. Unless stated otherwise below, the user can change all values in this tab.
D48: Coloured cells indicate data sources as follows (this colour-coding holds in the other spreadsheets):
F49: Cells in light grey indicate a Commission forecast (available in the AMECO database)
F50: Cells in light red indicate whether the country is subject to an ongoing excessive deficit procedure (EDP) or whether the Commission's June 2024 report under Art. 126(3) of the Treaty recommends opening an EDP. If neither of these conditions are met, the deficit benchmark is not relevant and therefore not applied.
F51: Cells in light blue indicate values from the Ageing Report 2024
F52: Cells in light orange provide parameters needed to compute the decomposition of government debt according to its maturity structure (i.e. short-term and long-term debt, maturing, rolled-over and non-maturing debt). These are fixed shares which the user cannot change.
F53: Cells in dark orange indicate financial market prices.
D54: Non-coloured parameters in cells C49:C70 were calibrated based on different data sources. The data sources are indicated in the corresponding cells of column E. The last part of the sheet "Input data" (cells C73:G77) provides the parameters measuring the size of the cone of the fanchart that results from the stochastic analysis. For reproducibility reasons, these parameters are kept constant.
C56: The next spreadsheets present the deterministic and stochastic projections. Each deterministic projection provides a single path for debt until 2038 or 2041 under certain assumptions for budgetary, macroeconomic and financial variables, while the outcome of the stochastic projections is a distribution of debt paths resulting from a wide set of shocks. The sheets are grouped in four blocs, identified by their colour coding:
D58: The sheet in blue provides, as a reference, the baseline no-fiscal-policy-change scenario. The background colour coding is the same as in the sheet "Input data".
D60: The sheet in orange presents the scenario that automatically corrects the yearly adjustment path to account for the deficit benchmark and the deficit resillience safeguard. By contrast, the yearly adjustment profile is not automatically adjusted to ensure that the debt sustainability safeguard is met. However, the sheet "Criteria results" indicates whether that safeguard is met.
D62: The sheets in green present the deterministic projections that are used to compute the DSA-based requirements (in the sheet "Criteria results"). They include four scenarios:
D63: · Adjustment scenario without safeguard and benchmark
D64: · Financial stress scenario
D65: · Lower SPB scenario
D66: · Adverse 'r-g' scenario
D68: Each scenario is computed automatically based on the yearly adjustment path set in "Criteria results" (see above).
D70: The sheet in dark green presents the stochastic projections surrounding the adjustment scenario without safeguard and benchmark .
C72: Within the orange sheet and each green sheet, the background of the SPB line has three colours. Each colour corresponds to a specific period of the projections:
...

Sheet Criteria results
U2: 4 | V2: 0
D3: Table 1 - Adjustment input data | H3: =IF(OR(AND($G$12="ok",$G$13="ok",$G$14="ok",$G$15="ok",$H$12="ok",$I$12="ok",$L$12<>"Not met"), AND($I$12="ok",$J$12="ok",$J$13="ok",$J$14="ok",$J$15="ok",$L$12<>"Not met")), "OK"&CHAR(10)&"adjustment"&CHAR(10)&"complies with all requirements", "NOT OK"&CHAR(10)&"adjustment does not"&CHAR(10)&"comply with all requirements") -> OK adjustment complies with all requirements | U3: 7 | V3: 0.02
D4: Country | F4: MT | V4: 0.04
D5: Number of years of adjustment | F5: 4 | V5: 0.06
D6: Annual adjustment (when benchmark not binding) | F6: 0.44 | V6: 0.08
V7: 0.1
V8: 0.12
G9: Table 2 - DSA-based criteria | L9: Table 3 - Safeguards and benchmark | V9: 0.14
L10: Debt sustainability safeguard * | N10: Deficit benchmark ** | P10: Deficit resilience safeguard | V10: 0.16
G11: Criterion 1 (Debt decreasing under deterministic scenarios) | H11: Criterion 2 * (Debt declining with sufficient probability) | I11: Criterion 3 (Deficit below 3% of GDP) | J11: ="Debt below 60% of GDP in T+"&10+F5&" **" -> Debt below 60% of GDP in T+14 ** | L11: Debt declines by 1pp (0.5pp) of GDP on average as long as debt exceeds 90% (60%) of GDP | M11: Average change in debt | N11: 0.5 pp. of GDP adjustment if deficit in previous year > 3% of GDP | O11: Number of years the benchmark applies | P11: 0.40 pp. (0.25 pp.) of GDP adjustment under plan without (with) extension if structural deficit in previous year > 1.5% of GDP | Q11: Number of years the deficit resilience safeguard applies (over the adjustment horizon) | V11: 0.18
D12: Adjustment scenario | G12: =IF(OR('Adjust. no safeguard'!F57>60,'Adjust. no safeguard'!F77<-3),IF(SUM(OFFSET('Adjust. no safeguard'!$F$83,0,$F$5+1,1,10))=0,"ok","Not met"),"") -> Not met | H12: =IF(OR('Adjust. no safeguard'!F57>60,'Adjust. no safeguard'!F77<-3),IF($F$5=4,IF(Stochastic!$O$17<Stochastic!$J$17,"ok","Not met"),IF(Stochastic!$R$17<Stochastic!$M$17,"ok","Not met")),"") -> Not met | I12: =IF(MIN(OFFSET('Adjust. no safeguard'!$F$77,0,$F$5,1,11))>-3.05,"ok","Not met") -> ok | J12: =IF(OFFSET('Adjust. no safeguard'!$F$57,0,$F$5+10,1,1)<60,"ok","Not met") -> ok | L12: =_xlfn.LET(_xlpm.debtChange,OFFSET('Adjustment scenario'!F58,0,1,1,$F$5), _xlpm.debt6090,OFFSET('Adjustment scenario'!F85,0,1,1,$F$5), _xlpm.debt90,OFFSET('Adjustment scenario'!F84,0,1,1,$F$5), _xlpm.EDP,OFFSET('Adjustment scenario'!F87,0,1,1,$F$5), IF(AND(MAX(_xlpm.debt90)=0,MAX(_xlpm.debt6090)=0),"Debt below 60% of GDP over the adjustment period", IF(MIN(_xlpm.EDP)=1,"Not applicable, reference year is the last year of adjustment", IF(AND(MAX(_xlpm.debt90)=0,MAX(_xlpm.debt6090)=1),IF(AVERAGEIFS(_xlpm.debtChange,_xlpm.debt6090,1,_xlpm.EDP,0)<-0.5,"ok","Not met"), IF(AND(MAX(_xlpm.debt90)=1,MAX(_xlpm.debt6090)=0),IF(AVERAGEIFS(_xlpm.debtChange,_xlpm.EDP,0)<-1,"ok","Not met"), IF(AND(MAX(_xlpm.debt90)=1,MAX(_xlpm.debt6090)=1),IF(AND(AVERAGEIFS(_xlpm.debtChange,_xlpm.debt90,1,_xlpm.EDP,0)<-1,AVERAGEIFS(_xlpm.debtChange,_xlpm.debt6090,1,_xlpm.EDP,0)<-0.5),"ok","Not met"))))))) -> Debt below 60% of GDP over the adjustment period | M12: =_xlfn.LET(_xlpm.debtChange,OFFSET('Adjustment scenario'!F58,0,1,1,$F$5), _xlpm.debt60,OFFSET('Adjustment scenario'!F86,0,1,1,$F$5), _xlpm.debt6090,OFFSET('Adjustment scenario'!F85,0,1,1,$F$5), _xlpm.debt90,OFFSET('Adjustment scenario'!F84,0,1,1,$F$5), _xlpm.EDP,OFFSET('Adjustment scenario'!F87,0,1,1,$F$5), IF(AND(MAX(_xlpm.debt90)=0,MAX(_xlpm.debt6090)=0),"Debt below 60% of GDP over the adjustment period", IF(MIN(_xlpm.EDP)=1,"Not applicable, reference year is the last year of adjustment", IF(AND(MAX(_xlpm.debt90)=0,MAX(_xlpm.debt6090)=1),AVERAGEIFS(_xlpm.debtChange,_xlpm.debt60,1,_xlpm.EDP,0), IF(AND(MAX(_xlpm.debt90)=1,MAX(_xlpm.debt6090)=0),AVERAGEIFS(_xlpm.debtChange,_xlpm.EDP,0), IF(AND(MAX(_xlpm.debt90)=1,MAX(_xlpm.debt6090)=1),AVERAGEIFS(_xlpm.debtChange,_xlpm.debt60,1,_xlpm.EDP,0))))))) -> Debt below 60% of GDP over the adjustment period | N12: =IF(AND(O12=0,F6<0.5),"not relevant","ok") -> ok | O12: =IF(F6<0.5,COUNTIFS('Adjustment scenario'!F77:H77,"<"&-3.049),0)+IF(AND(F5=4,J19>0.5,J19>F6),1,COUNTIFS(J19:M19,">" & F6,J19:M19,">"&0.5)) -> 4 | P12: =IF(OR(AND(F5=4,Q12=0,F6<0.4),AND(F5=7,Q12=0,F6<0.25)),"not relevant, (over the adjustment horizon)","ok") -> ok | Q12: =IF(AND('Criteria results'!$F$5=4,'Criteria results'!$F$6<=0.4),COUNTIFS('Adjustment scenario'!G13:J13,0.4,'Adjustment scenario'!F88:I88,0),IF(AND('Criteria results'!$F$5=7,'Criteria results'!$F$6<=0.25),COUNTIFS('Adjustment scenario'!G13:M13,0.25,'Adjustment scenario'!F88:L88,0),0)) -> 0 | V12: 0.2
D13: Financial stress scenario | G13: =IF(OR('Adjustment scenario'!F57>60,'Adjustment scenario'!F77<-3),IF(SUM(OFFSET('Financial stress'!$F$75,0,$F$5+1,1,10))=0,"ok","Not met"),"") -> Not met | J13: =IF(OR('Adjustment scenario'!F57>60,'Adjustment scenario'!F77<-3),IF(OFFSET('Financial stress'!$F$56,0,$F$5+10,1,1)<60,"ok","Not met"),"") -> ok | V13: 0.22
D14: Lower SPB scenario | G14: =IF(OR('Adjustment scenario'!F57>60,'Adjustment scenario'!F77<-3),IF(SUM(OFFSET('Lower SPB'!$F$75,0,$F$5+1,1,10))=0,"ok","Not met"),"") -> Not met | J14: =IF(OR('Adjustment scenario'!F57>60,'Adjustment scenario'!F77<-3),IF(OFFSET('Lower SPB'!$F$56,0,$F$5+10,1,1)<60,"ok","Not met"),"") -> ok | V14: 0.24
D15: Adverse r-g scenario | G15: =IF(OR('Adjustment scenario'!F57>60,'Adjustment scenario'!F77<-3),IF(SUM(OFFSET('Adverse (r-g)'!$F$76,0,$F$5+1,1,10))=0,"ok","Not met"),"") -> Not met | J15: =IF(OR('Adjustment scenario'!F57>60,'Adjustment scenario'!F77<-3),IF(OFFSET('Adverse (r-g)'!$F$57,0,$F$5+10,1,1)<60,"ok","Not met"),"") -> ok | V15: 0.26
D16: * The stochastic simulations are provided mainly for information, as the Excel worksheet only allows for an approximation of what is done in the Commission's Stata model. Indeed, in this Excel worksheet, the size of the cone of the fanchart is assumed to be constant over different adjustment paths. In ther Stata model, it is a non linear function of the level of debt, as shocks (in particular interest rate shocks) have different impacts according to the level of debt ratio. ** In case a smaller adjustment than the one implied by criterion 1 and criterion 2 is sufficient to ensure that debt is brought (and/or remains) below 60% of GDP under the adjustment scenario and all deterministic stress tests while ensuring that the criterion 3 is met, then that smaller, 'eased-up' adjustment is chosen. | L16: * The average change in debt is computed from the year before the start of the reference trajectory or the year in which the excessive deficit procedure is projected to be abrogated, whichever occurs last, until the end of the adjustment period. ** The deficit benchmark is applied in terms of change in SPB during the transitory period of 2025-2027 and in terms of change in SB thereafter. | V16: 0.28
G17: Table 4 - Main fiscal variables | V17: 0.3
G18: 2025 | H18: 2026 | I18: 2027 | J18: 2028 | K18: 2029 | L18: 2030 | M18: 2031 | V18: 0.32
D19: Annual adjustment (change in SPB) | G19: ='Adjustment scenario'!G12-'Adjustment scenario'!F12 -> 0.5 | H19: ='Adjustment scenario'!H12-'Adjustment scenario'!G12 -> 0.5 | I19: ='Adjustment scenario'!I12-'Adjustment scenario'!H12 -> 0.5 | J19: ='Adjustment scenario'!J12-'Adjustment scenario'!I12 -> 0.53092026 | K19: ='Adjustment scenario'!K12-'Adjustment scenario'!J12 -> 0 | L19: ='Adjustment scenario'!L12-'Adjustment scenario'!K12 -> 0 | M19: ='Adjustment scenario'!M12-'Adjustment scenario'!L12 -> 0 | V19: 0.34
D20: Net primary expenditure growth | G20: ='Adjustment scenario'!G79 -> 6.0362927 | H20: ='Adjustment scenario'!H79 -> 5.8465578 | I20: ='Adjustment scenario'!I79 -> 5.8786849 | J20: ='Adjustment scenario'!J79 -> 5.7334207 | K20: ='Adjustment scenario'!K79 -> 7.1401375 | L20: ='Adjustment scenario'!L79 -> 7.0482306 | M20: ='Adjustment scenario'!M79 -> 6.8942157 | V20: 0.36
D21: Headline balance | G21: ='Adjustment scenario'!G77 -> -4.0758413 | H21: ='Adjustment scenario'!H77 -> -3.6908327 | I21: ='Adjustment scenario'!I77 -> -3.2702742 | J21: ='Adjustment scenario'!J77 -> -2.8034928 | K21: ='Adjustment scenario'!K77 -> -2.5954043 | L21: ='Adjustment scenario'!L77 -> -2.3851764 | M21: ='Adjustment scenario'!M77 -> -2.1778649 | V21: 0.38
D22: Structural balance | G22: ='Adjustment scenario'!G78 -> -3.7272734 | H22: ='Adjustment scenario'!H78 -> -3.288104 | I22: ='Adjustment scenario'!I78 -> -2.8316814 | J22: ='Adjustment scenario'!J78 -> -2.3304991 | K22: ='Adjustment scenario'!K78 -> -2.2800751 | L22: ='Adjustment scenario'!L78 -> -2.2275118 | M22: ='Adjustment scenario'!M78 -> -2.1778649 | V22: 0.4
D23: Debt | G23: ='Adjustment scenario'!G57 -> 52.712875 | H23: ='Adjustment scenario'!H57 -> 52.858887 | I23: ='Adjustment scenario'!I57 -> 52.540436 | J23: ='Adjustment scenario'!J57 -> 51.80375 | K23: ='Adjustment scenario'!K57 -> 50.734076 | L23: ='Adjustment scenario'!L57 -> 49.571815 | M23: ='Adjustment scenario'!M57 -> 48.352048 | V23: 0.42
D24: Average annual adjustment over the plan period | G24: =AVERAGE(G19:J19) -> 0.50773007 | V24: 0.44
D25: Average annual adjustment over the adjustment period | G25: =IF(F5=4,AVERAGE(G19:J19),AVERAGE(G19:M19)) -> 0.50773007 | V25: 0.46
D26: Average net primary expenditure growth over the plan period | G26: =AVERAGE(G20:J20) -> 5.873739 | V26: 0.48
D27: Average net primary expenditure growth over the adjustment period | G27: =IF(F5=4,AVERAGE(G20:J20),AVERAGE(G20:M20)) -> 5.873739 | V27: 0.5
D28: In case of a plan with no extension, both the plan period and the adjustment period last 4 years. In case of a plan with extension, the plan period remains 4 years while the adjustment period lasts 7 years. Morever, in case of extension, if neither the deficit benchmark nor the deficit resilience safeguard are binding, the values in G24 and G25 (and G26 and G27) are the same. However, if the benchmark or the safeguard is binding, the values in those cells can be different. | V28: 0.52
V29: 0.54
G30: Table 5 - DSA-based adjustment * | V30: 0.56
G31: No extension | H31: Extension | V31: 0.58
D32: Number of years of adjustment | G32: 4 | H32: 7 | V32: 0.6
D33: Annual adjustment | G33: 0.44 | H33: 0.28 | V33: 0.62
D34: Probability that debt decreases | G34: 60.049999 | H34: 55.830002 | V34: 0.64
D35: * The adjustment in this table does not account for the minimum adjustment of 0.5 pp. of GDP as a benchmark nor for the debt sustainability and deficit resillience safeguards. | V35: 0.66
V36: 0.68
H37: Table 6 - Reference trajectory | V37: 0.7
G38: Average (2025-28) | H38: 2025 | I38: 2026 | J38: 2027 | K38: 2028 | L38: 2029 | M38: 2030 | N38: 2031 | V38: 0.72
D39: Adjustment in a plan without extension | V39: 0.74
D40: Net primary expenditure growth | G40: 5.873739 | H40: 6.0362927 | I40: 5.8465578 | J40: 5.8786849 | K40: 5.7334207 | V40: 0.76
D41: Annual change in SPB | G41: 0.50773007 | H41: 0.5 | I41: 0.5 | J41: 0.5 | K41: 0.53092026 | V41: 0.78
...

Sheet Input data
B3: Country | C3: MT
B5: Last year before the adjustment | C5: 2024
B6: Last year of adjustment | C6: =C5+'Criteria results'!$F$5 -> 2028
B8: Key assumptions
C9: 2021 | D9: 2022 | E9: 2023 | F9: 2024 | G9: 2025 | H9: 2026 | I9: 2027 | J9: 2028 | K9: 2029 | L9: 2030 | M9: 2031 | N9: 2032 | O9: 2033 | P9: 2034 | Q9: 2035 | R9: 2036 | S9: 2037 | T9: 2038 | U9: 2039 | V9: 2040 | W9: 2041
B10: Fiscal assumptions (% of GDP)
B11: Key fiscal variables (based on the Commission 2024 spring forecast ("SF 2024") T+2 forecast and the June 2024 report prepared under Art. 126(3) of the Treaty)
B12: Debt | C12: 53.92565 | D12: 51.62644 | E12: 50.39661 | F12: 52.02717
B13: Structural primary balance ('+' means 'surplus') | C13: -5.650948 | D13: -4.355204 | E13: -3.790994 | F13: -2.897243
B14: One-off and other temporary measures | C14: 0 | D14: 0 | E14: 0 | F14: 0 | G14: 0 | H14: 0 | I14: 0 | J14: 0 | K14: 0 | L14: 0 | M14: 0 | N14: 0 | O14: 0 | P14: 0 | Q14: 0 | R14: 0 | S14: 0 | T14: 0 | U14: 0 | V14: 0 | W14: 0
B15: Stock-flow adjustments (without exchange rate effect) | C15: 0.8044612 | D15: -1.310275 | E15: -0.9404473 | F15: 1.185197 | G15: 0.0667276 | H15: 0 | I15: 0 | J15: 0 | K15: 0 | L15: 0 | M15: 0 | N15: 0 | O15: 0 | P15: 0 | Q15: 0 | R15: 0 | S15: 0 | T15: 0 | U15: 0 | V15: 0 | W15: 0
B16: Stock-flow adjustment (total) | C16: 0.8044617 | D16: -1.310275 | E16: -0.940448 | F16: 1.185199 | G16: 0.0667244 | H16: 0 | I16: 0 | J16: 0 | K16: 0 | L16: 0 | M16: 0 | N16: 0 | O16: 0 | P16: 0 | Q16: 0 | R16: 0 | S16: 0 | T16: 0 | U16: 0 | V16: 0 | W16: 0
B17: Subject to an excessive deficit procedure (EDP) (0-no/1-yes) | D17: 0 | E17: 0 | F17: 1
B19: Cost of ageing and selected public revenue (based on the Commission-Council 2024 Ageing Report ("AR 2024"))
B20: Total ageing cost (net of taxes on pensions) | C20: =(C21+C22+C23+C24-C25) -> 0 | D20: =(D21+D22+D23+D24-D25) -> 16.93779 | E20: =(E21+E22+E23+E24-E25) -> 16.70416 | F20: =(F21+F22+F23+F24-F25) -> 16.66552 | G20: =(G21+G22+G23+G24-G25) -> 16.60096 | H20: =(H21+H22+H23+H24-H25) -> 16.33519 | I20: =(I21+I22+I23+I24-I25) -> 16.23882 | J20: =(J21+J22+J23+J24-J25) -> 16.15621 | ... W20: =(W21+W22+W23+W24-W25) -> 16.22383
B21: of which: Public pensions expenditure | C21: 0 | D21: 6.15371 | E21: 6.09795 | F21: 6.08687 | G21: 6.00425 | H21: 5.80539 | I21: 5.70283 | J21: 5.60481 | K21: 5.51349 | L21: 5.42252 | M21: 5.33926 | N21: 5.26656 | O21: 5.2159 | P21: 5.17276 | Q21: 5.14267 | R21: 5.12868 | S21: 5.1284 | T21: 5.13779 | U21: 5.1628 | V21: 5.20522 | W21: 5.26226
B22: Health care expenditure | C22: 0 | D22: 5.12169 | E22: 5.0423 | F22: 5.07449 | G22: 5.11459 | H22: 5.06796 | I22: 5.0936 | J22: 5.11895 | K22: 5.14656 | L22: 5.17165 | M22: 5.19882 | N22: 5.2257 | O22: 5.25414 | P22: 5.28374 | Q22: 5.31158 | R22: 5.34077 | S22: 5.36878 | T22: 5.39487 | U22: 5.42025 | V22: 5.44458 | W22: 5.46881
B23: Long-term care expenditure | C23: 0 | D23: 1.16699 | E23: 1.17897 | F23: 1.19932 | G23: 1.23734 | H23: 1.26842 | I23: 1.29737 | J23: 1.32267 | K23: 1.35671 | L23: 1.39339 | M23: 1.42621 | N23: 1.45625 | O23: 1.48419 | P23: 1.51361 | Q23: 1.54132 | R23: 1.56501 | S23: 1.58707 | T23: 1.60587 | U23: 1.62209 | V23: 1.63843 | W23: 1.65457
B24: Education & unemployment benefits expenditure | C24: 0 | D24: 4.4954 | E24: 4.38494 | F24: 4.30484 | G24: 4.24478 | H24: 4.19342 | I24: 4.14502 | J24: 4.10978 | K24: 4.0776 | L24: 4.04751 | M24: 4.01825 | N24: 3.99225 | O24: 3.96234 | P24: 3.93775 | Q24: 3.9192 | R24: 3.90152 | S24: 3.88271 | T24: 3.86701 | U24: 3.85467 | V24: 3.84457 | W24: 3.83819
B25: Taxes on pensions | C25: 0 | D25: 0 | E25: 0 | F25: 0 | G25: 0 | H25: 0 | I25: 0 | J25: 0 | K25: 0 | L25: 0 | M25: 0 | N25: 0 | O25: 0 | P25: 0 | Q25: 0 | R25: 0 | S25: 0 | T25: 0 | U25: 0 | V25: 0 | W25: 0
B26: Property income | C26: 0.5214214 | D26: 0.4365457 | E26: 0.4337021 | F26: 0.4308586 | G26: 0.428015 | H26: 0.4251715 | I26: 0.4223279 | J26: 0.4194843 | K26: 0.4166408 | L26: 0.4137973 | M26: 0.4109537 | N26: 0.4081101 | O26: 0.4052666 | P26: 0.4024231 | Q26: 0.3995795 | R26: 0.396736 | S26: 0.3938924 | T26: 0.3910489 | U26: 0.3882053 | V26: 0.3853618 | W26: 0.3825183
B28: Real GDP growth assumptions (based on SF 2024 T+10 projections and AR 2024 projections)
B29: Actual GDP
B30: Growth rate | C30: 12.51395 | D30: 8.075569 | E30: 5.613926 | F30: 4.57228 | G30: 4.845198 | H30: 4.807363 | I30: 4.880684 | J30: 4.731095 | K30: 4.59818 | L30: 4.504259 | M30: 4.348238 | N30: 4.170129 | O30: 4.115924 | P30: 3.776726 | Q30: 3.437526 | R30: 3.098332 | S30: 2.986427 | T30: 2.845796 | U30: 2.678466 | V30: 2.518222 | W30: 2.369435
B31: Level (billions, national currency) | C31: 13.62455
B32: Potential GDP
B33: Growth rate | C33: 3.858198 | D33: 6.663338 | E33: 5.106291 | F33: 4.918544 | G33: 4.869064 | H33: 4.677318 | I33: 4.707434 | J33: 4.644675 | K33: 4.598182 | L33: 4.504264 | M33: 4.348238 | N33: 4.170125 | O33: 4.115922 | P33: 3.776724 | Q33: 3.437526 | R33: 3.098329 | S33: 2.986424 | T33: 2.845797 | U33: 2.678468 | V33: 2.518225 | W33: 2.369437
B34: Level (billions, national currency) | C34: 13.87421
B36: Interest rates (SF 2024, %)
B37: Nominal implicit interest rate on debt | C37: 2.40894 | D37: 1.98347 | E37: 2.37675 | F37: 2.749095 | G37: 2.738361
B38: Short-term nominal interest rate | D38: 0.35 | E38: 3.43 | F38: 3.564208 | G38: 2.816375
B39: Long-term nominal interest rate | D39: 2.41 | E39: 3.71 | F39: 3.497002 | G39: 3.505358
F40: Bloomberg data, country-specific forward market rates.
B41: Inflation (SF 2024, %)
B42: GDP deflator (national currency) | C42: 2.005253 | D42: 5.261471 | E42: 5.273616 | F42: 3.642343 | G42: 2.533911
B44: Net primary expenditure growth (SF 2024, %)
B45: Net primary expenditure growth | C45: 19.796114 | D45: 13.084528 | E45: 9.2925168 | F45: 5.4768547
B47: Additional parameters
E48: Sources
B49: Fiscal multiplier | C49: 0.75 | E49: Carnot, N. and de Castro, F. (2015), “The Discretionary Fiscal Effort: an Assessment of Fiscal Policy and its Output Effect”, European Economy, Economic Papers, No. 543.
...

Sheet Baseline NFPC
B3: Country | C3: ='Input data'!C3 -> MT
B4: Key years
B5: ='Input data'!B5 -> Last year before the adjustment | C5: =+'Input data'!C5 -> 2024
B6: Last year of adjustment | C6: =+C5+'Criteria results'!$F$5 -> 2028
B9: Key assumptions
C10: 2021 | D10: 2022 | E10: 2023 | F10: 2024 | G10: 2025 | H10: 2026 | I10: 2027 | J10: 2028 | K10: 2029 | L10: 2030 | M10: 2031 | N10: 2032 | O10: 2033 | P10: 2034 | Q10: 2035 | R10: 2036 | S10: 2037 | T10: 2038 | U10: 2039 | V10: 2040 | W10: 2041
B11: Fiscal assumptions (% of GDP)
B12: Structural primary balance ('+' means 'surplus') | C12: ='Input data'!C13 -> -5.650948 | D12: ='Input data'!D13 -> -4.355204 | E12: ='Input data'!E13 -> -3.790994 | F12: ='Input data'!F13 -> -2.897243 | G12: =F12 -> -2.897243 | H12: =G12 -> -2.897243 | I12: =H12 -> -2.897243 | J12: =I12 -> -2.897243 | K12: =J12 -> -2.897243 | L12: =K12 -> -2.897243 | M12: =L12 -> -2.897243 | N12: =M12 -> -2.897243 | ... W12: =V12 -> -2.897243
B13: One-off and other temporary measures | C13: ='Input data'!C14 -> 0 | D13: ='Input data'!D14 -> 0 | E13: ='Input data'!E14 -> 0 | F13: ='Input data'!F14 -> 0 | G13: ='Input data'!G14 -> 0 | H13: 0 | I13: 0 | J13: 0 | K13: 0 | L13: 0 | M13: 0 | N13: 0 | O13: 0 | P13: 0 | Q13: 0 | R13: 0 | S13: 0 | T13: 0 | U13: 0 | V13: 0 | W13: 0
B14: Stock flow adjustments (without exchange rate effect) | C14: ='Input data'!C15 -> 0.8044612 | D14: ='Input data'!D15 -> -1.310275 | E14: ='Input data'!E15 -> -0.9404473 | F14: ='Input data'!F15 -> 1.185197 | G14: ='Input data'!G15 -> 0.0667276 | H14: ='Input data'!H15 -> 0 | I14: ='Input data'!I15 -> 0 | J14: ='Input data'!J15 -> 0 | ... W14: ='Input data'!W15 -> 0
B16: ='Input data'!B19 -> Cost of ageing and selected public revenue (based on the Commission-Council 2024 Ageing Report ("AR 2024"))
B17: Total ageing cost (net of taxes on pensions) | C17: ='Input data'!C20 -> 0 | D17: ='Input data'!D20 -> 16.93779 | E17: ='Input data'!E20 -> 16.70416 | F17: ='Input data'!F20 -> 16.66552 | G17: ='Input data'!G20 -> 16.60096 | H17: ='Input data'!H20 -> 16.33519 | I17: ='Input data'!I20 -> 16.23882 | J17: ='Input data'!J20 -> 16.15621 | ... W17: ='Input data'!W20 -> 16.22383
B18: ='Input data'!B26 -> Property income | C18: ='Input data'!C26 -> 0.5214214 | D18: ='Input data'!D26 -> 0.4365457 | E18: ='Input data'!E26 -> 0.4337021 | F18: ='Input data'!F26 -> 0.4308586 | G18: ='Input data'!G26 -> 0.428015 | H18: ='Input data'!H26 -> 0.4251715 | I18: ='Input data'!I26 -> 0.4223279 | ... W18: ='Input data'!W26 -> 0.3825183
B20: GDP growth assumptions
B21: Actual GDP (real)
B22: Level | C22: ='Input data'!C31 -> 13.62455 | D22: =C22*(D23/100+1) -> 14.72481 | E22: =D22*(E23/100+1) -> 15.55145 | F22: =E22*(F23/100+1) -> 16.262506 | G22: =F22*(G23/100+1) -> 17.050456 | H22: =IF(AND(H49>1,G49>1),IF(AND(H49>0,G49>0),H26*(H50/100+1),0)+IF(H49>0,G22*(1+H51/100),0)-G22*(1+'Input data'!H30/100),IF(H49=1,H26,G22*(1+H51/100))) -> 17.870134 | I22: =IF(AND(I49>1,H49>1),IF(AND(I49>0,H49>0),I26*(I50/100+1),0)+IF(I49>0,H22*(1+I51/100),0)-H22*(1+'Input data'!I30/100),IF(I49=1,I26,H22*(1+I51/100))) -> 18.742318 | J22: =IF(AND(J49>1,I49>1),IF(AND(J49>0,I49>0),J26*(J50/100+1),0)+IF(J49>0,I22*(1+J51/100),0)-I22*(1+'Input data'!J30/100),IF(J49=1,J26,I22*(1+J51/100))) -> 19.629035 | K22: =IF(AND(K49>1,J49>1),IF(AND(K49>0,J49>0),K26*(K50/100+1),0)+IF(K49>0,J22*(1+K51/100),0)-J22*(1+'Input data'!K30/100),IF(K49=1,K26,J22*(1+K51/100))) -> 20.531614 | L22: =IF(AND(L49>1,K49>1),IF(AND(L49>0,K49>0),L26*(L50/100+1),0)+IF(L49>0,K22*(1+L51/100),0)-K22*(1+'Input data'!L30/100),IF(L49=1,L26,K22*(1+L51/100))) -> 21.456411 | M22: =IF(AND(M49>1,L49>1),IF(AND(M49>0,L49>0),M26*(M50/100+1),0)+IF(M49>0,L22*(1+M51/100),0)-L22*(1+'Input data'!M30/100),IF(M49=1,M26,L22*(1+M51/100))) -> 22.389387 | N22: =IF(AND(N49>1,M49>1),IF(AND(N49>0,M49>0),N26*(N50/100+1),0)+IF(N49>0,M22*(1+N51/100),0)-M22*(1+'Input data'!N30/100),IF(N49=1,N26,M22*(1+N51/100))) -> 23.323053 | O22: =IF(AND(O49>1,N49>1),IF(AND(O49>0,N49>0),O26*(O50/100+1),0)+IF(O49>0,N22*(1+O51/100),0)-N22*(1+'Input data'!O30/100),IF(O49=1,O26,N22*(1+O51/100))) -> 24.283012 | ... W22: =IF(AND(W49>1,V49>1),IF(AND(W49>0,V49>0),W26*(W50/100+1),0)+IF(W49>0,V22*(1+W51/100),0)-V22*(1+'Input data'!W30/100),IF(W49=1,W26,V22*(1+W51/100))) -> 30.672527
B23: Growth rate | C23: =+'Input data'!C30 -> 12.51395 | D23: =+'Input data'!D30 -> 8.075569 | E23: =+'Input data'!E30 -> 5.613926 | F23: =+'Input data'!F30 -> 4.57228 | G23: =+'Input data'!G30 -> 4.845198 | H23: =100*(H22/G22-1) -> 4.807363 | I23: =100*(I22/H22-1) -> 4.880684 | J23: =100*(J22/I22-1) -> 4.731095 | K23: =100*(K22/J22-1) -> 4.59818 | L23: =100*(L22/K22-1) -> 4.504259 | M23: =100*(M22/L22-1) -> 4.348238 | N23: =100*(N22/M22-1) -> 4.170129 | O23: =100*(O22/N22-1) -> 4.115924 | ... W23: =100*(W22/V22-1) -> 2.369435
B25: Potential GDP (real)
B26: Level | C26: ='Input data'!C34 -> 13.87421 | D26: =+C26*(1+'Input data'!D33/100) -> 14.798696 | E26: =+D26*(1+'Input data'!E33/100) -> 15.55436 | F26: =+E26*(1+'Input data'!F33/100) -> 16.319408 | G26: =+F26*(1+'Input data'!G33/100) -> 17.11401 | H26: =+G26*(1+'Input data'!H33/100) -> 17.914487 | I26: =+H26*(1+'Input data'!I33/100) -> 18.7578 | J26: =+I26*(1+'Input data'!J33/100) -> 19.629039 | K26: =+J26*(1+'Input data'!K33/100) -> 20.531618 | ... W26: =+V26*(1+'Input data'!W33/100) -> 30.672533
B28: Output gap
B29: Output gap | C29: =100*(C22/C26-1) -> -1.7994538 | D29: =100*(D22/D26-1) -> -0.49927084 | E29: =100*(E22/E26-1) -> -0.018709187 | F29: =100*(F22/F26-1) -> -0.34867871 | G29: =100*(G22/G26-1) -> -0.37135726 | H29: =100*(H22/H26-1) -> -0.24758444 | I29: =100*(I22/I26-1) -> -0.082533063 | J29: =100*(J22/J26-1) -> -1.6991809e-05 | ... W29: =100*(W22/W26-1) -> -1.7977685e-05
B31: Actual GDP (nominal, national currency)
B32: Growth rate | C32: =100*((1+C23/100)*(1+C41/100)-1) -> 14.770139 | D32: =100*((1+D23/100)*(1+D41/100)-1) -> 13.761934 | E32: =100*((1+E23/100)*(1+E41/100)-1) -> 11.183599 | F32: =100*((1+F23/100)*(1+F41/100)-1) -> 8.3811611 | G32: =100*((1+G23/100)*(1+G41/100)-1) -> 7.501882 | H32: =100*((1+H23/100)*(1+H41/100)-1) -> 7.4651961 | I32: =100*((1+I23/100)*(1+I41/100)-1) -> 7.5424858 | J32: =100*((1+J23/100)*(1+J41/100)-1) -> 7.3912066 | ... W32: =100*((1+W23/100)*(1+W41/100)-1) -> 4.7546428
B34: Interest rate
B35: Nominal implicit interest rate on debt | C35: ='Input data'!C37 -> 2.40894 | D35: ='Input data'!D37 -> 1.98347 | E35: ='Input data'!E37 -> 2.37675 | F35: ='Input data'!F37 -> 2.749095 | G35: ='Input data'!G37 -> 2.738361 | H35: =H96 -> 2.8541319 | I35: =I96 -> 2.9384591 | J35: =J96 -> 3.01999 | K35: =K96 -> 3.0997302 | L35: =L96 -> 3.1785659 | M35: =M96 -> 3.2566136 | N35: =N96 -> 3.3340054 | O35: =O96 -> 3.4108901 | ... W35: =W96 -> 3.7130399
B36: Long-term interest rate | E36: ='Input data'!E39 -> 3.71 | F36: ='Input data'!F39 -> 3.497002 | G36: ='Input data'!G39 -> 3.505358 | H36: =G36+($O$36-$G$36)/($O$10-$G$10) -> 3.584932 | I36: =H36+($O$36-$G$36)/($O$10-$G$10) -> 3.664506 | J36: =I36+($O$36-$G$36)/($O$10-$G$10) -> 3.74408 | K36: =J36+($O$36-$G$36)/($O$10-$G$10) -> 3.823654 | L36: =K36+($O$36-$G$36)/($O$10-$G$10) -> 3.903228 | M36: =L36+($O$36-$G$36)/($O$10-$G$10) -> 3.982802 | N36: =M36+($O$36-$G$36)/($O$10-$G$10) -> 4.062376 | O36: ='Input data'!$C$52 -> 4.14195 | P36: =$O$36+('Input data'!$C$54-'Input data'!$C$52)/20*('Baseline NFPC'!P$10-2033) -> 4.1348525 | Q36: =$O$36+('Input data'!$C$54-'Input data'!$C$52)/20*('Baseline NFPC'!Q$10-2033) -> 4.127755 | R36: =$O$36+('Input data'!$C$54-'Input data'!$C$52)/20*('Baseline NFPC'!R$10-2033) -> 4.1206575 | S36: =$O$36+('Input data'!$C$54-'Input data'!$C$52)/20*('Baseline NFPC'!S$10-2033) -> 4.11356 | T36: =$O$36+('Input data'!$C$54-'Input data'!$C$52)/20*('Baseline NFPC'!T$10-2033) -> 4.1064625 | U36: =$O$36+('Input data'!$C$54-'Input data'!$C$52)/20*('Baseline NFPC'!U$10-2033) -> 4.099365 | V36: =$O$36+('Input data'!$C$54-'Input data'!$C$52)/20*('Baseline NFPC'!V$10-2033) -> 4.0922675 | W36: =$O$36+('Input data'!$C$54-'Input data'!$C$52)/20*('Baseline NFPC'!W$10-2033) -> 4.08517
B37: Short-term interest rate | E37: ='Input data'!E$38 -> 3.43 | F37: ='Input data'!F$38 -> 3.564208 | G37: ='Input data'!G$38 -> 2.816375 | H37: =G37+($O$37-$G$37)/($O$10-$G$10) -> 2.8050894 | I37: =H37+($O$37-$G$37)/($O$10-$G$10) -> 2.7938037 | J37: =I37+($O$37-$G$37)/($O$10-$G$10) -> 2.7825181 | K37: =J37+($O$37-$G$37)/($O$10-$G$10) -> 2.7712325 | L37: =K37+($O$37-$G$37)/($O$10-$G$10) -> 2.7599469 | M37: =L37+($O$37-$G$37)/($O$10-$G$10) -> 2.7486612 | N37: =M37+($O$37-$G$37)/($O$10-$G$10) -> 2.7373756 | O37: ='Input data'!$C$53 -> 2.72609 | P37: =$O$37+('Input data'!$C$55-'Input data'!$C$53)/20*('Baseline NFPC'!P$10-2033) -> 2.6897855 | Q37: =$O$37+('Input data'!$C$55-'Input data'!$C$53)/20*('Baseline NFPC'!Q$10-2033) -> 2.653481 | R37: =$O$37+('Input data'!$C$55-'Input data'!$C$53)/20*('Baseline NFPC'!R$10-2033) -> 2.6171765 | S37: =$O$37+('Input data'!$C$55-'Input data'!$C$53)/20*('Baseline NFPC'!S$10-2033) -> 2.580872 | T37: =$O$37+('Input data'!$C$55-'Input data'!$C$53)/20*('Baseline NFPC'!T$10-2033) -> 2.5445675 | U37: =$O$37+('Input data'!$C$55-'Input data'!$C$53)/20*('Baseline NFPC'!U$10-2033) -> 2.508263 | V37: =$O$37+('Input data'!$C$55-'Input data'!$C$53)/20*('Baseline NFPC'!V$10-2033) -> 2.4719585 | W37: =$O$37+('Input data'!$C$55-'Input data'!$C$53)/20*('Baseline NFPC'!W$10-2033) -> 2.435654
B38: Share of long-term debt that matures every year | C38: 0.08190323 | D38: 0.001 | E38: 0.04901889 | F38: 0.04747952 | G38: =IF(OR($C$3="EL",$C$3="CY",$C$3="IE",$C$3="PT"),VLOOKUP($C$3,$B$110:$T$114,MATCH(G$10,$B$110:$T$110,0),0),$F$38+('Input data'!$C$59-$F$38)/($O$10-$F$10)*(G10-$F$10)) -> 0.048981602 | H38: =IF(OR($C$3="EL",$C$3="CY",$C$3="IE",$C$3="PT"),VLOOKUP($C$3,$B$110:$T$114,MATCH(H$10,$B$110:$T$110,0),0),$F$38+('Input data'!$C$59-$F$38)/($O$10-$F$10)*(H10-$F$10)) -> 0.050483684 | I38: =IF(OR($C$3="EL",$C$3="CY",$C$3="IE",$C$3="PT"),VLOOKUP($C$3,$B$110:$T$114,MATCH(I$10,$B$110:$T$110,0),0),$F$38+('Input data'!$C$59-$F$38)/($O$10-$F$10)*(I10-$F$10)) -> 0.051985767 | J38: =IF(OR($C$3="EL",$C$3="CY",$C$3="IE",$C$3="PT"),VLOOKUP($C$3,$B$110:$T$114,MATCH(J$10,$B$110:$T$110,0),0),$F$38+('Input data'!$C$59-$F$38)/($O$10-$F$10)*(J10-$F$10)) -> 0.053487849 | K38: =IF(OR($C$3="EL",$C$3="CY",$C$3="IE",$C$3="PT"),VLOOKUP($C$3,$B$110:$T$114,MATCH(K$10,$B$110:$T$110,0),0),$F$38+('Input data'!$C$59-$F$38)/($O$10-$F$10)*(K10-$F$10)) -> 0.054989931 | L38: =IF(OR($C$3="EL",$C$3="CY",$C$3="IE",$C$3="PT"),VLOOKUP($C$3,$B$110:$T$114,MATCH(L$10,$B$110:$T$110,0),0),$F$38+('Input data'!$C$59-$F$38)/($O$10-$F$10)*(L10-$F$10)) -> 0.056492013 | M38: =IF(OR($C$3="EL",$C$3="CY",$C$3="IE",$C$3="PT"),VLOOKUP($C$3,$B$110:$T$114,MATCH(M$10,$B$110:$T$110,0),0),$F$38+('Input data'!$C$59-$F$38)/($O$10-$F$10)*(M10-$F$10)) -> 0.057994096 | N38: =IF(OR($C$3="EL",$C$3="CY",$C$3="IE",$C$3="PT"),VLOOKUP($C$3,$B$110:$T$114,MATCH(N$10,$B$110:$T$110,0),0),$F$38+('Input data'!$C$59-$F$38)/($O$10-$F$10)*(N10-$F$10)) -> 0.059496178 | O38: =IF(OR($C$3="EL",$C$3="CY",$C$3="IE",$C$3="PT"),VLOOKUP($C$3,$B$110:$T$114,MATCH(O$10,$B$110:$T$110,0),0),'Input data'!$C$59) -> 0.06099826 | P38: =IF(OR($C$3="EL",$C$3="CY",$C$3="IE",$C$3="PT"),VLOOKUP($C$3,$B$110:$T$114,MATCH(P$10,$B$110:$T$110,0),0),'Input data'!$C$59) -> 0.06099826 | Q38: =IF(OR($C$3="EL",$C$3="CY",$C$3="IE",$C$3="PT"),VLOOKUP($C$3,$B$110:$T$114,MATCH(Q$10,$B$110:$T$110,0),0),'Input data'!$C$59) -> 0.06099826 | R38: =IF(OR($C$3="EL",$C$3="CY",$C$3="IE",$C$3="PT"),VLOOKUP($C$3,$B$110:$T$114,MATCH(R$10,$B$110:$T$110,0),0),'Input data'!$C$59) -> 0.06099826 | S38: =IF(OR($C$3="EL",$C$3="CY",$C$3="IE",$C$3="PT"),VLOOKUP($C$3,$B$110:$T$114,MATCH(S$10,$B$110:$T$110,0),0),'Input data'!$C$59) -> 0.06099826 | T38: =IF(OR($C$3="EL",$C$3="CY",$C$3="IE",$C$3="PT"),VLOOKUP($C$3,$B$110:$T$114,MATCH(T$10,$B$110:$T$110,0),0),'Input data'!$C$59) -> 0.06099826 | U38: =IF(OR($C$3="EL",$C$3="CY",$C$3="IE",$C$3="PT"),VLOOKUP($C$3,$B$110:$W$114,MATCH(U$10,$B$110:$W$110,0),0),'Input data'!$C$59) -> 0.06099826 | V38: =IF(OR($C$3="EL",$C$3="CY",$C$3="IE",$C$3="PT"),VLOOKUP($C$3,$B$110:$W$114,MATCH(V$10,$B$110:$W$110,0),0),'Input data'!$C$59) -> 0.06099826 | W38: =IF(OR($C$3="EL",$C$3="CY",$C$3="IE",$C$3="PT"),VLOOKUP($C$3,$B$110:$W$114,MATCH(W$10,$B$110:$W$110,0),0),'Input data'!$C$59) -> 0.06099826
B40: Inflation and exchange rate
B41: GDP deflator (national currency) | C41: ='Input data'!C42 -> 2.005253 | D41: ='Input data'!D42 -> 5.261471 | E41: ='Input data'!E42 -> 5.273616 | F41: ='Input data'!F42 -> 3.642343 | G41: ='Input data'!G42 -> 2.533911 | H41: =$G$41+($O$41-$G$41)/($O$10-$G$10)*(H10-$G$10) -> 2.5359221 | I41: =$G$41+($O$41-$G$41)/($O$10-$G$10)*(I10-$G$10) -> 2.5379333 | J41: =$G$41+($O$41-$G$41)/($O$10-$G$10)*(J10-$G$10) -> 2.5399444 | K41: =$G$41+($O$41-$G$41)/($O$10-$G$10)*(K10-$G$10) -> 2.5419555 | L41: =$G$41+($O$41-$G$41)/($O$10-$G$10)*(L10-$G$10) -> 2.5439666 | M41: =$G$41+($O$41-$G$41)/($O$10-$G$10)*(M10-$G$10) -> 2.5459777 | N41: =$G$41+($O$41-$G$41)/($O$10-$G$10)*(N10-$G$10) -> 2.5479889 | O41: ='Input data'!$C$61 -> 2.55 | P41: =$O$41+('Input data'!$C$62-'Input data'!$C$61)/20*(P$10-2033) -> 2.5225 | Q41: =$O$41+('Input data'!$C$62-'Input data'!$C$61)/20*(Q$10-2033) -> 2.495 | R41: =$O$41+('Input data'!$C$62-'Input data'!$C$61)/20*(R$10-2033) -> 2.4675 | S41: =$O$41+('Input data'!$C$62-'Input data'!$C$61)/20*(S$10-2033) -> 2.44 | T41: =$O$41+('Input data'!$C$62-'Input data'!$C$61)/20*(T$10-2033) -> 2.4125 | U41: =$O$41+('Input data'!$C$62-'Input data'!$C$61)/20*(U$10-2033) -> 2.385 | V41: =$O$41+('Input data'!$C$62-'Input data'!$C$61)/20*(V$10-2033) -> 2.3575 | W41: =$O$41+('Input data'!$C$62-'Input data'!$C$61)/20*(W$10-2033) -> 2.33
B42: Exchange rate composite change (weighted by share of debt in each currency) | C42: 1 | D42: 1 | E42: 1 | F42: 1 | G42: 0.9999999 | H42: 1 | I42: 1 | J42: 1 | K42: 1 | L42: 1 | M42: 1 | N42: 1 | O42: 1 | P42: 1 | Q42: 1 | R42: 1 | S42: 1 | T42: 1 | U42: 1 | V42: 1 | W42: 1
B44: Intermediate calculations (growth rate equation)
B46: Fiscal multiplier | C46: ='Input data'!C49 -> 0.75
B47: Budget balance semi-elasticity | C47: ='Input data'!C50 -> 0.479
B49: Auxiliary variable to control the closure of the output gap | D49: =IF(AND(ABS((D12-C12)-('Input data'!D13-'Input data'!C13))>0.0001,ABS(D12-C12)>0.0001,D$10>$C$5),4,IF(C49=4,3,IF(C49=3,2,IF(C49=2,1,0)))) -> 0 | E49: =IF(AND(ABS((E12-D12)-('Input data'!E13-'Input data'!D13))>0.0001,ABS(E12-D12)>0.0001,E$10>$C$5),4,IF(D49=4,3,IF(D49=3,2,IF(D49=2,1,0)))) -> 0 | F49: =IF(AND(ABS((F12-E12)-('Input data'!F13-'Input data'!E13))>0.0001,ABS(F12-E12)>0.0001,F$10>$C$5),4,IF(E49=4,3,IF(E49=3,2,IF(E49=2,1,0)))) -> 0 | G49: =IF(AND(ABS((G12-F12)-('Input data'!G13-'Input data'!F13))>0.0001,ABS(G12-F12)>0.0001,G$10>$C$5),4,IF(F49=4,3,IF(F49=3,2,IF(F49=2,1,0)))) -> 0 | H49: =IF(AND(ABS((H12-G12)-('Input data'!H13-'Input data'!G13))>0.0001,ABS(H12-G12)>0.0001,H$10>$C$5),4,IF(G49=4,3,IF(G49=3,2,IF(G49=2,1,0)))) -> 0 | I49: =IF(AND(ABS((I12-H12)-('Input data'!I13-'Input data'!H13))>0.0001,ABS(I12-H12)>0.0001,I$10>$C$5),4,IF(H49=4,3,IF(H49=3,2,IF(H49=2,1,0)))) -> 0 | J49: =IF(AND(ABS((J12-I12)-('Input data'!J13-'Input data'!I13))>0.0001,ABS(J12-I12)>0.0001,J$10>$C$5),4,IF(I49=4,3,IF(I49=3,2,IF(I49=2,1,0)))) -> 0 | K49: =IF(AND(ABS((K12-J12)-('Input data'!K13-'Input data'!J13))>0.0001,ABS(K12-J12)>0.0001,K$10>$C$5),4,IF(J49=4,3,IF(J49=3,2,IF(J49=2,1,0)))) -> 0 | ... W49: =IF(AND(ABS((W12-V12)-('Input data'!W13-'Input data'!V13))>0.0001,ABS(W12-V12)>0.0001,W$10>$C$5),4,IF(V49=4,3,IF(V49=3,2,IF(V49=2,1,0)))) -> 0
B50: OG intermediate auxiliary value | D50: =IF(C49=4,2/3*C29,IF(C49=3,1/3*B29,0)) -> 0 | E50: =IF(D49=4,2/3*D29,IF(D49=3,1/3*C29,0)) -> 0 | F50: =IF(E49=4,2/3*E29,IF(E49=3,1/3*D29,0)) -> 0 | G50: =IF(F49=4,2/3*F29,IF(F49=3,1/3*E29,0)) -> 0 | H50: =IF(G49=4,2/3*G29,IF(G49=3,1/3*F29,0)) -> 0 | I50: =IF(H49=4,2/3*H29,IF(H49=3,1/3*G29,0)) -> 0 | J50: =IF(I49=4,2/3*I29,IF(I49=3,1/3*H29,0)) -> 0 | K50: =IF(J49=4,2/3*J29,IF(J49=3,1/3*I29,0)) -> 0 | ... W50: =IF(V49=4,2/3*V29,IF(V49=3,1/3*U29,0)) -> 0
B51: GDP intermediate growth rate - only feedback effect and no closure of the OG | D51: ='Input data'!D30-$C$46*((D12-C12)-('Input data'!D13-'Input data'!C13)) -> 8.075569 | E51: ='Input data'!E30-$C$46*((E12-D12)-('Input data'!E13-'Input data'!D13)) -> 5.613926 | F51: ='Input data'!F30-$C$46*((F12-E12)-('Input data'!F13-'Input data'!E13)) -> 4.57228 | G51: ='Input data'!G30-$C$46*((G12-F12)-('Input data'!G13-'Input data'!F13)) -> 7.0181303 | H51: ='Input data'!H30-$C$46*((H12-G12)) -> 4.807363 | I51: ='Input data'!I30-$C$46*((I12-H12)) -> 4.880684 | J51: ='Input data'!J30-$C$46*((J12-I12)) -> 4.731095 | K51: ='Input data'!K30-$C$46*((K12-J12)) -> 4.59818 | L51: ='Input data'!L30-$C$46*((L12-K12)) -> 4.504259 | M51: ='Input data'!M30-$C$46*((M12-L12)) -> 4.348238 | N51: ='Input data'!N30-$C$46*((N12-M12)) -> 4.170129 | O51: ='Input data'!O30-$C$46*((O12-N12)) -> 4.115924 | ... W51: ='Input data'!W30-$C$46*((W12-V12)) -> 2.369435
B53: Debt projections
C55: 2021 | D55: 2022 | E55: 2023 | F55: 2024 | G55: 2025 | H55: 2026 | I55: 2027 | J55: 2028 | K55: 2029 | L55: 2030 | M55: 2031 | N55: 2032 | O55: 2033 | P55: 2034 | Q55: 2035 | R55: 2036 | S55: 2037 | T55: 2038 | U55: 2039 | V55: 2040 | W55: 2041
B56: Gross debt | C56: =+'Input data'!C12 -> 53.92565 | D56: =+C56+D57 -> 51.62648 | E56: =+D56+E57 -> 50.396658 | F56: =+E56+F57 -> 52.027241 | G56: =+F56+G57 -> 52.801993 | H56: =+G56+H57 -> 53.227584 | I56: =+H56+I57 -> 53.467452 | J56: =+I56+J57 -> 53.690446 | K56: =+J56+K57 -> 53.94971 | ... W56: =+V56+W57 -> 65.588764
...

Sheet Adjustment scenario
B3: Country | C3: ='Input data'!C3 -> MT
B4: Key years
B5: ='Input data'!B5 -> Last year before the adjustment | C5: =+'Input data'!C5 -> 2024
B6: Last year of adjustment | C6: =+C5+'Criteria results'!$F$5 -> 2028
B7: Last year of no-fiscal-policy-change projections | C7: =C5+'Criteria results'!$F$5+10 -> 2038
B9: Key assumptions
C10: 2021 | D10: 2022 | E10: 2023 | F10: 2024 | G10: 2025 | H10: 2026 | I10: 2027 | J10: 2028 | K10: 2029 | L10: 2030 | M10: 2031 | N10: 2032 | O10: 2033 | P10: 2034 | Q10: 2035 | R10: 2036 | S10: 2037 | T10: 2038 | U10: 2039 | V10: 2040 | W10: 2041
B11: Fiscal assumptions (% of GDP)
B12: Structural primary balance ('+' means 'surplus') | C12: ='Input data'!C13 -> -5.650948 | D12: ='Input data'!D13 -> -4.355204 | E12: ='Input data'!E13 -> -3.790994 | F12: ='Input data'!F13 -> -2.897243 | G12: =IF(G10<=$C$6, IF(AND(F87=1,F77<=-3.05,'Criteria results'!$F$6<0.5),F12+0.5, IF(AND(F78<=-1.55,'Criteria results'!$F$5=4,'Criteria results'!$F$6<0.4),F12+0.4, IF(AND(F78<=-1.55,'Criteria results'!$F$5=7,'Criteria results'!$F$6<0.25),F12+0.25, F12+'Criteria results'!$F$6))),F12) -> -2.397243 | H12: =IF(H10<=$C$6, IF(AND(G87=1,G77<=-3.05,'Criteria results'!$F$6<0.5),G12+0.5, IF(AND(G78<=-1.55,'Criteria results'!$F$5=4,'Criteria results'!$F$6<0.4),G12+0.4, IF(AND(G78<=-1.55,'Criteria results'!$F$5=7,'Criteria results'!$F$6<0.25),G12+0.25, G12+'Criteria results'!$F$6))),G12) -> -1.897243 | I12: =IF(I10<=$C$6, IF(AND(H87=1,H77<=-3.05,'Criteria results'!$F$6<0.5),H12+0.5, IF(AND(H78<=-1.55,'Criteria results'!$F$5=4,'Criteria results'!$F$6<0.4),H12+0.4, IF(AND(H78<=-1.55,'Criteria results'!$F$5=7,'Criteria results'!$F$6<0.25),H12+0.25, H12+'Criteria results'!$F$6))),H12) -> -1.397243 | J12: =IF(J10<=$C$6, IF(AND(I87=1,I77<=-3.05,'Criteria results'!$F$6<0.5+J91),I12+0.5+J91, IF(AND(I78<=-1.55,'Criteria results'!$F$5=4,'Criteria results'!$F$6<0.4),I12+0.4, IF(AND(I78<=-1.55,'Criteria results'!$F$5=7,'Criteria results'!$F$6<0.25),I12+0.25, I12+'Criteria results'!$F$6))),I12) -> -0.86632274 | K12: =IF(K10<=$C$6, IF(AND(J87=1,J77<=-3.05,'Criteria results'!$F$6<0.5+K91),J12+0.5+K91, IF(AND(J78<=-1.55,'Criteria results'!$F$5=4,'Criteria results'!$F$6<0.4),J12+0.4, IF(AND(J78<=-1.55,'Criteria results'!$F$5=7,'Criteria results'!$F$6<0.25),J12+0.25, J12+'Criteria results'!$F$6))),J12) -> -0.86632274 | L12: =IF(L10<=$C$6, IF(AND(K87=1,K77<=-3.05,'Criteria results'!$F$6<0.5+L91),K12+0.5+L91, IF(AND(K78<=-1.55,'Criteria results'!$F$5=4,'Criteria results'!$F$6<0.4),K12+0.4, IF(AND(K78<=-1.55,'Criteria results'!$F$5=7,'Criteria results'!$F$6<0.25),K12+0.25, K12+'Criteria results'!$F$6))),K12) -> -0.86632274 | M12: =IF(M10<=$C$6, IF(AND(L87=1,L77<=-3.05,'Criteria results'!$F$6<0.5+M91),L12+0.5+M91, IF(AND(L78<=-1.55,'Criteria results'!$F$5=4,'Criteria results'!$F$6<0.4),L12+0.4, IF(AND(L78<=-1.55,'Criteria results'!$F$5=7,'Criteria results'!$F$6<0.25),L12+0.25, L12+'Criteria results'!$F$6))),L12) -> -0.86632274 | N12: =M12 -> -0.86632274 | O12: =N12 -> -0.86632274 | P12: =O12 -> -0.86632274 | Q12: =P12 -> -0.86632274 | R12: =Q12 -> -0.86632274 | S12: =R12 -> -0.86632274 | T12: =S12 -> -0.86632274 | U12: =T12 -> -0.86632274 | ... W12: =V12 -> -0.86632274
B13: Annual change in SPB | G13: =G12-F12 -> 0.5 | H13: =H12-G12 -> 0.5 | I13: =I12-H12 -> 0.5 | J13: =J12-I12 -> 0.53092026 | K13: =K12-J12 -> 0 | L13: =L12-K12 -> 0 | M13: =M12-L12 -> 0 | N13: =N12-M12 -> 0 | ... W13: =W12-V12 -> 0
B14: One-off and other temporary measures | C14: ='Input data'!C14 -> 0 | D14: ='Input data'!D14 -> 0 | E14: ='Input data'!E14 -> 0 | F14: ='Input data'!F14 -> 0 | G14: ='Input data'!G14 -> 0 | H14: =0 -> 0 | I14: =0 -> 0 | J14: =0 -> 0 | K14: =0 -> 0 | L14: =0 -> 0 | M14: =0 -> 0 | N14: =0 -> 0 | O14: =0 -> 0 | ... W14: =0 -> 0
B15: Stock flow adjustments (without exchange rate effect) | C15: ='Input data'!C15 -> 0.8044612 | D15: ='Input data'!D15 -> -1.310275 | E15: ='Input data'!E15 -> -0.9404473 | F15: ='Input data'!F15 -> 1.185197 | G15: ='Input data'!G15 -> 0.0667276 | H15: ='Input data'!H15 -> 0 | I15: ='Input data'!I15 -> 0 | J15: ='Input data'!J15 -> 0 | ... W15: ='Input data'!W15 -> 0
B17: ='Input data'!B19 -> Cost of ageing and selected public revenue (based on the Commission-Council 2024 Ageing Report ("AR 2024"))
B18: Total ageing cost (net of taxes on pensions) | C18: ='Input data'!C20 -> 0 | D18: ='Input data'!D20 -> 16.93779 | E18: ='Input data'!E20 -> 16.70416 | F18: ='Input data'!F20 -> 16.66552 | G18: ='Input data'!G20 -> 16.60096 | H18: ='Input data'!H20 -> 16.33519 | I18: ='Input data'!I20 -> 16.23882 | J18: ='Input data'!J20 -> 16.15621 | ... W18: ='Input data'!W20 -> 16.22383
B19: Property income | C19: ='Input data'!C26 -> 0.5214214 | D19: ='Input data'!D26 -> 0.4365457 | E19: ='Input data'!E26 -> 0.4337021 | F19: ='Input data'!F26 -> 0.4308586 | G19: ='Input data'!G26 -> 0.428015 | H19: ='Input data'!H26 -> 0.4251715 | I19: ='Input data'!I26 -> 0.4223279 | J19: ='Input data'!J26 -> 0.4194843 | ... W19: ='Input data'!W26 -> 0.3825183
B21: GDP growth assumptions
B22: Actual GDP (real)
B23: Level | C23: ='Input data'!C31 -> 13.62455 | D23: ='Baseline NFPC'!D22 -> 14.72481 | E23: ='Baseline NFPC'!E22 -> 15.55145 | F23: ='Baseline NFPC'!F22 -> 16.262506 | G23: =IF(AND(G50>1,F50>1),IF(AND(G50>0,F50>0),G27*(G51/100+1),0)+IF(G50>0,F23*(1+G52/100),0)-F23*(1+'Input data'!G30/100),IF(G50=1,G27,F23*(1+G52/100))) -> 16.989472 | H23: =IF(AND(H50>1,G50>1),IF(AND(H50>0,G50>0),H27*(H51/100+1),0)+IF(H50>0,G23*(1+H52/100),0)-G23*(1+'Input data'!H30/100),IF(H50=1,H27,G23*(1+H52/100))) -> 17.763868 | I23: =IF(AND(I50>1,H50>1),IF(AND(I50>0,H50>0),I27*(I51/100+1),0)+IF(I50>0,H23*(1+I52/100),0)-H23*(1+'Input data'!I30/100),IF(I50=1,I27,H23*(1+I52/100))) -> 18.586045 | J23: =IF(AND(J50>1,I50>1),IF(AND(J50>0,I50>0),J27*(J51/100+1),0)+IF(J50>0,I23*(1+J52/100),0)-I23*(1+'Input data'!J30/100),IF(J50=1,J27,I23*(1+J52/100))) -> 19.43521 | K23: =IF(AND(K50>1,J50>1),IF(AND(K50>0,J50>0),K27*(K51/100+1),0)+IF(K50>0,J23*(1+K52/100),0)-J23*(1+'Input data'!K30/100),IF(K50=1,K27,J23*(1+K52/100))) -> 20.396456 | L23: =IF(AND(L50>1,K50>1),IF(AND(L50>0,K50>0),L27*(L51/100+1),0)+IF(L50>0,K23*(1+L52/100),0)-K23*(1+'Input data'!L30/100),IF(L50=1,L27,K23*(1+L52/100))) -> 21.385791 | M23: =IF(AND(M50>1,L50>1),IF(AND(M50>0,L50>0),M27*(M51/100+1),0)+IF(M50>0,L23*(1+M52/100),0)-L23*(1+'Input data'!M30/100),IF(M50=1,M27,L23*(1+M52/100))) -> 22.389392 | N23: =IF(AND(N50>1,M50>1),IF(AND(N50>0,M50>0),N27*(N51/100+1),0)+IF(N50>0,M23*(1+N52/100),0)-M23*(1+'Input data'!N30/100),IF(N50=1,N27,M23*(1+N52/100))) -> 23.323058 | ... W23: =IF(AND(W50>1,V50>1),IF(AND(W50>0,V50>0),W27*(W51/100+1),0)+IF(W50>0,V23*(1+W52/100),0)-V23*(1+'Input data'!W30/100),IF(W50=1,W27,V23*(1+W52/100))) -> 30.672534
B24: Growth rate | C24: =+'Input data'!C30 -> 12.51395 | D24: ='Baseline NFPC'!D23 -> 8.075569 | E24: ='Baseline NFPC'!E23 -> 5.613926 | F24: ='Baseline NFPC'!F23 -> 4.57228 | G24: =100*(G23/F23-1) -> 4.470198 | H24: =100*(H23/G23-1) -> 4.5580913 | I24: =100*(I23/H23-1) -> 4.6283716 | J24: =100*(J23/I23-1) -> 4.5688268 | K24: =100*(K23/J23-1) -> 4.9459043 | L24: =100*(L23/K23-1) -> 4.850523 | M24: =100*(M23/L23-1) -> 4.6928382 | N24: =100*(N23/M23-1) -> 4.170129 | ... W24: =100*(W23/V23-1) -> 2.369435
B26: Potential GDP (real)
B27: Level | C27: ='Input data'!C34 -> 13.87421 | D27: =+C27*(1+'Input data'!D33/100) -> 14.798696 | E27: =+D27*(1+'Input data'!E33/100) -> 15.55436 | F27: =+E27*(1+'Input data'!F33/100) -> 16.319408 | G27: =+F27*(1+'Input data'!G33/100) -> 17.11401 | H27: =+G27*(1+'Input data'!H33/100) -> 17.914487 | I27: =+H27*(1+'Input data'!I33/100) -> 18.7578 | J27: =+I27*(1+'Input data'!J33/100) -> 19.629039 | K27: =+J27*(1+'Input data'!K33/100) -> 20.531618 | ... W27: =+V27*(1+'Input data'!W33/100) -> 30.672533
B29: Output gap
B30: Output gap | C30: =100*(C23/C27-1) -> -1.7994538 | D30: =100*(D23/D27-1) -> -0.49927084 | E30: =100*(E23/E27-1) -> -0.018709187 | F30: =100*(F23/F27-1) -> -0.34867871 | G30: =100*(G23/G27-1) -> -0.7276992 | H30: =100*(H23/H27-1) -> -0.84076966 | I30: =100*(I23/I27-1) -> -0.91564273 | J30: =100*(J23/J27-1) -> -0.98746076 | ... W30: =100*(W23/W27-1) -> 5.7106968e-06
B32: Actual GDP (nominal, national currency)
B33: Growth rate | C33: =100*((1+C24/100)*(1+C42/100)-1) -> 14.770139 | D33: =100*((1+D24/100)*(1+D42/100)-1) -> 13.761934 | E33: =100*((1+E24/100)*(1+E42/100)-1) -> 11.183599 | F33: =100*((1+F24/100)*(1+F42/100)-1) -> 8.3811611 | G33: =100*((1+G24/100)*(1+G42/100)-1) -> 7.1173798 | H33: =100*((1+H24/100)*(1+H42/100)-1) -> 7.209603 | I33: =100*((1+I24/100)*(1+I42/100)-1) -> 7.2837698 | J33: =100*((1+J24/100)*(1+J42/100)-1) -> 7.2248168 | ... W33: =100*((1+W24/100)*(1+W42/100)-1) -> 4.7546428
B35: Interest rates
B36: Nominal implicit interest rate on debt | C36: ='Input data'!C37 -> 2.40894 | D36: ='Input data'!D37 -> 1.98347 | E36: ='Input data'!E37 -> 2.37675 | F36: ='Input data'!F37 -> 2.749095 | G36: ='Input data'!G37 -> 2.738361 | H36: =H109 -> 2.82879 | I36: =I109 -> 2.9113734 | J36: =J109 -> 2.9880994 | K36: =K109 -> 3.059409 | L36: =L109 -> 3.1293648 | M36: =M109 -> 3.1980675 | N36: =N109 -> 3.2656344 | O36: =O109 -> 3.3342651 | ... W36: =W109 -> 3.6452522
B37: Long-term interest rate | D37: ='Input data'!D$39 -> 2.41 | E37: ='Input data'!E$39 -> 3.71 | F37: ='Input data'!F$39 -> 3.497002 | G37: ='Input data'!G$39 -> 3.505358 | H37: =G37+($O$37-$G$37)/($O$10-$G$10) -> 3.584932 | I37: =H37+($O$37-$G$37)/($O$10-$G$10) -> 3.664506 | J37: =I37+($O$37-$G$37)/($O$10-$G$10) -> 3.74408 | K37: =J37+($O$37-$G$37)/($O$10-$G$10) -> 3.823654 | L37: =K37+($O$37-$G$37)/($O$10-$G$10) -> 3.903228 | M37: =L37+($O$37-$G$37)/($O$10-$G$10) -> 3.982802 | N37: =M37+($O$37-$G$37)/($O$10-$G$10) -> 4.062376 | O37: ='Input data'!$C$52 -> 4.14195 | P37: ='Baseline NFPC'!P36 -> 4.1348525 | Q37: ='Baseline NFPC'!Q36 -> 4.127755 | R37: ='Baseline NFPC'!R36 -> 4.1206575 | S37: ='Baseline NFPC'!S36 -> 4.11356 | T37: ='Baseline NFPC'!T36 -> 4.1064625 | U37: ='Baseline NFPC'!U36 -> 4.099365 | V37: ='Baseline NFPC'!V36 -> 4.0922675 | W37: ='Baseline NFPC'!W36 -> 4.08517
B38: Short-term interest rate | D38: ='Input data'!D$38 -> 0.35 | E38: ='Input data'!E$38 -> 3.43 | F38: ='Input data'!F$38 -> 3.564208 | G38: ='Input data'!G$38 -> 2.816375 | H38: =G38+($O$38-$G$38)/($O$10-$G$10) -> 2.8050894 | I38: =H38+($O$38-$G$38)/($O$10-$G$10) -> 2.7938037 | J38: =I38+($O$38-$G$38)/($O$10-$G$10) -> 2.7825181 | K38: =J38+($O$38-$G$38)/($O$10-$G$10) -> 2.7712325 | L38: =K38+($O$38-$G$38)/($O$10-$G$10) -> 2.7599469 | M38: =L38+($O$38-$G$38)/($O$10-$G$10) -> 2.7486612 | N38: =M38+($O$38-$G$38)/($O$10-$G$10) -> 2.7373756 | O38: ='Input data'!$C$53 -> 2.72609 | P38: ='Baseline NFPC'!P37 -> 2.6897855 | Q38: ='Baseline NFPC'!Q37 -> 2.653481 | R38: ='Baseline NFPC'!R37 -> 2.6171765 | S38: ='Baseline NFPC'!S37 -> 2.580872 | T38: ='Baseline NFPC'!T37 -> 2.5445675 | U38: ='Baseline NFPC'!U37 -> 2.508263 | V38: ='Baseline NFPC'!V37 -> 2.4719585 | W38: ='Baseline NFPC'!W37 -> 2.435654
B39: Share of long-term debt that matures every year | C39: ='Baseline NFPC'!C38 -> 0.08190323 | D39: ='Baseline NFPC'!D38 -> 0.001 | E39: ='Baseline NFPC'!E38 -> 0.04901889 | F39: ='Baseline NFPC'!F38 -> 0.04747952 | G39: ='Baseline NFPC'!G38 -> 0.048981602 | H39: ='Baseline NFPC'!H38 -> 0.050483684 | I39: ='Baseline NFPC'!I38 -> 0.051985767 | J39: ='Baseline NFPC'!J38 -> 0.053487849 | ... W39: ='Baseline NFPC'!W38 -> 0.06099826
B41: Inflation and exchange rate
B42: GDP deflator (National currency) | C42: ='Input data'!C42 -> 2.005253 | D42: ='Input data'!D42 -> 5.261471 | E42: ='Input data'!E42 -> 5.273616 | F42: ='Input data'!F42 -> 3.642343 | G42: ='Input data'!G42 -> 2.533911 | H42: ='Baseline NFPC'!H41 -> 2.5359221 | I42: ='Baseline NFPC'!I41 -> 2.5379333 | J42: ='Baseline NFPC'!J41 -> 2.5399444 | K42: ='Baseline NFPC'!K41 -> 2.5419555 | L42: ='Baseline NFPC'!L41 -> 2.5439666 | M42: ='Baseline NFPC'!M41 -> 2.5459777 | N42: ='Baseline NFPC'!N41 -> 2.5479889 | O42: ='Baseline NFPC'!O41 -> 2.55 | ... W42: ='Baseline NFPC'!W41 -> 2.33
B43: Exchange rate composite change (weighted by share of debt in each currency) | C43: ='Baseline NFPC'!C42 -> 1 | D43: ='Baseline NFPC'!D42 -> 1 | E43: ='Baseline NFPC'!E42 -> 1 | F43: ='Baseline NFPC'!F42 -> 1 | G43: ='Baseline NFPC'!G42 -> 0.9999999 | H43: ='Baseline NFPC'!H42 -> 1 | I43: ='Baseline NFPC'!I42 -> 1 | J43: ='Baseline NFPC'!J42 -> 1 | ... W43: ='Baseline NFPC'!W42 -> 1
B45: Intermediate calculations (growth rate equation)
B47: Fiscal multiplier | C47: ='Input data'!C49 -> 0.75
B48: Budget balance semi-elasticity | C48: ='Input data'!C50 -> 0.479
B50: Auxiliary variable to control the closure of the output gap | C50: 0 | D50: =IF(AND(ABS((D12-C12)-('Input data'!D13-'Input data'!C13))>0.0001,ABS(D12-C12)>0.0001,D$10>$C$5),4,IF(C50=4,3,IF(C50=3,2,IF(C50=2,1,0)))) -> 0 | E50: =IF(AND(ABS((E12-D12)-('Input data'!E13-'Input data'!D13))>0.0001,ABS(E12-D12)>0.0001,E$10>$C$5),4,IF(D50=4,3,IF(D50=3,2,IF(D50=2,1,0)))) -> 0 | F50: =IF(AND(ABS((F12-E12)-('Input data'!F13-'Input data'!E13))>0.0001,ABS(F12-E12)>0.0001,F$10>$C$5),4,IF(E50=4,3,IF(E50=3,2,IF(E50=2,1,0)))) -> 0 | G50: =IF(AND(ABS((G12-F12)-('Input data'!G13-'Input data'!F13))>0.0001,ABS(G12-F12)>0.0001,G$10>$C$5),4,IF(F50=4,3,IF(F50=3,2,IF(F50=2,1,0)))) -> 4 | H50: =IF(AND(ABS((H12-G12)-('Input data'!H13-'Input data'!G13))>0.0001,ABS(H12-G12)>0.0001,H$10>$C$5),4,IF(G50=4,3,IF(G50=3,2,IF(G50=2,1,0)))) -> 4 | I50: =IF(AND(ABS((I12-H12)-('Input data'!I13-'Input data'!H13))>0.0001,ABS(I12-H12)>0.0001,I$10>$C$5),4,IF(H50=4,3,IF(H50=3,2,IF(H50=2,1,0)))) -> 4 | J50: =IF(AND(ABS((J12-I12)-('Input data'!J13-'Input data'!I13))>0.0001,ABS(J12-I12)>0.0001,J$10>$C$5),4,IF(I50=4,3,IF(I50=3,2,IF(I50=2,1,0)))) -> 4 | K50: =IF(AND(ABS((K12-J12)-('Input data'!K13-'Input data'!J13))>0.0001,ABS(K12-J12)>0.0001,K$10>$C$5),4,IF(J50=4,3,IF(J50=3,2,IF(J50=2,1,0)))) -> 3 | ... W50: =IF(AND(ABS((W12-V12)-('Input data'!W13-'Input data'!V13))>0.0001,ABS(W12-V12)>0.0001,W$10>$C$5),4,IF(V50=4,3,IF(V50=3,2,IF(V50=2,1,0)))) -> 0
B51: OG intermediate auxiliary value | C51: 0 | D51: =IF(C50=4,2/3*C30,IF(C50=3,1/3*B30,0)) -> 0 | E51: =IF(D50=4,2/3*D30,IF(D50=3,1/3*C30,0)) -> 0 | F51: =IF(E50=4,2/3*E30,IF(E50=3,1/3*D30,0)) -> 0 | G51: =IF(F50=4,2/3*F30,IF(F50=3,1/3*E30,0)) -> 0 | H51: =IF(G50=4,2/3*G30,IF(G50=3,1/3*F30,0)) -> -0.4851328 | I51: =IF(H50=4,2/3*H30,IF(H50=3,1/3*G30,0)) -> -0.56051311 | J51: =IF(I50=4,2/3*I30,IF(I50=3,1/3*H30,0)) -> -0.61042848 | K51: =IF(J50=4,2/3*J30,IF(J50=3,1/3*I30,0)) -> -0.65830717 | ... W51: =IF(V50=4,2/3*V30,IF(V50=3,1/3*U30,0)) -> 0
B52: GDP intermediate growth rate - only feedback effect and no closure of the OG | D52: ='Input data'!D30-$C$47*((D12-C12)-('Input data'!D13-'Input data'!C13)) -> 8.075569 | E52: ='Input data'!E30-$C$47*((E12-D12)-('Input data'!E13-'Input data'!D13)) -> 5.613926 | F52: ='Input data'!F30-$C$47*((F12-E12)-('Input data'!F13-'Input data'!E13)) -> 4.57228 | G52: ='Input data'!G30-$C$47*((G12-F12)) -> 4.470198 | H52: ='Input data'!H30-$C$47*((H12-G12)) -> 4.432363 | I52: ='Input data'!I30-$C$47*((I12-H12)) -> 4.505684 | J52: ='Input data'!J30-$C$47*((J12-I12)) -> 4.3329048 | K52: ='Input data'!K30-$C$47*((K12-J12)) -> 4.59818 | L52: ='Input data'!L30-$C$47*((L12-K12)) -> 4.504259 | M52: ='Input data'!M30-$C$47*((M12-L12)) -> 4.348238 | N52: ='Input data'!N30-$C$47*((N12-M12)) -> 4.170129 | ... W52: ='Input data'!W30-$C$47*((W12-V12)) -> 2.369435
B54: Debt projections
...

Sheet Adjust. no safeguard
B3: Country | C3: ='Input data'!C3 -> MT
B4: Key years
B5: ='Input data'!B5 -> Last year before the adjustment | C5: =+'Input data'!C5 -> 2024
B6: Last year of adjustment | C6: =+C5+'Criteria results'!$F$5 -> 2028
B7: Last year of no-fiscal-policy-change projections | C7: =C5+'Criteria results'!$F$5+10 -> 2038
B9: Key assumptions
C10: 2021 | D10: 2022 | E10: 2023 | F10: 2024 | G10: 2025 | H10: 2026 | I10: 2027 | J10: 2028 | K10: 2029 | L10: 2030 | M10: 2031 | N10: 2032 | O10: 2033 | P10: 2034 | Q10: 2035 | R10: 2036 | S10: 2037 | T10: 2038 | U10: 2039 | V10: 2040 | W10: 2041
B11: Fiscal assumptions (% of GDP)
B12: Structural primary balance ('+' means 'surplus') | C12: ='Input data'!C13 -> -5.650948 | D12: ='Input data'!D13 -> -4.355204 | E12: ='Input data'!E13 -> -3.790994 | F12: ='Input data'!F13 -> -2.897243 | G12: =IF(G10<=$C$6,F12+'Criteria results'!$F$6,F12) -> -2.457243 | H12: =IF(H10<=$C$6,G12+'Criteria results'!$F$6,G12) -> -2.017243 | I12: =IF(I10<=$C$6,H12+'Criteria results'!$F$6,H12) -> -1.577243 | J12: =IF(J10<=$C$6,I12+'Criteria results'!$F$6,I12) -> -1.137243 | K12: =IF(K10<=$C$6,J12+'Criteria results'!$F$6,J12) -> -1.137243 | L12: =IF(L10<=$C$6,K12+'Criteria results'!$F$6,K12) -> -1.137243 | M12: =IF(M10<=$C$6,L12+'Criteria results'!$F$6,L12) -> -1.137243 | N12: =M12 -> -1.137243 | O12: =N12 -> -1.137243 | P12: =O12 -> -1.137243 | Q12: =P12 -> -1.137243 | R12: =Q12 -> -1.137243 | S12: =R12 -> -1.137243 | T12: =S12 -> -1.137243 | U12: =T12 -> -1.137243 | ... W12: =V12 -> -1.137243
B13: Annual change in SPB | G13: =G12-F12 -> 0.44 | H13: =H12-G12 -> 0.44 | I13: =I12-H12 -> 0.44 | J13: =J12-I12 -> 0.44 | K13: =K12-J12 -> 0 | L13: =L12-K12 -> 0 | M13: =M12-L12 -> 0 | N13: =N12-M12 -> 0 | ... W13: =W12-V12 -> 0
