Workbook

Sheet Read me
G4: European Commission
G6: Directorate-General for Economic and Financial Affairs
G7: Unit C2 - Sustainability of public finances
G8: ECFIN-Secretariat-C2@ec.europa.eu
C16: FILE DESCRIPTION
C18: Data reported in this file are based on the European Commission (EC) 2025 autumn forecast (AF 2025) and macroeconomic and budgetary projections from the joint EC-EPC Ageing Report 2024 (AR 2024).
C22: This file contains a simplified version of the EC model used to calculate the general governement debt ratio dynamics for EU countries under different scenarios. A detailed description of the EC's general governement debt projections can be found in the "Debt Sustainability Monitor 2023" (DSM, March 2024).
C27: HOW TO USE THIS TOOL TO CALCULATE NEW DEBT PROJECTIONS
C29: This tool can be used to calculate debt projections under different macroeconomic and structural primary balance adjustment assumptions. Debt projections for each scenario will update automatically with changes in the macroeconomic assumptions or the adjustment parameters. The fulfilment of DSA-based criteria, the safeguards and the benchmark will be automatically calculated in the sheet "Criteria results". Formulas are fully visible. To assess the impact of alternative fiscal paths or to check the robustness of underlying macroeconomic assumptions, the user can modify the content of key cells in the sheets "Criteria results" and "Input data" (see below). Note that, for a proper functioning of the file, you should make sure that Excel is in "Automatic" computation mode, i.e. in the File menu, Option tab, click on "Formulas", "Calculation Options" and "Automatic".
C31: The spreadsheet is composed of the following elements:
D33: The grey sheet "Criteria results" contains three types of cells identified by different colours:
F34: Cells with a yellow background and a red frame can be modified to see the impact of a different duration or pace of adjustment.
F35: Cells with a white or pale red (in case the deficit resilience safeguard is binding) background provide results obtained with the adjustment chosen in the yellow cells. To replicate the Commission's calculations, the underlying formulas should not be modified.
F37: Cells with a pale blue background correspond to the Commission's prior guidance provided to the Member State. Those are hard numbers that do not depend on the adjustment chosen in the file.
D39: "Criteria results" contains five tables. Table 1 "Adjustment input data": the user can set the duration of the plan in cell F5 (4 years without extension or 7 years with extension), the yearly adjustment pace under the scenario that does not take into account the deficit resilience safeguard (F7) and for the scenario that automatically applies that safeguard (F6). Note that the country cell (F4) cannot be changed.
D40: The adjustement in F7 needs to be selected first so that the message on line 13 signals that the two DSA-based criteria are fulfilled. As a second step, the adjustment in F6 can be selected (and cannot be lower than in F7) so that line 12 reports compliance with the requirements.
D41: Table 2 "DSA-based criteria and deficit resilience safeguard" reports whether the chosen adjustment fulfils the DSA-based criteria (cells H12:I13) and whether the deficit resillience safeguard is binding.
D42: Table 3 "Main fiscal variables with automatic deficit resilience safeguard" reports the annual adjustment over the adjustment period, in terms of change in SPB (line 18), level of the structural balance (line 19) and SPB level at the end of the adjustment (line 20). This table reports the results for the scenario that automatically applies the deficit resillience safeguard. For this reason, the SB is highlighted in red if it is lower than -1.5% of GDP.
D43: Table 4 "Main fiscal variables without automatic deficit resilience safeguard" reports the annual adjustment over the adjustment period, in terms of change in SPB (line 25), level of the structural balance (line 26) and SPB level at the end of the adjustment (line 27). This table reports the results for the scenario without the deficit resillience safeguard.
D44: Table 5 "Technical information" reports the SPB level at the end of the adjustment period that fulfils the DSA-based criteria and takes into account the deficit resilience safeguard, both without and with extension.
D46: The sheet "Input data" in light blue presents the input data, including fiscal and GDP growth assumptions as well as additional fiscal parameters. Unless stated otherwise below, the user can change all values in this tab.
D47: Coloured cells indicate data sources as follows (this colour-coding holds in the other spreadsheets):
F48: Cells in light grey indicate Commission forecast (available in the AMECO database)
F49: Cells in light blue indicate values from the Ageing Report 2024
F50: Cells in light orange provide parameters needed to compute the decomposition of government debt according to its maturity structure (i.e. short-term and long-term debt, maturing, rolled-over and non-maturing debt). These are fixed shares which the user cannot change.
F51: Cells in dark orange indicate financial market prices.
D52: Non coloured parameters in cells C50:C70 were calibrated based on different data sources. Data sources are given in corresponding cells of column E.
C54: The next spreadsheets present the no-fiscal-policy-change baseline and the adjustment scenario, with and without the impact of the deficit resilience safeguard. Each deterministic projection provides a single path for debt until 2039 or 2042 under certain assumptions for budgetary, macroeconomic and financial variables.
D56: The sheet in blue provides, as a reference, the baseline no-fiscal-policy-change scenario. The background colour coding is the same as in the sheet "Input data".
D58: The sheet in orange presents the scenario that automatically corrects the yearly adjustment path to account for the deficit resillience safeguard.
D60: The sheet in green presents the adjustment scenarios without the deficit resilience safeguard. This scenario is computed automatically based on the yearly adjustment path set in "Criteria results" (see above).
C62: Within the orange sheet and each green sheet, the background of the SPB line has three colours. Each colour corresponds to a specific period of the projections:
E63: Light grey indicates the pre-plan period, corresponding to the EC forecast
E64: Mild grey indicates the period during which the SPB adjusts according to the path set in sheet "Criteria results"
E65: Dark grey indicates the period in which the SPB, net of changes in cost of ageing, remains constant at its value of end of adjustment.
C68: WHERE ARE THE MAIN RESULTS LOCATED?
C69: The fullfilment of the criteria is checked in the sheet "Criteria results". Debt projections can be found in line 57 of each scenario.
D71: The 'FASTOP reporting' sheet in violet provides help for preparing reporting tables. It readily provides all the tables foreseen by the guidance notice on the "Information Requirements for the Medium-Term Fiscal-Structural Plans" once the parameters are set in the rest of this file. This sheet is meant to be an assistance. The need for a thorough scrutiny of the figures before submitting such tables remains.

Sheet Criteria results
U2: 4 | V2: -1.5
D3: Table 1 - Adjustment input data | U3: 7 | V3: -1.48
D4: Country | F4: NL | V4: -1.46
D5: Number of years of adjustment | F5: 4 | V5: -1.44
C6: 2. | D6: Annual adjustment (with safeguard) | F6: 0 | V6: -1.42
C7: 1. | D7: Annual adjustment (without safeguard) | F7: 0 | V7: -1.4
V8: -1.38
H9: Table 2 - DSA-based criteria and deficit resilience safeguard | V9: -1.36
H10: DSA-based criteria | J10: Deficit resilience safeguard | V10: -1.34
H11: Deficit below 3% of GDP | I11: ="Debt below 60% of GDP in T+"&10+F5 -> Debt below 60% of GDP in T+14 | V11: -1.32
C12: 2. | D12: Adjustment scenario with automatic deficit resilience safeguard * (sheet "Adjustment scenario") | H12: =IF(MIN(OFFSET('Adjustment scenario'!$D$77,0,$F$5,1,11))>-3.05,"ok","Not met") -> Not met | I12: =IF(OFFSET('Adjustment scenario'!$D$57,0,$F$5+10,1,1)<60,"ok","Not met") -> ok | J12: =IF(AND($F$5=4,COUNTIF(G18:J18,">" & F6)=0),"Not binding",IF(AND($F$5=7,COUNTIF(G18:M18,">" & F6)=0),"Not binding","Binding")) -> Not binding | K12: =IF(OR($H$13="Not met",$I$13="Not met"),"Please adjust cell F7 so that both DSA-based criteria are met", IF($F$6<$F$7,"The adjustment in F6 cannot be lower than in F7", IF(AND($H$12="ok",$I$12="ok",$H$13="ok",$I$13="ok",$F$6>=$F$7, OR(AND($F$5=4,$G$18>=$H$18,$H$18>=$I$18,$I$18>=$J$18,OR($J$18>=0.4,$J$19>-1.55)), AND($F$5=7,$G$18>=$H$18,$H$18>=$I$18,$I$18>=$J$18,$J$18>=$K$18,$K$18>=$L$18,$L$18>=$M$18,OR($M$18>=0.25,$M$19>-1.55)))), "OK"&CHAR(10)&"The adjustment in F6 fulfills all requirements including the deficit resilience safeguard", "NOT OK"&CHAR(10)&"The adjustment in F6 does not fulfill all requirements"))) -> Please adjust cell F7 so that both DSA-based criteria are met | V12: -1.3
C13: 1. | D13: Adjustment scenario without deficit resilience safeguard (sheet "Adjust. no safeguard") | H13: =IF(MIN(OFFSET('Adjust. no safeguard'!$D$77,0,$F$5,1,11))>-3.05,"ok","Not met") -> Not met | I13: =IF(OFFSET('Adjust. no safeguard'!$D$57,0,$F$5+10,1,1)<60,"ok","Not met") -> ok | K13: =IF(AND($H$13="ok",$I$13="ok"), "OK"&CHAR(10)&"The adjustment in F7 ensures that the debt and deficit remain"&CHAR(10)&"below the Treaty reference values over the medium term", "NOT OK"&CHAR(10)&"The adjustment in F7 does not ensure that the debt and deficit remain"&CHAR(10)&"below the Treaty reference values over the medium term") -> NOT OK The adjustment in F7 does not ensure that the debt and deficit remain below the Treaty reference values over the medium term | V13: -1.28
D14: * Under a plan without (with) extension, an adjustment of 0.40 pp. (0.25 pp.) of GDP in SPB terms is applied if the structural deficit in the previous year exceeds 1.5% of GDP. | V14: -1.26
V15: -1.24
G16: Table 3 - Main fiscal variables with automatic deficit resilience safeguard * | V16: -1.22
G17: ='Input data'!$C$5+1 -> 2026 | H17: =G17+1 -> 2027 | I17: =H17+1 -> 2028 | J17: =I17+1 -> 2029 | K17: =J17+1 -> 2030 | L17: =K17+1 -> 2031 | M17: =L17+1 -> 2032 | V17: -1.2
D18: Annual adjustment (change in SPB) | G18: ='Adjustment scenario'!E12-'Adjustment scenario'!D12 -> 0 | H18: ='Adjustment scenario'!F12-'Adjustment scenario'!E12 -> 0 | I18: ='Adjustment scenario'!G12-'Adjustment scenario'!F12 -> 0 | J18: ='Adjustment scenario'!H12-'Adjustment scenario'!G12 -> 0 | K18: ='Adjustment scenario'!I12-'Adjustment scenario'!H12 -> 0 | L18: ='Adjustment scenario'!J12-'Adjustment scenario'!I12 -> 0 | M18: ='Adjustment scenario'!K12-'Adjustment scenario'!J12 -> 0 | V18: -1.18
D19: Structural balance | G19: ='Adjustment scenario'!E78 -> -1.3057584 | H19: ='Adjustment scenario'!F78 -> -1.4003147 | I19: ='Adjustment scenario'!G78 -> -1.4672003 | J19: ='Adjustment scenario'!H78 -> -1.5328785 | K19: ='Adjustment scenario'!I78 -> -1.701993 | L19: ='Adjustment scenario'!J78 -> -2.0752787 | M19: ='Adjustment scenario'!K78 -> -2.3623048 | V19: -1.16
D20: SPB at the end of the adjustment | J20: =IF(F5=4,'Adjustment scenario'!H12,"") -> -0.5577395 | M20: =IF(F5=7,'Adjustment scenario'!K12,"") | V20: -1.14
D21: * The structural balance is flagged in red if it is below -1.5% of GDP. | V21: -1.12
V22: -1.1
G23: Table 4 - Main fiscal variables without automatic deficit resilience safeguard | V23: -1.08
G24: ='Input data'!$C$5+1 -> 2026 | H24: =G24+1 -> 2027 | I24: =H24+1 -> 2028 | J24: =I24+1 -> 2029 | K24: =J24+1 -> 2030 | L24: =K24+1 -> 2031 | M24: =L24+1 -> 2032 | V24: -1.06
D25: Annual adjustment (change in SPB) | G25: ='Adjust. no safeguard'!E12-'Adjust. no safeguard'!D12 -> 0 | H25: ='Adjust. no safeguard'!F12-'Adjust. no safeguard'!E12 -> 0 | I25: ='Adjust. no safeguard'!G12-'Adjust. no safeguard'!F12 -> 0 | J25: ='Adjust. no safeguard'!H12-'Adjust. no safeguard'!G12 -> 0 | K25: ='Adjust. no safeguard'!I12-'Adjust. no safeguard'!H12 -> 0 | L25: ='Adjust. no safeguard'!J12-'Adjust. no safeguard'!I12 -> 0 | M25: ='Adjust. no safeguard'!K12-'Adjust. no safeguard'!J12 -> 0 | V25: -1.04
D26: Structural balance | G26: ='Adjust. no safeguard'!E78 -> -1.3057584 | H26: ='Adjust. no safeguard'!F78 -> -1.4003147 | I26: ='Adjust. no safeguard'!G78 -> -1.4672003 | J26: ='Adjust. no safeguard'!H78 -> -1.5328785 | K26: ='Adjust. no safeguard'!I78 -> -1.701993 | L26: ='Adjust. no safeguard'!J78 -> -2.0752787 | M26: ='Adjust. no safeguard'!K78 -> -2.3623048 | V26: -1.02
D27: SPB at the end of the adjustment | J27: =IF(F5=4,'Adjust. no safeguard'!H12,"") -> -0.5577395 | M27: =IF(F5=7,'Adjust. no safeguard'!K12,"") | V27: -1
V28: -0.98
V29: -0.96
V30: -0.94
G31: Table 5 - Technical information* | V31: -0.92
G32: Without extension | H32: With extension | V32: -0.9
D33: Number of years of adjustment | G33: 4 | H33: 7 | V33: -0.88
D34: SPB at the end of the adjustment | G34: 0.0822605 | H34: 0.0022605 | V34: -0.86
D35: * The technical information provides the structural primary balance necessary to ensure that the deficit remains below 3% of GDP and debt remains below 60% of GDP over the medium term in the absence of additional fiscal measures beyond the adjustment period. In line with the deficit resilience safeguard, and when necessary, an adjustment of 0.4 pp of GDP (0.25 pp. in case of extension) in structural primary terms is applied until the structural balance is at least equal to -1.5% of GDP. Note that the SPB at the end of the adjustment period may be lower than the SPB at the beginning of the plan, indicating that the Member State does not need to adjust. | V35: -0.84
V36: -0.82
V37: -0.8
V38: -0.78
V39: -0.76
V40: -0.74
V41: -0.72
...

Sheet Input data
B3: Country | C3: NL
B5: Last year before the adjustment | C5: 2025
B6: Last year of adjustment | C6: =C5+'Criteria results'!$F$5 -> 2029
B8: Key assumptions
C9: 2024 | D9: 2025 | E9: 2026 | F9: 2027 | G9: 2028 | H9: 2029 | I9: 2030 | J9: 2031 | K9: 2032 | L9: 2033 | M9: 2034 | N9: 2035 | O9: 2036 | P9: 2037 | Q9: 2038 | R9: 2039 | S9: 2040 | T9: 2041 | U9: 2042
B10: Fiscal assumptions (% of GDP)
B11: Key fiscal variables (based on the Commission 2025 autumn forecast ("AF 2025"))
B12: Debt | C12: 43.74815 | D12: 45.1576
B13: Structural primary balance ('+' means 'surplus') | C13: 0.386237 | D13: -0.5577395
B14: One-off and other temporary measures | C14: -0.026727 | D14: -0.0254775 | E14: -0.6901042 | F14: 0 | G14: 0 | H14: 0 | I14: 0 | J14: 0 | K14: 0 | L14: 0 | M14: 0 | N14: 0 | O14: 0 | P14: 0 | Q14: 0 | R14: 0 | S14: 0 | T14: 0 | U14: 0
B15: Stock-flow adjustments (without exchange rate effect) | C15: -0.0919396 | D15: 1.579996 | E15: 2.014675 | F15: 0 | G15: 0 | H15: 0 | I15: 0 | J15: 0 | K15: 0 | L15: 0 | M15: 0 | N15: 0 | O15: 0 | P15: 0 | Q15: 0 | R15: 0 | S15: 0 | T15: 0 | U15: 0
B16: Stock-flow adjustment (total) | C16: -0.091941 | D16: 1.579997 | E16: 2.014677 | F16: -2.05e-06 | G16: 0 | H16: 0 | I16: 0 | J16: 0 | K16: 0 | L16: 0 | M16: 0 | N16: 0 | O16: 0 | P16: 0 | Q16: 0 | R16: 0 | S16: 0 | T16: 0 | U16: 0
B17: Subject to an excessive deficit procedure (EDP) (0-no/1-yes) | C17: 0 | D17: 0
B19: Cost of ageing and selected public revenue (based on the Commission-Council 2024 Ageing Report ("AR 2024"))
B20: Total ageing cost (net of taxes on pensions) | C20: =(C21+C22+C23+C24-C25) -> 18.2 | D20: =(D21+D22+D23+D24-D25) -> 18.1 | E20: =(E21+E22+E23+E24-E25) -> 18.1 | F20: =(F21+F22+F23+F24-F25) -> 18.3 | G20: =(G21+G22+G23+G24-G25) -> 18.4 | H20: =(H21+H22+H23+H24-H25) -> 18.5 | I20: =(I21+I22+I23+I24-I25) -> 18.6 | J20: =(J21+J22+J23+J24-J25) -> 18.9 | ... U20: =(U21+U22+U23+U24-U25) -> 20.2
B21: of which: Public pensions expenditure | C21: 6.8 | D21: 6.8 | E21: 6.9 | F21: 7 | G21: 7.1 | H21: 7.2 | I21: 7.3 | J21: 7.4 | K21: 7.5 | L21: 7.6 | M21: 7.7 | N21: 7.7 | O21: 7.8 | P21: 7.9 | Q21: 7.9 | R21: 7.9 | S21: 8 | T21: 8 | U21: 8
B22: Health care expenditure | C22: 5.8 | D22: 5.8 | E22: 5.8 | F22: 5.9 | G22: 5.9 | H22: 5.9 | I22: 5.9 | J22: 6 | K22: 6 | L22: 6 | M22: 6 | N22: 6.1 | O22: 6.1 | P22: 6.1 | Q22: 6.1 | R22: 6.1 | S22: 6.1 | T22: 6.2 | U22: 6.2
B23: Long-term care expenditure | C23: 3.9 | D23: 3.9 | E23: 3.9 | F23: 4.1 | G23: 4.1 | H23: 4.2 | I23: 4.2 | J23: 4.3 | K23: 4.4 | L23: 4.4 | M23: 4.5 | N23: 4.5 | O23: 4.6 | P23: 4.7 | Q23: 4.7 | R23: 4.8 | S23: 4.8 | T23: 4.9 | U23: 4.9
B24: Education & unemployment benefits expenditure | C24: 4.6 | D24: 4.5 | E24: 4.4 | F24: 4.3 | G24: 4.3 | H24: 4.2 | I24: 4.2 | J24: 4.2 | K24: 4.2 | L24: 4.2 | M24: 4.2 | N24: 4.2 | O24: 4.2 | P24: 4.2 | Q24: 4.2 | R24: 4.2 | S24: 4.2 | T24: 4.2 | U24: 4.2
B25: Taxes on pensions | C25: 2.9 | D25: 2.9 | E25: 2.9 | F25: 3 | G25: 3 | H25: 3 | I25: 3 | J25: 3 | K25: 3 | L25: 3 | M25: 3.1 | N25: 3.1 | O25: 3.1 | P25: 3.1 | Q25: 3.1 | R25: 3.1 | S25: 3.1 | T25: 3.1 | U25: 3.1
B26: Property income | C26: 0.6265708 | D26: 0.6208305 | E26: 0.6150902 | F26: 0.6093498 | G26: 0.6036096 | H26: 0.5978693 | I26: 0.5921289 | J26: 0.5863886 | K26: 0.5806483 | L26: 0.574908 | M26: 0.5691677 | N26: 0.5634273 | O26: 0.557687 | P26: 0.5519468 | Q26: 0.5462064 | R26: 0.5404661 | S26: 0.5347258 | T26: 0.5289855 | U26: 0.5232452
B28: Real GDP growth assumptions (based on AF 2025 T+10 projections and AR 2024 projections)
B29: Actual GDP
B30: Growth rate | C30: 1.081005 | D30: 1.69667 | E30: 1.273747 | F30: 1.581865 | G30: 1.521399 | H30: 1.41368 | I30: 1.393831 | J30: 1.069126 | K30: 1.03431 | L30: 1.012531 | M30: 1.026592 | N30: 1.054951 | O30: 1.133299 | P30: 1.211654 | Q30: 1.290001 | R30: 1.450001 | S30: 1.609996 | T30: 1.659995 | U30: 1.710004
B31: Level (EUR bn) | C31: 915.5005
B32: Potential GDP
B33: Growth rate | C33: 1.824226 | D33: 1.656294 | E33: 1.426257 | F33: 1.292883 | G33: 1.24374 | H33: 1.137065 | I33: 1.118027 | J33: 1.069128 | K33: 1.03431 | L33: 1.01253 | M33: 1.026594 | N33: 1.054945 | O33: 1.133297 | P33: 1.211648 | Q33: 1.29 | R33: 1.45 | S33: 1.61 | T33: 1.66 | U33: 1.71
B34: Level (EUR bn) | C34: 924.6414
B36: Interest rates (AF 2025, %)
B37: Nominal implicit interest rate on debt | C37: 1.646586 | D37: 1.72 | E37: 1.732298 | F37: 1.826186
B38: Short-term nominal interest rate | C38: 3.570833 | D38: 2.172583 | E38: 1.91225 | F38: 2.024375
B39: Long-term nominal interest rate | C39: 2.6205 | D39: 2.78965 | E39: 2.894953 | F39: 3.081676
D40: Bloomberg data, country-specific forward market rates.
B41: Inflation (AF 2025, %)
B42: GDP deflator (national currency) | C42: 5.744214 | D42: 3.154387 | E42: 3.262934 | F42: 2.103313
B44: Net primary expenditure growth (AF 2025, %)
B45: Net primary expenditure growth | C45: 6.2115937 | D45: 7.2645885
B47: Additional parameters
E48: Sources
B49: Fiscal multiplier | C49: 0.6
...

Sheet Baseline NFPC
B3: Country | C3: ='Input data'!C3 -> NL
B4: Key years
B5: ='Input data'!B5 -> Last year before the adjustment | C5: =+'Input data'!C5 -> 2025
B6: Last year of adjustment | C6: =+C5+'Criteria results'!$F$5 -> 2029
B9: Key assumptions
C10: ='Input data'!$C$5-1 -> 2024 | D10: =C10+1 -> 2025 | E10: =D10+1 -> 2026 | F10: =E10+1 -> 2027 | G10: =F10+1 -> 2028 | H10: =G10+1 -> 2029 | I10: =H10+1 -> 2030 | J10: =I10+1 -> 2031 | K10: =J10+1 -> 2032 | ... U10: =T10+1 -> 2042
B11: Fiscal assumptions (% of GDP)
B12: Structural primary balance ('+' means 'surplus') | C12: ='Input data'!C13 -> 0.386237 | D12: ='Input data'!D13 -> -0.5577395 | E12: =D12 -> -0.5577395 | F12: =E12 -> -0.5577395 | G12: =F12 -> -0.5577395 | H12: =G12 -> -0.5577395 | I12: =H12 -> -0.5577395 | J12: =I12 -> -0.5577395 | K12: =J12 -> -0.5577395 | L12: =K12 -> -0.5577395 | ... U12: =T12 -> -0.5577395
B13: One-off and other temporary measures | C13: ='Input data'!C14 -> -0.026727 | D13: ='Input data'!D14 -> -0.0254775 | E13: ='Input data'!E14 -> -0.6901042 | F13: ='Input data'!F14 -> 0 | G13: ='Input data'!G14 -> 0 | H13: ='Input data'!H14 -> 0 | I13: ='Input data'!I14 -> 0 | J13: ='Input data'!J14 -> 0 | ... U13: ='Input data'!U14 -> 0
B14: Stock flow adjustments (without exchange rate effect) | C14: ='Input data'!C15 -> -0.0919396 | D14: ='Input data'!D15 -> 1.579996 | E14: ='Input data'!E15 -> 2.014675 | F14: ='Input data'!F15 -> 0 | G14: ='Input data'!G15 -> 0 | H14: ='Input data'!H15 -> 0 | I14: ='Input data'!I15 -> 0 | J14: ='Input data'!J15 -> 0 | ... U14: ='Input data'!U15 -> 0
B16: ='Input data'!B19 -> Cost of ageing and selected public revenue (based on the Commission-Council 2024 Ageing Report ("AR 2024"))
B17: Total ageing cost (net of taxes on pensions) | C17: ='Input data'!C20 -> 18.2 | D17: ='Input data'!D20 -> 18.1 | E17: ='Input data'!E20 -> 18.1 | F17: ='Input data'!F20 -> 18.3 | G17: ='Input data'!G20 -> 18.4 | H17: ='Input data'!H20 -> 18.5 | I17: ='Input data'!I20 -> 18.6 | J17: ='Input data'!J20 -> 18.9 | ... U17: ='Input data'!U20 -> 20.2
B18: ='Input data'!B26 -> Property income | C18: ='Input data'!C26 -> 0.6265708 | D18: ='Input data'!D26 -> 0.6208305 | E18: ='Input data'!E26 -> 0.6150902 | F18: ='Input data'!F26 -> 0.6093498 | G18: ='Input data'!G26 -> 0.6036096 | H18: ='Input data'!H26 -> 0.5978693 | I18: ='Input data'!I26 -> 0.5921289 | ... U18: ='Input data'!U26 -> 0.5232452
B20: GDP growth assumptions
B21: Actual GDP (real)
B22: Level | C22: ='Input data'!C31 -> 915.5005 | D22: =C22*(D23/100+1) -> 931.03352 | E22: =D22*(E23/100+1) -> 942.89253 | F22: =E22*(F23/100+1) -> 957.80782 | G22: =F22*(G23/100+1) -> 972.3799 | H22: =G22*(H23/100+1) -> 986.12624 | I22: =H22*(I23/100+1) -> 999.87117 | J22: =I22*(J23/100+1) -> 1010.5611 | K22: =J22*(K23/100+1) -> 1021.0134 | ... U22: =T22*(U23/100+1) -> 1163.5727
B23: Growth rate | C23: =+'Input data'!C30 -> 1.081005 | D23: =+'Input data'!D30 -> 1.69667 | E23: =+'Input data'!E30 -> 1.273747 | F23: =+'Input data'!F30 -> 1.581865 | G23: =+'Input data'!G30 -> 1.521399 | H23: =+'Input data'!H30 -> 1.41368 | I23: =+'Input data'!I30 -> 1.393831 | J23: =+'Input data'!J30 -> 1.069126 | ... U23: =+'Input data'!U30 -> 1.710004
B25: Potential GDP (real)
B26: Level | C26: ='Input data'!C34 -> 924.6414 | D26: =+C26*(1+'Input data'!D33/100) -> 939.95618 | E26: =+D26*(1+'Input data'!E33/100) -> 953.36237 | F26: =+E26*(1+'Input data'!F33/100) -> 965.68823 | G26: =+F26*(1+'Input data'!G33/100) -> 977.69888 | H26: =+G26*(1+'Input data'!H33/100) -> 988.81595 | I26: =+H26*(1+'Input data'!I33/100) -> 999.87118 | J26: =+I26*(1+'Input data'!J33/100) -> 1010.5611 | K26: =+J26*(1+'Input data'!K33/100) -> 1021.0134 | ... U26: =+T26*(1+'Input data'!U33/100) -> 1163.5726
B28: Output gap
B29: Output gap | C29: =100*(C22/C26-1) -> -0.98858866 | D29: =100*(D22/D26-1) -> -0.94926316 | E29: =100*(E22/E26-1) -> -1.0982012 | F29: =100*(F22/F26-1) -> -0.8160408 | G29: =100*(G22/G26-1) -> -0.54403071 | H29: =100*(H22/H26-1) -> -0.27201359 | I29: =100*(I22/I26-1) -> -9.9246313e-07 | J29: =100*(J22/J26-1) -> -2.9713068e-06 | ... U29: =100*(U22/U26-1) -> 6.9328616e-06
B31: Actual GDP (nominal, national currency)
B32: Growth rate | C32: =100*((1+C23/100)*(1+C41/100)-1) -> 6.8873142 | D32: =100*((1+D23/100)*(1+D41/100)-1) -> 4.9045765 | E32: =100*((1+E23/100)*(1+E41/100)-1) -> 4.5782425 | F32: =100*((1+F23/100)*(1+F41/100)-1) -> 3.7184496 | G32: =100*((1+G23/100)*(1+G41/100)-1) -> 3.6791337 | H32: =100*((1+H23/100)*(1+H41/100)-1) -> 3.5915233 | I32: =100*((1+I23/100)*(1+I41/100)-1) -> 3.5936418 | J32: =100*((1+J23/100)*(1+J41/100)-1) -> 3.2842141 | ... U32: =100*((1+U23/100)*(1+U41/100)-1) -> 3.9293163
B34: Interest rate
B35: Nominal implicit interest rate on debt | C35: ='Input data'!C37 -> 1.646586 | D35: ='Input data'!D37 -> 1.72 | E35: ='Input data'!E37 -> 1.732298 | F35: ='Input data'!F37 -> 1.826186 | G35: =G96 -> 1.9680346 | H35: =H96 -> 2.1106557 | I35: =I96 -> 2.2537821 | J35: =J96 -> 2.3971883 | K35: =K96 -> 2.5478088 | L35: =L96 -> 2.7018156 | M35: =M96 -> 2.8561372 | N35: =N96 -> 3.0100965 | ... U35: =U96 -> 3.5677364
B36: Long-term interest rate | C36: ='Input data'!C39 -> 2.6205 | D36: ='Input data'!D39 -> 2.78965 | E36: ='Input data'!E39 -> 2.894953 | F36: ='Input data'!F39 -> 3.081676 | G36: =F36+($N$36-$F$36)/($N$10-$F$10) -> 3.188669 | H36: =G36+($N$36-$F$36)/($N$10-$F$10) -> 3.295662 | I36: =H36+($N$36-$F$36)/($N$10-$F$10) -> 3.402655 | J36: =I36+($N$36-$F$36)/($N$10-$F$10) -> 3.509648 | K36: =J36+($N$36-$F$36)/($N$10-$F$10) -> 3.616641 | L36: =K36+($N$36-$F$36)/($N$10-$F$10) -> 3.723634 | M36: =L36+($N$36-$F$36)/($N$10-$F$10) -> 3.830627 | N36: ='Input data'!$C$52 -> 3.93762 | O36: =$N$36+('Input data'!$C$54-'Input data'!$C$52)/20*(O$10-$N$10) -> 3.940739 | P36: =$N$36+('Input data'!$C$54-'Input data'!$C$52)/20*(P$10-$N$10) -> 3.943858 | Q36: =$N$36+('Input data'!$C$54-'Input data'!$C$52)/20*(Q$10-$N$10) -> 3.946977 | R36: =$N$36+('Input data'!$C$54-'Input data'!$C$52)/20*(R$10-$N$10) -> 3.950096 | S36: =$N$36+('Input data'!$C$54-'Input data'!$C$52)/20*(S$10-$N$10) -> 3.953215 | T36: =$N$36+('Input data'!$C$54-'Input data'!$C$52)/20*(T$10-$N$10) -> 3.956334 | U36: =$N$36+('Input data'!$C$54-'Input data'!$C$52)/20*(U$10-$N$10) -> 3.959453
B37: Short-term interest rate | C37: ='Input data'!C$38 -> 3.570833 | D37: ='Input data'!D$38 -> 2.172583 | E37: ='Input data'!E$38 -> 1.91225 | F37: ='Input data'!F$38 -> 2.024375 | G37: =F37+($N$37-$F$37)/($N$10-$F$10) -> 2.1784319 | H37: =G37+($N$37-$F$37)/($N$10-$F$10) -> 2.3324888 | I37: =H37+($N$37-$F$37)/($N$10-$F$10) -> 2.4865456 | J37: =I37+($N$37-$F$37)/($N$10-$F$10) -> 2.6406025 | K37: =J37+($N$37-$F$37)/($N$10-$F$10) -> 2.7946594 | L37: =K37+($N$37-$F$37)/($N$10-$F$10) -> 2.9487163 | M37: =L37+($N$37-$F$37)/($N$10-$F$10) -> 3.1027731 | N37: ='Input data'!$C$53 -> 3.25683 | O37: =$N$37+('Input data'!$C$55-'Input data'!$C$53)/20*(O$10-$N$10) -> 3.1939885 | P37: =$N$37+('Input data'!$C$55-'Input data'!$C$53)/20*(P$10-$N$10) -> 3.131147 | Q37: =$N$37+('Input data'!$C$55-'Input data'!$C$53)/20*(Q$10-$N$10) -> 3.0683055 | R37: =$N$37+('Input data'!$C$55-'Input data'!$C$53)/20*(R$10-$N$10) -> 3.005464 | S37: =$N$37+('Input data'!$C$55-'Input data'!$C$53)/20*(S$10-$N$10) -> 2.9426225 | T37: =$N$37+('Input data'!$C$55-'Input data'!$C$53)/20*(T$10-$N$10) -> 2.879781 | U37: =$N$37+('Input data'!$C$55-'Input data'!$C$53)/20*(U$10-$N$10) -> 2.8169395
B38: Share of long-term debt that matures every year | C38: 0.08837902 | D38: 0.05460046 | E38: 0.05795577 | F38: =IF(OR($C$3="EL",$C$3="CY",$C$3="IE",$C$3="PT"),VLOOKUP($C$3,$B$110:$R$114,MATCH(F$10,$B$110:$R$110,0),0),$E$38+('Input data'!$C$59-$E$38)/($N$10-$E$10)*(F10-$E$10)) -> 0.061311081 | G38: =IF(OR($C$3="EL",$C$3="CY",$C$3="IE",$C$3="PT"),VLOOKUP($C$3,$B$110:$R$114,MATCH(G$10,$B$110:$R$110,0),0),$E$38+('Input data'!$C$59-$E$38)/($N$10-$E$10)*(G10-$E$10)) -> 0.064666392 | H38: =IF(OR($C$3="EL",$C$3="CY",$C$3="IE",$C$3="PT"),VLOOKUP($C$3,$B$110:$R$114,MATCH(H$10,$B$110:$R$110,0),0),$E$38+('Input data'!$C$59-$E$38)/($N$10-$E$10)*(H10-$E$10)) -> 0.068021703 | I38: =IF(OR($C$3="EL",$C$3="CY",$C$3="IE",$C$3="PT"),VLOOKUP($C$3,$B$110:$R$114,MATCH(I$10,$B$110:$R$110,0),0),$E$38+('Input data'!$C$59-$E$38)/($N$10-$E$10)*(I10-$E$10)) -> 0.071377014 | J38: =IF(OR($C$3="EL",$C$3="CY",$C$3="IE",$C$3="PT"),VLOOKUP($C$3,$B$110:$R$114,MATCH(J$10,$B$110:$R$110,0),0),$E$38+('Input data'!$C$59-$E$38)/($N$10-$E$10)*(J10-$E$10)) -> 0.074732326 | K38: =IF(OR($C$3="EL",$C$3="CY",$C$3="IE",$C$3="PT"),VLOOKUP($C$3,$B$110:$R$114,MATCH(K$10,$B$110:$R$110,0),0),$E$38+('Input data'!$C$59-$E$38)/($N$10-$E$10)*(K10-$E$10)) -> 0.078087637 | L38: =IF(OR($C$3="EL",$C$3="CY",$C$3="IE",$C$3="PT"),VLOOKUP($C$3,$B$110:$R$114,MATCH(L$10,$B$110:$R$110,0),0),$E$38+('Input data'!$C$59-$E$38)/($N$10-$E$10)*(L10-$E$10)) -> 0.081442948 | M38: =IF(OR($C$3="EL",$C$3="CY",$C$3="IE",$C$3="PT"),VLOOKUP($C$3,$B$110:$R$114,MATCH(M$10,$B$110:$R$110,0),0),$E$38+('Input data'!$C$59-$E$38)/($N$10-$E$10)*(M10-$E$10)) -> 0.084798259 | N38: =IF(OR($C$3="EL",$C$3="CY",$C$3="IE",$C$3="PT"),VLOOKUP($C$3,$B$110:$R$114,MATCH(N$10,$B$110:$R$110,0),0),'Input data'!$C$59) -> 0.08815357 | O38: =IF(OR($C$3="EL",$C$3="CY",$C$3="IE",$C$3="PT"),VLOOKUP($C$3,$B$110:$R$114,MATCH(O$10,$B$110:$R$110,0),0),'Input data'!$C$59) -> 0.08815357 | P38: =IF(OR($C$3="EL",$C$3="CY",$C$3="IE",$C$3="PT"),VLOOKUP($C$3,$B$110:$R$114,MATCH(P$10,$B$110:$R$110,0),0),'Input data'!$C$59) -> 0.08815357 | Q38: =IF(OR($C$3="EL",$C$3="CY",$C$3="IE",$C$3="PT"),VLOOKUP($C$3,$B$110:$R$114,MATCH(Q$10,$B$110:$R$110,0),0),'Input data'!$C$59) -> 0.08815357 | R38: =IF(OR($C$3="EL",$C$3="CY",$C$3="IE",$C$3="PT"),VLOOKUP($C$3,$B$110:$R$114,MATCH(R$10,$B$110:$R$110,0),0),'Input data'!$C$59) -> 0.08815357 | S38: =IF(OR($C$3="EL",$C$3="CY",$C$3="IE",$C$3="PT"),VLOOKUP($C$3,$B$110:$U$114,MATCH(S$10,$B$110:$U$110,0),0),'Input data'!$C$59) -> 0.08815357 | T38: =IF(OR($C$3="EL",$C$3="CY",$C$3="IE",$C$3="PT"),VLOOKUP($C$3,$B$110:$U$114,MATCH(T$10,$B$110:$U$110,0),0),'Input data'!$C$59) -> 0.08815357 | U38: =IF(OR($C$3="EL",$C$3="CY",$C$3="IE",$C$3="PT"),VLOOKUP($C$3,$B$110:$U$114,MATCH(U$10,$B$110:$U$110,0),0),'Input data'!$C$59) -> 0.08815357
B40: Inflation and exchange rate
B41: GDP deflator (national currency) | C41: ='Input data'!C42 -> 5.744214 | D41: ='Input data'!D42 -> 3.154387 | E41: ='Input data'!E42 -> 3.262934 | F41: ='Input data'!F42 -> 2.103313 | G41: =$F$41+($N$41-$F$41)/($N$10-$F$10)*(G10-$F$10) -> 2.1253989 | H41: =$F$41+($N$41-$F$41)/($N$10-$F$10)*(H10-$F$10) -> 2.1474847 | I41: =$F$41+($N$41-$F$41)/($N$10-$F$10)*(I10-$F$10) -> 2.1695706 | J41: =$F$41+($N$41-$F$41)/($N$10-$F$10)*(J10-$F$10) -> 2.1916565 | K41: =$F$41+($N$41-$F$41)/($N$10-$F$10)*(K10-$F$10) -> 2.2137424 | L41: =$F$41+($N$41-$F$41)/($N$10-$F$10)*(L10-$F$10) -> 2.2358282 | M41: =$F$41+($N$41-$F$41)/($N$10-$F$10)*(M10-$F$10) -> 2.2579141 | N41: ='Input data'!$C$61 -> 2.28 | O41: =$N$41+('Input data'!$C$62-'Input data'!$C$61)/20*(O$10-$N$10) -> 2.266 | P41: =$N$41+('Input data'!$C$62-'Input data'!$C$61)/20*(P$10-$N$10) -> 2.252 | Q41: =$N$41+('Input data'!$C$62-'Input data'!$C$61)/20*(Q$10-$N$10) -> 2.238 | R41: =$N$41+('Input data'!$C$62-'Input data'!$C$61)/20*(R$10-$N$10) -> 2.224 | S41: =$N$41+('Input data'!$C$62-'Input data'!$C$61)/20*(S$10-$N$10) -> 2.21 | T41: =$N$41+('Input data'!$C$62-'Input data'!$C$61)/20*(T$10-$N$10) -> 2.196 | U41: =$N$41+('Input data'!$C$62-'Input data'!$C$61)/20*(U$10-$N$10) -> 2.182
B42: Exchange rate composite change (weighted by share of debt in each currency) | C42: 0.9999999 | D42: 1 | E42: 1 | F42: 0.9999999 | G42: 1 | H42: 1 | I42: 1 | J42: 1 | K42: 1 | L42: 1 | M42: 1 | N42: 1 | O42: 1 | P42: 1 | Q42: 1 | R42: 1 | S42: 1 | T42: 1 | U42: 1
B44: Intermediate calculations (growth rate equation)
B46: Fiscal multiplier | C46: ='Input data'!C49 -> 0.6
B47: Budget balance semi-elasticity | C47: ='Input data'!C50 -> 0.605
B49: Auxiliary variable to control the closure of the output gap | C49: 0 | D49: =IF(AND(ABS((D12-C12)-('Input data'!D13-'Input data'!C13))>0.0001,ABS(D12-C12)>0.0001,D$10>$C$5),4,IF(C49=4,3,IF(C49=3,2,IF(C49=2,1,0)))) -> 0 | E49: =IF(AND(ABS(E12-D12)>0.0001,E$10>$C$5),4,IF(D49=4,3,IF(D49=3,2,IF(D49=2,1,0)))) -> 0 | F49: =IF(AND(ABS(F12-E12)>0.0001,F$10>$C$5),4,IF(E49=4,3,IF(E49=3,2,IF(E49=2,1,0)))) -> 0 | G49: =IF(AND(ABS(G12-F12)>0.0001,G$10>$C$5),4,IF(F49=4,3,IF(F49=3,2,IF(F49=2,1,0)))) -> 0 | H49: =IF(AND(ABS(H12-G12)>0.0001,H$10>$C$5),4,IF(G49=4,3,IF(G49=3,2,IF(G49=2,1,0)))) -> 0 | I49: =IF(AND(ABS(I12-H12)>0.0001,I$10>$C$5),4,IF(H49=4,3,IF(H49=3,2,IF(H49=2,1,0)))) -> 0 | J49: =IF(AND(ABS(J12-I12)>0.0001,J$10>$C$5),4,IF(I49=4,3,IF(I49=3,2,IF(I49=2,1,0)))) -> 0 | K49: =IF(AND(ABS(K12-J12)>0.0001,K$10>$C$5),4,IF(J49=4,3,IF(J49=3,2,IF(J49=2,1,0)))) -> 0 | L49: =IF(AND(ABS(L12-K12)>0.0001,L$10>$C$5),4,IF(K49=4,3,IF(K49=3,2,IF(K49=2,1,0)))) -> 0 | ... U49: =IF(AND(ABS(U12-T12)>0.0001,U$10>$C$5),4,IF(T49=4,3,IF(T49=3,2,IF(T49=2,1,0)))) -> 0
B50: OG intermediate auxiliary value | C50: 0 | D50: =IF(C49=4,2/3*C29,IF(C49=3,1/3*#REF!,0)) -> 0 | E50: =IF(D49=4,2/3*D29,IF(D49=3,1/3*C29,0)) -> 0 | F50: =IF(E49=4,2/3*E29,IF(E49=3,1/3*D29,0)) -> 0 | G50: =IF(F49=4,2/3*F29,IF(F49=3,1/3*E29,0)) -> 0 | H50: =IF(G49=4,2/3*G29,IF(G49=3,1/3*F29,0)) -> 0 | I50: =IF(H49=4,2/3*H29,IF(H49=3,1/3*G29,0)) -> 0 | J50: =IF(I49=4,2/3*I29,IF(I49=3,1/3*H29,0)) -> 0 | K50: =IF(J49=4,2/3*J29,IF(J49=3,1/3*I29,0)) -> 0 | L50: =IF(K49=4,2/3*K29,IF(K49=3,1/3*J29,0)) -> 0 | ... U50: =IF(T49=4,2/3*T29,IF(T49=3,1/3*S29,0)) -> 0
B51: GDP intermediate growth rate - only feedback effect and no closure of the OG | C51: 0 | D51: ='Input data'!D30-$C$46*((D12-C12)-('Input data'!D13-'Input data'!C13)) -> 1.69667 | E51: ='Input data'!E30-$C$46*((E12-D12)-('Input data'!E13-'Input data'!D13)) -> 1.6083907 | F51: ='Input data'!F30-$C$46*((F12-E12)) -> 1.581865 | G51: ='Input data'!G30-$C$46*((G12-F12)) -> 1.521399 | H51: ='Input data'!H30-$C$46*((H12-G12)) -> 1.41368 | I51: ='Input data'!I30-$C$46*((I12-H12)) -> 1.393831 | J51: ='Input data'!J30-$C$46*((J12-I12)) -> 1.069126 | K51: ='Input data'!K30-$C$46*((K12-J12)) -> 1.03431 | L51: ='Input data'!L30-$C$46*((L12-K12)) -> 1.012531 | M51: ='Input data'!M30-$C$46*((M12-L12)) -> 1.026592 | ... U51: ='Input data'!U30-$C$46*((U12-T12)) -> 1.710004
B53: Debt projections
C55: ='Input data'!$C$5-1 -> 2024 | D55: =C55+1 -> 2025 | E55: =D55+1 -> 2026 | F55: =E55+1 -> 2027 | G55: =F55+1 -> 2028 | H55: =G55+1 -> 2029 | I55: =H55+1 -> 2030 | J55: =I55+1 -> 2031 | K55: =J55+1 -> 2032 | ... U55: =T55+1 -> 2042
B56: Gross debt | C56: =+'Input data'!C12 -> 43.74815 | D56: =+C56+D57 -> 45.15761 | E56: =+D56+E57 -> 47.861385 | F56: =+E56+F57 -> 48.251114 | G56: =+F56+G57 -> 48.658886 | H56: =+G56+H57 -> 49.108564 | I56: =+H56+I57 -> 49.559845 | J56: =+I56+J57 -> 50.526398 | K56: =+J56+K57 -> 51.770518 | ... U56: =+T56+U57 -> 72.409633
...

Sheet Adjustment scenario
B3: Country | C3: ='Input data'!C3 -> NL
B4: Key years
B5: ='Input data'!B5 -> Last year before the adjustment | C5: =+'Input data'!C5 -> 2025
B6: Last year of adjustment | C6: =+C5+'Criteria results'!$F$5 -> 2029
B7: Last year of no-fiscal-policy-change projections | C7: =C5+'Criteria results'!$F$5+10 -> 2039
B9: Key assumptions
C10: ='Input data'!$C$5-1 -> 2024 | D10: =C10+1 -> 2025 | E10: =D10+1 -> 2026 | F10: =E10+1 -> 2027 | G10: =F10+1 -> 2028 | H10: =G10+1 -> 2029 | I10: =H10+1 -> 2030 | J10: =I10+1 -> 2031 | K10: =J10+1 -> 2032 | ... U10: =T10+1 -> 2042
B11: Fiscal assumptions (% of GDP)
B12: Structural primary balance ('+' means 'surplus') | C12: ='Input data'!C13 -> 0.386237 | D12: ='Input data'!D13 -> -0.5577395 | E12: =IF(E10<=$C$6, IF(AND(D78<=-1.55,'Criteria results'!$F$5=4,'Criteria results'!$F$6<0.4),D12+0.4, IF(AND(D78<=-1.55,'Criteria results'!$F$5=7,'Criteria results'!$F$6<0.25),D12+0.25, D12+'Criteria results'!$F$6)),D12) -> -0.5577395 | F12: =IF(F10<=$C$6, IF(AND(E78<=-1.55,'Criteria results'!$F$5=4,'Criteria results'!$F$6<0.4),E12+0.4, IF(AND(E78<=-1.55,'Criteria results'!$F$5=7,'Criteria results'!$F$6<0.25),E12+0.25, E12+'Criteria results'!$F$6)),E12) -> -0.5577395 | G12: =IF(G10<=$C$6, IF(AND(F78<=-1.55,'Criteria results'!$F$5=4,'Criteria results'!$F$6<0.4),F12+0.4, IF(AND(F78<=-1.55,'Criteria results'!$F$5=7,'Criteria results'!$F$6<0.25),F12+0.25, F12+'Criteria results'!$F$6)),F12) -> -0.5577395 | H12: =IF(H10<=$C$6, IF(AND(G78<=-1.55,'Criteria results'!$F$5=4,'Criteria results'!$F$6<0.4),G12+0.4, IF(AND(G78<=-1.55,'Criteria results'!$F$5=7,'Criteria results'!$F$6<0.25),G12+0.25, G12+'Criteria results'!$F$6)),G12) -> -0.5577395 | I12: =IF(I10<=$C$6, IF(AND(H78<=-1.55,'Criteria results'!$F$5=4,'Criteria results'!$F$6<0.4),H12+0.4, IF(AND(H78<=-1.55,'Criteria results'!$F$5=7,'Criteria results'!$F$6<0.25),H12+0.25, H12+'Criteria results'!$F$6)),H12) -> -0.5577395 | J12: =IF(J10<=$C$6, IF(AND(I78<=-1.55,'Criteria results'!$F$5=4,'Criteria results'!$F$6<0.4),I12+0.4, IF(AND(I78<=-1.55,'Criteria results'!$F$5=7,'Criteria results'!$F$6<0.25),I12+0.25, I12+'Criteria results'!$F$6)),I12) -> -0.5577395 | K12: =IF(K10<=$C$6, IF(AND(J78<=-1.55,'Criteria results'!$F$5=4,'Criteria results'!$F$6<0.4),J12+0.4, IF(AND(J78<=-1.55,'Criteria results'!$F$5=7,'Criteria results'!$F$6<0.25),J12+0.25, J12+'Criteria results'!$F$6)),J12) -> -0.5577395 | L12: =K12 -> -0.5577395 | M12: =L12 -> -0.5577395 | N12: =M12 -> -0.5577395 | O12: =N12 -> -0.5577395 | P12: =O12 -> -0.5577395 | Q12: =P12 -> -0.5577395 | R12: =Q12 -> -0.5577395 | S12: =R12 -> -0.5577395 | ... U12: =T12 -> -0.5577395
B13: Annual change in SPB | E13: =E12-D12 -> 0 | F13: =F12-E12 -> 0 | G13: =G12-F12 -> 0 | H13: =H12-G12 -> 0 | I13: =I12-H12 -> 0 | J13: =J12-I12 -> 0 | K13: =K12-J12 -> 0 | L13: =L12-K12 -> 0 | ... U13: =U12-T12 -> 0
B14: One-off and other temporary measures | C14: ='Input data'!C14 -> -0.026727 | D14: ='Input data'!D14 -> -0.0254775 | E14: ='Input data'!E14 -> -0.6901042 | F14: ='Input data'!F14 -> 0 | G14: ='Input data'!G14 -> 0 | H14: ='Input data'!H14 -> 0 | I14: ='Input data'!I14 -> 0 | J14: ='Input data'!J14 -> 0 | ... U14: ='Input data'!U14 -> 0
B15: Stock flow adjustments (without exchange rate effect) | C15: ='Input data'!C15 -> -0.0919396 | D15: ='Input data'!D15 -> 1.579996 | E15: ='Input data'!E15 -> 2.014675 | F15: ='Input data'!F15 -> 0 | G15: ='Input data'!G15 -> 0 | H15: ='Input data'!H15 -> 0 | I15: ='Input data'!I15 -> 0 | J15: ='Input data'!J15 -> 0 | ... U15: ='Input data'!U15 -> 0
B17: ='Input data'!B19 -> Cost of ageing and selected public revenue (based on the Commission-Council 2024 Ageing Report ("AR 2024"))
B18: Total ageing cost (net of taxes on pensions) | C18: ='Input data'!C20 -> 18.2 | D18: ='Input data'!D20 -> 18.1 | E18: ='Input data'!E20 -> 18.1 | F18: ='Input data'!F20 -> 18.3 | G18: ='Input data'!G20 -> 18.4 | H18: ='Input data'!H20 -> 18.5 | I18: ='Input data'!I20 -> 18.6 | J18: ='Input data'!J20 -> 18.9 | ... U18: ='Input data'!U20 -> 20.2
B19: Property income | C19: ='Input data'!C26 -> 0.6265708 | D19: ='Input data'!D26 -> 0.6208305 | E19: ='Input data'!E26 -> 0.6150902 | F19: ='Input data'!F26 -> 0.6093498 | G19: ='Input data'!G26 -> 0.6036096 | H19: ='Input data'!H26 -> 0.5978693 | I19: ='Input data'!I26 -> 0.5921289 | J19: ='Input data'!J26 -> 0.5863886 | ... U19: ='Input data'!U26 -> 0.5232452
B21: GDP growth assumptions
B22: Actual GDP (real)
B23: Level | C23: ='Baseline NFPC'!C22 -> 915.5005 | D23: ='Baseline NFPC'!D22 -> 931.03352 | E23: =IF(AND(E50>1,D50>1), E27*(1+('Baseline NFPC'!E$29+E51)/100)-D23*$C$47*(E12-D12)/100, IF(E50=1,E27,D23*(1+E52/100))) -> 942.89253 | F23: =IF(AND(F50>1,E50>1), F27*(1+('Baseline NFPC'!F$29+F51)/100)-E23*$C$47*(F12-E12)/100, IF(F50=1,F27,E23*(1+F52/100))) -> 957.80782 | G23: =IF(AND(G50>1,F50>1), G27*(1+G51/100)-F23*$C$47*(G12-F12)/100, IF(G50=1,G27,F23*(1+G52/100))) -> 972.3799 | H23: =IF(AND(H50>1,G50>1), H27*(1+H51/100)-G23*$C$47*(H12-G12)/100, IF(H50=1,H27,G23*(1+H52/100))) -> 986.12624 | I23: =IF(AND(I50>1,H50>1), I27*(1+I51/100)-H23*$C$47*(I12-H12)/100, IF(I50=1,I27,H23*(1+I52/100))) -> 999.87117 | J23: =IF(AND(J50>1,I50>1), J27*(1+J51/100)-I23*$C$47*(J12-I12)/100, IF(J50=1,J27,I23*(1+J52/100))) -> 1010.5611 | K23: =IF(AND(K50>1,J50>1), K27*(1+K51/100)-J23*$C$47*(K12-J12)/100, IF(K50=1,K27,J23*(1+K52/100))) -> 1021.0134 | L23: =IF(AND(L50>1,K50>1), L27*(1+L51/100)-K23*$C$47*(L12-K12)/100, IF(L50=1,L27,K23*(1+L52/100))) -> 1031.3515 | M23: =IF(AND(M50>1,L50>1), M27*(1+M51/100)-L23*$C$47*(M12-L12)/100, IF(M50=1,M27,L23*(1+M52/100))) -> 1041.9392 | N23: =IF(AND(N50>1,M50>1), N27*(1+N51/100)-M23*$C$47*(N12-M12)/100, IF(N50=1,N27,M23*(1+N52/100))) -> 1052.9312 | ... U23: =IF(AND(U50>1,T50>1), U27*(1+U51/100)-T23*$C$47*(U12-T12)/100, IF(U50=1,U27,T23*(1+U52/100))) -> 1163.5727
B24: Growth rate | C24: ='Baseline NFPC'!C23 -> 1.081005 | D24: ='Baseline NFPC'!D23 -> 1.69667 | E24: =100*(E23/D23-1) -> 1.273747 | F24: =100*(F23/E23-1) -> 1.581865 | G24: =100*(G23/F23-1) -> 1.521399 | H24: =100*(H23/G23-1) -> 1.41368 | I24: =100*(I23/H23-1) -> 1.393831 | J24: =100*(J23/I23-1) -> 1.069126 | K24: =100*(K23/J23-1) -> 1.03431 | L24: =100*(L23/K23-1) -> 1.012531 | ... U24: =100*(U23/T23-1) -> 1.710004
B26: Potential GDP (real)
B27: Level | C27: ='Input data'!C34 -> 924.6414 | D27: =+C27*(1+'Input data'!D33/100) -> 939.95618 | E27: =+D27*(1+'Input data'!E33/100) -> 953.36237 | F27: =+E27*(1+'Input data'!F33/100) -> 965.68823 | G27: =+F27*(1+'Input data'!G33/100) -> 977.69888 | H27: =+G27*(1+'Input data'!H33/100) -> 988.81595 | I27: =+H27*(1+'Input data'!I33/100) -> 999.87118 | J27: =+I27*(1+'Input data'!J33/100) -> 1010.5611 | K27: =+J27*(1+'Input data'!K33/100) -> 1021.0134 | ... U27: =+T27*(1+'Input data'!U33/100) -> 1163.5726
B29: Output gap
B30: Output gap | C30: =100*(C23/C27-1) -> -0.98858866 | D30: =100*(D23/D27-1) -> -0.94926316 | E30: =100*(E23/E27-1) -> -1.0982012 | F30: =100*(F23/F27-1) -> -0.8160408 | G30: =100*(G23/G27-1) -> -0.54403071 | H30: =100*(H23/H27-1) -> -0.27201359 | I30: =100*(I23/I27-1) -> -9.9246313e-07 | J30: =100*(J23/J27-1) -> -2.9713068e-06 | ... U30: =100*(U23/U27-1) -> 6.9328616e-06
B32: Actual GDP (nominal, national currency)
B33: Growth rate | C33: =100*((1+C24/100)*(1+C42/100)-1) -> 6.8873142 | D33: =100*((1+D24/100)*(1+D42/100)-1) -> 4.9045765 | E33: =100*((1+E24/100)*(1+E42/100)-1) -> 4.5782425 | F33: =100*((1+F24/100)*(1+F42/100)-1) -> 3.7184496 | G33: =100*((1+G24/100)*(1+G42/100)-1) -> 3.6791337 | H33: =100*((1+H24/100)*(1+H42/100)-1) -> 3.5915233 | I33: =100*((1+I24/100)*(1+I42/100)-1) -> 3.5936418 | J33: =100*((1+J24/100)*(1+J42/100)-1) -> 3.2842141 | ... U33: =100*((1+U24/100)*(1+U42/100)-1) -> 3.9293163
B35: Interest rates
B36: Nominal implicit interest rate on debt | C36: ='Input data'!C37 -> 1.646586 | D36: ='Input data'!D37 -> 1.72 | E36: ='Input data'!E37 -> 1.732298 | F36: =F99 -> 1.8261287 | G36: =G99 -> 1.9630297 | H36: =H99 -> 2.0990021 | I36: =I99 -> 2.234119 | J36: =J99 -> 2.3707683 | K36: =K99 -> 2.5163135 | L36: =L99 -> 2.6668445 | M36: =M99 -> 2.8190428 | ... U36: =U99 -> 3.5460259
B37: Long-term interest rate | C37: ='Input data'!C$39 -> 2.6205 | D37: ='Input data'!D$39 -> 2.78965 | E37: ='Input data'!E$39 -> 2.894953 | F37: ='Input data'!F$39 -> 3.081676 | G37: ='Baseline NFPC'!G36 -> 3.188669 | H37: ='Baseline NFPC'!H36 -> 3.295662 | I37: ='Baseline NFPC'!I36 -> 3.402655 | J37: ='Baseline NFPC'!J36 -> 3.509648 | K37: ='Baseline NFPC'!K36 -> 3.616641 | L37: ='Baseline NFPC'!L36 -> 3.723634 | M37: ='Baseline NFPC'!M36 -> 3.830627 | N37: ='Baseline NFPC'!N36 -> 3.93762 | ... U37: ='Baseline NFPC'!U36 -> 3.959453
B38: Short-term interest rate | C38: ='Input data'!C$38 -> 3.570833 | D38: ='Input data'!D$38 -> 2.172583 | E38: ='Input data'!E$38 -> 1.91225 | F38: ='Input data'!F$38 -> 2.024375 | G38: ='Baseline NFPC'!G37 -> 2.1784319 | H38: ='Baseline NFPC'!H37 -> 2.3324888 | I38: ='Baseline NFPC'!I37 -> 2.4865456 | J38: ='Baseline NFPC'!J37 -> 2.6406025 | K38: ='Baseline NFPC'!K37 -> 2.7946594 | L38: ='Baseline NFPC'!L37 -> 2.9487163 | M38: ='Baseline NFPC'!M37 -> 3.1027731 | N38: ='Baseline NFPC'!N37 -> 3.25683 | ... U38: ='Baseline NFPC'!U37 -> 2.8169395
B39: Share of long-term debt that matures every year | C39: ='Baseline NFPC'!C38 -> 0.08837902 | D39: ='Baseline NFPC'!D38 -> 0.05460046 | E39: ='Baseline NFPC'!E38 -> 0.05795577 | F39: ='Baseline NFPC'!F38 -> 0.061311081 | G39: ='Baseline NFPC'!G38 -> 0.064666392 | H39: ='Baseline NFPC'!H38 -> 0.068021703 | I39: ='Baseline NFPC'!I38 -> 0.071377014 | J39: ='Baseline NFPC'!J38 -> 0.074732326 | ... U39: ='Baseline NFPC'!U38 -> 0.08815357
B41: Inflation and exchange rate
B42: GDP deflator (National currency) | C42: ='Input data'!C42 -> 5.744214 | D42: ='Input data'!D42 -> 3.154387 | E42: ='Input data'!E42 -> 3.262934 | F42: ='Input data'!F42 -> 2.103313 | G42: ='Baseline NFPC'!G41 -> 2.1253989 | H42: ='Baseline NFPC'!H41 -> 2.1474847 | I42: ='Baseline NFPC'!I41 -> 2.1695706 | J42: ='Baseline NFPC'!J41 -> 2.1916565 | K42: ='Baseline NFPC'!K41 -> 2.2137424 | L42: ='Baseline NFPC'!L41 -> 2.2358282 | M42: ='Baseline NFPC'!M41 -> 2.2579141 | N42: ='Baseline NFPC'!N41 -> 2.28 | ... U42: ='Baseline NFPC'!U41 -> 2.182
B43: Exchange rate composite change (weighted by share of debt in each currency) | C43: ='Baseline NFPC'!C42 -> 0.9999999 | D43: ='Baseline NFPC'!D42 -> 1 | E43: ='Baseline NFPC'!E42 -> 1 | F43: ='Baseline NFPC'!F42 -> 0.9999999 | G43: ='Baseline NFPC'!G42 -> 1 | H43: ='Baseline NFPC'!H42 -> 1 | I43: ='Baseline NFPC'!I42 -> 1 | J43: ='Baseline NFPC'!J42 -> 1 | ... U43: ='Baseline NFPC'!U42 -> 1
B45: Intermediate calculations (growth rate equation)
B47: Fiscal multiplier | C47: ='Input data'!C49 -> 0.6
B48: Budget balance semi-elasticity | C48: ='Input data'!C50 -> 0.605
B50: Auxiliary variable to control the closure of the output gap | C50: 0 | D50: =IF(AND(ABS((D12-C12)-('Input data'!D13-'Input data'!C13))>0.0001,ABS(D12-C12)>0.0001,D$10>$C$5),4,IF(C50=4,3,IF(C50=3,2,IF(C50=2,1,0)))) -> 0 | E50: =IF(AND(ABS((E12-D12)-('Baseline NFPC'!E12-'Baseline NFPC'!D12))>0.0001,ABS(E12-D12)>0.0001,E$10>$C$5),4,IF(D50=4,3,IF(D50=3,2,IF(D50=2,1,0)))) -> 0 | F50: =IF(AND(ABS((F12-E12)-('Baseline NFPC'!F12-'Baseline NFPC'!E12))>0.0001,ABS(F12-E12)>0.0001,F$10>$C$5),4,IF(E50=4,3,IF(E50=3,2,IF(E50=2,1,0)))) -> 0 | G50: =IF(AND(ABS((G12-F12)-('Baseline NFPC'!G12-'Baseline NFPC'!F12))>0.0001,ABS(G12-F12)>0.0001,G$10>$C$5),4,IF(F50=4,3,IF(F50=3,2,IF(F50=2,1,0)))) -> 0 | H50: =IF(AND(ABS((H12-G12)-('Baseline NFPC'!H12-'Baseline NFPC'!G12))>0.0001,ABS(H12-G12)>0.0001,H$10>$C$5),4,IF(G50=4,3,IF(G50=3,2,IF(G50=2,1,0)))) -> 0 | I50: =IF(AND(ABS((I12-H12)-('Baseline NFPC'!I12-'Baseline NFPC'!H12))>0.0001,ABS(I12-H12)>0.0001,I$10>$C$5),4,IF(H50=4,3,IF(H50=3,2,IF(H50=2,1,0)))) -> 0 | J50: =IF(AND(ABS((J12-I12)-('Baseline NFPC'!J12-'Baseline NFPC'!I12))>0.0001,ABS(J12-I12)>0.0001,J$10>$C$5),4,IF(I50=4,3,IF(I50=3,2,IF(I50=2,1,0)))) -> 0 | K50: =IF(AND(ABS((K12-J12)-('Baseline NFPC'!K12-'Baseline NFPC'!J12))>0.0001,ABS(K12-J12)>0.0001,K$10>$C$5),4,IF(J50=4,3,IF(J50=3,2,IF(J50=2,1,0)))) -> 0 | L50: =IF(AND(ABS((L12-K12)-('Baseline NFPC'!L12-'Baseline NFPC'!K12))>0.0001,ABS(L12-K12)>0.0001,L$10>$C$5),4,IF(K50=4,3,IF(K50=3,2,IF(K50=2,1,0)))) -> 0 | ... U50: =IF(AND(ABS((U12-T12)-('Baseline NFPC'!U12-'Baseline NFPC'!T12))>0.0001,ABS(U12-T12)>0.0001,U$10>$C$5),4,IF(T50=4,3,IF(T50=3,2,IF(T50=2,1,0)))) -> 0
B51: OG intermediate auxiliary value | C51: 0 | D51: =IF(C50=4,2/3*(C30-'Baseline NFPC'!C29),IF(C50=3,1/3*(#REF!-'Baseline NFPC'!#REF!),0)) -> 0 | E51: =IF(D50=4,2/3*(D30-'Baseline NFPC'!D29),IF(D50=3,1/3*(C30-'Baseline NFPC'!C29),0)) -> 0 | F51: =IF(E50=4,2/3*(E30-'Baseline NFPC'!E29),IF(E50=3,1/3*(D30-'Baseline NFPC'!D29),0)) -> 0 | G51: =IF(F50=4,2/3*F30,IF(F50=3,1/3*E30,0)) -> 0 | H51: =IF(G50=4,2/3*G30,IF(G50=3,1/3*F30,0)) -> 0 | I51: =IF(H50=4,2/3*H30,IF(H50=3,1/3*G30,0)) -> 0 | J51: =IF(I50=4,2/3*I30,IF(I50=3,1/3*H30,0)) -> 0 | K51: =IF(J50=4,2/3*J30,IF(J50=3,1/3*I30,0)) -> 0 | L51: =IF(K50=4,2/3*K30,IF(K50=3,1/3*J30,0)) -> 0 | M51: =IF(L50=4,2/3*L30,IF(L50=3,1/3*K30,0)) -> 0 | N51: =IF(M50=4,2/3*M30,IF(M50=3,1/3*L30,0)) -> 0 | ... U51: =IF(T50=4,2/3*T30,IF(T50=3,1/3*S30,0)) -> 0
B52: GDP intermediate growth rate - only feedback effect and no closure of the OG | C52: 0 | D52: ='Input data'!D30-$C$47*((D12-C12)-('Input data'!D13-'Input data'!C13)) -> 1.69667 | E52: ='Input data'!E30-$C$47*(E12-D12) -> 1.273747 | F52: ='Input data'!F30-$C$47*(F12-E12) -> 1.581865 | G52: ='Input data'!G30-$C$47*(G12-F12) -> 1.521399 | H52: ='Input data'!H30-$C$47*(H12-G12) -> 1.41368 | I52: ='Input data'!I30-$C$47*(I12-H12) -> 1.393831 | J52: ='Input data'!J30-$C$47*(J12-I12) -> 1.069126 | K52: ='Input data'!K30-$C$47*(K12-J12) -> 1.03431 | L52: ='Input data'!L30-$C$47*(L12-K12) -> 1.012531 | ... U52: ='Input data'!U30-$C$47*(U12-T12) -> 1.710004
B54: Debt projections
...

Sheet Adjust. no safeguard
B3: Country | C3: ='Input data'!C3 -> NL
B4: Key years
B5: ='Input data'!B5 -> Last year before the adjustment | C5: =+'Input data'!C5 -> 2025
B6: Last year of adjustment | C6: =+C5+'Criteria results'!$F$5 -> 2029
B7: Last year of no-fiscal-policy-change projections | C7: =C5+'Criteria results'!$F$5+10 -> 2039
B9: Key assumptions
C10: ='Input data'!$C$5-1 -> 2024 | D10: =C10+1 -> 2025 | E10: =D10+1 -> 2026 | F10: =E10+1 -> 2027 | G10: =F10+1 -> 2028 | H10: =G10+1 -> 2029 | I10: =H10+1 -> 2030 | J10: =I10+1 -> 2031 | K10: =J10+1 -> 2032 | ... U10: =T10+1 -> 2042
B11: Fiscal assumptions (% of GDP)
B12: Structural primary balance ('+' means 'surplus') | C12: ='Input data'!C13 -> 0.386237 | D12: ='Input data'!D13 -> -0.5577395 | E12: =IF(E10<=$C$6,D12+'Criteria results'!$F$7,D12) -> -0.5577395 | F12: =IF(F10<=$C$6,E12+'Criteria results'!$F$7,E12) -> -0.5577395 | G12: =IF(G10<=$C$6,F12+'Criteria results'!$F$7,F12) -> -0.5577395 | H12: =IF(H10<=$C$6,G12+'Criteria results'!$F$7,G12) -> -0.5577395 | I12: =IF(I10<=$C$6,H12+'Criteria results'!$F$7,H12) -> -0.5577395 | J12: =IF(J10<=$C$6,I12+'Criteria results'!$F$7,I12) -> -0.5577395 | K12: =IF(K10<=$C$6,J12+'Criteria results'!$F$7,J12) -> -0.5577395 | L12: =K12 -> -0.5577395 | M12: =L12 -> -0.5577395 | N12: =M12 -> -0.5577395 | O12: =N12 -> -0.5577395 | P12: =O12 -> -0.5577395 | Q12: =P12 -> -0.5577395 | R12: =Q12 -> -0.5577395 | S12: =R12 -> -0.5577395 | ... U12: =T12 -> -0.5577395
B13: Annual change in SPB | E13: =E12-D12 -> 0 | F13: =F12-E12 -> 0 | G13: =G12-F12 -> 0 | H13: =H12-G12 -> 0 | I13: =I12-H12 -> 0 | J13: =J12-I12 -> 0 | K13: =K12-J12 -> 0 | L13: =L12-K12 -> 0 | ... U13: =U12-T12 -> 0
B14: One-off and other temporary measures | C14: ='Input data'!C14 -> -0.026727 | D14: ='Input data'!D14 -> -0.0254775 | E14: ='Input data'!E14 -> -0.6901042 | F14: ='Input data'!F14 -> 0 | G14: ='Input data'!G14 -> 0 | H14: ='Input data'!H14 -> 0 | I14: ='Input data'!I14 -> 0 | J14: ='Input data'!J14 -> 0 | ... U14: ='Input data'!U14 -> 0
B15: Stock flow adjustments (without exchange rate effect) | C15: ='Input data'!C15 -> -0.0919396 | D15: ='Input data'!D15 -> 1.579996 | E15: ='Input data'!E15 -> 2.014675 | F15: ='Input data'!F15 -> 0 | G15: ='Input data'!G15 -> 0 | H15: ='Input data'!H15 -> 0 | I15: ='Input data'!I15 -> 0 | J15: ='Input data'!J15 -> 0 | ... U15: ='Input data'!U15 -> 0
B17: ='Input data'!B19 -> Cost of ageing and selected public revenue (based on the Commission-Council 2024 Ageing Report ("AR 2024"))
B18: Total ageing cost (net of taxes on pensions) | C18: ='Input data'!C20 -> 18.2 | D18: ='Input data'!D20 -> 18.1 | E18: ='Input data'!E20 -> 18.1 | F18: ='Input data'!F20 -> 18.3 | G18: ='Input data'!G20 -> 18.4 | H18: ='Input data'!H20 -> 18.5 | I18: ='Input data'!I20 -> 18.6 | J18: ='Input data'!J20 -> 18.9 | ... U18: ='Input data'!U20 -> 20.2
B19: Property income | C19: ='Input data'!C26 -> 0.6265708 | D19: ='Input data'!D26 -> 0.6208305 | E19: ='Input data'!E26 -> 0.6150902 | F19: ='Input data'!F26 -> 0.6093498 | G19: ='Input data'!G26 -> 0.6036096 | H19: ='Input data'!H26 -> 0.5978693 | I19: ='Input data'!I26 -> 0.5921289 | J19: ='Input data'!J26 -> 0.5863886 | ... U19: ='Input data'!U26 -> 0.5232452
B21: GDP growth assumptions
B22: Actual GDP (real)
B23: Level | C23: ='Baseline NFPC'!C22 -> 915.5005 | D23: ='Baseline NFPC'!D22 -> 931.03352 | E23: =IF(AND(E50>1,D50>1), E27*(1+('Baseline NFPC'!E$29+E51)/100)-D23*$C$47*(E12-D12)/100, IF(E50=1,E27,D23*(1+E52/100))) -> 942.89253 | F23: =IF(AND(F50>1,E50>1), F27*(1+('Baseline NFPC'!F$29+F51)/100)-E23*$C$47*(F12-E12)/100, IF(F50=1,F27,E23*(1+F52/100))) -> 957.80782 | G23: =IF(AND(G50>1,F50>1), G27*(1+G51/100)-F23*$C$47*(G12-F12)/100, IF(G50=1,G27,F23*(1+G52/100))) -> 972.3799 | H23: =IF(AND(H50>1,G50>1), H27*(1+H51/100)-G23*$C$47*(H12-G12)/100, IF(H50=1,H27,G23*(1+H52/100))) -> 986.12624 | I23: =IF(AND(I50>1,H50>1), I27*(1+I51/100)-H23*$C$47*(I12-H12)/100, IF(I50=1,I27,H23*(1+I52/100))) -> 999.87117 | J23: =IF(AND(J50>1,I50>1), J27*(1+J51/100)-I23*$C$47*(J12-I12)/100, IF(J50=1,J27,I23*(1+J52/100))) -> 1010.5611 | K23: =IF(AND(K50>1,J50>1), K27*(1+K51/100)-J23*$C$47*(K12-J12)/100, IF(K50=1,K27,J23*(1+K52/100))) -> 1021.0134 | L23: =IF(AND(L50>1,K50>1), L27*(1+L51/100)-K23*$C$47*(L12-K12)/100, IF(L50=1,L27,K23*(1+L52/100))) -> 1031.3515 | M23: =IF(AND(M50>1,L50>1), M27*(1+M51/100)-L23*$C$47*(M12-L12)/100, IF(M50=1,M27,L23*(1+M52/100))) -> 1041.9392 | N23: =IF(AND(N50>1,M50>1), N27*(1+N51/100)-M23*$C$47*(N12-M12)/100, IF(N50=1,N27,M23*(1+N52/100))) -> 1052.9312 | ... U23: =IF(AND(U50>1,T50>1), U27*(1+U51/100)-T23*$C$47*(U12-T12)/100, IF(U50=1,U27,T23*(1+U52/100))) -> 1163.5727
B24: Growth rate | C24: ='Baseline NFPC'!C23 -> 1.081005 | D24: ='Baseline NFPC'!D23 -> 1.69667 | E24: =100*(E23/D23-1) -> 1.273747 | F24: =100*(F23/E23-1) -> 1.581865 | G24: =100*(G23/F23-1) -> 1.521399 | H24: =100*(H23/G23-1) -> 1.41368 | I24: =100*(I23/H23-1) -> 1.393831 | J24: =100*(J23/I23-1) -> 1.069126 | K24: =100*(K23/J23-1) -> 1.03431 | L24: =100*(L23/K23-1) -> 1.012531 | ... U24: =100*(U23/T23-1) -> 1.710004
B26: Potential GDP (real)
B27: Level | C27: ='Input data'!C34 -> 924.6414 | D27: =+C27*(1+'Input data'!D33/100) -> 939.95618 | E27: =+D27*(1+'Input data'!E33/100) -> 953.36237 | F27: =+E27*(1+'Input data'!F33/100) -> 965.68823 | G27: =+F27*(1+'Input data'!G33/100) -> 977.69888 | H27: =+G27*(1+'Input data'!H33/100) -> 988.81595 | I27: =+H27*(1+'Input data'!I33/100) -> 999.87118 | J27: =+I27*(1+'Input data'!J33/100) -> 1010.5611 | K27: =+J27*(1+'Input data'!K33/100) -> 1021.0134 | ... U27: =+T27*(1+'Input data'!U33/100) -> 1163.5726
B29: Output gap
B30: Output gap | C30: =100*(C23/C27-1) -> -0.98858866 | D30: =100*(D23/D27-1) -> -0.94926316 | E30: =100*(E23/E27-1) -> -1.0982012 | F30: =100*(F23/F27-1) -> -0.8160408 | G30: =100*(G23/G27-1) -> -0.54403071 | H30: =100*(H23/H27-1) -> -0.27201359 | I30: =100*(I23/I27-1) -> -9.9246313e-07 | J30: =100*(J23/J27-1) -> -2.9713068e-06 | ... U30: =100*(U23/U27-1) -> 6.9328616e-06
B32: Actual GDP (nominal, national currency)
B33: Growth rate | C33: =100*((1+C24/100)*(1+C42/100)-1) -> 6.8873142 | D33: =100*((1+D24/100)*(1+D42/100)-1) -> 4.9045765 | E33: =100*((1+E24/100)*(1+E42/100)-1) -> 4.5782425 | F33: =100*((1+F24/100)*(1+F42/100)-1) -> 3.7184496 | G33: =100*((1+G24/100)*(1+G42/100)-1) -> 3.6791337 | H33: =100*((1+H24/100)*(1+H42/100)-1) -> 3.5915233 | I33: =100*((1+I24/100)*(1+I42/100)-1) -> 3.5936418 | J33: =100*((1+J24/100)*(1+J42/100)-1) -> 3.2842141 | ... U33: =100*((1+U24/100)*(1+U42/100)-1) -> 3.9293163
B35: Interest rates
B36: Nominal implicit interest rate on debt | C36: ='Input data'!C37 -> 1.646586 | D36: ='Input data'!D37 -> 1.72 | E36: ='Input data'!E37 -> 1.732298 | F36: =F101 -> 1.8261287 | G36: =G101 -> 1.9630297 | H36: =H101 -> 2.0990021 | I36: =I101 -> 2.234119 | J36: =J101 -> 2.3707683 | K36: =K101 -> 2.5163135 | L36: =L101 -> 2.6668445 | M36: =M101 -> 2.8190428 | ... U36: =U101 -> 3.5460259
B37: Long-term interest rate | C37: ='Input data'!C$39 -> 2.6205 | D37: ='Input data'!D$39 -> 2.78965 | E37: ='Input data'!E$39 -> 2.894953 | F37: ='Input data'!F$39 -> 3.081676 | G37: ='Baseline NFPC'!G36 -> 3.188669 | H37: ='Baseline NFPC'!H36 -> 3.295662 | I37: ='Baseline NFPC'!I36 -> 3.402655 | J37: ='Baseline NFPC'!J36 -> 3.509648 | K37: ='Baseline NFPC'!K36 -> 3.616641 | L37: ='Baseline NFPC'!L36 -> 3.723634 | M37: ='Baseline NFPC'!M36 -> 3.830627 | N37: ='Baseline NFPC'!N36 -> 3.93762 | ... U37: ='Baseline NFPC'!U36 -> 3.959453
B38: Short-term interest rate | C38: ='Input data'!C$38 -> 3.570833 | D38: ='Input data'!D$38 -> 2.172583 | E38: ='Input data'!E$38 -> 1.91225 | F38: ='Input data'!F$38 -> 2.024375 | G38: ='Baseline NFPC'!G37 -> 2.1784319 | H38: ='Baseline NFPC'!H37 -> 2.3324888 | I38: ='Baseline NFPC'!I37 -> 2.4865456 | J38: ='Baseline NFPC'!J37 -> 2.6406025 | K38: ='Baseline NFPC'!K37 -> 2.7946594 | L38: ='Baseline NFPC'!L37 -> 2.9487163 | M38: ='Baseline NFPC'!M37 -> 3.1027731 | N38: ='Baseline NFPC'!N37 -> 3.25683 | ... U38: ='Baseline NFPC'!U37 -> 2.8169395
B39: Share of long-term debt that matures every year | C39: ='Baseline NFPC'!C38 -> 0.08837902 | D39: ='Baseline NFPC'!D38 -> 0.05460046 | E39: ='Baseline NFPC'!E38 -> 0.05795577 | F39: ='Baseline NFPC'!F38 -> 0.061311081 | G39: ='Baseline NFPC'!G38 -> 0.064666392 | H39: ='Baseline NFPC'!H38 -> 0.068021703 | I39: ='Baseline NFPC'!I38 -> 0.071377014 | J39: ='Baseline NFPC'!J38 -> 0.074732326 | ... U39: ='Baseline NFPC'!U38 -> 0.08815357
B41: Inflation and exchange rate
B42: GDP deflator (National currency) | C42: ='Input data'!C42 -> 5.744214 | D42: ='Input data'!D42 -> 3.154387 | E42: ='Input data'!E42 -> 3.262934 | F42: ='Input data'!F42 -> 2.103313 | G42: ='Baseline NFPC'!G41 -> 2.1253989 | H42: ='Baseline NFPC'!H41 -> 2.1474847 | I42: ='Baseline NFPC'!I41 -> 2.1695706 | J42: ='Baseline NFPC'!J41 -> 2.1916565 | K42: ='Baseline NFPC'!K41 -> 2.2137424 | L42: ='Baseline NFPC'!L41 -> 2.2358282 | M42: ='Baseline NFPC'!M41 -> 2.2579141 | N42: ='Baseline NFPC'!N41 -> 2.28 | ... U42: ='Baseline NFPC'!U41 -> 2.182
B43: Exchange rate composite change (weighted by share of debt in each currency) | C43: ='Baseline NFPC'!C42 -> 0.9999999 | D43: ='Baseline NFPC'!D42 -> 1 | E43: ='Baseline NFPC'!E42 -> 1 | F43: ='Baseline NFPC'!F42 -> 0.9999999 | G43: ='Baseline NFPC'!G42 -> 1 | H43: ='Baseline NFPC'!H42 -> 1 | I43: ='Baseline NFPC'!I42 -> 1 | J43: ='Baseline NFPC'!J42 -> 1 | ... U43: ='Baseline NFPC'!U42 -> 1
B45: Intermediate calculations (growth rate equation)
B47: Fiscal multiplier | C47: ='Input data'!C49 -> 0.6
B48: Budget balance semi-elasticity | C48: ='Input data'!C50 -> 0.605
B50: Auxiliary variable to control the closure of the output gap | C50: 0 | D50: =IF(AND(ABS((D12-C12)-('Input data'!D13-'Input data'!C13))>0.0001,ABS(D12-C12)>0.0001,D$10>$C$5),4,IF(C50=4,3,IF(C50=3,2,IF(C50=2,1,0)))) -> 0 | E50: =IF(AND(ABS((E12-D12)-('Baseline NFPC'!E12-'Baseline NFPC'!D12))>0.0001,ABS(E12-D12)>0.0001,E$10>$C$5),4,IF(D50=4,3,IF(D50=3,2,IF(D50=2,1,0)))) -> 0 | F50: =IF(AND(ABS((F12-E12)-('Baseline NFPC'!F12-'Baseline NFPC'!E12))>0.0001,ABS(F12-E12)>0.0001,F$10>$C$5),4,IF(E50=4,3,IF(E50=3,2,IF(E50=2,1,0)))) -> 0 | G50: =IF(AND(ABS((G12-F12)-('Baseline NFPC'!G12-'Baseline NFPC'!F12))>0.0001,ABS(G12-F12)>0.0001,G$10>$C$5),4,IF(F50=4,3,IF(F50=3,2,IF(F50=2,1,0)))) -> 0 | H50: =IF(AND(ABS((H12-G12)-('Baseline NFPC'!H12-'Baseline NFPC'!G12))>0.0001,ABS(H12-G12)>0.0001,H$10>$C$5),4,IF(G50=4,3,IF(G50=3,2,IF(G50=2,1,0)))) -> 0 | I50: =IF(AND(ABS((I12-H12)-('Baseline NFPC'!I12-'Baseline NFPC'!H12))>0.0001,ABS(I12-H12)>0.0001,I$10>$C$5),4,IF(H50=4,3,IF(H50=3,2,IF(H50=2,1,0)))) -> 0 | J50: =IF(AND(ABS((J12-I12)-('Baseline NFPC'!J12-'Baseline NFPC'!I12))>0.0001,ABS(J12-I12)>0.0001,J$10>$C$5),4,IF(I50=4,3,IF(I50=3,2,IF(I50=2,1,0)))) -> 0 | K50: =IF(AND(ABS((K12-J12)-('Baseline NFPC'!K12-'Baseline NFPC'!J12))>0.0001,ABS(K12-J12)>0.0001,K$10>$C$5),4,IF(J50=4,3,IF(J50=3,2,IF(J50=2,1,0)))) -> 0 | L50: =IF(AND(ABS((L12-K12)-('Baseline NFPC'!L12-'Baseline NFPC'!K12))>0.0001,ABS(L12-K12)>0.0001,L$10>$C$5),4,IF(K50=4,3,IF(K50=3,2,IF(K50=2,1,0)))) -> 0 | ... U50: =IF(AND(ABS((U12-T12)-('Baseline NFPC'!U12-'Baseline NFPC'!T12))>0.0001,ABS(U12-T12)>0.0001,U$10>$C$5),4,IF(T50=4,3,IF(T50=3,2,IF(T50=2,1,0)))) -> 0
B51: OG intermediate auxiliary value | C51: 0 | D51: =IF(C50=4,2/3*(C30-'Baseline NFPC'!C29),IF(C50=3,1/3*(#REF!-'Baseline NFPC'!#REF!),0)) -> 0 | E51: =IF(D50=4,2/3*(D30-'Baseline NFPC'!D29),IF(D50=3,1/3*(C30-'Baseline NFPC'!C29),0)) -> 0 | F51: =IF(E50=4,2/3*(E30-'Baseline NFPC'!E29),IF(E50=3,1/3*(D30-'Baseline NFPC'!D29),0)) -> 0 | G51: =IF(F50=4,2/3*F30,IF(F50=3,1/3*E30,0)) -> 0 | H51: =IF(G50=4,2/3*G30,IF(G50=3,1/3*F30,0)) -> 0 | I51: =IF(H50=4,2/3*H30,IF(H50=3,1/3*G30,0)) -> 0 | J51: =IF(I50=4,2/3*I30,IF(I50=3,1/3*H30,0)) -> 0 | K51: =IF(J50=4,2/3*J30,IF(J50=3,1/3*I30,0)) -> 0 | L51: =IF(K50=4,2/3*K30,IF(K50=3,1/3*J30,0)) -> 0 | M51: =IF(L50=4,2/3*L30,IF(L50=3,1/3*K30,0)) -> 0 | N51: =IF(M50=4,2/3*M30,IF(M50=3,1/3*L30,0)) -> 0 | ... U51: =IF(T50=4,2/3*T30,IF(T50=3,1/3*S30,0)) -> 0
